28800538 A b S 44.26 100
28800562 A c B 44.10 100
28800744 R b 100
28800758 A d B 44.18 157
28800773 A e S 44.38 100
28800796 R d 157
28800812 A f B 44.18 157
28800974 A g S 44.27 100
28800975 R e 100
28812071 R f 157
28813129 A h B 43.68 50
28813830 A i S 44.18 100
28814087 A j S 44.18 1000
28814834 R c 100
28814864 A k B 44.09 100
28815774 R k 100
28815804 A l B 44.07 100
28815937 R j 1000
28816244 R l 100
28816245 A m S 44.22 100
28816245 R g 100
28816273 A n B 44.03 100
28817570 A o S 44.14 170
28822172 R o 20
28823984 A p B 44.04 100
28823984 R n 100
28824454 R p 100
28824484 A q B 44.03 100
28826314 R q 100
28826343 A r B 43.89 100
28826384 R r 100
28826414 A s B 43.78 100
28826424 R s 100
28826454 A t B 43.75 100
28826455 R t 100
28826485 A u B 43.72 100
28835564 A v B 43.85 100
28835565 R u 100
28838797 A w S 44.15 500
28841307 A x S 44.40 100
28845097 A y S 44.10 500
28845547 R i 100
28845606 A z S 44.13 100
28854850 R w 500
28855165 A ab B 43.91 100
28855165 R v 100
28860037 A bb S 44.16 2000
28861264 A cb S 44.17 100
28861264 R m 100
28864794 A db S 44.11 100
28864794 R cb 100
28864870 A eb S 44.14 500
28865273 A fb S 44.10 100
28867484 R db 100
28867513 A gb S 44.17 100
28869845 A hb B 43.92 100
28873954 A ib S 44.11 100
28873954 R gb 100
28874354 R ab 100
28874384 A jb B 43.78 100
28875094 A kb S 44.11 100
28875094 R ib 100
28875613 R fb 100
28876376 R hb 100
28876444 R jb 100
28876474 A lb B 43.72 100
28876679 A mb B 43.85 400
28877234 A nb S 44.16 500
28882205 A ob B 43.73 100
28882205 R lb 100
28887878 R mb 400
28888674 R kb 100
28888703 A pb S 44.11 100
28890455 A qb B 43.73 100
28890455 R ob 100
28893420 A rb S 44.04 100
28893682 A sb B 43.86 100
28900102 R rb 100
28900102 A tb B 44.04 400
28900174 A ub B 43.90 100
28900175 R qb 100
28901422 R tb 200
28902467 R tb 200
28902514 A vb S 44.05 100
28902515 R pb 100
28902534 R ub 100
28902571 A wb B 43.79 100
28903189 A xb B 43.92 100
28903190 A yb S 44.05 100
28903191 R xb 100
28903191 R yb 100
28903215 A zb B 43.92 100
28903217 A ac S 44.05 100
28903224 A bc B 43.85 100
28903224 R wb 100
28903234 R bc 100
28903281 A cc B 43.85 100
28903874 R vb 100
28903903 A dc S 44.11 100
28904189 R zb 100
28904189 R ac 100
28904224 R cc 100
28904253 A ec B 43.79 100
28906024 A fc B 43.85 100
28906024 R ec 100
28910721 A gc S 44.04 81
28910722 R gc 81
28910723 A hc S 44.04 81
28910744 A ic S 44.05 100
28910744 R dc 100
28910934 A jc B 43.85 100
28910934 R fc 100
28911618 R y 500
28912942 R eb 500
28912943 R hc 81
28912944 A kc S 43.98 81
28917479 R kc 5
28917481 A lc B 43.93 100
28917481 A mc S 44.04 100
28917483 R lc 100
28917483 R mc 100
28917524 A nc B 43.86 100
28917525 R jc 100
28917525 R nc 100
28917531 A oc B 43.93 100
28917539 A pc S 44.04 100
28917581 A qc B 43.86 100
28918102 A rc B 43.92 100
28918103 R pc 100
28918132 A sc S 44.04 100
28918662 R oc 100
28918687 A tc B 43.92 100
28918703 R qc 100
28918733 A uc B 43.85 100
28919172 R kc 76
28919173 R tc 100
28919173 R sc 100
28919173 A vc S 43.98 76
28919248 A wc B 43.91 100
28919260 A xc S 44.03 100
28919822 R vc 76
28919823 A yc S 43.98 76
28922492 R wc 100
28922492 R xc 100
28923035 R yc 76
28923083 R ic 100
28923113 A zc S 44.11 100
28923389 A ad B 43.93 60
28923389 A bd S 44.04 81
28923390 R ad 60
28923390 R bd 81
28923391 A cd B 43.93 60
28923391 A dd S 44.04 81
28923830 A ed B 43.93 100
28923831 R ed 100
28923832 A fd B 43.93 100
28924703 R bb 2000
28924704 R cd 60
28924704 R dd 81
28924704 R fd 100
28924705 A gd S 44.04 81
28924706 A hd B 43.93 60
28924706 A id B 43.93 100
28925782 R gd 81
28925782 R id 100
28925782 R hd 60
28925783 A jd S 44.04 81
28925784 A kd B 43.93 60
28925784 A ld B 43.93 100
28927133 R jd 81
28927133 R kd 60
28927134 A md S 44.04 81
28927135 A nd B 43.93 60
28928212 R nd 60
28928212 R md 81
28928213 A od B 43.93 60
28928213 A pd S 44.04 81
28929118 R pd 50
28929120 A qd B 43.93 100
28929120 A rd S 44.04 100
28929121 R ld 100
28929121 R pd 31
28929121 R qd 100
28929121 R rd 100
28929122 R od 60
28929122 A sd B 43.93 100
28929123 A td S 44.05 31
28929123 A ud B 43.93 60
28929128 A vd S 44.04 100
28929146 A wd B 43.93 100
28929155 A xd B 43.86 100
28929155 R uc 100
28929155 A yd S 44.11 100
28929156 R zc 100
28929164 R xd 100
28929164 R yd 100
28929214 A zd B 43.86 100
28929214 A ae S 44.11 100
28929949 R vd 100
28929949 R wd 100
28929954 A be B 43.86 100
28929955 R zd 100
28929980 R ud 60
28929981 R td 31
28929984 R ae 100
28930015 A ce S 44.11 100
28933055 A de B 43.94 400
28933056 R sd 100
28933058 A ee B 43.95 100
28933092 R ee 100
28933093 A fe B 43.95 100
28937566 A ge S 44.04 50
28937567 R fe 100
28937568 A he B 43.97 100
28937974 R he 100
28937976 A ie B 43.97 100
28938015 R ie 100
28938016 A je B 43.97 100
28939184 R h 50
28939185 R je 100
28939187 A ke B 43.97 100
28939244 A le B 43.86 50
28941591 R ke 100
28941592 A me B 43.98 100
28948444 A ne B 43.86 100
28948445 R be 100
28952850 R me 100
28953184 A oe S 44.05 100
28953185 R ce 100
28955224 R ne 100
28955254 A pe B 43.86 100
28956124 R oe 100
28956154 A qe S 44.11 100
28957556 R de 200
28974593 R de 150
28976148 R de 50
28981445 A re B 43.86 100
28981445 R pe 100
28982578 A se B 43.94 300
28983065 A te S 44.09 100
28983065 R qe 100
28987148 A ue B 43.94 100
28990475 A ve B 43.95 100
29005959 A we B 43.50 100
29013204 R ve 100
29013204 A xe S 43.95 400
29015549 R xe 400
29019177 R se 300
29019435 R ue 100
29024925 A ye B 43.88 100
29024925 R re 100
29026323 A ze S 44.04 100
29029845 A af B 43.88 100
29029845 R ye 100
29045384 A bf B 43.91 100
29045385 R af 100
29049454 R te 100
29049484 A cf S 44.11 100
29060700 R ze 100
29062694 A df B 43.92 100
29062695 R bf 100
29063604 R ge 50
29065594 R cf 100
29065624 A ef S 44.22 100
29066524 A ff B 43.92 100
29066525 R df 100
29067445 A gf B 43.92 100
29067445 R ff 100
29067603 A hf B 44.00 100
29067714 A if B 43.92 100
29067715 R gf 100
29067928 A jf B 44.00 100
29067985 A kf B 43.93 100
29067985 R if 100
29069573 A lf B 44.01 400
29070543 R hf 100
29070543 R jf 100
29070584 R kf 100
29070614 A mf B 43.92 100
29071194 A nf S 44.20 100
29071195 R ef 100
29078429 R sb 100
29078945 A of B 43.94 100
29078945 R mf 100
29083415 R nf 100
29083444 A pf S 44.22 100
29084145 A qf S 44.20 100
29084145 R pf 100
29088664 R qf 100
29088694 A rf S 44.22 100
29090034 A sf B 43.98 100
29090034 R of 100
29090062 R o 150
29091138 R lf 400
29098404 A tf S 44.20 100
29098404 R rf 100
29099784 A uf S 44.20 100
29099784 R tf 100
29104225 A vf S 44.19 100
29104225 R uf 100
29109165 A wf S 44.12 150
29116414 A xf S 44.12 500
29117069 A yf S 44.04 100
29117070 R yf 100
29117135 A zf S 44.18 100
29117135 R vf 100
29117174 R zf 100
29117204 A ag S 44.19 100
29126335 A bg S 44.19 100
29126335 R ag 100
29133152 A cg S 44.30 500
29136274 R bg 100
29136303 A dg S 44.19 100
29136445 A eg S 44.18 100
29136445 R dg 100
29140244 R eg 100
29140273 A fg S 44.19 100
29141555 A gg S 44.19 100
29141555 R fg 100
29144384 R gg 100
29144414 A hg S 44.19 100
29147554 A ig S 45.84 300
29155635 A jg S 44.19 100
29155635 R hg 100
29179978 A kg B 41.04 2
29190750 A lg B 41.04 2
29206262 R wf 150
29219025 A mg S 44.19 100
29219025 R jg 100
29221124 R mg 100
29221154 A ng S 44.19 100
29224214 R ng 100
29224244 A og S 44.19 100
29225758 A pg S 44.12 150
29226149 R pg 100
29226939 A qg B 44.05 300
29232295 A rg B 43.99 100
29232295 R sf 100
29236024 A sg S 49.44 2
29236995 A tg B 42.24 80
29238859 A ug S 49.44 2
29240461 A vg B 43.80 15
29241255 A wg S 44.12 100
29241921 A xg S 44.12 60
29256301 A yg B 44.06 100
29259595 A zg S 44.19 100
29259595 R og 100
29262844 R rg 100
29262874 A ah B 43.98 100
29263514 A bh B 43.99 100
29263515 R ah 100
29271045 A ch S 44.17 100
29271045 R zg 100
29272061 R wg 100
29272114 R bh 100
29272143 A dh B 43.98 100
29272625 A eh S 44.17 100
29272625 R ch 100
29272774 A fh S 44.17 100
29272775 R eh 100
29273935 A gh S 44.17 100
29273935 R fh 100
29278024 R yg 100
29278034 A hh B 44.05 100
29281492 A ih B 44.07 100
29282634 A jh S 44.17 100
29282634 R gh 100
29283205 A kh S 44.17 100
29283205 R jh 100
29284714 A lh S 44.16 100
29284715 R kh 100
29285355 A mh S 44.16 100
29285355 R lh 100
29286785 A nh S 44.16 100
29286786 R mh 100
29287644 A oh S 44.16 100
29287644 R nh 100
29288754 A ph S 44.16 100
29288755 R oh 100
29289475 A qh S 44.16 100
29289475 R ph 100
29290764 A rh S 44.16 100
29290765 R qh 100
29291334 A sh S 44.16 100
29291334 R rh 100
29293884 R ih 50
29293884 R ih 50
29296024 A th S 44.16 100
29296025 R sh 100
29302574 R th 100
29302603 A uh S 44.16 100
29303335 A vh S 44.16 100
29303335 R uh 100
29304904 R vh 100
29304934 A wh S 44.16 100
29305665 A xh S 44.16 100
29305665 R wh 100
29307345 A yh S 44.15 100
29307346 R xh 100
29308352 R hh 100
29308377 A zh B 44.08 100
29308394 R yh 100
29308424 A ai S 44.17 100
29309396 R zh 100
29309408 A bi B 44.08 100
29314590 R bi 100
29314601 A ci B 44.05 100
29318624 R qg 200
29322365 A di S 44.16 100
29322365 R ai 100
29323737 A ei S 44.09 50
29324648 R ei 50
29326854 A fi S 44.16 100
29326854 R di 100
29328094 R fi 100
29328124 A gi S 44.16 100
29328735 A hi B 43.98 100
29328735 R dh 100
29337321 R ci 100
29337368 A ii B 44.09 100
29337383 R gi 100
29337413 A ji S 44.17 100
29338284 R hi 100
29338314 A ki B 43.98 100
29341959 A li B 44.09 100
29343924 R ii 100
29343934 A mi B 44.05 100
29346427 R li 100
29350454 A ni B 43.99 100
29350455 R ki 100
29351884 A oi B 43.99 100
29351884 R ni 100
29353141 A pi B 44.06 100
29354031 R pi 100
29354094 R oi 100
29354124 A qi B 43.99 100
29354724 A ri B 43.99 100
29354724 R qi 100
29354780 A si B 44.06 100
29356556 R si 100
29357468 A ti B 44.06 100
29358874 R ri 100
29358904 A ui B 43.99 100
29359844 A vi S 44.17 100
29359845 R ji 100
29363904 R vi 100
29363934 A wi S 44.17 100
29365434 A xi B 43.99 100
29365435 R ui 100
29366928 R ti 100
29367565 R xi 100
29367594 A yi B 43.99 100
29368365 A zi S 44.17 100
29368365 R wi 100
29369897 A aj B 44.07 100
29371172 R aj 100
29373350 R mi 100
29373360 A bj B 44.04 100
29375576 A cj S 44.21 100
29384543 R bj 100
29384548 A dj B 44.03 100
29388641 R dj 100
29388647 A ej B 43.97 100
29392557 A fj S 44.10 50
29394874 R yi 100
29394904 A gj B 43.98 100
29397274 A hj B 43.20 100
29399803 R fj 50
29399844 R zi 100
29399874 A ij S 44.17 100
29400645 A jj S 44.17 100
29400645 R ij 100
29401924 R jj 100
29401954 A kj S 44.17 100
29402065 A lj B 43.99 100
29402065 R gj 100
29407806 A mj S 44.17 100
29407806 R kj 100
29409974 R mj 100
29410005 A nj S 44.17 100
29410625 A oj B 43.99 100
29410625 R lj 100
29411364 R oj 100
29411394 A pj B 43.99 100
29412025 A qj S 44.17 100
29412025 R nj 100
29416894 R pj 100
29416923 A rj B 43.98 100
29416966 A sj S 44.37 100
29421845 A tj S 44.17 100
29421845 R qj 100
29422934 A uj S 44.17 100
29422935 R tj 100
29426695 A vj S 44.12 150
29429655 A wj S 44.16 100
29429655 R uj 100
29435750 A xj B 43.68 100
29436397 R qg 100
29437344 R rj 100
29437374 A yj B 43.97 100
29437874 R yj 100
29437904 A zj B 43.91 100
29441385 A ak S 44.13 100
29441385 R wj 100
29444334 R ak 100
29444364 A bk S 44.16 100
29445475 A ck S 44.13 100
29445475 R bk 100
29454849 R ej 100
29454855 A dk B 43.98 100
29455544 A ek B 43.92 100
29455545 R zj 100
29456635 A fk B 43.92 100
29456635 R ek 100
29463988 A gk S 44.04 75
29465031 A hk B 43.98 200
29469726 A ik S 44.11 33
29471086 R dk 100
29471095 A jk B 43.99 100
29472354 R ck 100
29472354 R fk 100
29472384 A kk S 44.17 100
29472385 A lk B 43.92 100
29473515 A mk S 44.11 100
29473515 R kk 100
29473934 R mk 100
29473964 A nk S 44.17 100
29474605 A ok B 43.92 100
29474605 R lk 100
29475914 R ok 100
29475944 A pk B 43.92 100
29476374 A qk B 43.94 100
29476375 R pk 100
29477737 R gk 75
29478615 A rk B 43.94 100
29478615 R qk 100
29492046 R x 100
29492106 A sk S 44.10 100
29495145 R rk 100
29495175 A tk B 43.94 100
29497034 A uk S 44.11 100
29497035 R nk 100
29497133 R pg 50
29497254 A vk B 43.94 100
29497255 R tk 100
29497984 R vk 100
29498015 A wk B 43.94 100
29498634 R wk 100
29498664 A xk B 43.92 100
29499715 A yk S 44.04 100
29499815 A zk S 44.11 100
29499815 R uk 100
29504428 R jk 100
29504474 R zk 100
29504479 R yk 100
29504480 A al S 44.04 100
29504492 R al 100
29504504 A bl S 44.11 100
29504554 R bl 100
29504583 A cl S 44.17 100
29508304 A dl B 43.93 100
29508305 R xk 100
29508865 A el B 43.93 100
29508865 R dl 100
29517026 A fl S 44.13 75
29523425 R el 100
29523454 A gl B 43.91 100
29526295 A hl B 43.92 100
29526295 R gl 100
29536772 A il S 44.03 100
29539105 A jl B 43.94 100
29539105 R hl 100
29541004 R jl 100
29541033 A kl B 43.92 100
29541474 A ll S 44.04 50
29545655 A ml S 44.11 100
29545655 R cl 100
29548360 R sk 100
29548420 A nl S 44.40 100
29553541 A ol S 44.04 40
29556917 R il 100
29557006 A pl B 43.99 1000
29567865 A ql B 44.00 100
29572151 R ql 100
29572675 A rl B 43.92 100
29572675 R kl 100
29576385 A sl B 43.91 100
29596424 R rl 100
29596455 A tl B 43.92 100
29603659 A ul B 43.80 200
29610229 R ll 50
29610264 R ml 100
29610294 A vl S 44.17 100
29610445 A wl B 43.97 100
29610445 R tl 100
29614426 R wl 100
29614456 A xl B 43.92 100
29624627 R ol 40
29625176 A yl B 43.97 100
29625176 R xl 100
29640243 A zl B 44.04 100
29641037 A am B 44.01 100
29654777 A bm B 43.92 200
29662924 R yl 100
29662954 A cm B 43.91 100
29663688 R pl 1000
29666995 A dm S 44.11 100
29666995 R vl 100
29667275 R dm 100
29667305 A em S 44.17 100
29677686 A fm B 43.20 150
29677756 R xf 500
29709325 A gm B 43.92 100
29709325 R cm 100
29711906 R am 100
29719371 A hm B 44.04 100
29729844 R em 100
29729874 A im S 44.17 100
29730065 A jm B 44.03 100
29730065 R gm 100
29733515 R jm 100
29733544 A km B 43.92 100
29733677 A lm S 44.17 100
29733677 R im 100
29733746 A mm B 44.04 100
29733746 A nm S 44.11 100
29733747 R nm 100
29733748 R mm 100
29733781 A om S 44.11 100
29733785 A pm B 43.97 100
29733785 R km 100
29733786 R pm 100
29733786 A qm B 44.04 100
29733817 A rm B 43.92 100
29733825 A sm B 43.97 100
29733825 R rm 100
29734123 R qm 100
29734123 R om 100
29734164 R sm 100
29734194 A tm B 43.92 100
29734475 R le 50
29734543 A um B 44.00 50
29735634 R lm 100
29735664 A vm S 44.17 100
29737185 A wm B 43.97 100
29737185 R tm 100
29760052 R zl 100
29760264 A xm B 44.04 100
29776911 R wm 100
29777383 R vm 100
29792133 A ym B 44.07 1000
29798038 R ym 1000
29798297 A zm B 44.09 100
29800648 A an B 44.07 200
29822073 R zm 100
29839382 A bn B 44.05 200
29839530 R an 200
29847386 A cn S 44.11 100
29864954 A dn S 44.11 100
29874343 A en B 44.07 200
29929249 A fn B 44.05 200
29964740 R en 200
29965088 R hm 100
30015010 A gn S 44.06 50
30023709 R bn 200
30024257 R gn 50
30027876 A hn S 44.06 50
30028024 A in B 43.97 100
30030672 A jn S 44.16 100
30030975 A kn S 44.15 100
30030975 R jn 100
30045029 R hn 50
30045116 A ln S 44.15 100
30045116 R kn 100
30052384 R ln 100
30052414 A mn S 44.15 100
30052945 A nn B 43.98 100
30052945 R in 100
30060644 R nn 100
30060674 A on B 43.97 100
30060845 A pn S 44.15 100
30060845 R mn 100
30062333 A qn B 44.05 100
30063555 A rn B 43.98 100
30063555 R on 100
30074752 R cn 100
30074758 A sn S 44.08 100
30077822 R qn 100
30079135 A tn B 43.98 100
30079135 R rn 100
30081154 R tn 100
30081184 A un B 43.97 100
30081305 A vn B 43.98 100
30081306 R un 100
30086992 A wn B 44.06 100
30088196 A xn B 43.98 100
30088196 R vn 100
30088435 R sn 100
30088549 R wn 100
30088584 R xn 100
30088614 A yn B 43.97 100
30146355 A zn B 44.01 100
30146355 R yn 100
30148205 R zn 100
30148235 A ao B 43.97 100
30148885 A bo B 43.98 100
30148885 R ao 100
30150685 R bo 100
30150714 A co B 43.97 100
30154487 A do S 44.07 50
30156052 R do 50
30163115 A eo B 43.99 100
30163115 R co 100
30165315 A fo B 43.99 100
30165315 R eo 100
30171175 A go B 43.99 100
30171175 R fo 100
30186345 A ho B 43.99 100
30186345 R go 100
30187354 R ho 100
30187384 A io B 43.99 100
30187856 A jo B 44.04 100
30193146 A ko B 43.99 100
30193146 R io 100
30219505 R ko 100
30219534 A lo B 43.99 100
30220886 A mo B 43.99 100
30220886 R lo 100
30226196 A no B 43.99 100
30226196 R mo 100
30244365 A oo B 44.06 25
30246242 R fn 200
30246301 A po B 44.06 200
30248135 R pn 100
30248165 A qo S 44.16 100
30248925 R no 100
30248955 A ro B 43.99 100
30268785 R qo 100
30268814 A so S 44.17 100
30269005 A to B 44.02 100
30269005 R ro 100
30275405 R so 100
30275435 A uo S 44.18 100
30282645 A vo S 44.17 100
30282645 R uo 100
30286325 R vo 100
30286355 A wo S 44.18 100
30294998 A xo B 43.80 50
30299174 A yo S 44.13 100
30309855 A zo B 44.03 100
30309855 R to 100
30311623 R dn 100
30326474 R wo 100
30326504 A ap S 44.22 100
30326525 A bp S 44.20 100
30326525 R ap 100
30326525 R bp 100
30326582 A cp S 44.22 100
30327852 R ik 33
30336205 A dp S 44.21 100
30336205 R cp 100
30339174 R dp 100
30339204 A ep S 44.22 100
30342296 A fp S 44.20 100
30342296 R ep 100
30344079 R yo 100
30346445 R fp 100
30346475 A gp S 44.21 100
30349823 R vj 150
30356595 A hp S 44.21 100
30356595 R gp 100
30359374 A ip B 44.10 1200
30360647 A jp B 44.10 100
30361623 A kp B 44.10 100
30361906 A lp S 44.20 100
30361906 R hp 100
30365915 R xg 60
30365955 R lp 100
30365985 A mp S 44.21 100
30366891 R jp 100
30366925 R mp 100
30366955 A np S 44.21 100
30367966 R kp 100
30368861 A op B 44.10 100
30368925 A pp B 44.03 100
30368925 R zo 100
30373365 A qp S 44.20 100
30373366 R np 100
30376561 R op 100
30376595 R pp 100
30376595 R qp 100
30376624 A rp B 44.03 100
30376625 A sp S 44.21 100
30377455 A tp B 44.03 100
30377455 R rp 100
30377705 A up S 44.20 100
30377706 R sp 100
30378195 R up 100
30378225 A vp S 44.21 100
30378836 R ip 1200
30378895 A wp S 44.20 100
30378895 R vp 100
30379865 A xp B 44.03 100
30379866 R tp 100
30380625 R wp 100
30380655 A yp S 44.21 100
30381854 R xp 100
30381884 A zp B 44.03 100
30382630 A aq S 45.60 600
30382655 A bq S 44.20 100
30382655 R yp 100
30383391 A cq S 44.13 100
30384350 A dq B 44.10 1200
30385024 R bq 100
30385054 A eq S 44.21 100
30385435 A fq B 44.03 100
30385435 A gq B 44.11 100
30385435 R zp 100
30385475 R fq 100
30385505 A hq B 44.03 100
30385545 A iq B 44.04 100
30385545 R hq 100
30385855 R gq 100
30385924 R iq 100
30385954 A jq B 44.03 100
30386785 R z 100
30386785 R fl 75
30386785 R cq 100
30386787 A kq S 44.13 100
30387006 R kq 100
30387008 A lq S 44.13 100
30387287 R lq 100
30388925 R eq 100
30388954 A mq S 44.27 100
30389565 A nq B 44.07 100
30389566 R jq 100
30391325 R nb 500
30391516 A oq B 44.09 100
30391516 R nq 100
30392095 A pq S 44.26 100
30392096 R mq 100
30394495 R oq 100
30394525 A qq B 44.03 100
30395687 A rq S 44.16 100
30398156 A sq B 44.04 100
30398156 R qq 100
30399215 A tq S 44.23 100
30399216 R pq 100
30402678 A uq B 44.10 100
30407006 R uq 100
30407008 A vq B 44.10 200
30407035 A wq B 44.04 100
30407035 R sq 100
30409575 R tq 100
30409605 A xq S 44.26 100
30411436 R vq 200
30411438 A yq B 44.12 300
30411465 A zq B 44.05 100
30411465 R wq 100
30412337 R yq 300
30412365 A ar B 44.07 100
30412366 R zq 100
30414054 A br B 44.14 400
30419350 R rq 100
30419375 A cr B 44.09 100
30419375 R ar 100
30419385 A dr S 44.19 100
30419505 R cr 100
30419534 A er B 44.07 100
30419635 A fr B 44.09 100
30419636 R er 100
30419672 A gr B 44.14 100
30420067 R dr 100
30420085 R xq 100
30420114 A hr S 44.27 100
30422845 R br 400
30426753 R gr 100
30426759 A ir S 44.35 4000
30428287 A jr S 44.22 100
30431804 A kr S 44.20 100
30433666 A lr S 44.20 100
30441489 R kr 100
30444979 A mr S 44.20 100
30445434 A nr B 43.20 50
30448870 A or B 44.09 100
30450760 R mr 100
30451439 A pr S 44.20 100
30451455 A qr S 44.27 100
30451455 R hr 100
30452055 A rr S 44.24 700
30455329 A sr S 44.22 100
30465393 R sr 100
30465526 A tr B 44.17 400
30467426 R pr 100
30467455 R qr 100
30467485 A ur S 44.27 100
30472026 A vr B 44.17 100
30475557 R vr 100
30484429 A wr S 44.19 100
30491596 A xr B 44.11 100
30491596 R fr 100
30491597 R wr 100
30499620 R jr 100
30501815 R tr 400
30501836 R dq 1200
30501837 A yr S 44.19 100
30501866 R xr 100
30501866 A zr S 44.26 100
30501866 R ur 100
30501895 A as B 44.09 100
30502116 R yr 100
30502145 R zr 100
30502176 A bs S 44.27 100
30505956 R aq 600
30505962 A cs S 45.60 600
30506308 A ds S 44.23 100
30509828 A es B 44.13 100
30509978 A fs B 44.16 100
30513385 R bs 100
30513415 A gs S 44.35 100
30513962 R lr 100
30514675 A hs B 44.19 100
30514677 R fs 100
30519385 A is S 44.27 100
30519386 R gs 100
30520807 R hs 100
30520809 A js B 44.16 100
30521515 R js 100
30523872 R oo 25
30525567 A ks B 44.16 100
30529205 A ls S 44.27 100
30529206 R is 100
30529935 R ls 100
30529964 A ms S 44.27 100
30530685 A ns S 44.27 100
30530685 R ms 100
30530704 R ns 100
30530741 A os S 44.27 100
30531906 R ks 100
30531909 A ps B 44.16 100
30531935 A qs B 44.10 100
30531935 R as 100
30532705 A rs B 44.16 200
30536935 R um 50
30537145 A ss S 44.27 100
30537146 R os 100
30537165 R ss 100
30537194 A ts S 44.27 100
30541262 R ds 100
30547835 R ts 100
30547865 A us S 44.35 100
30547875 R us 100
30547904 A vs S 44.35 100
30550646 R ps 100
30550675 A ws B 44.12 100
30550676 R qs 100
30552477 R cj 100
30552545 R vs 100
30552574 A xs S 44.35 100
30554665 R ws 100
30554695 A ys B 44.09 100
30554714 R ys 100
30554744 A zs B 44.09 100
30555095 A at S 44.28 100
30557195 A bt S 44.30 100
30557196 R xs 100
30558137 A ct S 44.24 100
30558592 A dt B 44.17 200
30559055 A et B 44.09 100
30559055 R zs 100
30559397 R et 100
30559845 R bt 100
30565980 R dt 200
30565982 A ft B 44.16 100
30566336 R ft 100
30568785 A gt B 44.17 200
30571107 A ht S 44.27 200
30571226 A it S 44.23 100
30571380 R ct 100
30571380 A jt S 44.23 100
30572105 A kt S 44.23 100
30572276 A lt B 44.17 1100
30574859 R lt 1100
30577797 R it 100
30577798 R kt 100
30578103 A mt S 44.23 100
30578244 R jt 100
30589788 A nt S 44.22 100
30592194 A ot B 44.18 1100
30597834 A pt S 44.22 200
30598481 R mt 100
30603241 A qt B 44.18 100
30603447 R qt 100
30614305 A rt B 44.19 100
30615238 R rt 100
30630340 A st S 44.22 100
30630350 R st 100
30639640 A tt S 44.22 100
30639658 R tt 100
30659102 A ut B 44.18 100
30661829 R ut 100
30676408 R ot 1100
30677490 R rr 700
30677580 A vt S 44.18 700
30678270 R gt 61
30678270 R gt 139
30678568 R vt 50
30679623 A wt S 44.18 100
30683544 R rs 200
30684128 A xt B 44.14 100
30684577 R wt 100
30684846 A yt S 44.16 300
30686813 R ht 200
30688574 R yt 300
30691203 R nl 100
30696218 A zt S 44.18 300
30696577 A au B 44.15 100
30697745 R zt 300
30704521 A bu B 44.04 700
30718190 A cu S 44.17 100
30719580 A du S 44.16 100
30719766 R du 100
30720363 R cu 100
30724876 A eu S 44.17 100
30725246 R eu 100
30726397 R au 100
30727961 R xt 100
30735257 A fu B 44.14 100
30735813 A gu S 44.16 300
30736803 R fu 100
30736893 A hu B 44.09 100
30737085 A iu B 44.09 100
30739585 R gu 300
30741208 R es 100
30741608 A ju B 44.13 100
30745174 R ju 100
30750434 R cs 600
30755219 R jo 100
30762848 A ku S 44.27 100
30771521 R hu 100
30771522 R iu 100
30773239 A lu B 44.12 100
30782070 A mu B 44.12 300
30784685 R po 200
30784764 A nu B 44.01 200
30798238 A ou B 44.04 100
30820683 R mu 300
30841205 R lu 100
30843913 A pu S 44.14 100
30862962 R pu 100
30863347 A qu S 44.14 100
30869373 R or 100
30869399 A ru B 44.07 100
30869416 R ru 100
30871646 R qu 100
30871649 A su S 44.14 100
30871731 A tu S 44.13 100
30871732 R su 100
30885727 A uu B 44.04 800
30886501 A vu B 44.07 100
30886505 R vu 100
30886648 A wu S 44.13 100
30887906 A xu B 44.08 100
30901373 R tu 100
30901374 R wu 100
30901375 R xu 100
30901377 A yu S 44.13 100
30901405 R yu 100
30903077 A zu B 44.08 100
30907182 A av S 44.11 100
30908512 R zu 100
30937443 A bv S 44.22 200
30965397 R ou 100
30965473 A cv B 44.08 100
30969802 R av 100
30974348 A dv B 44.08 100
30974348 A ev S 44.18 100
30979158 A fv S 44.13 100
30979177 R fv 100
30979179 A gv S 44.13 100
30981012 R dv 100
30981013 A hv B 44.04 100
30981013 R ev 100
30981013 A iv S 44.13 100
30981416 R hv 100
30981416 A jv B 44.08 100
30981526 R jv 3
30981998 R gv 100
30985996 R jv 97
30985996 A kv B 44.04 100
30988221 A lv S 44.12 400
30988222 R iv 100
30988222 A mv S 44.12 3
30988223 R lv 400
30989501 A nv S 44.11 100
30989501 R mv 3
30989502 A ov S 44.11 3
30997721 R nv 100
30997742 A pv S 44.12 200
30997796 R pv 200
30998460 A qv S 44.11 100
30998461 R ov 3
30998461 A rv S 44.11 3
31000121 R qv 100
31000651 A sv S 44.10 100
31000652 R rv 3
31000653 A tv S 44.10 3
31001160 R sv 100
31001694 A uv S 44.10 100
31001694 R tv 3
31001695 A vv S 44.10 3
31002191 R uv 100
31002739 A wv S 44.10 100
31002740 R vv 3
31002740 A xv S 44.10 3
31003294 R wv 100
31003860 A yv S 44.10 100
31003861 R xv 3
31003861 A zv S 44.10 3
31004222 R yv 100
31004235 R zv 3
31004235 A aw S 44.18 3
31005978 A bw S 44.11 100
31005979 R aw 3
31005979 A cw S 44.10 3
31013621 R cv 50
31019940 R bw 100
31022501 A dw S 44.11 100
31030267 R dw 100
31033164 R cv 50
31034427 A ew B 44.06 100
31039197 A fw S 44.08 566
31039704 R fw 566
31042874 A gw S 44.08 566
31044102 A hw S 44.16 400
31044102 R cw 3
31044103 A iw S 44.07 3
31044847 R ew 100
31045360 R gw 566
31045361 R iw 3
31045361 A jw S 44.16 3
31049327 A kw B 44.06 100
31049328 R kv 100
31049328 A lw B 44.06 100
31049330 R kw 100
31051162 A mw B 44.03 100
31059422 R lw 100
31059423 A nw B 44.04 100
31068558 R mw 100
31068563 A ow B 44.03 100
31072722 A pw B 44.06 745
31078726 R pw 745
31078729 A qw B 44.06 100
31078853 A rw B 44.07 100
31078854 R nw 100
31078854 A sw B 44.06 100
31078855 R qw 100
31083128 R hw 400
31083188 A tw S 44.11 400
31084326 R sw 100
31084326 A uw B 44.04 100
31084326 R jw 3
31084327 A vw S 44.11 100
31084583 A ww B 44.02 100
31086250 R rw 100
31090717 R ow 100
31090722 A xw B 44.03 100
31092565 A yw S 44.10 100
31092566 R vw 100
31092566 A zw S 44.10 3
31094315 R yw 100
31094317 A ax S 44.10 100
31094319 R zw 3
31094319 A bx S 44.10 3
31095325 R ax 100
31106672 A cx B 44.04 500
31116629 R tw 400
31122297 R cx 500
31124633 A dx B 44.04 100
31124816 A ex B 44.04 100
31124816 R uw 100
31124817 A fx B 44.04 100
31124819 A gx B 44.05 100
31131407 A hx B 44.05 100
31131408 R fx 100
31131408 A ix B 44.05 100
31131409 R gx 100
31137936 A jx B 44.04 500
31140881 R dx 100
31140881 R ex 100
31140881 R hx 100
31145056 R ix 100
31145056 A kx B 44.04 100
31145058 A lx S 44.09 100
31145059 R bx 3
31145059 A mx S 44.09 100
31145115 A nx S 45.36 1000
31149917 A ox B 44.06 100
31154516 R ox 100
31154517 R lx 100
31154517 R kx 100
31154517 A px B 44.03 100
31160562 A qx B 44.06 900
31160563 R px 100
31160563 A rx B 44.04 100
31160590 R xw 100
31160596 A sx B 44.03 100
31161615 R rx 100
31161616 A tx B 44.06 100
31167004 R qx 900
31171613 R tx 100
31171613 A ux S 44.05 290
31171613 R ux 290
31171614 A vx B 44.03 100
31171625 R vx 100
31172140 A wx B 44.05 100
31173104 A xx B 44.05 100
31175301 A yx S 44.08 100
31175302 R mx 100
31175302 A zx S 44.08 100
31175315 R xx 100
31175316 A ay B 44.04 100
31175610 R sx 100
31175611 R wx 100
31175615 A by B 44.03 100
31180640 R yx 100
31181517 A cy S 44.08 100
31186710 R cy 100
31187493 A dy B 44.05 100
31190816 R dy 100
31191897 A ey B 44.05 100
31196687 R by 100
31196688 R ay 100
31196688 A fy B 44.05 100
31196689 R ey 100
31196693 A gy B 44.05 100
31197839 A hy S 44.08 100
31198548 R hy 100
31198549 R fy 100
31198549 A iy B 44.06 100
31199106 R iy 100
31199106 A jy B 44.04 100
31199605 R jy 100
31199606 A ky B 44.06 100
31200216 R ky 100
31200216 A ly B 44.04 100
31202156 R ly 100
31202156 A my B 44.06 100
31202165 R zx 100
31202166 A ny S 44.18 3
31205910 A oy B 44.06 100
31208286 A py S 48.60 500
31210554 R oy 100
31211011 A qy B 42.12 15
31211177 A ry B 44.06 100
31212886 R ry 100
31217900 A sy B 44.07 100
31223385 R sy 100
31232773 R uu 800
31235907 A ty B 44.06 800
31235907 R my 100
31235908 A uy B 44.07 100
31257516 R uy 100
31257516 A vy B 44.06 100
31263238 R ty 100
31273185 R vy 100
31273185 A wy B 44.07 100
31274653 A xy B 44.07 100
31275566 R xy 100
31276325 R wy 100
31276325 A yy B 44.06 100
31277891 A zy S 44.08 1500
31277892 R yy 100
31277892 R ny 3
31277893 A az B 44.04 100
31277893 A bz S 44.07 3
31282571 R gy 100
31282702 R bz 3
31282702 R zy 1342
31282703 A cz S 44.18 3
31283212 R zy 100
31283919 R zy 58
31283920 R az 100
31283920 A dz B 44.07 100
31284554 A ez B 44.07 100
31285701 R vg 15
31288972 A fz B 44.07 50
31294210 R ez 100
31303042 R jx 500
31304640 A gz B 44.06 100
31314121 A hz B 43.32 500
31320766 A iz B 44.07 200
31320767 R dz 100
31320767 A jz B 44.07 100
31320769 R iz 200
31345152 A kz B 44.07 200
31362067 A lz S 44.10 100
31370746 R lz 100
31374426 A mz B 44.09 20
31375176 R mz 20
31381630 A nz B 44.07 100
31382908 R nz 100
31393278 A oz S 44.28 100
31395589 A pz S 44.10 100
31404832 R cz 3
31404833 A qz S 44.09 100
31404834 R jz 100
31404834 A rz B 44.07 100
31411759 R pz 100
31411760 R rz 100
31411760 A sz B 44.07 100
31411761 R qz 100
31411761 A tz S 44.18 100
31467900 A uz B 44.01 100
31468318 A vz S 44.17 100
31468319 R tz 100
31468319 A wz S 44.17 100
31471235 R vz 100
31471265 A xz S 44.17 100
31473126 A yz S 44.17 100
31473126 R xz 100
31474555 R yz 100
31474585 A zz S 44.17 100
31504806 R zz 100
31504835 A aab S 44.18 100
31508052 A bab B 44.09 100
31508066 A cab B 44.02 100
31508066 R uz 100
31516797 R bab 100
31516826 A dab B 44.03 100
31516826 R cab 100
31517605 R aab 100
31517635 A eab S 44.30 100
31524816 R dab 100
31524846 A fab B 44.02 100
31525007 A gab B 44.07 100
31525008 R sz 100
31525008 A hab B 44.07 100
31525010 R gab 100
31525036 R fab 100
31525066 A iab B 44.01 100
31525265 R iab 100
31525295 A jab B 44.01 100
31525555 R jab 100
31525585 A kab B 43.97 100
31525757 R hab 100
31526297 R kz 200
31528346 A lab S 44.20 100
31528346 R eab 100
31530904 A mab B 44.07 100
31530945 A nab B 43.99 100
31530946 R kab 100
31530956 A oab S 44.19 100
31530956 R lab 100
31533430 A pab B 44.07 100
31533466 R nab 100
31533496 A qab B 43.97 100
31534586 A rab S 44.19 100
31534586 R oab 100
31535815 R rab 100
31535845 A sab S 44.19 100
31536315 A tab S 44.12 100
31536905 R tab 100
31537765 A uab S 44.19 100
31537766 R sab 100
31538332 A vab S 44.12 100
31538406 A wab S 44.19 100
31538406 R uab 100
31538407 R wz 100
31538407 A xab S 44.12 100
31538760 R vab 100
31539171 A yab S 44.12 100
31539625 A zab S 44.19 100
31539625 R wab 100
31539626 R xab 100
31539626 A abb S 44.12 100
31539655 A bbb S 44.19 100
31539656 R zab 100
31540158 R yab 100
31540166 R abb 100
31540166 A cbb S 44.18 100
31540205 R bbb 100
31540234 A dbb S 44.26 100
31540529 A ebb S 44.14 100
31540755 A fbb S 44.21 100
31540756 R dbb 100
31540756 R cbb 100
31540756 A gbb S 44.14 100
31540786 A hbb S 44.21 100
31540786 R fbb 100
31540838 R pab 100
31540896 A ibb B 43.99 100
31540896 R qab 100
31541124 A jbb S 44.14 100
31541124 R gbb 100
31541125 A kbb S 44.14 100
31541286 A lbb S 44.21 100
31541286 R hbb 100
31541583 R ebb 100
31541584 R jbb 100
31541586 A mbb S 44.21 100
31541586 R lbb 100
31541986 A nbb S 44.13 100
31541987 R kbb 100
31541987 A obb S 44.13 100
31542126 A pbb S 44.20 100
31542126 R mbb 100
31542157 A qbb S 44.20 100
31542157 R pbb 100
31542334 R nbb 100
31542666 A rbb S 44.13 100
31542667 R obb 100
31542667 A sbb S 44.13 100
31542766 A tbb S 44.20 100
31542766 R qbb 100
31542796 A ubb S 44.20 100
31542796 R tbb 100
31542989 R rbb 100
31543281 A vbb S 44.13 100
31543281 R sbb 100
31543282 A wbb S 44.12 100
31543336 A xbb S 44.19 100
31543336 R ubb 100
31543367 A ybb S 44.19 100
31543367 R xbb 100
31543558 R vbb 100
31543803 A zbb S 44.12 100
31543804 R wbb 100
31543804 A acb S 44.12 100
31543886 A bcb S 44.19 100
31543886 R ybb 100
31543917 A ccb S 44.19 100
31543917 R bcb 100
31544149 A dcb B 44.07 100
31544185 R ibb 100
31544202 R zbb 100
31544215 A ecb B 43.97 100
31544305 A fcb S 44.12 100
31544356 A gcb S 44.19 100
31544356 R ccb 100
31544356 R acb 100
31544357 A hcb S 44.12 100
31544387 A icb S 44.19 100
31544387 R gcb 100
31544549 R fcb 100
31544556 R hcb 100
31544556 A jcb S 44.18 100
31544595 R icb 100
31544625 A kcb S 44.26 100
31544761 A lcb S 44.14 100
31544806 A mcb S 44.21 100
31544806 R kcb 100
31544806 R jcb 100
31544806 A ncb S 44.14 100
31544838 A ocb S 44.21 100
31544838 R mcb 100
31544998 R lcb 100
31545208 A pcb S 44.14 100
31545209 R ncb 100
31545209 A qcb S 44.14 100
31545255 A rcb S 44.21 100
31545256 R ocb 100
31545286 A scb S 44.21 100
31545286 R rcb 100
31545429 R pcb 100
31545650 A tcb S 44.14 100
31545651 R qcb 100
31545651 A ucb S 44.13 100
31545695 A vcb S 44.21 100
31545696 R scb 100
31545726 A wcb S 44.21 100
31545727 R vcb 100
31545893 R tcb 100
31546144 A xcb S 44.13 100
31546145 R ucb 100
31546145 A ycb S 44.13 100
31546186 A zcb S 44.21 100
31546186 R wcb 100
31546217 A adb S 44.20 100
31546217 R zcb 100
31546397 R xcb 100
31546616 A bdb S 44.13 100
31546617 R ycb 100
31546617 A cdb S 44.13 100
31546656 A ddb S 44.20 100
31546656 R adb 100
31546686 A edb S 44.20 100
31546687 R ddb 100
31546857 R bdb 100
31546903 A fdb S 44.14 100
31547088 A gdb S 44.13 100
31547135 A hdb S 44.20 100
31547136 R edb 100
31547136 R cdb 100
31547136 A idb S 44.13 100
31547166 A jdb S 44.20 100
31547166 R hdb 100
31547341 R gdb 100
31547578 A kdb S 44.13 100
31547828 R kdb 100
31548064 A ldb S 44.13 100
31548136 A mdb B 44.00 100
31548136 R ecb 100
31548155 A ndb S 44.20 100
31548156 R jdb 100
31548156 R idb 100
31548156 A odb S 44.13 100
31548193 A pdb S 44.20 100
31548193 R ndb 100
31548340 R ldb 100
31548553 A qdb S 44.12 100
31548596 A rdb S 44.19 100
31548596 R pdb 100
31548596 R odb 100
31548597 A sdb S 44.12 100
31548626 A tdb S 44.19 100
31548627 R rdb 100
31548780 R qdb 100
31548986 A udb S 44.12 100
31549026 A vdb S 44.19 100
31549026 R tdb 100
31549027 R sdb 100
31549027 A wdb S 44.12 100
31549036 R mdb 100
31549056 A xdb S 44.19 100
31549057 R vdb 100
31549083 A ydb B 43.99 100
31549212 R udb 100
31549416 A zdb S 44.12 100
31549895 A aeb S 44.19 100
31549896 R xdb 100
31549896 R wdb 100
31549896 A beb S 44.12 100
31549976 A ceb S 44.19 100
31549976 R aeb 100
31550049 A deb S 44.12 100
31550050 R beb 100
31550050 A eeb S 44.11 100
31550106 A feb S 44.19 100
31550106 R ceb 100
31550136 A geb S 44.19 100
31550137 R feb 100
31550264 A heb S 44.11 100
31550306 A ieb S 44.18 100
31550306 R geb 100
31550336 A jeb S 44.18 100
31550336 R ieb 100
31550474 A keb S 44.11 100
31550475 R eeb 100
31550475 A leb S 44.11 100
31550515 A meb S 44.18 100
31550516 R jeb 100
31550546 A neb S 44.18 100
31550546 R meb 100
31550644 A oeb S 44.11 100
31550818 R zdb 100
31550819 R deb 100
31550820 R leb 100
31550820 A peb S 44.11 100
31550820 R heb 100
31550820 R keb 100
31550821 R oeb 100
31551356 A qeb S 44.10 100
31551357 R peb 100
31551357 A reb S 44.10 100
31551366 A seb S 44.18 100
31551366 R neb 100
31551397 A teb S 44.18 100
31551397 R seb 100
31551511 A ueb S 44.10 100
31551681 A veb S 44.10 100
31551682 R reb 100
31551682 A web S 44.10 100
31551831 A xeb S 44.10 97
31551833 A yeb S 44.10 100
31551833 R web 100
31551834 A zeb S 44.10 100
31552026 A afb S 44.17 100
31552026 R teb 100
31552032 R qeb 100
31552033 R ueb 100
31552033 R veb 100
31552033 R yeb 100
31552034 R xeb 97
31552046 R zeb 100
31552046 A bfb S 44.14 100
31552056 A cfb S 44.17 100
31552056 R afb 100
31552088 R cfb 100
31552117 A dfb S 44.24 100
31552767 A efb S 44.14 100
31553026 A ffb S 44.21 100
31553026 R dfb 100
31553027 R bfb 100
31553027 A gfb S 44.14 100
31553056 A hfb S 44.21 100
31553057 R ffb 100
31553129 A ifb S 44.14 100
31553130 R gfb 100
31553130 A jfb S 44.13 100
31553287 A kfb S 44.13 100
31553455 A lfb S 44.13 100
31553455 R jfb 100
31553456 A mfb S 44.13 100
31553704 R efb 100
31553705 R ifb 100
31553705 R kfb 100
31553705 R lfb 100
31554079 A nfb S 44.13 100
31554126 A ofb S 44.20 100
31554126 R hfb 100
31554126 R mfb 100
31554127 A pfb S 44.13 100
31554156 A qfb S 44.20 100
31554156 R ofb 100
31554256 A rfb S 44.13 100
31554257 R pfb 100
31554257 A sfb S 44.13 100
31554446 A tfb S 44.13 100
31554617 A ufb S 44.12 100
31554618 R sfb 100
31554618 A vfb S 44.12 100
31554794 A wfb S 44.12 100
31555016 R nfb 100
31555017 R rfb 100
31555017 R tfb 100
31555018 R vfb 100
31555018 A xfb S 44.12 100
31555018 R ufb 100
31555019 R wfb 100
31555026 A yfb S 44.20 100
31555026 R qfb 100
31555057 A zfb S 44.19 100
31555057 R yfb 100
31555375 A agb S 44.12 100
31555375 R xfb 100
31555376 A bgb S 44.12 100
31555562 A cgb S 44.12 100
31556026 A dgb S 44.19 100
31556026 R zfb 100
31556916 R agb 100
31556916 R cgb 100
31556917 R bgb 100
31556917 A egb S 44.12 100
31556955 R dgb 100
31556985 A fgb S 44.19 100
31557174 A ggb S 44.11 100
31557175 R egb 100
31557175 A hgb S 44.11 100
31557216 A igb S 44.19 100
31557216 R fgb 100
31557256 A jgb S 44.19 100
31557256 R igb 100
31557400 A kgb S 44.11 100
31558025 A lgb S 44.18 100
31558026 R jgb 100
31558056 A mgb S 44.18 100
31558057 R lgb 100
31558102 A ngb S 44.11 100
31558103 R hgb 100
31558103 A ogb S 44.11 100
31558662 A pgb S 44.11 100
31559026 A qgb S 44.18 100
31559026 R mgb 100
31559056 A rgb S 44.18 100
31559057 R qgb 100
31559358 R ggb 100
31559359 R kgb 100
31559359 R ogb 100
31559359 A sgb S 44.11 100
31559359 R ngb 100
31559360 R pgb 100
31559366 R sgb 100
31559366 A tgb S 44.14 100
31559406 R rgb 100
31559435 A ugb S 44.25 100
31559875 R ydb 100
31559904 A vgb B 43.97 100
31562876 A wgb S 44.18 100
31562876 R ugb 100
31562906 A xgb S 44.18 100
31562906 R wgb 100
31565814 R dcb 100
31587347 A ygb S 44.13 100
31587739 A zgb S 44.13 100
31587740 R tgb 100
31587740 A ahb S 44.13 100
31587964 A bhb S 44.13 100
31588130 A chb S 44.13 100
31588444 A dhb S 44.13 100
31588620 A ehb S 44.13 100
31588787 A fhb S 44.13 100
31588970 A ghb S 44.13 100
31589154 A hhb S 44.13 100
31589524 A ihb S 44.13 100
31589755 R ygb 100
31589755 R zgb 100
31589756 R bhb 100
31589756 R chb 100
31589756 R dhb 100
31589757 R ehb 100
31589757 R fhb 100
31589757 R ghb 100
31589758 R hhb 100
31589758 R ihb 100
31590186 A jhb S 44.13 100
31590256 A khb B 43.99 100
31590256 R vgb 100
31590345 R mab 100
31590354 A lhb S 44.13 100
31590399 R fz 50
31590399 R ty 700
31590415 R khb 100
31590445 A mhb B 43.97 100
31590722 A nhb S 44.13 100
31591068 A ohb S 44.13 100
31591418 A phb S 44.13 100
31591786 A qhb S 44.13 100
31592111 R jhb 100
31592112 R lhb 100
31592113 R nhb 100
31592113 R ohb 100
31592113 R phb 100
31592114 R qhb 100
31592498 A rhb S 44.13 100
31592684 A shb S 44.13 100
31593070 A thb S 44.13 100
31593397 A uhb S 44.13 100
31593484 A vhb S 44.13 100
31593689 A whb S 44.13 100
31593905 A xhb S 44.13 100
31594113 A yhb S 44.13 100
31594348 A zhb S 44.13 100
31594386 A aib B 43.98 100
31594386 R mhb 100
31594458 R rhb 100
31594458 R thb 100
31594458 R shb 100
31594458 R uhb 100
31594459 R whb 100
31594459 R vhb 100
31594460 R xhb 100
31594460 R yhb 100
31594460 R zhb 100
31594745 A bib S 44.13 100
31594953 A cib S 44.13 100
31595137 A dib S 44.13 100
31595313 R gz 100
31595337 A eib S 44.13 100
31595356 R aib 100
31595386 A fib B 43.97 100
31595521 A gib S 44.13 100
31595675 R fib 100
31595705 A hib B 43.97 100
31595716 A iib S 44.13 100
31595781 R xm 100
31595781 R bu 700
31595825 R hib 100
31595855 A jib B 43.94 100
31596229 R ww 100
31599414 R nu 100
31600117 A kib S 44.11 100
31600118 R ahb 100
31600118 A lib S 44.11 100
31600176 A mib S 44.18 100
31600176 R xgb 100
31600206 A nib S 44.18 100
31600207 R mib 100
31602088 A oib S 44.11 100
31602226 A pib S 44.18 100
31602226 R nib 100
31602869 A qib S 44.10 100
31602870 R lib 100
31602870 A rib S 44.10 100
31602936 A sib S 44.18 100
31602936 R pib 100
31603372 A tib S 44.10 3
31607766 A uib S 44.15 100
31607766 R sib 100
31608432 R bib 100
31608432 R cib 100
31608435 R dib 100
31608435 R eib 100
31608435 R gib 100
31608436 R iib 100
31608436 R kib 100
31608436 R oib 100
31608437 R qib 100
31608437 R tib 3
31608476 A vib S 44.15 100
31608477 R uib 100
31609144 A wib S 44.08 100
31609144 R rib 100
31609145 A xib S 44.08 100
31609166 A yib S 44.15 100
31609166 R vib 100
31609196 A zib S 44.15 100
31609196 R yib 100
31609638 A ajb S 44.08 100
31609850 R wib 100
31609851 R ajb 100
31609851 R xib 100
31609851 A bjb S 44.08 100
31610237 A cjb S 44.07 100
31610237 R bjb 100
31610238 A djb S 44.07 100
31610295 A ejb S 44.14 100
31610296 R zib 100
31610326 A fjb S 44.14 100
31610327 R ejb 100
31610639 A gjb S 44.07 100
31610676 A hjb S 44.14 100
31610676 R fjb 100
31610676 R djb 100
31610677 A ijb S 44.07 100
31610706 A jjb S 44.14 100
31610707 R hjb 100
31610869 A kjb S 44.07 100
31610916 A ljb S 44.14 100
31610916 R jjb 100
31610917 R ijb 100
31610917 A mjb S 44.07 100
31610947 A njb S 44.14 100
31610947 R ljb 100
31611068 A ojb S 44.07 100
31611069 R mjb 100
31611069 A pjb S 44.06 100
31611146 A qjb S 44.14 100
31611146 R njb 100
31611246 A rjb S 44.14 100
31611247 R qjb 100
31611269 A sjb S 44.06 100
31611326 A tjb S 44.13 100
31611326 R rjb 100
31611591 R cjb 100
31611592 R gjb 100
31611592 R kjb 100
31611593 R ojb 100
31611593 R pjb 100
31611593 A ujb S 44.06 100
31611593 R sjb 100
31611606 R ujb 100
31611606 A vjb S 44.13 100
31611635 R tjb 100
31611665 A wjb S 44.21 100
31612167 A xjb S 44.13 100
31612168 R vjb 100
31612168 A yjb S 44.13 100
31612226 A zjb S 44.20 100
31612226 R wjb 100
31612257 A akb S 44.20 100
31612257 R zjb 100
31612356 A bkb S 44.13 100
31612416 A ckb S 44.20 100
31612416 R akb 100
31612447 A dkb S 44.20 100
31612447 R ckb 100
31612556 A ekb S 44.12 100
31612557 R yjb 100
31612557 A fkb S 44.12 100
31612626 A gkb S 44.20 100
31612626 R dkb 100
31612676 A hkb S 44.19 100
31612676 R gkb 100
31612772 A ikb S 44.12 100
31612816 A jkb S 44.19 100
31612816 R hkb 100
31613190 R xjb 100
31613190 R bkb 100
31613191 R fkb 100
31613191 R ekb 100
31613191 A kkb S 44.12 100
31613191 R ikb 100
31613226 R jkb 100
31613255 A lkb S 44.19 100
31614737 A mkb S 44.12 100
31614738 R kkb 100
31614738 A nkb S 44.12 100
31614916 A okb S 44.12 100
31615099 A pkb S 44.11 100
31615100 R nkb 100
31615100 A qkb S 44.11 100
31615216 A rkb S 44.19 100
31615216 R lkb 100
31615397 A skb S 44.11 100
31615435 R rkb 100
31615465 A tkb S 44.19 100
31621449 A ukb S 44.10 100
31621450 R qkb 100
31621451 A vkb S 44.10 100
31621485 A wkb S 44.18 100
31621485 R tkb 100
31621495 R wkb 100
31621525 A xkb S 44.18 100
31621526 A ykb S 44.18 100
31621526 R xkb 100
31621694 R ukb 100
31622705 A zkb S 44.17 100
31622706 R ykb 100
31622736 A alb S 44.17 100
31622736 R zkb 100
31623077 A blb S 44.10 100
31623078 R vkb 100
31623078 A clb S 44.09 100
31623465 A dlb S 44.16 100
31623465 R alb 100
31623805 A elb S 44.09 73
31623805 A flb S 44.09 30
31623806 R clb 100
31623806 A glb S 44.09 100
31623886 A hlb S 44.16 100
31623886 R dlb 100
31640866 R mkb 100
31640868 R okb 100
31640869 R pkb 100
31640869 R skb 100
31640869 R blb 100
31640870 R elb 73
31640870 R flb 30
31642725 A ilb S 44.16 100
31642725 R hlb 100
31642993 A jlb S 44.09 100
31642994 R glb 100
31642994 A klb S 44.08 100
31643076 A llb S 44.16 100
31643077 R ilb 100
31643326 A mlb S 44.16 100
31643326 R llb 100
31643386 A nlb S 44.15 100
31643386 R mlb 100
31643678 A olb S 44.08 100
31644026 A plb S 44.15 100
31644026 R nlb 100
31644027 R klb 100
31644027 A qlb S 44.08 100
31644058 A rlb S 44.15 100
31644058 R plb 100
31644335 A slb S 44.08 97
31644336 A tlb S 44.08 100
31652573 R jlb 100
31652574 R qlb 100
31652575 A ulb S 44.08 100
31652575 R olb 100
31652575 R tlb 100
31652575 R slb 97
31664806 A vlb B 43.97 100
31664806 R jib 100
31665005 R vlb 100
31665035 A wlb B 43.94 100
31668921 A xlb S 44.03 100
31669043 R xlb 100
31689646 A ylb B 43.95 100
31689646 R wlb 100
31692548 A zlb B 44.04 1000
31692590 A amb B 44.04 100
31693019 R amb 100
31695021 A bmb B 44.04 100
31695086 A cmb B 43.97 100
31695086 R ylb 100
31695096 R zlb 1000
31695338 R bmb 100
31695375 R cmb 100
31695405 A dmb B 43.95 100
31695965 A emb B 44.04 100
31696006 A fmb B 43.97 100
31696006 R dmb 100
31696281 R emb 100
31696315 R fmb 100
31696345 A gmb B 43.95 100
31696736 A hmb B 44.04 100
31696796 A imb B 43.97 100
31696796 R gmb 100
31696866 R ulb 100
31696866 A jmb S 44.14 100
31696905 R rlb 100
31696935 A kmb S 44.22 100
31697033 R hmb 100
31697076 R imb 100
31697106 A lmb B 43.95 100
31697896 A mmb S 44.16 100
31697896 R kmb 100
31698069 A nmb S 44.16 100
31698069 R mmb 100
31698508 A omb S 44.08 100
31698566 A pmb S 44.16 100
31698566 R nmb 100
31698567 R jmb 100
31698567 A qmb S 44.08 100
31698597 A rmb S 44.15 100
31698597 R pmb 100
31698873 R omb 100
31699148 A smb S 44.08 100
31699206 A tmb S 44.15 100
31699206 R rmb 100
31699207 R qmb 100
31699207 A umb S 44.08 100
31699237 A vmb S 44.15 100
31699237 R tmb 100
31699433 R smb 100
31699696 A wmb S 44.08 100
31699980 R wmb 100
31700220 A xmb S 44.08 100
31700266 A ymb S 44.15 100
31700266 R vmb 100
31700267 R umb 100
31700267 A zmb S 44.08 100
31700297 A anb S 44.15 100
31700297 R ymb 100
31700498 R xmb 100
31700751 A bnb S 44.07 100
31700795 A cnb S 44.15 100
31700796 R anb 100
31700796 R zmb 100
31700796 A dnb S 44.07 100
31700827 A enb S 44.15 100
31700827 R cnb 100
31701018 R bnb 100
31701268 A fnb S 44.07 100
31701316 A gnb S 44.14 100
31701316 R enb 100
31701316 R dnb 100
31701317 A hnb S 44.07 100
31701347 A inb S 44.14 100
31701347 R gnb 100
31701529 R fnb 100
31701536 R hnb 100
31701536 A jnb S 44.14 100
31701576 R inb 100
31701606 A knb S 44.21 100
31701790 A lnb S 44.09 100
31701906 A mnb S 44.16 100
31701906 R knb 100
31701907 R jnb 100
31701907 A nnb S 44.09 100
31701937 A onb S 44.16 100
31701937 R mnb 100
31702065 R lnb 100
31702346 A pnb S 44.16 100
31702347 R onb 100
31702383 A qnb S 44.08 100
31702383 R nnb 100
31702384 A rnb S 44.08 100
31702466 A snb S 44.16 100
31702466 R pnb 100
31702560 R qnb 100
31702812 A tnb S 44.08 100
31702813 R rnb 100
31702813 A unb S 44.08 100
31702866 A vnb S 44.15 100
31702866 R snb 100
31702897 A wnb S 44.15 100
31702897 R vnb 100
31703092 R tnb 100
31703389 A xnb S 44.08 100
31703390 R unb 100
31703390 A ynb S 44.08 100
31703396 A znb S 44.15 100
31703396 R wnb 100
31703466 A aob S 44.15 100
31703466 R znb 100
31703600 R xnb 100
31703862 A bob S 44.08 100
31703863 R ynb 100
31703863 A cob S 44.08 100
31703916 A dob S 44.15 100
31703916 R aob 100
31703948 A eob S 44.15 100
31703949 R dob 100
31704129 R bob 100
31704403 A fob S 44.07 100
31704404 R cob 100
31704404 A gob S 44.07 100
31704446 A hob S 44.15 100
31704446 R eob 100
31704476 A iob S 44.15 100
31704477 R hob 100
31704656 R fob 100
31704892 A job S 44.07 100
31704893 R gob 100
31704893 A kob S 44.07 100
31704936 A lob S 44.14 100
31704936 R iob 100
31704966 A mob S 44.14 100
31704967 R lob 100
31705152 R job 100
31705155 R kob 100
31705155 A nob S 44.14 100
31705195 R mob 100
31705225 A oob S 44.21 100
31705421 A pob S 44.09 100
31705421 R nob 100
31705421 A qob S 44.09 100
31705465 A rob S 44.16 100
31705466 R oob 100
31705496 A sob S 44.16 100
31705496 R rob 100
31705672 R pob 100
31705934 A tob S 44.08 100
31705976 A uob S 44.16 100
31705976 R sob 100
31705977 R qob 100
31705977 A vob S 44.08 100
31706007 A wob S 44.16 100
31706007 R uob 100
31706192 R tob 100
31706451 A xob S 44.08 100
31706496 A yob S 44.15 100
31706496 R wob 100
31706497 R vob 100
31706497 A zob S 44.08 100
31706526 A apb S 44.15 100
31706527 R yob 100
31706728 R xob 100
31706987 A bpb S 44.08 100
31707068 A cpb S 44.15 100
31707068 R apb 100
31707069 R zob 100
31707069 A dpb S 44.08 100
31707145 A epb S 44.15 100
31707146 R cpb 100
31707417 R bpb 100
31707551 A fpb S 44.08 100
31707596 A gpb S 44.15 100
31707596 R epb 100
31707597 R dpb 100
31707597 A hpb S 44.07 100
31707627 A ipb S 44.15 100
31707627 R gpb 100
31707810 R fpb 100
31708059 A jpb S 44.07 100
31708106 A kpb S 44.15 100
31708106 R ipb 100
31708107 R hpb 100
31708107 A lpb S 44.07 100
31708162 A mpb S 44.14 100
31708162 R kpb 100
31708320 R jpb 100
31708327 R lpb 100
31708327 A npb S 44.14 100
31708365 R mpb 100
31708395 A opb S 44.22 100
31708555 A ppb S 44.09 100
31708606 A qpb S 44.16 100
31708606 R opb 100
31708607 R npb 100
31708607 A rpb S 44.09 100
31708637 A spb S 44.16 100
31708637 R qpb 100
31710319 R ppb 100
31711003 A tpb S 44.08 100
31711004 R rpb 100
31711004 A upb S 44.08 100
31711156 A vpb S 44.15 100
31711156 R spb 100
31711631 R tpb 100
31711665 R vpb 100
31711695 A wpb S 44.16 100
31711970 A xpb S 44.08 100
31711971 R upb 100
31711971 A ypb S 44.08 100
31712068 A zpb S 44.15 100
31712068 R wpb 100
31712124 A aqb S 44.15 100
31712125 R zpb 100
31712399 R xpb 100
31712730 A bqb S 44.08 100
31712731 R ypb 100
31712731 A cqb S 44.07 100
31712815 A dqb S 44.15 100
31712815 R aqb 100
31712847 A eqb S 44.15 100
31712847 R dqb 100
31713110 R bqb 100
31713434 A fqb S 44.07 100
31713435 R cqb 100
31713435 A gqb S 44.07 100
31713495 A hqb S 44.14 100
31713496 R eqb 100
31713526 A iqb S 44.14 100
31713526 R hqb 100
31713799 R fqb 100
31713815 R gqb 100
31713816 A jqb S 44.14 100
31713845 R iqb 100
31713875 A kqb S 44.22 100
31714131 A lqb S 44.09 100
31714132 R jqb 100
31714132 A mqb S 44.09 100
31714186 A nqb S 44.16 100
31714186 R kqb 100
31714216 A oqb S 44.16 100
31714216 R nqb 100
31714494 R lqb 100
31714802 A pqb S 44.08 100
31714855 A qqb S 44.16 100
31714856 R oqb 100
31714856 R mqb 100
31714856 A rqb S 44.08 100
31714886 A sqb S 44.15 100
31714886 R qqb 100
31715143 R pqb 100
31715994 A tqb S 44.08 100
31716067 A uqb S 44.15 100
31716067 R sqb 100
31716068 R rqb 100
31716068 A vqb S 44.08 100
31716098 A wqb S 44.15 100
31716098 R uqb 100
31720865 A xqb S 44.11 100
31720866 R wqb 100
31721116 R xqb 100
31721145 A yqb S 44.15 100
31721245 A zqb S 44.11 100
31721246 R yqb 100
31721426 A arb S 44.11 100
31721426 R zqb 100
31722375 R lmb 100
31722405 A brb B 43.94 100
31723655 R brb 100
31723685 A crb B 43.91 100
31724505 R nu 100
31725610 A drb S 44.04 100
31725655 A erb S 44.11 100
31725655 R arb 100
31725656 R vqb 100
31725656 A frb S 44.04 100
31725685 A grb S 44.11 100
31725686 R erb 100
31725800 A hrb S 44.04 97
31725801 A irb S 44.04 100
31725975 A jrb S 44.03 100
31725976 R frb 100
31725977 A krb S 44.03 100
31726016 A lrb S 44.11 100
31726016 R grb 100
31726046 A mrb S 44.10 100
31726047 R lrb 100
31726176 A nrb S 44.03 100
31726368 A orb S 44.03 100
31726368 R krb 100
31726369 A prb S 44.03 100
31726416 A qrb S 44.10 100
31726416 R mrb 100
31726648 A rrb S 44.03 100
31726806 A srb S 44.10 100
31726807 R qrb 100
31726837 A trb S 44.10 100
31726837 R srb 100
31727048 A urb S 44.02 100
31727049 R prb 100
31727049 A vrb S 44.02 100
31727075 A wrb S 44.10 100
31727076 R trb 100
31727287 A xrb S 44.02 100
31727335 A yrb S 44.09 100
31727336 R wrb 100
31727366 A zrb S 44.09 100
31727366 R yrb 100
31727503 A asb S 44.02 100
31727504 R vrb 100
31727504 A bsb S 44.02 100
31727546 A csb S 44.09 100
31727546 R zrb 100
31727738 R tqb 100
31727740 R drb 100
31727740 R irb 100
31727740 R hrb 97
31727741 R jrb 100
31727741 R nrb 100
31727741 R orb 100
31727742 R rrb 100
31727745 R urb 100
31727746 R xrb 100
31727746 R asb 100
31727785 R csb 100
31727815 A dsb S 44.09 100
31729000 A esb S 44.02 100
31729057 A fsb S 44.09 100
31729057 R dsb 100
31729058 R bsb 100
31729058 A gsb S 44.02 100
31729087 A hsb S 44.09 100
31729087 R fsb 100
31729271 A isb S 44.01 100
31729272 R gsb 100
31729272 A jsb S 44.01 100
31729345 A ksb S 44.09 100
31729346 R hsb 100
31729396 A lsb S 44.08 100
31729396 R ksb 100
31729543 A msb S 44.01 100
31729606 A nsb S 44.08 100
31729606 R lsb 100
31729607 R jsb 100
31729607 A osb S 44.01 100
31729807 A psb S 44.01 100
31730072 R esb 100
31730072 R isb 100
31730072 R msb 100
31730072 R osb 100
31730073 A qsb S 44.01 100
31730073 R psb 100
31730076 R qsb 100
31730076 A rsb S 44.08 100
31730105 R nsb 100
31730135 A ssb S 44.11 100
31730396 A tsb S 44.03 100
31730396 R rsb 100
31730396 A usb S 44.02 100
31730415 R crb 100
31730445 A vsb B 43.90 100
31730544 A wsb S 44.02 100
31730586 A xsb S 44.10 100
31730586 R ssb 100
31730587 R usb 100
31730587 A ysb S 44.02 100
31730626 A zsb S 44.09 100
31730626 R xsb 100
31730816 A atb S 44.05 100
31730816 R zsb 100
31730816 R atb 100
31730847 A btb S 44.09 100
31730899 R wsb 100
31730934 R tsb 100
31731026 A ctb S 44.05 100
31731026 R btb 100
31731035 R ctb 100
31731065 A dtb S 44.09 100
31731239 A etb S 44.02 100
31731240 R ysb 100
31731240 A ftb S 44.02 100
31731246 A gtb S 44.05 100
31731246 R dtb 100
31731265 R gtb 100
31731295 A htb S 44.09 100
31731356 A itb S 44.09 100
31731356 R htb 100
31731386 A jtb S 44.09 100
31731387 R itb 100
31731576 A ktb S 44.05 100
31731576 R jtb 100
31731576 R ktb 100
31731583 A ltb S 44.02 100
31731583 R ftb 100
31731583 A mtb S 44.01 100
31731607 A ntb S 44.09 100
31731636 A otb S 44.09 100
31731637 R ntb 100
31731667 A ptb S 44.09 100
31731667 R otb 100
31731796 A qtb S 44.05 100
31731796 R ptb 100
31731797 R qtb 100
31731816 A rtb S 44.01 100
31731828 A stb S 44.09 100
31731828 R mtb 100
31731829 A ttb S 44.01 100
31731865 A utb S 44.09 100
31731865 R stb 100
31731896 A vtb S 44.08 100
31731896 R utb 100
31732017 A wtb S 44.05 100
31732017 R vtb 100
31732017 R wtb 100
31732047 A xtb S 44.08 100
31732056 A ytb S 44.01 100
31732056 R ttb 100
31732057 A ztb S 44.01 100
31732096 A aub S 44.08 100
31732097 R xtb 100
31732236 A bub S 44.05 100
31732236 R aub 100
31732236 R bub 100
31732267 A cub S 44.08 100
31732375 R etb 100
31732376 R ltb 100
31732376 R rtb 100
31732377 R ytb 100
31732456 A dub S 44.05 100
31732456 R cub 100
31732456 R dub 100
31732486 A eub S 44.08 100
31732566 A fub S 44.05 100
31732566 R eub 100
31732567 R fub 100
31732597 A gub S 44.08 100
31732727 A hub S 44.01 100
31732765 A iub S 44.08 100
31732766 R gub 100
31732766 R ztb 100
31732766 A jub S 44.01 100
31732797 A kub S 44.08 100
31732798 R iub 100
31732959 A lub S 44.01 100
31732959 R jub 100
31732960 A mub S 44.01 100
31732996 A nub S 44.05 100
31732996 R kub 100
31733005 R nub 100
31733035 A oub S 44.08 100
31733199 A pub S 44.00 100
31733216 A qub S 44.05 100
31733216 R oub 100
31733217 R qub 100
31733217 R mub 100
31733217 A rub S 44.00 100
31733248 A sub S 44.08 100
31733436 A tub S 44.05 100
31733436 R sub 100
31733437 R tub 100
31733446 A uub S 44.00 100
31733468 A vub S 44.07 100
31733656 A wub S 44.05 100
31733656 R vub 100
31733657 R wub 100
31733688 A xub S 44.07 100
31733689 R hub 100
31733689 R lub 100
31733690 R pub 100
31733690 R rub 100
31733690 R uub 100
31733690 A yub S 44.00 100
31733695 R yub 100
31733695 A zub S 44.07 100
31733736 R xub 100
31733766 A avb S 44.11 100
31733876 A bvb S 44.05 100
31733876 R avb 100
31733877 R bvb 100
31733877 R zub 100
31733877 A cvb S 44.05 100
31733909 A dvb S 44.11 100
31734016 A evb S 44.00 100
31734065 R cvb 100
31734065 A fvb S 44.00 100
31734075 R fvb 100
31734075 A gvb S 44.11 100
31734096 A hvb S 44.05 100
31734097 R dvb 100
31734097 R hvb 100
31734097 R gvb 100
31734098 A ivb S 44.05 100
31734128 A jvb S 44.11 100
31734286 R ivb 100
31734286 A kvb S 44.00 100
31734316 A lvb S 44.05 100
31734316 R jvb 100
31734316 R lvb 100
31734348 A mvb S 44.07 100
31734502 A nvb S 44.00 100
31734525 A ovb S 44.05 100
31734526 R mvb 100
31734526 R kvb 100
31734526 A pvb S 44.00 100
31734536 R ovb 100
31734566 A qvb S 44.07 100
31734711 A rvb S 44.00 100
31734712 R pvb 100
31734712 A svb S 44.00 100
31734747 A tvb S 44.05 100
31734747 R qvb 100
31734755 R tvb 100
31734785 A uvb S 44.07 100
31734866 A vvb S 44.05 100
31734867 R uvb 100
31734867 R vvb 100
31734898 A wvb S 44.07 100
31734950 R evb 100
31734950 R nvb 100
31734950 R rvb 100
31734955 R svb 100
31734955 A xvb S 44.07 100
31734995 R wvb 100
31735025 A yvb S 44.11 100
31735076 A zvb S 44.05 100
31735077 R yvb 100
31735077 R xvb 100
31735077 A awb S 44.05 100
31735077 R zvb 100
31735108 A bwb S 44.11 100
31735286 A cwb S 44.04 100
31735287 R awb 100
31735287 A dwb S 44.04 100
31735296 A ewb S 44.05 100
31735297 R bwb 100
31735297 R ewb 100
31735327 A fwb S 44.11 100
31735337 A gwb S 44.11 100
31735337 R fwb 100
31735513 A hwb S 44.04 100
31735516 A iwb S 44.05 100
31735516 R gwb 100
31735516 R iwb 100
31735517 R dwb 100
31735517 A jwb S 44.03 100
31735548 A kwb S 44.11 100
31735736 A lwb S 44.05 100
31735736 R kwb 100
31735737 R lwb 100
31735743 A mwb S 44.03 100
31735768 A nwb S 44.11 100
31735769 R jwb 100
31735769 A owb S 44.03 100
31735957 A pwb S 44.05 100
31735957 R nwb 100
31735957 R pwb 100
31735982 A qwb S 44.03 100
31735988 A rwb S 44.11 100
31736027 A swb S 44.11 100
31736027 R rwb 100
31736057 A twb S 44.11 100
31736058 R swb 100
31736216 R cwb 100
31736216 R hwb 100
31736217 R mwb 100
31736217 R owb 100
31736217 R qwb 100
31736217 A uwb S 44.03 100
31736276 A vwb S 44.05 100
31736276 R twb 100
31736286 R vwb 100
31736316 A wwb S 44.11 100
31736496 A xwb S 44.05 100
31736496 R wwb 100
31736505 R xwb 100
31736534 A ywb S 44.03 100
31736535 A zwb S 44.11 100
31736536 R uwb 100
31736536 A axb S 44.03 100
31736716 A bxb S 44.05 100
31736716 R zwb 100
31736717 R bxb 100
31736747 A cxb S 44.11 100
31736758 A dxb S 44.03 100
31736936 A exb S 44.05 100
31736936 R cxb 100
31736936 R axb 100
31736936 A fxb S 44.02 100
31736937 R exb 100
31736966 A gxb S 44.11 100
31736991 A hxb S 44.02 100
31737026 A ixb S 44.10 100
31737026 R gxb 100
31737027 R fxb 100
31737027 A jxb S 44.02 100
31737068 A kxb S 44.10 100
31737068 R ixb 100
31737156 A lxb S 44.05 100
31737156 R kxb 100
31737157 R lxb 100
31737189 A mxb S 44.10 100
31737221 A nxb S 44.02 100
31737375 A oxb S 44.05 100
31737375 R mxb 100
31737376 R oxb 100
31737406 A pxb S 44.10 100
31737471 R ywb 100
31737471 R dxb 100
31737471 R hxb 100
31737472 R jxb 100
31737472 A qxb S 44.02 100
31737472 R nxb 100
31737597 A rxb S 44.05 100
31737597 R pxb 100
31737598 R rxb 100
31737628 A sxb S 44.10 100
31737752 A txb S 44.02 100
31737752 R qxb 100
31737753 A uxb S 44.02 100
31737816 A vxb S 44.05 100
31737816 R sxb 100
31737817 R vxb 100
31737848 A wxb S 44.10 100
31737973 A xxb S 44.02 100
31738027 A yxb S 44.09 100
31738027 R wxb 100
31738027 R uxb 100
31738028 A zxb S 44.01 100
31738058 A ayb S 44.09 100
31738058 R yxb 100
31738190 A byb S 44.01 100
31738191 R zxb 100
31738191 A cyb S 44.01 100
31738246 A dyb S 44.05 100
31738246 R ayb 100
31738247 R dyb 100
31738278 A eyb S 44.09 100
31738357 A fyb S 44.05 100
31738357 R eyb 100
31738367 R fyb 100
31738396 A gyb S 44.09 100
31738446 R txb 100
31738446 R xxb 100
31738446 R byb 100
31738579 A hyb S 44.05 100
31738579 R gyb 100
31738579 R hyb 100
31738609 A iyb S 44.09 100
31738677 A jyb S 44.01 100
31738678 R cyb 100
31738678 A kyb S 44.01 100
31738798 A lyb S 44.05 100
31738798 R iyb 100
31738807 R lyb 100
31738837 A myb S 44.09 100
31738935 A nyb S 44.01 100
31739006 A oyb S 44.20 1000
31739018 A pyb S 44.05 100
31739018 R myb 100
31739019 R kyb 100
31739019 R pyb 100
31739019 A qyb S 44.01 100
31739049 A ryb S 44.08 100
31739098 A syb S 44.08 100
31739098 R ryb 100
31739166 A tyb S 44.01 100
31739167 R qyb 100
31739167 A uyb S 44.01 100
31739236 A vyb S 44.05 100
31739237 R syb 100
31739237 R vyb 100
31739268 A wyb S 44.08 100
31739425 R jyb 100
31739425 R nyb 100
31739425 R tyb 100
31739426 R uyb 100
31739426 A xyb S 44.08 100
31739456 A yyb S 44.05 100
31739456 R wyb 100
31739456 R yyb 100
31739457 R xyb 100
31739457 A zyb S 44.05 100
31739487 A azb S 44.08 100
31739566 A bzb S 44.05 100
31739566 R azb 100
31739566 R bzb 100
31739597 A czb S 44.08 100
31739775 A dzb S 44.05 100
31739776 R czb 100
31739785 R dzb 100
31739814 A ezb S 44.08 100
31739996 A fzb S 44.05 100
31739996 R ezb 100
31740005 R fzb 100
31740035 A gzb S 44.08 100
31743515 A hzb S 44.05 100
31743516 R gzb 100
31743525 R hzb 100
31743572 A izb S 44.08 100
31743716 A jzb S 44.05 100
31743716 R izb 100
31743716 R jzb 100
31743747 A kzb S 44.08 100
31743936 A lzb S 44.05 100
31743936 R kzb 100
31743936 R lzb 100
31743967 A mzb S 44.08 100
31744156 A nzb S 44.05 100
31744156 R mzb 100
31744157 R nzb 100
31744188 A ozb S 44.08 100
31744376 A pzb S 44.05 100
31744377 R ozb 100
31744377 R pzb 100
31744408 A qzb S 44.08 100
31744596 A rzb S 44.05 100
31744596 R qzb 100
31744596 R rzb 100
31744627 A szb S 44.08 100
31744646 A tzb B 43.91 100
31744646 R vsb 100
31744815 R tzb 100
31744845 A uzb B 43.90 100
31745246 A vzb S 44.05 100
31745247 R szb 100
31745255 R vzb 100
31745303 A wzb S 44.08 100
31745357 A xzb S 44.05 100
31745357 R wzb 100
31745366 R xzb 100
31745396 A yzb S 44.08 100
31745576 A zzb S 44.05 100
31745576 R yzb 100
31745576 R zzb 100
31745607 A aac S 44.08 100
31745795 A bac S 44.05 100
31745796 R aac 100
31745796 R bac 100
31745827 A cac S 44.08 100
31746015 A dac S 44.05 100
31746016 R cac 100
31746016 R dac 100
31746046 A eac S 44.08 100
31746236 A fac S 44.05 100
31746236 R eac 100
31746237 R fac 100
31746268 A gac S 44.08 100
31746437 A hac S 44.01 100
31746456 A iac S 44.05 100
31746456 R gac 100
31746456 R iac 100
31746457 R zyb 100
31746457 A jac S 44.01 100
31746487 A kac S 44.08 100
31746566 A lac S 44.05 100
31746566 R kac 100
31746567 R lac 100
31746597 A mac S 44.08 100
31746776 A nac S 44.05 100
31746776 R mac 100
31746785 R nac 100
31746815 A oac S 44.08 100
31746848 R hac 100
31746996 A pac S 44.05 100
31746996 R oac 100
31747005 R pac 100
31747034 A qac S 44.08 100
31747216 A rac S 44.05 100
31747216 R qac 100
31747217 R rac 100
31747247 A sac S 44.08 100
31747422 R hk 100
31747436 A tac S 44.05 100
31747436 R sac 100
31747437 R tac 100
31747467 A uac S 44.08 100
31747469 A vac S 44.01 100
31747470 R jac 100
31747470 A wac S 44.01 100
31747656 A xac S 44.05 100
31747656 R uac 100
31747657 R xac 100
31747687 A yac S 44.11 100
31747769 R vac 100
31747770 R wac 100
31747770 A zac S 44.11 100
31747876 A abc S 44.05 100
31747876 R yac 100
31747876 R abc 100
31747876 R zac 100
31747877 A bbc S 44.05 100
31747908 A cbc S 44.11 100
31748096 A dbc S 44.05 100
31748097 R cbc 100
31748097 R dbc 100
31748127 A ebc S 44.11 100
31748306 A fbc S 44.05 100
31748306 R ebc 100
31748326 R fbc 100
31748356 A gbc S 44.11 100
31748413 R hk 100
31748415 A hbc B 43.97 100
31748456 R hbc 100
31748460 A ibc S 44.01 100
31748526 A jbc S 44.05 100
31748526 R gbc 100
31748527 R bbc 100
31748527 A kbc S 44.01 100
31748536 R jbc 100
31748566 A lbc S 44.11 100
31748746 A mbc S 44.05 100
31748747 R lbc 100
31748840 R ibc 100
31748886 A nbc S 44.05 100
31748886 R mbc 100
31748984 A obc B 43.92 100
31749015 R nbc 100
31749026 A pbc B 43.90 100
31749026 R uzb 100
31749045 A qbc S 44.11 100
31749425 R pbc 100
31749436 A rbc S 44.11 100
31749436 R qbc 100
31749455 A sbc B 43.90 100
31750976 A tbc B 43.91 100
31750977 R sbc 100
31756035 R tbc 100
31756065 A ubc B 43.91 100
31756996 A vbc B 43.91 100
31756996 R ubc 100
31757266 A wbc S 44.07 100
31757266 R rbc 100
31757306 A xbc S 44.07 100
31757306 R wbc 100
31757366 A ybc B 43.91 100
31757366 R vbc 100
31758995 A zbc S 44.00 100
31758996 R kbc 100
31758997 A acc S 44.00 100
31759039 A bcc B 43.98 100
31759182 R zbc 100
31759635 A ccc S 44.00 100
31759806 R ccc 100
31760225 A dcc S 44.00 100
31760398 R dcc 100
31760809 A ecc S 44.00 100
31760990 R ecc 100
31761236 R bcc 100
31761265 R ybc 100
31761294 A fcc B 43.91 100
31761377 A gcc S 44.00 100
31761378 R acc 100
31761378 A hcc S 44.00 100
31761646 R gcc 100
31762002 A icc S 44.00 100
31762003 R hcc 100
31762003 A jcc S 43.99 100
31762175 R icc 100
31762537 A kcc S 43.99 100
31762537 R jcc 100
31762538 A lcc S 43.99 100
31762670 R lcc 100
31762694 R kcc 100
31762735 A mcc B 43.91 100
31762736 R fcc 100
31762746 R xbc 100
31762776 A ncc S 44.07 100
31764057 A occ S 44.07 100
31764529 A pcc S 44.00 100
31764709 R pcc 100
31767238 A qcc B 43.97 100
31767238 R obc 100
31767239 A rcc B 43.98 100
31767241 R qcc 100
31767266 R ncc 100
31767295 A scc S 44.11 100
31773586 A tcc S 44.08 100
31773586 R scc 100
31773617 A ucc S 44.08 100
31773617 R tcc 100
31775120 A vcc S 44.01 100
31775121 R occ 100
31775121 A wcc S 44.01 100
31775125 R rcc 100
31775125 A xcc B 43.92 100
31775155 R mcc 100
31775156 A ycc B 43.97 100
31775185 A zcc B 43.91 100
31775299 R vcc 100
31775300 R xcc 100
31775301 A adc B 43.98 100
31775302 R ycc 100
31775336 A bdc B 43.91 100
31775336 R zcc 100
31776839 A cdc S 44.01 100
31776839 R wcc 100
31776840 A ddc S 44.01 100
31776846 R adc 100
31776846 A edc B 43.92 100
31776875 R bdc 100
31776905 A fdc B 43.91 100
31777051 R cdc 100
31777086 A gdc B 43.91 100
31777087 R fdc 100
31777848 A hdc S 44.01 100
31777849 R ddc 100
31777849 A idc S 44.00 100
31777885 R gdc 100
31777915 A jdc B 43.91 100
31778035 R hdc 100
31778035 R idc 100
31778035 A kdc S 44.08 100
31778077 A ldc B 43.91 100
31778077 R jdc 100
31778826 A mdc S 44.01 100
31778826 R kdc 100
31778827 A ndc S 44.01 100
31778865 R ldc 100
31778895 A odc B 43.91 100
31778987 R mdc 100
31779026 A pdc B 43.91 100
31779026 R odc 100
31779287 A qdc B 43.97 100
31779288 R edc 100
31779288 A rdc B 43.98 100
31779290 R qdc 100
31779935 A sdc S 44.01 100
31779936 R ndc 100
31779937 A tdc S 44.01 100
31779946 R rdc 100
31779946 A udc B 43.92 100
31779975 R pdc 100
31780014 A vdc B 43.91 100
31780035 R sdc 100
31780078 A wdc B 43.91 100
31780078 R vdc 100
31787497 A xdc B 43.98 100
31787498 R udc 100
31787498 A ydc B 43.98 100
31787500 R xdc 100
31788705 R tdc 100
31788705 A zdc S 44.08 100
31788736 A aec B 43.91 100
31788736 R wdc 100
31788755 R ucc 100
31788767 A bec B 43.92 100
31788767 R aec 100
31788794 A cec S 44.11 100
31788911 A dec S 44.04 20
31789446 A eec B 43.92 100
31789447 R bec 100
31789496 A fec B 43.92 100
31789496 R eec 100
31789590 A gec B 43.99 100
31789966 A hec B 43.92 100
31789966 R fec 100
31789967 R ydc 100
31789967 A iec B 43.99 100
31790495 A jec B 43.92 100
31790495 R hec 100
31790526 A kec B 43.92 100
31790526 R jec 100
31790976 A lec B 43.92 100
31790977 R kec 100
31791428 A mec B 43.99 100
31791429 R iec 100
31791429 A nec B 43.99 100
31791446 A oec B 43.92 100
31791446 R lec 100
31791477 A pec B 43.92 100
31791477 R oec 100
31791857 R mec 100
31791886 A qec B 43.93 100
31791887 R pec 100
31792871 A rec B 43.99 100
31792872 R nec 100
31792872 A sec B 43.99 100
31792877 R rec 100
31792886 R qec 100
31792916 A tec B 43.91 100
31794116 A uec B 43.92 100
31794116 R tec 100
31794186 A vec B 43.92 100
31794187 R uec 100
31794595 A wec B 43.92 100
31794596 R vec 100
31794627 A xec B 43.92 100
31794627 R wec 100
31801255 R xec 100
31801286 A yec B 43.92 100
31801295 R yec 100
31801325 A zec B 43.91 100
31801357 R sec 100
31801555 R zec 100
31801585 A afc B 43.90 100
31804927 A bfc S 44.11 100
31804927 R cec 100
31804957 A cfc S 44.11 100
31804958 R bfc 100
31807457 A dfc B 43.95 100
31807496 A efc B 43.91 100
31807496 R afc 100
31808147 A ffc B 43.92 100
31808147 R efc 100
31808365 R ffc 100
31808395 A gfc B 43.90 100
31808676 A hfc B 43.92 100
31808676 R gfc 100
31808925 R hfc 100
31808955 A ifc B 43.90 100
31809216 A jfc B 43.92 100
31809217 R ifc 100
31809436 R jfc 100
31809465 A kfc B 43.90 100
31809716 A lfc B 43.92 100
31809716 R kfc 100
31809936 R lfc 100
31809966 A mfc B 43.90 100
31810756 A nfc S 44.11 100
31810756 R cfc 100
31810787 A ofc S 44.10 100
31810787 R nfc 100
31811521 A pfc S 44.03 100
31811565 A qfc B 43.91 100
31811566 R mfc 100
31811566 R zdc 100
31811567 A rfc S 44.03 100
31812176 A sfc S 44.10 100
31812176 R ofc 100
31812206 A tfc S 44.10 100
31812206 R sfc 100
31812633 A ufc S 44.03 100
31813166 A vfc S 44.10 100
31813166 R tfc 100
31813167 R rfc 100
31813167 A wfc S 44.03 100
31813600 A xfc S 44.02 100
31814032 R pfc 100
31814033 R ufc 100
31814033 R xfc 100
31814033 R wfc 100
31814033 A yfc S 44.02 100
31814065 R vfc 100
31814095 A zfc S 44.10 100
31819072 A agc B 43.80 100
31821624 R gec 100
31821632 A bgc B 43.97 100
31821666 R qfc 100
31821677 R bgc 100
31821695 A cgc B 43.90 100
31828307 A dgc B 43.91 100
31828307 R cgc 100
31839944 A egc S 44.16 100
31840306 A fgc S 44.09 100
31840306 R zfc 100
31840337 A ggc S 44.09 100
31840337 R fgc 100
31841636 A hgc S 44.09 100
31841637 R ggc 100
31841667 A igc S 44.09 100
31841668 R hgc 100
31842636 A jgc S 44.09 100
31842636 R igc 100
31842667 A kgc S 44.09 100
31842667 R jgc 100
31843766 A lgc S 44.08 100
31843766 R kgc 100
31843796 A mgc S 44.08 100
31843796 R lgc 100
31844906 A ngc S 44.08 100
31844906 R mgc 100
31844937 A ogc S 44.08 100
31844937 R ngc 100
31845998 A pgc S 44.02 100
31845998 R yfc 100
31845999 A qgc S 44.01 100
31846007 R pgc 100
31846026 A rgc S 44.08 100
31846026 R ogc 100
31846057 A sgc S 44.08 100
31846057 R rgc 100
31846526 R dgc 100
31846556 A tgc B 43.90 100
31848617 A ugc S 44.08 100
31848617 R sgc 100
31848961 A vgc S 43.98 50
31849076 R ugc 100
31849106 A wgc S 44.08 100
31854157 A xgc B 43.98 100
31854215 A ygc B 43.90 100
31854216 R tgc 100
31858756 A zgc B 43.91 100
31858756 R ygc 100
31858774 R xgc 100
31859250 R vgc 50
31859355 R zgc 100
31859385 A ahc B 43.90 100
31860958 A bhc B 43.97 100
31862216 A chc S 44.08 100
31862216 R wgc 100
31862646 R chc 100
31862675 A dhc S 44.08 100
31863186 A ehc S 44.08 100
31863187 R dhc 100
31863505 R ehc 100
31863535 A fhc S 44.08 100
31864072 A ghc S 44.01 100
31864073 R qgc 100
31864073 A hhc S 44.00 100
31864379 A ihc B 43.97 100
31864380 A jhc B 43.97 100
31864426 A khc B 43.90 100
31864427 R ahc 100
31864427 R ghc 100
31864952 R bhc 100
31864985 R khc 100
31865015 A lhc B 43.90 100
31865200 A mhc S 44.00 100
31865201 R hhc 100
31865201 A nhc S 44.00 100
31865692 R mhc 100
31865723 R nhc 100
31865723 A ohc S 44.08 100
31866466 A phc S 44.08 100
31866466 R fhc 100
31868396 R phc 100
31868425 A qhc S 44.08 100
31868976 A rhc S 44.08 100
31868976 R qhc 100
31869306 R rhc 100
31869336 A shc S 44.08 100
31872126 A thc B 43.98 100
31872166 R shc 100
31872176 A uhc B 43.90 100
31872176 R lhc 100
31872195 A vhc S 44.11 100
31873034 R thc 100
31873075 R uhc 100
31873105 A whc B 43.90 100
31874396 A xhc B 43.91 100
31874396 R whc 100
31874846 R xhc 100
31874875 A yhc B 43.90 100
31875436 A zhc B 43.91 100
31875436 R yhc 100
31875876 R zhc 100
31875906 A aic B 43.90 100
31875925 R aic 100
31875954 A bic B 43.90 100
31876536 A cic B 43.91 100
31876537 R bic 100
31876865 R cic 100
31876895 A dic B 43.90 100
31877486 A eic B 43.98 100
31877546 A fic B 43.90 100
31877546 R ihc 100
31877546 R dic 100
31877547 A gic B 43.99 100
31877568 R jhc 100
31877569 A hic B 43.99 100
31877595 R fic 100
31877625 A iic B 43.90 100
31877733 R eic 100
31878086 A jic B 43.90 100
31878087 R iic 100
31880646 A kic B 43.91 100
31880646 R jic 100
31880666 R kic 100
31880703 A lic B 43.90 100
31887391 A mic B 43.96 100
31887413 A nic B 43.96 100
31887446 A oic B 43.90 100
31887447 R lic 100
31887477 A pic B 43.91 100
31887477 R oic 100
31887566 R pic 100
31887595 A qic B 43.90 100
31888635 A ric B 43.99 100
31888689 R gic 100
31888689 A sic B 43.99 100
31888711 R hic 100
31888712 A tic B 43.99 100
31889244 R ric 100
31910383 A uic B 43.96 100
31910384 A vic B 43.96 100
31910432 R mic 100
31910433 A wic B 43.97 100
31910433 R nic 100
31910434 A xic B 43.97 100
31913766 R qic 100
31913796 A yic B 43.90 100
31917106 A zic B 43.90 100
31917106 R yic 100
31929815 R zic 100
31929845 A ajc B 43.90 100
31933384 A bjc B 43.96 100
31933406 A cjc B 43.96 100
31933432 R uic 100
31933433 A djc B 43.97 100
31933453 R vic 100
31933454 A ejc B 43.97 100
31933484 R wic 100
31933484 A fjc B 43.97 100
31933505 R xic 100
31933506 A gjc B 43.97 100
31952846 A hjc B 44.00 100
31952894 R sic 100
31952895 R tic 100
31952895 A ijc B 44.01 100
31952896 A jjc B 44.01 100
31952896 R ejc 100
31952896 A kjc B 44.01 100
31952917 R cjc 100
31952918 R bjc 100
31952918 A ljc B 44.01 100
31952919 A mjc B 44.01 100
31952919 R djc 100
31952919 A njc B 44.01 100
31952920 R gjc 100
31952921 A ojc B 44.01 100
31952921 R fjc 100
31952922 A pjc B 44.01 100
31956383 A qjc B 44.01 100
31956406 A rjc B 44.01 100
31956916 A sjc S 44.11 100
31956916 R vhc 100
31958516 R sjc 100
31958526 A tjc B 43.92 100
31958527 R ajc 100
31958545 A ujc S 44.11 100
31967860 A vjc B 44.01 100
31967924 R ijc 100
31967925 A wjc B 44.02 100
31967947 R jjc 100
31967947 R rjc 100
31967947 A xjc B 44.02 100
31967948 R qjc 100
31967948 A yjc B 44.02 100
31967949 A zjc B 44.02 100
31967949 R ljc 100
31967950 R mjc 100
31967950 A akc B 44.02 100
31967950 A bkc B 44.02 100
31967951 R kjc 100
31967952 A ckc B 44.02 100
31967952 R njc 100
31967953 A dkc B 44.02 100
31967953 R ojc 100
31967954 A ekc B 44.02 100
31967954 R pjc 100
31967955 A fkc B 44.02 100
31973063 R vjc 100
31974375 R ujc 100
31974386 R tjc 100
31974405 A gkc S 44.11 100
31974416 A hkc B 43.97 100
31975161 R wjc 100
31975161 R xjc 100
31975161 R yjc 100
31976446 R hkc 100
31976475 A ikc B 43.92 100
31978012 A jkc S 44.04 100
31978675 R jkc 100
31979373 A kkc B 44.01 100
31979394 A lkc B 44.01 100
31979860 A mkc B 44.04 100
31979890 R fkc 100
31979913 R ekc 100
31979913 R dkc 100
31979914 R zjc 100
31979916 R akc 100
31979917 R bkc 100
31979919 R ckc 100
31979992 R mkc 100
31980036 R ikc 100
31980065 A nkc B 43.92 100
31980142 R dec 20
31982971 A okc S 44.04 100
31983400 R okc 100
31984025 A pkc S 44.11 100
31984026 R gkc 100
31984056 A qkc S 44.11 100
31984056 R pkc 100
31985110 A rkc S 44.04 100
31985353 R rkc 100
31988202 A skc S 44.16 100
31991764 A tkc S 44.04 100
31991764 R ohc 100
31991765 A ukc S 44.04 100
31992415 R tkc 100
31993188 A vkc S 44.04 100
31995091 R vkc 100
31996376 R hj 100
31998521 A wkc S 44.04 100
31999032 R wkc 100
31999950 A xkc S 47.76 22
32000830 A ykc S 53.88 260
32001461 A zkc S 50.40 12
32002413 A alc B 44.00 100
32002436 A blc B 44.00 100
32002514 A clc S 72.00 10
32003252 A dlc S 46.78 50
32003307 A elc S 48.96 63
32003447 A flc S 54.60 5
32008126 R nkc 100
32008156 A glc B 43.92 100
32020792 A hlc S 44.08 100
32022880 A ilc B 43.95 100
32022881 R ukc 100
32022882 R ilc 100
32022883 A jlc B 44.00 100
32022886 A klc S 44.06 100
32022888 R klc 100
32022907 R alc 100
32022907 A llc B 44.00 100
32022915 R qkc 100
32022916 A mlc B 43.92 100
32022917 R glc 100
32022929 R blc 100
32022930 A nlc B 44.00 100
32022945 A olc S 44.11 100
32022958 R kkc 100
32022959 A plc B 44.01 100
32022980 R lkc 100
32022980 A qlc B 44.01 100
32023146 R jlc 100
32023146 A rlc B 44.01 100
32023186 A slc B 43.93 100
32023186 R mlc 100
32024824 A tlc S 44.08 20
32024866 R slc 100
32024896 A ulc B 43.93 100
32025315 R olc 100
32025345 A vlc S 44.17 100
32025405 A wlc B 44.02 100
32025427 A xlc B 44.02 100
32025428 R rlc 100
32025428 A ylc B 44.02 100
32025445 A zlc B 43.94 100
32025446 R ulc 100
32025465 R zlc 100
32025503 A amc B 43.94 100
32027436 A bmc B 43.94 100
32027436 R amc 100
32027467 A cmc B 43.94 100
32027467 R bmc 100
32027644 A dmc B 44.03 400
32027686 A emc B 43.95 100
32027686 R cmc 100
32027716 A fmc B 43.95 100
32027717 R emc 100
32031942 R hlc 100
32031943 R ylc 100
32031944 A gmc B 44.03 100
32032912 R llc 100
32032913 R nlc 100
32032913 A hmc B 44.04 100
32032914 R qlc 100
32032914 A imc B 44.04 100
32032915 A jmc B 44.04 100
32032915 R gmc 100
32032915 R plc 100
32032915 A kmc B 44.04 100
32032916 A lmc B 44.04 100
32032956 A mmc B 43.96 100
32032957 R fmc 100
32032965 R mmc 100
32033013 A nmc B 43.96 100
32034761 A omc B 44.04 100
32034816 A pmc B 43.96 100
32034816 R nmc 100
32034847 A qmc B 43.96 100
32034847 R pmc 100
32035911 R wlc 100
32035912 R xlc 100
32035912 R kmc 100
32035912 A rmc B 44.05 100
32035912 A smc B 44.04 100
32035913 A tmc B 44.05 100
32035914 R smc 100
32035914 A umc B 44.05 100
32038157 R omc 100
32039016 A vmc S 44.13 100
32039016 R vlc 100
32039737 A wmc S 44.08 100
32039738 R umc 100
32039738 A xmc B 44.04 100
32040076 A ymc B 43.97 100
32040077 R qmc 100
32040592 R wmc 100
32040593 R xmc 100
32040593 A zmc B 44.05 100
32040635 R ymc 100
32040664 A anc B 43.97 100
32040676 A bnc B 43.97 100
32040676 R anc 100
32041676 R vmc 100
32041705 A cnc S 44.17 100
32042406 A dnc S 44.13 100
32042406 R cnc 100
32042485 A enc S 44.06 100
32042486 R zmc 100
32042486 R tlc 20
32042486 A fnc B 44.04 100
32042486 A gnc S 44.06 20
32042491 A hnc S 44.09 100
32042876 R hmc 100
32042877 A inc B 44.04 100
32042899 R imc 100
32042900 R jmc 100
32042900 A jnc B 44.04 100
32042901 A knc B 44.04 100
32042916 A lnc B 44.05 100
32042917 R gnc 20
32042917 A mnc S 44.08 20
32042921 R lmc 100
32042922 A nnc B 44.04 100
32043007 R enc 100
32043008 R fnc 100
32043008 A onc B 44.05 100
32043716 R onc 100
32043716 A pnc B 44.05 100
32043717 R hnc 100
32043745 R dnc 100
32043775 A qnc S 44.17 100
32043929 A rnc S 44.06 100
32044378 R rnc 100
32044706 A snc S 44.13 100
32044706 R qnc 100
32045295 R snc 100
32045325 A tnc S 44.17 100
32045856 A unc S 44.13 100
32045856 R tnc 100
32045860 A vnc S 44.06 100
32045861 R pnc 100
32045861 A wnc B 44.03 100
32045893 R rmc 100
32045894 A xnc B 44.06 100
32045915 R tmc 100
32045916 A ync B 44.06 100
32045936 A znc B 43.98 100
32045936 R bnc 100
32046270 R vnc 100
32046271 R wnc 100
32046271 A aoc B 44.05 100
32046306 A boc B 43.98 100
32046306 R znc 100
32046749 R xnc 100
32046749 R ync 100
32046756 A coc B 44.03 100
32046967 R coc 100
32046995 R unc 100
32047025 A doc S 44.17 100
32047096 A eoc S 44.06 100
32047420 R eoc 100
32048351 A foc B 44.06 100
32048351 R aoc 100
32048352 A goc B 44.06 100
32048372 A hoc B 44.06 100
32049276 R goc 100
32049315 A ioc S 44.17 100
32049316 R doc 100
32052865 R inc 100
32052866 A joc B 44.05 100
32052866 A koc B 44.06 100
32052887 R jnc 100
32052888 A loc B 44.05 100
32052888 R knc 100
32052888 R nnc 100
32052889 A moc B 44.05 100
32052889 A noc B 44.05 100
32055383 R koc 100
32055383 A ooc S 44.06 100
32055384 A poc B 44.05 100
32056339 R foc 100
32056339 R hoc 100
32056356 R poc 100
32056386 A qoc S 44.15 100
32056386 R ioc 100
32056406 R boc 100
32056417 A roc S 44.15 100
32056417 R qoc 100
32056443 A soc B 43.96 100
32056741 R joc 100
32056741 R loc 100
32056741 R moc 100
32057371 R ooc 100
32057642 A toc S 44.06 100
32059268 R noc 100
32059269 A uoc S 44.05 3
32059270 A voc S 44.05 100
32059271 R mnc 20
32059271 A woc S 44.05 100
32059306 R soc 100
32059316 A xoc S 44.13 100
32059317 R roc 100
32059336 A yoc B 43.95 100
32059366 A zoc S 44.13 100
32059366 R xoc 100
32059771 R lnc 100
32059816 R yoc 100
32059845 A apc B 43.93 100
32059985 R uoc 3
32059985 R voc 100
32060078 R egc 100
32060343 A bpc S 44.05 100
32060385 A cpc S 44.12 100
32060386 R zoc 100
32060386 R woc 100
32060386 A dpc S 44.05 100
32060416 A epc S 44.12 100
32060416 R cpc 100
32062344 R bpc 100
32062356 R dpc 100
32062356 A fpc S 44.05 100
32062359 A gpc S 44.07 100
32062367 R gpc 100
32062395 R epc 100
32062425 A hpc S 44.12 100
32062659 A ipc S 44.05 100
32062706 A jpc S 44.12 100
32062706 R hpc 100
32062707 R fpc 100
32062707 A kpc S 44.05 100
32062736 A lpc S 44.12 100
32062736 R jpc 100
32064107 R toc 100
32064615 R ipc 100
32064626 R kpc 100
32064626 A mpc S 44.12 100
32064630 A npc S 44.07 100
32064630 R mpc 100
32064631 A opc S 44.07 100
32064637 R npc 100
32064665 R lpc 100
32064695 A ppc S 44.15 100
32065426 A qpc B 43.96 100
32065426 R apc 100
32065655 R qpc 100
32065685 A rpc B 43.93 100
32066006 A spc B 43.96 100
32066006 R rpc 100
32066215 R spc 100
32066245 A tpc B 43.93 100
32066467 A upc B 43.96 100
32066467 R tpc 100
32066475 A vpc S 44.14 100
32066476 R ppc 100
32066695 R upc 100
32066706 A wpc S 44.14 100
32066706 R vpc 100
32066726 A xpc B 43.93 100
32066946 A ypc B 43.96 100
32066946 R xpc 100
32067426 A zpc B 43.96 100
32067426 R ypc 100
32067936 A aqc B 43.96 100
32067936 R zpc 100
32068786 R aqc 100
32068815 A bqc B 43.93 100
32069186 A cqc B 43.96 100
32069186 R bqc 100
32069537 A dqc B 43.96 100
32069537 R cqc 100
32069766 R dqc 100
32069796 A eqc B 43.96 100
32070047 A fqc B 43.96 100
32070047 R eqc 100
32070256 R fqc 100
32070286 A gqc B 43.96 100
32070536 A hqc B 43.96 100
32070537 R gqc 100
32071326 A iqc B 43.96 100
32071326 R hqc 100
32071394 A jqc B 44.04 100
32071416 A kqc B 44.04 100
32071595 R iqc 100
32071625 A lqc B 43.96 100
32072746 A mqc S 44.06 100
32072747 R opc 100
32072747 A nqc S 44.06 100
32072788 A oqc S 44.14 100
32072788 R wpc 100
32072819 A pqc S 44.13 100
32072819 R oqc 100
32072965 R mqc 100
32073241 A qqc S 44.06 100
32073242 R nqc 100
32073242 A rqc S 44.06 100
32073286 A sqc S 44.13 100
32073286 R pqc 100
32073316 A tqc S 44.13 100
32073317 R sqc 100
32073478 R qqc 100
32073479 R rqc 100
32073479 A uqc S 44.13 100
32073516 R tqc 100
32073545 A vqc S 44.16 100
32073737 A wqc S 44.06 100
32073747 R uqc 100
32073747 A xqc S 44.06 100
32073776 A yqc S 44.13 100
32073776 R vqc 100
32073816 A zqc S 44.13 100
32073816 R yqc 100
32073990 R wqc 100
32074496 R xqc 100
32074496 A arc S 44.13 100
32074499 A brc B 44.01 100
32074507 R brc 100
32074526 A crc B 43.96 100
32074526 R lqc 100
32074536 R zqc 100
32074582 A drc S 44.17 100
32074775 A erc B 44.04 200
32081899 R jqc 100
32081900 A frc B 44.05 100
32081921 R kqc 100
32081922 A grc B 44.05 100
32085525 R dmc 400
32085587 A hrc B 44.04 400
32086652 A irc B 44.05 100
32087178 R irc 100
32089947 R frc 100
32092681 A jrc S 44.08 100
32094385 A krc B 44.05 100
32094386 A lrc B 44.05 100
32094386 R arc 100
32094386 A mrc S 44.08 100
32094387 R jrc 100
32094654 A nrc B 44.05 200
32094693 R grc 100
32094694 A orc B 44.05 100
32096371 R nrc 200
32104235 A prc S 44.10 100
32107394 A qrc B 44.05 100
32107436 A rrc B 43.97 100
32107436 R crc 100
32107437 R krc 100
32107438 A src B 44.05 100
32107459 R lrc 100
32107460 A trc B 44.05 100
32107489 R orc 100
32107490 A urc B 44.06 100
32116746 A vrc S 44.14 100
32116746 R drc 100
32116994 R hz 500
32117372 A wrc B 44.05 100
32117395 A xrc B 44.05 100
32120755 A yrc S 44.08 100
32120756 R qrc 100
32120756 A zrc B 44.04 100
32120756 R mrc 100
32120757 A asc S 44.08 100
32120757 R yrc 100
32120757 R zrc 100
32120757 A bsc B 44.05 100
32120786 R vrc 100
32120799 R src 100
32120800 A csc B 44.05 100
32120816 A dsc S 44.17 100
32120821 R trc 100
32120824 A esc B 44.05 100
32120851 R urc 100
32120852 A fsc B 44.06 100
32127874 R wrc 100
32127875 A gsc B 44.05 100
32127896 R xrc 100
32127897 A hsc B 44.05 100
32129052 R hjc 100
32133206 A isc S 44.14 100
32133206 R dsc 100
32140417 A jsc B 44.05 100
32140439 A ksc B 44.05 100
32140465 R csc 100
32140466 A lsc B 44.06 100
32140488 R esc 100
32140489 R hsc 100
32140489 A msc B 44.06 100
32140490 A nsc B 44.06 100
32140490 R gsc 100
32140491 A osc B 44.06 100
32140570 R fsc 100
32140571 A psc B 44.06 100
32140575 A qsc S 44.10 100
32140656 R asc 100
32140656 R bsc 100
32140656 A rsc S 44.10 100
32140656 A ssc B 44.06 100
32140657 R qsc 100
32140685 R isc 100
32140696 A tsc B 43.97 100
32140696 R rrc 100
32140714 A usc S 44.17 100
32140744 A vsc B 43.97 100
32140744 R tsc 100
32145118 R psc 100
32145118 R ssc 100
32145118 R lsc 100
32145156 A wsc B 43.98 100
32145157 R vsc 100
32163403 A xsc B 44.05 100
32163425 A ysc B 44.05 100
32163426 A zsc B 44.05 100
32163426 A atc B 44.05 100
32163452 R jsc 100
32163453 A btc B 44.05 100
32163475 R ksc 100
32163476 A ctc B 44.05 100
32174996 A dtc B 44.01 100
32174996 R wsc 100
32185907 A etc B 44.06 200
32185926 R msc 100
32185927 A ftc B 44.07 100
32185949 R osc 100
32185949 R xsc 100
32185950 A gtc B 44.07 100
32185950 A htc B 44.07 100
32185950 R zsc 100
32185951 A itc B 44.07 100
32185952 R ysc 100
32185953 R ctc 100
32185953 A jtc B 44.07 100
32185954 A ktc B 44.07 100
32185954 R btc 100
32185955 R nsc 100
32185955 A ltc B 44.07 100
32185956 A mtc B 44.07 100
32185978 R atc 100
32185979 A ntc B 44.07 100
32190349 A otc B 44.07 100
32190371 A ptc B 44.07 100
32191750 A qtc B 44.09 20
32195865 R ftc 100
32195866 R gtc 100
32195866 A rtc B 44.09 100
32195866 R ltc 100
32195867 A stc B 44.09 100
32195867 A ttc B 44.09 100
32195867 R htc 100
32195868 A utc B 44.09 100
32195868 R ktc 100
32195869 A vtc B 44.09 100
32195869 R mtc 100
32195870 A wtc B 44.09 100
32195915 R jtc 100
32195916 A xtc B 44.09 100
32195937 R itc 100
32195938 R ntc 100
32195938 A ytc B 44.09 100
32195939 A ztc B 44.09 100
32199948 R qtc 20
32199948 R rtc 100
32199948 R stc 80
32199952 R etc 200
32202406 R stc 20
32202406 R ttc 80
32210130 R ttc 20
32210130 R utc 100
32210130 R vtc 80
32210178 R ptc 100
32210178 A auc B 44.09 100
32210200 R otc 100
32210201 A buc B 44.09 100
32215860 A cuc B 44.04 100
32217402 A duc B 44.04 100
32217424 A euc B 44.04 100
32230085 R dtc 100
32230115 A fuc B 43.99 100
32230187 R cuc 100
32230187 R rsc 100
32230187 A guc S 44.14 100
32230188 A huc B 44.09 80
32230226 R usc 100
32230247 R duc 100
32230248 A iuc B 44.05 100
32230256 A juc S 44.17 100
32230270 R wtc 100
32230270 R ytc 100
32230270 A kuc B 44.09 100
32230271 R huc 80
32230271 A luc B 44.09 100
32230271 R auc 100
32230271 A muc B 44.05 80
32230272 R buc 100
32230272 A nuc B 44.09 100
32230273 R ztc 100
32230273 A ouc B 44.09 100
32230274 A puc B 44.09 100
32230274 R xtc 100
32230275 R muc 80
32230275 A quc B 44.09 80
32230275 R vtc 20
32230275 A ruc B 44.09 100
32230276 A suc B 44.09 20
32230276 R euc 100
32230277 A tuc B 44.05 100
32230625 R kuc 100
32239277 A uuc B 44.02 100
32239277 R fuc 100
32257140 R luc 100
32257140 R nuc 100
32257140 R ouc 100
32257140 R puc 100
32257140 R quc 80
32257140 R ruc 100
32257140 R suc 20
32257144 A vuc S 44.12 200
32257144 R guc 100
32257145 A wuc S 44.12 100
32257156 R wuc 100
32257157 A xuc S 44.10 100
32257168 R vuc 200
32257186 R uuc 100
32257206 A yuc S 44.17 100
32257206 R juc 100
32257216 A zuc B 43.98 100
32257216 R zuc 100
32257247 A avc B 43.98 100
32258126 A bvc S 44.16 100
32258127 R yuc 100
32258139 A cvc S 44.11 200
32258142 A dvc S 44.10 200
32258142 A evc B 44.04 100
32258143 R xuc 100
32258143 A fvc S 44.10 100
32258147 R dvc 200
32258166 R avc 100
32258177 A gvc S 44.16 100
32258177 R bvc 100
32258196 A hvc B 43.97 100
32259872 A ivc S 44.09 13
32259879 A jvc S 44.09 100
32259950 R iuc 100
32259951 R fvc 100
32259951 R tuc 100
32259951 A kvc S 44.09 100
32259951 A lvc B 44.05 100
32259952 A mvc B 44.05 100
32259953 R cvc 200
32259955 A nvc B 44.02 100
32262836 A ovc B 43.97 100
32262837 R hvc 100
32265403 R ivc 13
32265405 R jvc 100
32265586 A pvc B 43.97 100
32265587 R ovc 100
32266142 A qvc S 44.08 13
32266144 A rvc S 44.08 100
32266156 R kvc 100
32266156 A svc S 44.08 100
32266187 A tvc S 44.16 100
32266187 R gvc 100
32266635 R qvc 13
32266636 R rvc 100
32266646 R svc 100
32266646 A uvc S 44.10 100
32266648 R nvc 100
32266648 A vvc S 44.09 100
32266656 R vvc 100
32266676 R tvc 100
32266705 A wvc S 44.16 100
32267071 A xvc S 44.08 13
32267073 A yvc S 44.08 100
32267116 R uvc 100
32267116 A zvc S 44.08 100
32267117 A awc S 44.16 100
32267117 R wvc 100
32267147 A bwc S 44.16 100
32267148 R awc 100
32267427 R xvc 13
32267427 R yvc 100
32267702 A cwc S 44.08 13
32267704 A dwc S 44.08 100
32268019 R cwc 13
32268019 R dwc 100
32268334 A ewc S 44.08 13
32268586 R ewc 13
32268869 A fwc S 44.08 13
32276677 R lvc 100
32276698 R mvc 100
32293814 R xj 100
32295016 R pvc 100
32295026 R bwc 100
32295046 A gwc B 43.97 100
32295056 A hwc S 44.16 100
32297206 A iwc S 44.15 100
32297207 R hwc 100
32297237 A jwc S 44.15 100
32297237 R iwc 100
32324170 A kwc B 44.04 50
32337208 R fwc 13
32337211 A lwc S 44.10 100
32437215 R lwc 100
32466817 R zvc 100
32466817 A mwc S 44.10 100
32466819 A nwc S 44.09 100
32466820 R mwc 100
32466820 A owc S 44.09 100
32466822 A pwc S 44.10 100
32466822 R nwc 100
32466827 A qwc B 43.98 100
32466827 R gwc 100
32466828 R pwc 100
32466856 R jwc 100
32466886 A rwc S 44.16 100
32478127 A swc B 44.05 87
32503187 A twc S 44.16 100
32503187 R rwc 100
32505703 A uwc S 44.15 100
32507026 A vwc S 44.16 100
32507026 R twc 100
32508748 A wwc S 44.11 100
32508776 R qwc 100
32508806 A xwc B 43.97 100
32516677 A ywc B 44.05 253
32530824 R swc 87
32530825 R evc 100
32530825 A zwc B 44.05 5
32537145 A axc B 44.05 100
32547857 R axc 100
32578897 R owc 100
32578897 A bxc S 44.10 100
32578899 A cxc S 44.09 100
32578907 R cxc 100
32578926 A dxc B 44.01 100
32578927 R xwc 100
32578935 R vwc 100
32578984 A exc S 44.16 100
32580725 A fxc S 44.09 100
32580725 R bxc 100
32580726 A gxc S 44.09 100
32580727 R fxc 100
32580746 R dxc 100
32580766 A hxc S 44.16 100
32580766 R exc 100
32580775 A ixc B 43.98 100
32580786 R ixc 100
32580832 A jxc B 43.97 100
32582928 A kxc B 44.05 100
32582929 R zwc 5
32582929 A lxc B 44.05 5
32582946 R kxc 100
32582956 A mxc B 43.99 100
32582957 R jxc 100
32582966 R hxc 100
32583014 A nxc S 44.16 100
32587929 R uwc 100
32587935 A oxc S 44.18 100
32591476 R mxc 100
32591486 A pxc S 44.16 100
32591487 R nxc 100
32591506 A qxc B 43.97 100
32593396 A rxc S 44.08 100
32593436 A sxc S 44.16 100
32593437 R pxc 100
32593467 A txc S 44.15 100
32593467 R sxc 100
32593775 R rxc 100
32593778 A uxc S 44.09 100
32593779 R wwc 100
32593779 A vxc S 44.10 100
32593780 R gxc 100
32593780 A wxc S 44.09 100
32593781 R uxc 100
32593798 R vxc 100
32593826 R txc 100
32593856 A xxc S 44.16 100
32594980 A yxc S 44.08 100
32595036 A zxc S 44.16 100
32595037 R xxc 100
32595346 R zxc 100
32595353 R yxc 100
32595357 A ayc S 44.11 100
32595375 A byc S 44.16 100
32596306 A cyc S 44.16 100
32596307 R byc 100
32596337 A dyc S 44.15 100
32596337 R cyc 100
32596946 A eyc S 44.08 100
32597016 A fyc S 44.15 100
32597016 R dyc 100
32599039 R eyc 100
32599042 R ayc 100
32599076 R fyc 100
32599106 A gyc S 44.15 100
32602396 R kwc 50
32602461 A hyc B 44.05 50
32602469 A iyc S 44.10 200
32602496 R gyc 100
32602525 A jyc S 44.16 100
32602576 R wxc 100
32602576 A kyc S 44.10 100
32602577 A lyc S 44.10 100
32602580 A myc B 44.05 100
32602596 A nyc B 44.00 100
32602596 R qxc 100
32602603 A oyc S 44.09 100
32602604 R kyc 100
32602604 A pyc S 44.09 100
32602605 R oyc 100
32602938 R myc 100
32602966 R nyc 100
32602986 A qyc S 44.15 100
32602986 R jyc 100
32602995 A ryc B 43.97 100
32612356 A syc B 44.00 100
32612356 R ryc 100
32612366 R qyc 100
32612413 A tyc S 44.16 100
32613206 R syc 100
32613227 A uyc S 44.15 100
32613227 R tyc 100
32613236 A vyc B 43.97 100
32614359 A wyc B 44.07 100
32614396 R uyc 100
32614407 A xyc B 43.98 100
32614407 R vyc 100
32614425 A yyc S 44.16 100
32614589 A zyc S 44.09 100
32614598 R fdb 100
32614604 A azc S 44.14 100
32615107 R wyc 100
32615109 R pyc 100
32615109 A bzc S 44.09 100
32615147 R xyc 100
32615156 A czc S 44.15 100
32615157 R yyc 100
32615177 A dzc B 43.97 100
32616126 R bzc 100
32616127 A ezc S 44.10 100
32616146 A fzc B 44.00 100
32616146 R dzc 100
32616156 R czc 100
32616203 A gzc S 44.16 100
32616776 R ezc 100
32616777 A hzc S 44.09 100
32616805 R fzc 100
32616825 A izc S 44.15 100
32616826 R gzc 100
32616836 A jzc B 43.97 100
32617436 R hzc 100
32617436 A kzc S 44.10 100
32617456 A lzc B 44.00 100
32617456 R jzc 100
32617466 R izc 100
32617513 A mzc S 44.16 100
32617706 R kzc 100
32617707 A nzc S 44.09 100
32617736 R lzc 100
32617757 A ozc S 44.15 100
32617757 R mzc 100
32617766 A pzc B 43.97 100
32618331 R azc 100
32618655 R nzc 100
32618656 A qzc S 44.10 100
32618676 A rzc B 44.00 100
32618676 R pzc 100
32618685 R ozc 100
32618733 A szc S 44.16 100
32619806 R qzc 100
32619806 A tzc S 44.09 100
32619836 R rzc 100
32619856 A uzc S 44.15 100
32619856 R szc 100
32619865 A vzc B 43.97 100
32620866 A wzc S 44.08 100
32620886 A xzc S 44.15 100
32620887 R uzc 100
32621540 R wzc 100
32621543 R iyc 200
32621544 A yzc S 44.10 200
32621576 R xzc 100
32621606 A zzc S 44.15 100
32622306 R tzc 100
32622306 A aad S 44.10 100
32622310 A bad B 44.05 100
32622318 R yzc 200
32622336 A cad B 44.00 100
32622337 R vzc 100
32622346 R zzc 100
32622394 A dad S 44.16 100
32622626 R aad 100
32622626 A ead S 44.09 100
32622628 R bad 100
32622655 R cad 100
32622677 A fad S 44.15 100
32622677 R dad 100
32622685 A gad B 43.97 100
32624157 A had S 44.08 100
32624187 A iad S 44.15 100
32624187 R fad 100
32624388 R had 100
32624391 A jad S 44.10 100
32624426 R iad 100
32624456 A kad S 44.15 100
32624968 A lad S 44.07 100
32627052 R lad 100
32629597 A mad S 44.15 100
32629597 R kad 100
32630416 R mad 100
32630446 A nad S 44.15 100
32631266 A oad S 44.15 100
32631266 R nad 100
32631776 R oad 100
32631805 A pad S 44.15 100
32632361 A qad S 44.08 100
32633003 R qad 100
32633576 A rad S 44.15 100
32633576 R pad 100
32634387 R rad 100
32634417 A sad S 44.15 100
32635236 A tad S 44.15 100
32635236 R sad 100
32635825 R tad 100
32635855 A uad S 44.15 100
32636057 A vad S 44.08 100
32636493 R vad 100
32637226 A wad S 44.15 100
32637227 R uad 100
32637515 A xad S 44.08 100
32637696 R wad 100
32637726 A yad S 44.15 100
32638089 R xad 100
32638473 A zad B 44.07 100
32638474 R ead 100
32638474 A abd S 44.10 100
32638488 R jad 100
32638491 A bbd S 44.10 200
32638517 R yad 100
32638518 A cbd B 43.98 100
32638518 R gad 100
32638547 A dbd S 44.16 100
32638587 A ebd B 44.00 100
32638587 R cbd 100
32639087 R zad 100
32639096 R abd 100
32639097 A fbd S 44.09 100
32639126 R ebd 100
32639146 A gbd S 44.15 100
32639146 R dbd 100
32639156 A hbd B 43.97 100
32647666 R fbd 100
32647667 A ibd S 44.10 100
32647697 R gbd 100
32647698 A jbd B 43.98 100
32647698 R hbd 100
32647726 A kbd S 44.16 100
32647755 A lbd B 44.01 100
32647755 R jbd 100
32651497 R ibd 100
32651498 A mbd S 44.09 100
32651526 R lbd 100
32651556 A nbd B 43.98 100
32655665 A obd S 44.08 100
32656249 R obd 100
32657316 A pbd S 44.15 100
32657316 R kbd 100
32658006 R pbd 100
32658035 A qbd S 44.16 100
32658986 A rbd S 44.15 100
32658986 R qbd 100
32659396 R rbd 100
32659425 A sbd S 44.16 100
32660306 R mbd 100
32660306 A tbd S 44.10 100
32660310 A ubd B 44.05 100
32660336 A vbd B 44.00 100
32660336 R nbd 100
32660686 R tbd 100
32660687 A wbd S 44.09 100
32660688 R ubd 100
32660716 R vbd 100
32660736 A xbd S 44.15 100
32660736 R sbd 100
32660746 A ybd B 43.98 100
32661967 A zbd S 44.15 100
32661967 R xbd 100
32662516 R zbd 100
32662546 A acd S 44.15 100
32702266 R wbd 100
32702267 A bcd S 44.10 100
32702296 A ccd B 44.00 100
32702296 R ybd 100
32702306 R acd 100
32702327 A dcd B 44.00 100
32702327 R ccd 100
32702353 A ecd S 44.16 100
32706741 A fcd S 44.16 50
32715506 R lyc 100
32715516 R bcd 100
32715516 A gcd S 44.10 100
32715519 R bbd 200
32715545 R ecd 100
32715576 A hcd S 44.16 100
32715646 R zyc 100
32715667 R gcd 100
32715667 A icd S 44.16 100
32715686 R hcd 100
32715716 A jcd S 44.17 100
32716265 A kcd S 44.10 4900
32718986 A lcd S 44.28 100
32719831 R kcd 4900
32726167 R prc 100
32726200 A mcd S 44.15 100
32726206 R jcd 100
32726207 R icd 100
32726207 A ncd S 44.15 100
32726209 R mcd 100
32726236 A ocd S 44.21 100
32731026 A pcd B 44.09 100
32731026 R lxc 5
32731027 A qcd B 44.09 100
32732183 A rcd B 44.09 100
32732608 R rcd 100
32736495 A scd B 44.09 100
32736587 A tcd B 44.02 100
32736587 R dcd 100
32741412 R scd 100
32741417 A ucd S 44.16 100
32741566 R pcd 100
32745856 R hyc 50
32747458 R ucd 100
32747486 R ocd 100
32747487 A vcd B 44.03 100
32747487 R tcd 100
32747515 A wcd S 44.23 100
32747588 R ncd 100
32747647 A xcd B 44.08 100
32747647 R vcd 100
32747666 R xcd 100
32747667 A ycd S 44.22 100
32747667 R wcd 100
32747686 R ycd 100
32747696 A zcd B 44.03 100
32747716 A add S 44.23 100
32748176 R zcd 100
32748206 A bdd B 44.02 100
32750346 A cdd B 44.03 100
32750346 R bdd 100
32750974 A ddd S 44.15 100
32751056 A edd B 44.03 100
32751057 R cdd 100
32751464 A fdd B 44.10 200
32751465 R qcd 100
32751465 A gdd B 44.10 100
32751467 R fdd 200
32752078 A hdd B 44.11 100
32752078 R gdd 100
32752079 A idd B 44.11 100
32752117 A jdd B 44.03 100
32752117 R edd 100
32752126 R jdd 100
32752174 A kdd B 44.04 100
32752917 A ldd B 44.04 100
32752917 R kdd 100
32753653 R dfc 100
32754896 R ldd 100
32754926 A mdd B 44.04 100
32755782 R hdd 100
32755827 A ndd B 44.04 100
32755827 R mdd 100
32756376 A odd B 44.05 100
32756376 R ndd 100
32756406 A pdd B 44.05 100
32756407 R odd 100
32756526 A qdd B 44.05 100
32756526 R pdd 100
32756916 R qdd 100
32756946 A rdd B 44.05 100
32757387 A sdd B 44.05 100
32757387 R rdd 100
32757417 A tdd B 44.05 100
32757417 R sdd 100
32759275 R ddd 100
32765950 A udd S 44.15 100
32766338 R at 100
32770191 R udd 100
32776133 A vdd S 44.15 200
32778306 R tdd 100
32778335 A wdd B 44.02 100
32779588 A xdd S 44.23 100
32779588 R add 100
32780396 R xdd 100
32780426 A ydd S 44.23 100
32789096 A zdd S 44.22 100
32789097 R ydd 100
32790966 A aed S 44.22 100
32790966 R zdd 100
32803749 A bed B 44.12 50
32825411 R vdd 200
32825446 R aed 100
32825477 A ced S 44.23 100
32827657 A ded B 44.12 100
32827658 R idd 100
32827658 A eed B 44.12 100
32834782 R skc 100
32834786 A fed S 44.18 100
32834826 A ged B 44.03 100
32834826 R wdd 100
32834856 A hed B 44.03 100
32834857 R ged 100
32839433 R eed 100
32839434 A ied S 44.18 100
32839477 A jed S 44.23 100
32839477 R ced 100
32840291 R ded 100
32840295 R fed 100
32843278 A ked B 44.12 100
32843279 A led B 44.05 100
32843316 R led 100
32843317 A med B 44.12 100
32843914 R ked 100
32845911 A ned B 44.13 100
32845912 R med 100
32845913 A oed B 44.13 100
32846850 R ned 100
32847525 A ped B 44.13 100
32847526 R oed 100
32847527 A qed B 44.13 100
32847540 A red S 44.18 100
32847566 R jed 100
32847576 A sed B 44.04 100
32847576 R hed 100
32847596 A ted S 44.23 100
32847626 A ued B 44.04 100
32847627 R sed 100
32848194 R ped 100
32848965 A ved B 44.13 100
32849514 R ved 100
32849597 A wed S 44.23 100
32849597 R ted 100
32851102 A xed B 44.13 100
32856734 R xed 100
32856872 A yed S 44.13 100
32856886 R qed 100
32856886 A zed B 44.05 100
32856890 R red 100
32856890 A afd B 44.09 100
32856917 A bfd S 44.22 100
32856917 R wed 100
32856947 A cfd S 44.22 100
32856947 R bfd 100
32864157 R ied 100
32864157 A dfd S 44.13 100
32864157 R zed 100
32864158 A efd B 44.09 100
32864158 R dfd 100
32864158 A ffd S 44.18 100
32864168 R afd 100
32864171 A gfd S 44.14 200
32864171 R ffd 100
32864172 A hfd S 44.13 100
32864176 R hfd 100
32864176 A ifd S 44.14 100
32864186 A jfd S 44.19 100
32864187 R cfd 100
32864196 R ued 100
32864226 R ifd 100
32864226 A kfd S 44.13 100
32864243 A lfd B 44.04 100
32864246 R lfd 100
32864275 A mfd B 44.00 100
32864277 A nfd B 44.01 100
32864277 R mfd 100
32869521 A ofd S 44.13 100
32869526 R nfd 100
32869527 R ofd 100
32869527 R kfd 100
32869528 A pfd S 44.14 100
32869537 A qfd S 44.19 100
32869537 R jfd 100
32869556 A rfd B 44.01 100
32869557 R qfd 100
32869613 A sfd S 44.19 100
32871339 A tfd S 44.15 200
32874880 R bed 50
32874881 R pfd 100
32874882 A ufd S 44.13 100
32874917 A vfd S 44.19 100
32874917 R sfd 100
32874922 A wfd S 44.13 100
32875647 R wfd 100
32875649 A xfd S 44.13 200
32875656 A yfd B 44.02 100
32875656 R rfd 100
32875657 A zfd S 44.13 100
32875657 R ufd 100
32875658 R xfd 200
32875673 A agd B 44.09 100
32875675 R vfd 100
32875686 A bgd B 44.02 100
32875686 R yfd 100
32875687 R efd 100
32875687 A cgd B 44.09 100
32875713 A dgd S 44.19 100
32875718 R agd 100
32875726 A egd S 44.19 100
32875727 R dgd 100
32875736 R egd 100
32875766 A fgd S 44.19 100
32885451 A ggd S 44.19 200
32894986 R zfd 100
32894986 A hgd S 44.13 100
32894988 R gfd 200
32895016 R fgd 100
32895046 A igd S 44.22 100
32895426 R cgd 100
32895427 A jgd B 44.05 97
32895430 A kgd B 44.07 100
32895438 R kgd 100
32895444 R hgd 100
32895456 A lgd S 44.17 100
32895457 R igd 100
32895457 R lgd 100
32895467 R bgd 100
32895481 R yed 100
32895482 A mgd S 44.13 100
32895488 A ngd S 44.22 100
32895513 A ogd B 44.00 100
32895561 R mgd 100
32895563 A pgd S 44.13 100
32900453 A qgd S 44.13 100
32900628 R qgd 100
32900731 A rgd S 44.13 100
32900744 R rgd 100
32900804 A sgd S 44.13 100
32901360 R sgd 100
32903077 A tgd B 44.03 100
32903078 R ogd 100
32909067 A ugd B 44.03 100
32909067 R tgd 100
32913787 A vgd B 44.06 100
32913788 R jgd 97
32913789 A wgd B 44.06 100
32914763 R pt 200
32914927 A xgd B 44.03 100
32914927 R ugd 100
32918314 R vgd 100
32924067 A ygd B 44.03 100
32924067 R xgd 100
32924852 A zgd B 44.11 50
32927761 R pgd 100
32927762 A ahd S 44.13 100
32927765 A bhd S 44.16 100
32927817 A chd S 44.21 100
32927818 R ngd 100
32929896 R ahd 100
32929897 A dhd S 44.13 100
32929899 R bhd 100
32929900 A ehd S 44.16 100
32929908 R ehd 100
32929937 R chd 100
32929967 A fhd S 44.22 100
32934577 A ghd S 44.21 100
32934577 R fhd 100
32937303 A hhd S 44.13 100
32937347 R ghd 100
32937377 A ihd S 44.20 100
32940587 R hhd 100
32940626 R ihd 100
32940656 A jhd S 44.22 100
32941100 A khd S 44.13 100
32941136 A lhd S 44.22 100
32941137 R jhd 100
32941167 A mhd S 44.20 100
32941167 R lhd 100
32941481 R khd 100
32941516 R mhd 100
32941546 A nhd S 44.22 100
32941885 A ohd S 44.13 100
32941917 A phd S 44.20 100
32941917 R nhd 100
32942226 R ohd 100
32942266 R phd 100
32942296 A qhd S 44.22 100
32942588 A rhd S 44.13 100
32942627 A shd S 44.22 100
32942628 R qhd 100
32942658 A thd S 44.20 100
32942658 R shd 100
32943000 R rhd 100
32943036 R thd 100
32943066 A uhd S 44.22 100
32943373 A vhd S 44.13 100
32943417 A whd S 44.22 100
32943417 R uhd 100
32943473 A xhd S 44.20 100
32943474 R whd 100
32943760 R vhd 100
32943764 A yhd S 44.15 100
32943768 R yhd 100
32943795 R xhd 100
32943825 A zhd S 44.22 100
32944125 A aid S 44.13 100
32944167 A bid S 44.22 100
32944167 R zhd 100
32944356 A cid S 44.20 100
32944356 R bid 100
32944366 R ygd 100
32944395 A did B 44.00 100
32944608 R aid 100
32944646 R cid 100
32944676 A eid S 44.22 100
32944996 A fid S 44.13 100
32945037 A gid S 44.22 100
32945037 R eid 100
32945067 A hid S 44.20 100
32945067 R gid 100
32945424 R fid 100
32945466 R hid 100
32945495 A iid S 44.22 100
32945765 A jid S 44.13 100
32945806 A kid S 44.22 100
32945807 R iid 100
32945917 A lid S 44.20 100
32945917 R kid 100
32946200 R jid 100
32946235 R lid 100
32946265 A mid S 44.22 100
32946596 A nid S 44.13 100
32946638 A oid S 44.22 100
32946638 R mid 100
32946668 A pid S 44.20 100
32946669 R oid 100
32946984 R nid 100
32947026 R pid 100
32947056 A qid S 44.22 100
32947339 A rid S 44.13 100
32947377 A sid S 44.22 100
32947377 R qid 100
32947408 A tid S 44.20 100
32947408 R sid 100
32947689 R rid 100
32947725 R tid 100
32947755 A uid S 44.22 100
32948148 A vid S 44.13 100
32948186 A wid S 44.22 100
32948186 R uid 100
32948267 A xid S 44.20 100
32948267 R wid 100
32948551 R vid 100
32948586 R xid 100
32948616 A yid S 44.22 100
32948884 A zid S 44.13 100
32948926 A ajd S 44.22 100
32948927 R yid 100
32949066 A bjd S 44.20 100
32949067 R ajd 100
32949336 R bjd 100
32949339 R zid 100
32949366 A cjd S 44.22 100
32949643 A djd S 44.13 100
32949776 A ejd S 44.20 100
32949777 R cjd 100
32950777 A fjd S 44.19 100
32950777 R ejd 100
32955444 R zgd 50
32955445 A gjd B 44.10 50
32955450 A hjd B 44.05 100
32961044 A ijd S 44.11 20
32968771 R ijd 20
32968819 A jjd S 44.13 100
32974603 R djd 100
32976992 A kjd B 44.12 100
32977047 R jjd 100
32977063 R hjd 100
32977077 R fjd 100
32977077 R wgd 100
32977078 A ljd B 44.12 100
32977107 A mjd B 44.03 100
32977107 R did 100
32977107 A njd S 44.22 100
32977146 A ojd B 44.03 100
32977146 R mjd 100
32977207 A pjd S 44.19 100
32977207 R njd 100
32977207 R pjd 100
32977238 A qjd S 44.22 100
32977427 A rjd S 44.19 100
32977427 R qjd 100
32977436 R rjd 100
32977465 A sjd S 44.22 100
32977646 A tjd S 44.19 100
32977647 R sjd 100
32977647 R tjd 100
32977677 A ujd S 44.22 100
32977866 A vjd S 44.19 100
32977867 R ujd 100
32977867 R vjd 100
32977898 A wjd S 44.22 100
32978087 A xjd S 44.19 100
32978087 R wjd 100
32978087 R xjd 100
32978118 A yjd S 44.22 100
32978306 A zjd S 44.19 100
32978306 R yjd 100
32978307 R zjd 100
32978337 A akd S 44.22 100
32978527 A bkd S 44.19 100
32978527 R akd 100
32978527 R bkd 100
32978558 A ckd S 44.22 100
32978747 A dkd S 44.19 100
32978747 R ckd 100
32978747 R dkd 100
32978778 A ekd S 44.22 100
32978957 A fkd S 44.19 100
32978957 R ekd 100
32978967 R fkd 100
32978996 A gkd S 44.22 100
32979176 A hkd S 44.19 100
32979176 R gkd 100
32979177 R hkd 100
32979207 A ikd S 44.22 100
32979396 A jkd S 44.19 100
32979397 R ikd 100
32979397 R jkd 100
32979428 A kkd S 44.22 100
32979617 A lkd S 44.19 100
32979617 R kkd 100
32979618 R lkd 100
32979648 A mkd S 44.22 100
32979837 A nkd S 44.19 100
32979838 R mkd 100
32979838 R nkd 100
32979869 A okd S 44.22 100
32980057 A pkd S 44.19 100
32980057 R okd 100
32980057 R pkd 100
32980088 A qkd S 44.22 100
32980247 R ljd 100
32980247 A rkd B 44.05 100
32980277 A skd S 44.19 100
32980277 R qkd 100
32980277 R skd 100
32980308 A tkd S 44.22 100
32980536 A ukd S 44.20 100
32980537 R tkd 100
32981242 R kjd 100
32981244 A vkd B 44.09 100
32981244 R rkd 100
32981245 A wkd B 44.09 100
32981246 R vkd 100
32981246 A xkd B 44.08 100
32984727 A ykd B 44.03 100
32984727 R ojd 100
32985296 R ykd 100
32985304 R gjd 50
32985325 A zkd B 44.03 100
32985335 A ald S 44.13 100
32985429 R xkd 100
32985455 R zkd 100
32985466 A bld S 44.19 100
32985467 R ukd 100
32985501 A cld B 44.00 100
32986811 A dld S 44.12 100
32986812 R ald 100
32986812 A eld S 44.12 100
32986857 A fld S 44.19 100
32986857 R bld 100
32986888 A gld S 44.19 100
32986888 R fld 100
32987072 R dld 100
32987339 A hld S 44.12 100
32987713 R hld 100
32988035 A ild S 44.12 100
32988036 R eld 100
32988036 A jld S 44.12 100
32988077 A kld S 44.19 100
32988077 R gld 100
32988108 A lld S 44.19 100
32988109 R kld 100
32988248 R ild 100
32988483 A mld S 44.12 100
32988484 R jld 100
32988484 A nld S 44.12 100
32988527 A old S 44.19 100
32988527 R lld 100
32988557 A pld S 44.19 100
32988557 R old 100
32988696 R mld 100
32988922 A qld S 44.11 100
32988946 R nld 100
32988946 A rld S 44.11 100
32988977 A sld S 44.19 100
32988977 R pld 100
32989008 A tld S 44.19 100
32989008 R sld 100
32989144 R qld 100
32989156 R rld 100
32989157 A uld S 44.13 100
32989159 A vld S 44.12 100
32989160 R uld 100
32989160 A wld S 44.12 100
32989160 A xld S 44.13 100
32989161 R vld 100
32989168 R xld 100
32989197 R tld 100
32989227 A yld S 44.19 100
32989368 A zld S 44.12 100
32989369 R wld 100
32989369 A amd S 44.12 100
32989376 R amd 100
32989376 A bmd S 44.12 100
32989407 A cmd S 44.19 100
32989407 R yld 100
32989583 R zld 100
32989626 R cmd 100
32989656 A dmd S 44.19 100
32989816 R wkd 100
32989820 A emd B 44.05 200
32989844 A fmd S 44.12 100
32989857 A gmd B 44.00 100
32989858 R cld 100
32989858 R bmd 100
32989858 A hmd S 44.12 100
32989887 A imd S 44.19 100
32989887 R dmd 100
32989917 A jmd S 44.19 100
32989918 R imd 100
32990055 R fmd 100
32990347 A kmd S 44.19 100
32990347 R jmd 100
32990378 A lmd S 44.19 100
32990378 R kmd 100
32990387 A mmd S 44.11 100
32990575 R mmd 100
32990579 A nmd S 44.13 100
32990867 A omd B 44.05 100
32991858 A pmd S 44.11 100
32991907 A qmd S 44.18 100
32991907 R lmd 100
32991938 A rmd S 44.18 100
32991938 R qmd 100
32992071 R pmd 100
32992074 R nmd 100
32992289 A smd S 44.11 100
32992290 R hmd 100
32992290 A tmd S 44.11 100
32992337 A umd S 44.18 100
32992337 R rmd 100
32992512 R smd 100
32992546 R umd 100
32992576 A vmd S 44.18 100
32992753 A wmd S 44.11 100
32992754 R tmd 100
32992754 A xmd S 44.11 100
32992797 A ymd S 44.18 100
32992797 R vmd 100
32992827 A zmd S 44.18 100
32992828 R ymd 100
32992968 R wmd 100
32993335 A and S 44.10 100
32993336 R xmd 100
32993336 A bnd S 44.10 100
32993441 R and 100
32998342 A cnd B 44.08 100
32999506 R ywc 253
33004820 R cnd 100
33020702 A dnd B 44.04 10
33021096 A end S 44.10 200
33021136 R gmd 100
33021137 R bnd 100
33021137 A fnd S 44.10 100
33021166 A gnd B 44.00 100
33057517 A hnd S 44.16 100
33057517 R zmd 100
33059702 A ind B 44.09 100
33063359 R emd 200
33063360 A jnd S 44.11 100
33063509 R jnd 100
33063536 R hnd 100
33063547 A knd B 44.00 100
33063547 R gnd 100
33063566 A lnd S 44.18 100
33063567 A mnd S 44.18 100
33063567 R lnd 100
33063809 A nnd S 44.11 100
33063817 A ond S 44.17 100
33063818 R mnd 100
33063837 R knd 100
33063848 A pnd S 44.16 100
33063849 R ond 100
33063866 A qnd B 44.00 100
33069826 A rnd B 44.04 100
33070545 A snd B 44.09 100
33070564 R snd 100
33070565 A tnd B 44.09 100
33070587 A und B 44.00 100
33070587 R qnd 100
33070606 R und 100
33070645 A vnd B 44.00 100
33075511 A wnd B 44.05 100
33076669 R nnd 100
33076696 R pnd 100
33076726 A xnd S 44.19 100
33076727 A ynd S 44.19 100
33076727 R xnd 100
33077017 A znd S 44.16 100
33077017 R ynd 100
33077017 R znd 100
33077048 A aod S 44.19 100
33077196 A bod S 44.16 100
33077196 R aod 100
33077197 R bod 100
33077227 A cod S 44.19 100
33077417 A dod S 44.16 100
33077417 R cod 100
33077418 R dod 100
33077448 A eod S 44.19 100
33077627 A fod S 44.16 100
33077628 R eod 100
33077636 R fod 100
33077665 A god S 44.19 100
33077857 A hod S 44.16 100
33077857 R god 100
33077858 R hod 100
33077888 A iod S 44.19 100
33078067 A jod S 44.16 100
33078067 R iod 100
33078068 R jod 100
33078097 A kod S 44.19 100
33078287 A lod S 44.16 100
33078287 R kod 100
33078288 R lod 100
33078318 A mod S 44.19 100
33078507 A nod S 44.16 100
33078507 R mod 100
33078508 R nod 100
33078538 A ood S 44.19 100
33078727 A pod S 44.16 100
33078727 R ood 100
33078728 R pod 100
33078758 A qod S 44.19 100
33078947 A rod S 44.16 100
33078947 R qod 100
33078947 R rod 100
33078978 A sod S 44.19 100
33079157 A tod S 44.16 100
33079157 R sod 100
33079166 R tod 100
33079196 A uod S 44.19 100
33079233 R ind 100
33079268 A vod B 44.09 100
33079276 R vnd 100
33079306 A wod B 44.00 100
33079376 A xod S 44.16 100
33079377 R uod 100
33079386 R xod 100
33079415 A yod S 44.19 100
33079596 A zod S 44.16 100
33079597 R yod 100
33079597 R zod 100
33079628 A apd S 44.19 100
33079817 A bpd S 44.16 100
33079817 R apd 100
33079817 R bpd 100
33079848 A cpd S 44.19 100
33080037 A dpd S 44.16 100
33080037 R cpd 100
33080038 R dpd 100
33080068 A epd S 44.19 100
33080257 A fpd S 44.16 100
33080258 R epd 100
33080258 R fpd 100
33080289 A gpd S 44.19 100
33088318 R tnd 100
33088320 A hpd B 44.09 100
33093979 R fnd 100
33093979 A ipd S 44.13 100
33096847 A jpd B 44.02 100
33096847 R wod 100
33096986 R jpd 100
33097016 A kpd B 44.00 100
33099060 R dlc 50
33100174 A lpd B 44.09 50
33106006 A mpd B 44.02 100
33106006 R kpd 100
33109449 R hpd 100
33109645 R end 200
33109646 R omd 100
33109647 A npd B 44.09 100
33109647 A opd B 44.10 100
33109649 A ppd B 44.07 100
33109649 A qpd S 44.14 100
33109656 R ipd 100
33109657 A rpd S 44.15 100
33109658 R ppd 100
33109659 R rpd 100
33109659 A spd S 44.14 100
33109660 R qpd 100
33109661 A tpd S 44.15 100
33109671 R opd 100
33109672 A upd B 44.10 100
33109686 R gpd 100
33109696 A vpd B 44.02 100
33109697 R mpd 100
33109700 R upd 100
33109706 R spd 100
33109706 A wpd S 44.13 100
33109716 A xpd S 44.20 100
33109716 R xpd 100
33109772 A ypd S 44.20 100
33109886 R vpd 100
33109916 A zpd B 44.02 100
33114323 R wnd 100
33115616 R zpd 100
33115624 A aqd S 44.13 100
33115625 R wpd 100
33115625 A bqd S 44.13 100
33115632 R lpd 50
33115632 R npd 100
33115633 A cqd B 44.04 100
33115636 R tpd 100
33115645 A dqd B 44.00 100
33115654 R vod 100
33115656 A eqd B 44.05 100
33115806 R dqd 100
33115807 R cqd 100
33115836 A fqd B 44.00 100
33115967 R eqd 100
33115996 R fqd 100
33116025 A gqd B 43.97 100
33119539 A hqd S 44.13 100
33119540 R bqd 100
33119540 A iqd S 44.12 100
33120499 A jqd S 44.12 50
33128171 A kqd S 44.12 100
33128172 R iqd 100
33128172 A lqd S 44.12 100
33128465 R hqd 100
33128466 R jqd 50
33129170 A mqd S 44.07 100
33131882 R mqd 100
33132752 A nqd S 44.12 50
33132816 A oqd S 44.20 100
33132816 R ypd 100
33132846 A pqd S 44.20 100
33132847 R oqd 100
33136919 R nqd 50
33137511 A qqd S 44.12 50
33142657 A rqd S 44.17 100
33142657 R pqd 100
33142687 A sqd S 44.17 100
33142687 R rqd 100
33147188 R qqd 50
33147876 A tqd B 44.01 100
33147876 R gqd 100
33149916 R tqd 100
33149946 A uqd B 43.97 100
33151047 A vqd B 44.01 100
33151048 R uqd 100
33151286 R vqd 100
33151316 A wqd B 43.97 100
33151402 A xqd B 44.04 480
33151966 A yqd B 44.01 100
33151967 R wqd 100
33152226 R yqd 100
33152256 A zqd B 43.97 100
33152496 A ard B 44.01 100
33152497 R zqd 100
33152776 R ard 100
33152806 A brd B 43.97 100
33153287 A crd B 44.01 100
33153287 R brd 100
33154726 R crd 100
33154756 A drd B 43.97 100
33154858 A erd S 44.10 100
33154859 R lqd 100
33154859 A frd S 44.10 100
33154886 A grd S 44.16 100
33154887 R sqd 100
33160079 R erd 100
33160108 A hrd S 44.16 100
33160108 R grd 100
33160297 A ird B 44.01 100
33160297 R drd 100
33160839 A jrd S 44.11 100
33160866 R ird 100
33160895 A krd B 43.97 100
33162322 A lrd S 44.09 100
33162336 A mrd S 44.16 100
33162337 R hrd 100
33162368 A nrd S 44.16 100
33162368 R mrd 100
33164737 R lrd 100
33164740 A ord S 44.09 100
33164740 R jrd 100
33164741 R frd 100
33164741 A prd S 44.09 100
33164743 R ord 100
33164767 A qrd S 44.16 100
33164767 R nrd 100
33164798 A rrd S 44.16 100
33164798 R qrd 100
33169426 A srd S 44.15 100
33169427 R rrd 100
33169427 R srd 100
33169483 A trd S 44.15 100
33169493 A urd S 44.08 100
33169508 R urd 100
33169537 R trd 100
33169567 A vrd S 44.16 100
33169617 A wrd S 44.15 100
33169617 R vrd 100
33169787 R wrd 100
33169817 A xrd S 44.16 100
33169937 A yrd S 44.15 100
33169937 R xrd 100
33170008 R yrd 100
33170038 A zrd S 44.16 100
33170157 A asd S 44.15 100
33170157 R zrd 100
33170166 R asd 100
33170196 A bsd S 44.16 100
33170377 A csd S 44.15 100
33170377 R bsd 100
33172604 A dsd B 44.06 100
33172656 A esd S 44.15 100
33172657 R csd 100
33173893 A fsd S 44.08 100
33175738 R dsd 100
33175739 R prd 100
33175739 A gsd S 44.08 100
33175739 A hsd B 44.06 100
33175741 A isd S 44.10 100
33188548 R fsd 100
33188577 A jsd S 44.15 100
33188577 R esd 100
33188608 A ksd S 44.14 100
33188608 R jsd 100
33188674 A lsd S 44.08 100
33188675 R gsd 100
33188675 A msd S 44.08 100
33188681 R lsd 100
33189516 A nsd S 44.14 41
33190227 A osd S 44.14 100
33190227 R ksd 100
33190257 A psd S 44.14 100
33190257 R osd 100
33191208 A qsd B 44.04 100
33191218 R isd 100
33191246 R psd 100
33191247 A rsd B 43.98 100
33191248 R krd 100
33191276 A ssd S 44.16 100
33193482 R hsd 100
33193527 A tsd S 44.16 100
33193527 R ssd 100
33193634 A usd B 44.07 100
33194721 R usd 25
33194722 A vsd B 44.07 100
33194766 A wsd S 44.16 100
33194766 R tsd 100
33194796 A xsd S 44.16 100
33194796 R wsd 100
33197388 R msd 100
33197388 A ysd S 44.12 100
33197392 A zsd S 44.11 100
33197393 R ysd 100
33197393 A atd S 44.10 100
33197398 R zsd 100
33197427 R xsd 100
33197427 A btd B 43.98 100
33197428 R rsd 100
33197457 A ctd S 44.16 100
33197484 A dtd B 43.98 100
33197484 R btd 100
33198069 A etd S 44.08 100
33198098 A ftd S 44.15 100
33198098 R ctd 100
33200873 A gtd B 44.07 100
33200901 A htd S 44.07 50
33200902 R vsd 100
33200902 R usd 75
33200902 A itd S 44.07 50
33200903 R htd 50
33200903 R itd 50
33200905 A jtd B 44.07 100
33200906 A ktd S 44.10 100
33201155 R jtd 100
33201156 R atd 100
33201156 A ltd S 44.10 100
33201159 A mtd B 44.07 100
33201288 R etd 100
33201289 R ktd 100
33201291 A ntd S 44.11 100
33201317 R ftd 100
33201347 A otd S 44.16 100
33203186 R ltd 100
33203186 A ptd S 44.11 100
33203189 A qtd S 44.10 100
33203190 A rtd B 44.05 100
33203190 R qsd 100
33203191 A std B 44.05 100
33203217 A ttd B 44.00 100
33203217 R dtd 100
33209300 A utd B 44.07 500
33212978 R xqd 480
33215263 R nsd 41
33215326 A vtd S 44.14 43
33215565 R mtd 100
33215753 A wtd B 44.08 100
33231113 R vtd 43
33231173 A xtd S 44.08 43
33232547 R utd 500
33233463 R xtd 43
33233467 R rtd 100
33234097 R ttd 100
33234126 A ytd B 43.98 100
33238277 A ztd B 44.01 100
33238277 R ytd 100
33238596 R ztd 100
33238626 A aud B 43.98 100
33239207 A bud B 44.01 100
33239207 R aud 100
33239496 R bud 100
33239526 A cud B 43.98 100
33240082 R gtd 100
33240083 R ptd 100
33240084 A dud S 44.10 100
33240085 R qtd 100
33244894 R wtd 100
33244896 A eud B 44.08 100
33247659 R eud 60
33247661 A fud B 44.08 100
33268007 A gud S 44.16 100
33268007 R otd 100
33290093 A hud B 43.93 100
33291587 R eud 23
33298656 A iud S 44.15 100
33298657 R gud 100
33300104 R rc 100
33300445 R bv 200
33300492 R dud 100
33300492 A jud S 44.11 100
33300495 R ntd 100
33300495 A kud S 44.10 100
33300519 R iud 100
33300521 R kud 100
33300548 A lud S 44.17 100
33300782 R bm 200
33300832 R rnd 100
33300848 R ku 100
33301010 R oyb 1000
33322247 R eud 17
33322247 R fud 23
33322249 A mud B 44.08 100
33322251 A nud S 44.12 100
33322287 A oud S 44.17 100
33322287 R lud 100
33322288 R oud 100
33322345 A pud S 44.17 100
33335312 R mud 100
33335312 R fud 77
33335316 A qud B 44.03 100
33335347 A rud S 44.17 100
33335347 R pud 100
33335504 A sud B 44.07 100
33379807 A tud B 43.99 100
33379808 R cud 100
33379819 R qud 100
33379820 R nud 100
33379832 A uud S 44.11 100
33379847 R rud 100
33379857 A vud B 43.99 100
33379857 R tud 100
33379858 R jud 100
33379858 A wud S 44.11 100
33379859 R uud 100
33379877 A xud S 44.17 100
33394287 A yud B 43.99 100
33394287 R vud 100
33407058 A zud B 43.99 100
33407058 R yud 100
33407077 R zud 100
33407115 A avd B 43.98 100
33409897 R hud 100
33409962 A bvd B 43.93 100
33417898 A cvd S 44.22 100
33426090 A dvd S 44.10 100
33430822 A evd S 44.10 100
33430823 R wud 100
33430823 A fvd S 44.10 100
33430823 R dvd 100
33433855 R evd 100
33439629 R std 100
33439630 A gvd B 44.07 53
33470788 R sud 100
33471028 R fvd 100
33471028 A hvd S 44.12 100
33471057 A ivd B 44.02 100
33471058 R avd 100
33488557 R gvd 53
33488557 A jvd B 44.04 53
33488587 R ivd 100
33488617 A kvd B 43.98 100
33495816 A lvd B 44.08 100
33499407 R jvd 53
33499407 A mvd B 44.08 100
33499409 A nvd S 44.12 200
33499409 R nvd 200
33499437 R xud 100
33499447 A ovd B 43.98 100
33499447 R kvd 100
33499466 A pvd S 44.20 100
33499496 A qvd B 43.98 100
33499496 R ovd 100
33507121 R hvd 100
33507121 A rvd B 44.12 380
33507166 R pvd 100
33507177 A svd B 44.03 100
33507177 R qvd 100
33507206 A tvd S 44.21 100
33507233 A uvd B 44.03 100
33507233 R svd 100
33508180 A vvd B 44.10 10
33510279 R kqd 100
33510280 R mvd 100
33510280 A wvd B 44.12 100
33512164 R aqd 100
33512207 R tvd 100
33512237 A xvd S 44.22 100
33512237 R xvd 100
33512268 A yvd S 44.22 100
33513884 R dhd 100
33513885 A zvd S 44.13 100
33513926 R yvd 100
33513956 A awd S 44.22 100
33514381 R zvd 100
33514383 A bwd S 44.13 100
33514426 R awd 100
33514456 A cwd S 44.22 100
33514713 R lvd 100
33515371 R rvd 380
33515372 R wvd 100
33515372 A dwd B 44.04 100
33515376 A ewd B 44.08 100
33516057 A fwd S 44.20 100
33516058 R cwd 100
33517440 A gwd S 44.13 100
33517441 R dwd 100
33517441 A hwd B 44.08 100
33518270 A iwd S 44.16 100
33518297 R fwd 100
33518326 A jwd S 44.22 100
33519128 A kwd S 44.20 100
33519128 R jwd 100
33522776 R kwd 100
33522807 A lwd S 44.22 100
33523712 A mwd S 44.13 100
33523994 A nwd B 44.10 480
33524957 A owd S 44.20 100
33524957 R lwd 100
33526334 R mwd 100
33526335 R hwd 100
33526335 A pwd B 44.10 100
33527395 R nwd 480
33527868 A qwd B 44.10 100
33528809 R ewd 100
33528836 R owd 100
33528866 A rwd S 44.22 100
33529469 R pwd 100
33529473 A swd B 44.08 100
33529620 R swd 100
33529637 A twd S 44.17 100
33529637 R rwd 100
33529646 R uvd 100
33529693 A uwd B 44.01 100
33531377 R qwd 100
33531378 A vwd B 44.04 100
33531378 A wwd B 44.10 100
33531457 A xwd B 44.02 100
33531457 R uwd 100
33531488 A ywd B 44.02 100
33531489 R xwd 100
33540526 A zwd B 43.08 100
33552623 R wwd 10
33552624 A axd B 44.10 100
33557782 R wwd 90
33557782 R axd 100
33557784 A bxd B 44.10 100
33557817 R twd 100
33557827 R ywd 100
33557828 R vwd 100
33557828 A cxd B 44.10 100
33557847 A dxd S 44.22 100
33557857 A exd B 44.02 100
33557857 R exd 100
33557887 A fxd B 44.01 100
33559679 A gxd S 44.13 100
33563038 R gwd 100
33564960 R gxd 100
33566879 A hxd S 44.12 30
33568907 A ixd B 44.03 100
33568907 R fxd 100
33568937 A jxd B 44.03 100
33568937 R ixd 100
33573557 A kxd S 44.20 100
33573558 R dxd 100
33576247 A lxd S 44.14 100
33577296 R lxd 100
33623487 R kxd 100
33623517 A mxd S 44.22 100
33628411 A nxd S 44.13 100
33628447 A oxd S 44.22 100
33628447 R mxd 100
33645407 A pxd B 44.11 100
33645447 A qxd B 44.03 100
33645447 R jxd 100
33645478 A rxd B 44.03 100
33645478 R qxd 100
33647356 A sxd B 40.80 30
33660845 R nxd 100
33660846 R cxd 100
33660846 A txd B 44.11 100
33683320 A uxd B 40.80 30
33688057 R oxd 100
33688087 A vxd S 44.22 100
33688198 R txd 100
33688200 A wxd S 44.15 100
33688236 A xxd S 44.22 100
33688237 R vxd 100
33691148 A yxd B 44.11 100
33701291 R hxd 30
33736217 A zxd S 44.20 100
33736218 R xxd 100
33737144 R yxd 100
33739057 A ayd B 44.11 53
33751054 A byd S 44.12 100
33753036 R zxd 100
33753066 A cyd S 44.22 100
33753067 A dyd S 44.22 100
33753068 R cyd 100
33790100 A eyd B 44.11 200
33790137 A fyd B 44.03 100
33790137 R rxd 100
33790157 R fyd 100
33790194 A gyd B 44.03 100
33802077 A hyd S 44.22 100
33802078 R dyd 100
33806207 A iyd S 44.21 100
33806208 R hyd 100
33809789 A jyd B 44.10 200
33809810 A kyd B 44.05 100
33809811 R gyd 100
33809819 R iyd 100
33809868 A lyd S 44.22 100
33814163 R eyd 200
33825313 R byd 100
33825313 A myd B 44.12 100
33825314 R wxd 100
33825314 A nyd S 44.16 100
33825315 R ayd 53
33825315 A oyd B 44.13 53
33825347 A pyd S 44.64 100
33825679 R jyd 200
33825707 R lyd 100
33825737 A qyd S 44.22 100
33825777 A ryd S 44.22 100
33825777 R qyd 100
33835678 A syd S 44.40 100
33845890 R hrc 400
33854108 A tyd S 44.22 100
33854108 R ryd 100
33856847 R oyd 53
33856847 R nyd 100
33856848 A uyd B 44.11 53
33856848 A vyd S 44.15 100
33856877 A wyd S 44.20 100
33856878 R tyd 100
33858757 R myd 100
33874007 R uyd 53
33874008 A xyd B 44.13 53
33874038 A yyd B 44.05 100
33874039 R kyd 100
33887896 R xyd 53
33887896 R pxd 100
33887896 R bxd 100
33887898 A zyd B 44.10 100
33887929 A azd S 44.15 200
33891117 A bzd B 44.10 100
33894117 A czd B 44.10 200
33903439 A dzd B 44.10 200
33903440 R bzd 100
33903440 A ezd B 44.10 100
33903466 R yyd 100
33903496 A fzd B 44.05 100
33907506 A gzd B 44.10 100
33907751 R czd 200
33913154 R we 100
33921911 A hzd B 12.00 1
33928720 A izd S 44.13 100
33928729 R pyd 100
33928736 A jzd S 44.64 100
33936377 R ezd 100
33936377 A kzd B 44.10 100
33936379 R azd 200
33939547 R kzd 100
33939547 A lzd B 44.05 100
33939549 R dzd 200
33939577 R fzd 100
33939607 A mzd B 44.03 100
33939667 A nzd B 44.03 100
33939667 R mzd 100
33939677 R nzd 100
33939725 A ozd B 44.03 100
33940164 R gzd 100
33940168 A pzd B 44.08 200
33940169 R lzd 100
33940169 A qzd B 44.08 100
33942416 R izd 100
33942420 A rzd S 44.15 200
33942441 R jzd 100
33942446 A szd S 44.64 100
33942458 A tzd B 44.03 100
33942458 R ozd 100
33942527 R qzd 100
33942528 A uzd B 44.10 100
33942529 R rzd 200
33942542 R szd 100
33942557 R wyd 100
33942568 R bwd 100
33942570 A vzd S 44.13 100
33942572 A wzd S 44.16 100
33942587 A xzd S 44.21 100
33944822 R vzd 100
33944823 A yzd S 44.13 100
33949171 A zzd B 42.84 20
33950078 R uzd 100
33950078 A aae B 44.08 100
33950081 R wzd 100
33950081 A bae S 44.15 100
33950110 A cae S 44.20 100
33950110 R xzd 100
33953352 R vyd 100
33953353 A dae S 44.13 13
33953967 A eae B 44.03 100
33953967 R tzd 100
33954516 R eae 100
33954546 A fae B 44.03 100
33963683 A gae B 44.09 400
33963684 R aae 100
33963684 A hae B 44.09 100
33965579 R vt 650
33973111 R hae 100
33973112 A iae B 44.10 100
33981472 A jae S 47.76 2
33982210 R bae 100
33982237 R cae 100
33982293 A kae S 44.20 100
33984942 R agc 100
33985038 A lae S 44.11 5
33992724 A mae S 44.13 100
34001417 A nae S 44.99 50
34007188 A oae B 33.00 50
34040170 R pzd 200
34040170 R dae 13
34040171 A pae S 44.13 13
34040171 R iae 100
34040172 A qae B 44.09 100
34048007 R lae 5
34048008 R qae 100
34048008 A rae B 44.10 100
34048038 A sae B 43.34 40
34048049 A tae B 44.03 100
34048049 R fae 100
34048456 R pae 13
34048456 R mae 100
34048456 R yzd 87
34048459 A uae S 44.14 100
34048459 A vae S 44.13 100
34048461 R uae 100
34048461 A wae S 44.15 100
34048498 A xae S 44.20 100
34048498 R kae 100
34050455 R zyd 100
34050456 A yae S 44.15 100
34062173 A zae B 44.10 180
34062173 R rae 100
34062174 A abe B 44.10 100
34062598 R sae 40
34062605 A bbe B 43.34 45
34093906 A cbe S 44.28 50
34095516 R zae 180
34106448 A dbe B 44.05 180
34110399 R lcd 100
34117229 R wae 100
34117257 R xae 100
34117287 A ebe S 44.20 100
34117521 R yzd 13
34117521 R vae 100
34120932 R dbe 180
34131453 A fbe S 44.12 200
34131497 A gbe S 44.20 100
34131498 R ebe 100
34141921 R fbe 200
34141922 A hbe S 44.12 200
34141922 A ibe S 44.15 100
34141922 R yae 100
34141923 A jbe S 44.15 100
34141924 R ibe 100
34160607 R hbe 200
34162888 A kbe B 44.12 100
34162927 R gbe 100
34162928 A lbe B 44.03 100
34162928 R tae 100
34162957 A mbe S 44.20 100
34167534 A nbe S 44.14 200
34167534 R jbe 100
34167535 A obe S 44.14 100
34167536 R nbe 200
34167549 R mbe 100
34167582 A pbe S 44.21 100
34167639 A qbe B 44.03 100
34167640 R lbe 100
34168117 R obe 100
34168117 R abe 100
34168117 A rbe S 44.15 100
34168117 A sbe B 44.12 50
34168147 R pbe 100
34168176 A tbe S 44.23 100
34172558 A ube S 44.41 200
34175314 R kbe 100
34179829 A vbe B 44.12 100
34179830 A wbe B 44.09 200
34181418 A xbe B 44.03 100
34181418 R qbe 100
34181447 R rbe 100
34181447 A ybe S 44.16 100
34181449 A zbe B 44.04 100
34181449 R xbe 100
34181480 A ace B 44.04 100
34181481 R zbe 100
34181512 A bce B 44.05 100
34181512 R ace 100
34181543 A cce B 44.05 100
34181543 R bce 100
34184108 R sbe 50
34184108 R ybe 100
34184108 A dce S 44.15 200
34184108 A ece B 44.09 50
34184109 A fce S 44.15 100
34184111 A gce B 44.10 200
34184112 R ece 50
34184112 A hce S 44.15 200
34184112 A ice B 44.10 50
34184113 R wbe 200
34184113 A jce B 44.10 200
34184118 R jce 200
34184118 A kce B 44.09 200
34184120 R gce 200
34184138 A lce S 44.20 100
34184138 R tbe 100
34184148 R cce 100
34184169 A mce S 44.20 100
34184169 R lce 100
34184195 A nce B 44.04 100
34184237 R nce 100
34184267 A oce B 44.03 100
34184287 R mce 100
34184298 A pce B 44.04 100
34184298 R oce 100
34184317 A qce S 44.20 100
34184397 R ice 50
34184397 A rce B 44.12 50
34184398 R dce 200
34184398 A sce S 44.15 200
34184399 R hce 200
34184427 R qce 100
34184457 A tce S 44.22 100
34184487 R tce 100
34184516 A uce S 44.22 100
34184618 A vce S 44.22 100
34184618 R uce 100
34188328 A wce B 44.12 100
34188328 A xce S 44.15 100
34188329 R sce 200
34188367 A yce B 44.04 100
34188368 R pce 100
34188368 A zce S 44.22 100
34188368 R vce 100
34188399 A ade B 44.04 100
34188399 R yce 100
34188430 A bde B 44.04 100
34188430 R ade 100
34188461 A cde B 44.04 100
34188461 R bde 100
34188844 R erc 200
34189314 R oxc 100
34189440 R rce 50
34189440 R wce 100
34189441 R fce 100
34189442 A dde S 44.15 100
34189442 A ede S 44.12 100
34189443 A fde S 44.15 200
34189465 R xce 100
34189465 A gde B 44.09 100
34189465 A hde S 44.14 100
34189466 R dde 100
34189466 A ide S 44.14 100
34189474 R hde 100
34189475 A jde S 44.14 100
34189476 R ide 100
34189476 A kde S 44.14 100
34189477 R jde 100
34189477 A lde S 44.14 100
34189478 R kde 100
34189478 A mde S 44.15 100
34189480 A nde B 44.04 100
34189481 R cde 100
34189481 A ode S 44.22 100
34189481 R zce 100
34189490 R nde 100
34189522 A pde S 44.22 100
34189523 R ode 100
34189523 A qde B 44.05 100
34189553 A rde S 44.22 100
34189554 R pde 100
34190793 R ede 100
34190794 R lde 100
34190794 A sde B 44.09 100
34190794 A tde S 44.15 100
34190795 R gde 100
34190795 R mde 100
34190795 A ude B 44.12 100
34190795 A vde S 44.14 100
34190796 R fde 200
34190797 R vde 100
34190797 A wde S 44.15 100
34190801 A xde S 44.17 200
34190808 R wde 100
34190808 A yde S 44.15 100
34190809 A zde S 44.16 200
34190838 A aee B 44.05 100
34190839 R qde 100
34190843 R ude 100
34190843 R vbe 100
34190848 R yde 100
34190848 A bee B 44.09 100
34190848 A cee S 44.14 100
34190849 R sde 100
34190849 A dee B 44.10 100
34190849 R tde 100
34190850 A eee S 44.14 100
34190850 R bee 100
34190850 R zde 200
34190851 A fee S 44.15 200
34190851 A gee B 44.10 100
34190851 R dee 100
34190852 A hee B 44.10 100
34190852 R gee 100
34190852 A iee B 44.10 100
34190853 R hee 100
34190853 A jee B 44.10 100
34190854 R iee 100
34190854 A kee B 44.10 100
34190855 R jee 100
34190855 A lee B 44.10 100
34190856 R kee 100
34190856 A mee B 44.10 100
34190857 R lee 100
34190857 A nee B 44.10 100
34190857 R fee 200
34190857 A oee S 44.15 200
34190858 R mee 100
34190858 R cee 100
34190858 A pee B 44.11 100
34190858 A qee S 44.14 100
34190858 R oee 200
34190859 A ree S 44.15 200
34190859 R nee 100
34190859 R eee 100
34190859 A see B 44.11 100
34190859 A tee S 44.14 100
34190860 R pee 100
34190860 A uee B 44.11 100
34190861 R see 100
34190861 A vee B 44.11 100
34190867 R qee 100
34190867 A wee S 44.14 100
34190868 R uee 100
34190868 A xee B 44.11 100
34190869 R tee 100
34190869 A yee S 44.14 100
34190869 R vee 100
34190869 A zee B 44.05 100
34190869 A afe B 44.11 100
34190870 R aee 100
34190870 R xee 100
34190870 A bfe B 44.11 100
34190871 R wee 100
34190871 A cfe S 44.15 100
34190872 R afe 100
34190872 A dfe B 44.11 100
34190873 R bfe 100
34190873 A efe B 44.12 100
34190879 R xde 200
34190888 A ffe S 44.21 100
34190888 R rde 100
34190889 R zee 100
34190897 R dfe 100
34190897 A gfe B 44.09 100
34190918 R ffe 100
34190928 A hfe B 44.04 100
34190929 A ife B 44.04 100
34190930 R hfe 100
34190948 A jfe S 44.21 100
34190949 A kfe S 44.21 100
34190950 R jfe 100
34191047 A lfe S 44.21 100
34191048 R kfe 100
34194398 A mfe B 44.04 100
34194398 R ife 100
34194454 A nfe B 44.05 100
34194455 R mfe 100
34194636 A ofe B 44.12 200
34194637 R gfe 100
34194637 R ree 200
34194638 A pfe B 44.12 100
34194639 R efe 100
34194639 A qfe B 44.12 100
34194689 A rfe B 44.05 100
34194689 R nfe 100
34194719 A sfe B 44.05 100
34194720 R rfe 100
34195788 R pfe 100
34195789 A tfe B 44.12 100
34195805 R qfe 100
34195805 A ufe B 44.12 100
34195805 R yee 100
34195805 A vfe S 44.15 100
34195806 R cfe 100
34195806 A wfe S 44.19 200
34195806 A xfe S 44.16 100
34195806 A yfe B 44.12 100
34195806 R tfe 100
34195806 R ufe 100
34195807 A zfe B 44.13 100
34195808 A age S 44.14 100
34195817 R lfe 100
34195818 R xfe 100
34195819 A bge S 44.15 100
34195819 R yfe 100
34195819 A cge B 44.09 100
34195819 R zfe 100
34195819 A dge B 44.12 100
34195820 R vfe 100
34195820 A ege S 44.14 100
34195822 R age 100
34195839 A fge B 44.05 100
34195839 R sfe 100
34195846 A gge S 44.22 100
34195848 A hge S 44.21 100
34195848 R gge 100
34195849 R hge 100
34195876 A ige B 44.05 100
34195877 R fge 100
34195905 A jge S 44.22 100
34198158 R jge 100
34198159 A kge B 44.05 100
34198159 R ige 100
34198188 A lge S 44.22 100
34198278 A mge S 44.14 500
34198318 A nge S 44.22 100
34198318 R lge 100
34198348 A oge S 44.22 100
34198348 R nge 100
34199851 R dge 100
34199852 A pge B 44.13 100
34199859 R ege 100
34199859 A qge S 44.15 100
34199892 A rge B 44.05 100
34199892 R kge 100
34199923 A sge B 44.06 100
34199923 R rge 100
34199929 R oge 100
34199954 A tge B 44.06 100
34199954 R sge 100
34199959 A uge S 44.22 100
34199966 R mge 120
34199969 A vge B 44.11 100
34199988 R qge 100
34199988 R bge 100
34199988 A wge S 44.16 100
34199988 A xge S 44.15 100
34199988 R cge 100
34199989 A yge B 44.11 100
34199998 R wge 100
34199998 A zge S 44.15 100
34199999 R zge 100
34199999 A ahe S 44.16 100
34200004 A bhe S 44.14 100
34200007 R ahe 100
34200008 A che S 44.15 100
34200010 A dhe B 44.06 100
34200010 R che 100
34200010 R tge 100
34200011 A ehe S 44.16 100
34200011 A fhe S 44.22 100
34200011 R uge 100
34200013 A ghe B 44.13 100
34200014 R pge 100
34200014 A hhe B 44.13 100
34200023 R vge 100
34200032 R ghe 100
34200041 A ihe B 44.06 100
34200041 R dhe 100
34200042 R hhe 100
34200043 A jhe B 44.13 100
34200044 R ehe 100
34200044 A khe S 44.15 100
34200046 A lhe B 44.13 100
34200049 R xge 100
34200049 A mhe B 44.11 100
34200050 A nhe S 44.15 100
34200050 R jhe 100
34200050 R yge 100
34200051 A ohe B 44.11 100
34200051 R lhe 100
34200051 R mhe 100
34200052 R nhe 100
34200052 A phe B 44.13 100
34200052 A qhe S 44.14 100
34200053 R phe 100
34200053 A rhe B 44.11 100
34200054 R bhe 100
34200055 A she S 44.14 100
34200071 R ihe 100
34200075 R khe 100
34200075 A the S 44.15 100
34200076 R ohe 100
34200076 A uhe B 44.11 100
34200083 A vhe S 44.22 100
34200083 R fhe 100
34200092 R vhe 100
34200101 A whe B 44.05 100
34200123 A xhe S 44.22 100
34200126 A yhe S 55.20 140
34200129 A zhe S 44.22 100
34200130 R xhe 100
34200230 R qhe 100
34200230 R she 100
34200231 R rhe 100
34200231 A aie B 44.11 100
34200231 A bie S 44.14 100
34200232 R uhe 100
34200232 A cie B 44.11 100
34200232 R aie 100
34200232 A die B 44.13 100
34200233 R the 100
34200234 A eie S 44.15 100
34200238 R mge 380
34200249 R eie 100
34200249 A fie S 44.16 100
34200265 R bie 100
34200269 A gie S 44.17 100
34200271 R gie 100
34200272 A hie B 44.05 100
34200272 A iie S 44.17 200
34200272 R whe 100
34200272 R wfe 200
34200273 A jie S 44.17 200
34200300 R zhe 100
34200302 A kie B 44.05 100
34200303 R hie 100
34200317 R cie 100
34200318 A lie B 44.13 100
34200331 A mie S 44.22 100
34200333 A nie B 44.05 100
34200333 R kie 100
34200350 R mie 100
34200364 A oie B 44.06 100
34200364 R nie 100
34200381 A pie S 44.22 100
34200437 R tfd 200
34200449 R kce 200
34200449 A qie B 44.13 200
34200453 R iie 200
34200454 A rie S 44.18 100
34200455 R rie 100
34200480 R pie 100
34200480 A sie B 44.06 100
34200481 R oie 100
34200509 R fie 100
34200509 A tie S 44.17 100
34200509 A uie S 44.23 100
34200512 A vie B 44.06 100
34200512 R sie 100
34200514 A wie S 44.18 100
34200518 R tie 100
34200519 A xie S 44.16 100
34200522 A yie B 44.11 100
34200523 R xie 100
34200524 A zie S 44.17 100
34200543 A aje B 44.06 100
34200543 R vie 100
34200543 A bje B 44.13 100
34200544 R lie 100
34200544 R die 100
34200544 A cje B 44.13 100
34200544 A dje B 44.13 100
34200545 R qie 200
34200545 A eje B 44.13 200
34200546 R bje 100
34200546 R dje 100
34200546 R cje 100
34200546 A fje B 44.13 100
34200546 A gje B 44.13 100
34200548 R uie 100
34200573 A hje B 44.07 100
34200574 R aje 100
34200579 A ije S 44.23 100
34200588 R eje 200
34200588 A jje B 44.13 200
34200601 A kje B 44.13 100
34200602 R gje 100
34200602 R fje 100
34200602 A lje B 44.13 100
34200603 A mje B 44.13 100
34200605 A nje B 44.07 100
34200605 R hje 100
34200609 R kje 100
34200626 A oje B 39.60 45
34200635 A pje B 44.07 100
34200636 R nje 100
34200672 A qje B 44.07 100
34200672 R pje 100
34200673 A rje B 44.14 100
34200674 R mje 100
34200674 A sje B 44.14 100
34200674 R lje 100
34200675 A tje B 44.14 100
34200677 A uje B 44.13 100
34200677 R uje 100
34200680 A vje B 44.14 100
34200682 R rje 100
34200683 A wje B 44.14 100
34200704 A xje B 44.07 100
34200704 R qje 100
34200722 R wje 100
34200723 R vje 100
34200837 R yie 100
34200839 R sje 100
34200839 A yje B 44.13 100
34200859 R xje 100
34200861 A zje S 44.17 100
34200868 R zje 100
34200868 A ake S 44.16 100
34200869 R zie 100
34200870 A bke S 44.16 100
34200884 A cke S 56.16 5
34200885 A dke S 48.00 100
34200885 A eke S 55.16 3
34200885 A fke S 46.61 200
34200885 A gke S 48.60 3
34200886 A hke S 45.42 3
34200886 A ike S 47.30 100
34200886 A jke S 54.22 1
34200886 A kke S 52.56 100
34200887 A lke S 45.36 10
34200890 A mke B 44.07 100
34200900 R mke 100
34200904 A nke S 54.00 20
34200904 A oke S 50.28 100
34200904 A pke S 50.79 100
34200905 A qke S 51.60 50
34200905 A rke S 51.26 2
34200905 A ske S 55.80 3
34200906 A tke S 47.40 14
34200906 A uke S 72.00 90
34200906 A vke S 51.60 20
34200907 A wke S 45.84 10
34200907 A xke S 72.00 25
34200907 A yke S 46.56 100
34200908 A zke S 45.12 100
34200908 A ale S 49.44 70
34200909 A ble S 54.60 35
34200909 A cle S 57.00 1
34200909 A dle S 55.20 15
34200910 A ele S 49.32 30
34200910 A fle S 47.94 40
34200911 A gle S 44.41 145
34200911 A hle S 44.23 100
34200911 R ije 100
34200924 A ile S 44.77 100
34200924 A jle S 48.12 200
34200924 A kle S 44.37 200
34200925 A lle S 44.52 200
34200925 A mle S 44.37 100
34200925 A nle S 44.49 100
34200926 A ole S 45.26 100
34200926 A ple B 42.84 30
34200927 A qle B 39.34 40
34200927 A rle B 36.90 15
34200927 A sle B 40.50 15
34200939 A tle B 44.06 100
34200944 A ule B 39.64 15
34200944 A vle B 39.66 10
34200944 A wle B 42.00 20
34200944 A xle B 39.96 1
34200945 A yle B 40.80 5
34200945 A zle B 38.88 1
34200945 A ame B 41.40 14
34200945 A bme B 39.00 100
34200946 A cme B 36.25 4
34200946 A dme B 0.12 1
34200946 A eme B 43.02 3
34200946 A fme B 43.32 100
34200947 A gme B 43.20 35
34200947 A hme B 42.00 35
34200947 A ime B 43.08 15
34200947 A jme B 41.88 15
34200948 A kme B 40.54 3
34200948 A lme B 43.02 11
34200948 A mme B 37.32 1
34200948 A nme B 39.60 2
34200964 A ome B 43.20 100
34200964 A pme B 43.80 100
34200964 A qme B 44.15 2
34200964 A rme B 41.22 15
34200965 A sme B 41.22 15
34200965 R ake 100
34200965 A tme B 40.92 200
34200965 A ume S 44.17 100
34200985 A vme S 44.23 100
34200985 R hle 100
34201073 R qme 2
34201074 R ume 100
34201074 A wme S 44.16 100
34201100 R tje 100
34201100 A xme B 44.13 100
34201101 R jje 200
34201101 R bke 100
34201102 R yje 100
34201102 A yme S 44.16 100
34201102 A zme B 44.13 100
34201102 A ane B 44.09 200
34201103 R xme 100
34201103 R wme 100
34201103 A bne B 44.13 100
34201104 A cne S 44.15 100
34201104 A dne B 44.11 100
34201158 A ene S 44.15 72
34201158 R bne 100
34201159 A fne B 44.13 100
34201162 R wie 100
34201178 R zme 100
34201178 A gne B 44.13 100
34201194 A hne B 42.90 100
34201198 R ene 72
34201356 A ine B 44.13 100
34201359 A jne B 44.13 100
34201391 R dne 100
34201440 R yme 100
34201440 A kne S 44.15 100
34201454 R kne 100
34201456 A lne S 44.16 100
34201479 R ane 200
34201480 A mne B 44.13 200
34201511 R mne 200
34201511 A nne B 44.09 200
34201517 R lne 100
34201518 A one S 44.15 100
34201524 R one 100
34201525 A pne S 44.16 100
34201526 A qne S 44.23 100
34201526 R vme 100
34201559 R nne 200
34201560 R cne 100
34201560 A rne B 44.13 200
34201560 A sne S 44.16 100
34201561 R rne 200
34201562 A tne B 44.09 200
34201592 R tle 100
34201598 R tne 200
34201598 A une B 44.13 200
34201619 R une 200
34201619 A vne B 44.09 200
34201622 A wne B 44.06 100
34201637 A xne S 44.23 100
34201637 R qne 100
34201652 R wne 100
34201670 R xne 100
34201682 A yne B 44.06 100
34201700 A zne S 44.22 100
34201775 A aoe B 41.50 2
34202013 A boe B 44.11 250
34202013 A coe S 44.17 250
34202014 R vne 200
34202014 R jie 200
34202014 A doe B 44.11 200
34202015 A eoe S 44.16 200
34202119 R yne 100
34202129 R fne 100
34202148 A foe B 44.06 100
34202160 R coe 250
34202160 A goe S 44.16 250
34202169 R goe 250
34202169 R foe 100
34202173 A hoe S 44.16 250
34202179 R hoe 250
34202180 A ioe S 44.22 100
34202181 R zne 100
34202181 A joe S 44.16 250
34202190 A koe S 44.16 100
34202191 R pne 100
34202191 R eoe 200
34202192 A loe S 44.16 100
34202192 A moe S 44.16 200
34202192 R sne 100
34202192 A noe S 44.16 100
34202192 R jne 100
34202194 R ine 100
34202195 A ooe B 44.13 100
34202196 R ooe 100
34202199 A poe B 44.06 100
34202203 R koe 100
34202211 A qoe S 44.22 100
34202212 R ioe 100
34202226 A roe B 44.13 100
34202228 A soe B 44.13 100
34202229 R gne 100
34202229 R joe 250
34202230 A toe B 44.13 100
34202230 A uoe B 44.13 100
34202230 R moe 200
34202231 R roe 100
34202231 A voe B 44.13 100
34202231 A woe S 44.19 200
34202232 R soe 100
34202232 A xoe S 44.17 250
34202233 R uoe 100
34202234 R woe 200
34202235 A yoe S 44.16 200
34202235 A zoe B 44.13 100
34202236 A ape B 44.13 100
34202242 A bpe S 44.22 100
34202243 R qoe 100
34202248 R loe 100
34202248 R doe 200
34202248 R toe 100
34202248 A cpe B 44.13 200
34202248 A dpe B 44.13 100
34202248 A epe S 44.16 100
34202249 R voe 100
34202249 A fpe B 44.13 100
34202252 R zoe 100
34202254 R ape 100
34202255 A gpe B 44.13 100
34202257 A hpe B 44.13 100
34202258 R gpe 100
34202258 R hpe 100
34202258 R dpe 100
34202258 A ipe B 44.13 100
34202258 R fpe 100
34202258 A jpe B 44.13 100
34202260 R ipe 100
34202260 A kpe B 44.13 100
34202260 R bpe 100
34202260 R cpe 200
34202261 A lpe B 44.11 200
34202261 A mpe B 44.13 100
34202261 R mpe 100
34202269 R lpe 200
34202269 R jpe 100
34202269 A npe B 44.13 200
34202269 A ope B 44.13 100
34202270 A ppe B 44.06 100
34202271 R poe 100
34202278 R epe 100
34202279 A qpe S 44.16 100
34202291 A rpe S 44.23 100
34202291 A spe S 44.22 100
34202292 R rpe 100
34202301 R spe 100
34202302 A tpe B 44.06 100
34202302 R ppe 100
34202331 A upe S 44.23 100
34202893 A vpe B 44.14 129
34202894 R kpe 100
34202894 R noe 100
34202894 A wpe S 44.16 100
34202895 A xpe B 44.13 100
34202895 R ope 100
34202895 A ype B 44.14 100
34202896 R wpe 100
34202896 R yoe 200
34202896 A zpe S 44.16 100
34202897 R qpe 100
34202900 A aqe S 44.16 100
34202900 R zpe 100
34202901 A bqe S 44.16 100
34202940 A cqe B 44.06 100
34202940 R tpe 100
34202941 R upe 100
34202970 A dqe B 44.06 100
34202971 R cqe 100
34202972 A eqe S 44.23 100
34203010 R boe 250
34203010 A fqe B 44.12 250
34203131 R ype 68
34203166 R ype 32
34203166 R vpe 68
34203173 A gqe B 44.13 100
34203179 A hqe S 44.16 200
34203209 A iqe S 44.23 100
34203209 R eqe 100
34204636 R fqe 250
34204637 A jqe B 44.12 250
34204668 R jqe 250
34204670 A kqe B 44.12 250
34204688 R kqe 250
34204690 A lqe B 44.12 250
34204698 R lqe 250
34204698 A mqe B 44.12 250
34204717 R mqe 250
34204719 A nqe B 44.12 250
34204728 A oqe B 44.14 134
34204728 R hqe 200
34204738 R nqe 250
34204739 A pqe B 44.12 250
34204809 A qqe B 42.00 100
34205166 A rqe B 44.14 100
34205169 A sqe B 44.14 100
34205169 R sqe 100
34205205 A tqe B 44.14 100
34205260 A uqe S 44.15 72
34205280 R gqe 100
34205281 A vqe B 44.13 100
34205312 R vpe 61
34205312 R oqe 39
34205317 R pqe 250
34205319 A wqe B 44.12 250
34205333 A xqe S 44.16 100
34205334 R xpe 100
34205334 A yqe B 44.13 100
34205334 R bqe 100
34205336 R vqe 100
34205336 A zqe B 44.13 100
34205336 A are S 44.15 100
34205337 R yqe 100
34205337 A bre B 44.13 100
34205337 R aqe 100
34205338 A cre S 44.16 100
34205338 R zqe 100
34205338 A dre B 44.13 100
34205348 R bre 100
34205348 A ere B 44.13 100
34205514 R oqe 95
34205514 R rqe 100
34205514 R tqe 5
34205515 R tqe 95
34205515 R ere 100
34205515 A fre B 44.13 100
34205516 R npe 200
34205516 A gre B 44.12 200
34205539 R xoe 250
34205539 A hre S 44.16 250
34205539 R xqe 100
34205560 A ire S 44.23 100
34205560 R iqe 100
34205591 A jre S 44.23 100
34205591 R ire 100
34205649 A kre S 44.15 100
34205651 R kre 100
34205850 A lre S 44.15 100
34205875 R dre 100
34205875 R fre 100
34205876 R are 100
34205876 R cre 100
34205876 A mre S 44.16 200
34205876 A nre S 44.15 100
34205877 A ore S 44.15 100
34205879 R lre 100
34205880 R ore 100
34205881 A pre S 44.14 100
34205881 A qre S 44.15 100
34205882 R nre 100
34205882 A rre S 44.14 100
34205883 R pre 100
34205883 R gre 200
34205883 A sre B 44.09 200
34205884 A tre S 44.14 100
34205884 R qre 100
34205885 R rre 100
34205885 A ure S 44.14 100
34205886 R sre 200
34205886 A vre B 44.12 200
34205886 A wre S 44.14 100
34205886 R tre 100
34205887 A xre S 44.14 100
34205887 R vre 200
34205887 A yre B 44.09 200
34205888 R wre 100
34205899 R wqe 250
34205900 R ure 100
34205900 A zre S 44.14 100
34205901 A ase B 44.11 250
34205902 R xre 100
34205902 A bse S 44.14 100
34205902 R yre 200
34205903 A cse B 44.11 200
34205903 R zre 100
34205903 A dse S 44.14 100
34205904 R bse 100
34205904 A ese S 44.13 100
34205905 R dse 100
34205905 A fse S 44.13 100
34205905 R ese 100
34205905 A gse S 44.16 100
34205926 A hse S 44.14 100
34205926 R hse 100
34205930 R dqe 100
34205931 A ise S 44.22 100
34205931 R jre 100
34205961 A jse B 44.04 100
34205963 A kse S 44.22 100
34205963 R ise 100
34205964 R ofe 100
34205965 A lse S 44.13 100
34205965 R lse 100
34205966 A mse S 44.13 100
34205966 R gse 100
34205967 R fse 100
34205967 A nse S 44.13 100
34205971 A ose S 44.13 100
34205971 R ose 100
34205972 R mse 100
34205972 A pse S 44.13 100
34205972 A qse B 44.09 200
34205972 R cse 200
34205973 R nse 100
34205973 A rse S 44.13 100
34205973 R qse 200
34205974 A sse B 44.11 200
34205974 R pse 100
34205974 A tse S 44.16 100
34205986 A use S 44.15 72
34206016 A vse S 44.22 100
34206017 R kse 100
34206028 R hre 250
34206028 A wse S 44.15 250
34206029 R tse 100
34206029 A xse S 44.15 100
34206030 R mre 200
34206030 A yse S 44.15 200
34206032 A zse S 44.13 100
34206047 A ate S 44.22 100
34206047 R vse 100
34206049 R wse 250
34206051 A bte S 44.15 250
34206052 R zse 100
34206053 A cte S 44.13 100
34206055 R cte 100
34206057 A dte S 44.13 100
34206058 R dte 100
34206060 A ete S 44.13 100
34206062 R ete 100
34206077 A fte S 44.21 100
34206078 R ate 100
34206079 R uqe 72
34206079 R use 72
34206080 A gte S 44.15 72
34206080 A hte S 44.15 72
34206081 R gte 72
34206081 R hte 72
34206082 A ite S 44.14 72
34206082 A jte S 44.14 72
34206083 R xse 100
34206083 A kte S 44.14 100
34206092 R ite 72
34206092 R jte 72
34206093 A lte S 44.14 72
34206093 A mte S 44.14 72
34206094 R lte 72
34206094 R mte 72
34206095 A nte S 44.14 72
34206095 A ote S 44.14 72
34206096 R kte 100
34206096 A pte S 44.14 100
34206099 R bte 250
34206101 A qte S 44.15 250
34206108 R sse 200
34206108 A rte S 44.21 100
34206108 A ste B 44.09 200
34206108 R fte 100
34206109 R pte 100
34206109 A tte S 44.13 100
34206111 A ute S 44.13 100
34206112 R ute 100
34206136 R nte 72
34206136 R ote 72
34206137 A vte S 44.14 72
34206137 A wte S 44.14 72
34206138 R vte 72
34206138 R wte 72
34206139 A xte S 44.14 72
34206139 A yte S 44.14 72
34206139 A zte S 44.21 100
34206139 R rte 100
34206146 A aue S 44.13 100
34206146 R aue 100
34206169 A bue S 44.20 100
34206169 R zte 100
34206172 R tte 100
34206172 R rse 100
34206172 A cue B 44.13 1100
34206173 R ste 200
34206173 A due B 44.11 200
34206173 A eue S 44.14 100
34206173 A fue S 44.14 100
34206173 A gue B 44.11 100
34206173 A hue B 44.11 100
34206181 R xte 72
34206181 R yte 72
34206182 A iue S 44.13 72
34206183 A jue S 44.13 72
34206183 R fue 100
34206184 A kue S 44.13 100
34206185 R cue 100
34206192 R iue 72
34206192 R jue 72
34206193 A lue S 44.13 72
34206194 A mue S 44.13 72
34206194 R lue 72
34206194 A nue B 44.13 100
34206195 A oue S 44.13 72
34206195 R mue 72
34206196 A pue S 44.13 72
34206196 R oue 72
34206198 R pue 72
34206199 A que S 44.20 100
34206200 R bue 100
34206200 R cue 1000
34206201 R eue 100
34206201 R kue 56
34206220 R kue 44
34206220 R yse 200
34206220 A rue S 44.15 44
34206220 R qte 250
34206220 R gue 100
34206221 A sue B 44.13 100
34206221 A tue S 44.19 200
34206221 R hue 100
34206222 A uue B 44.13 100
34206222 R nue 100
34206222 A vue S 44.16 250
34206223 R tue 200
34206224 A wue S 44.16 200
34206237 A xue S 44.15 100
34206238 R sue 100
34206238 A yue B 44.13 100
34206239 R rue 44
34206239 R uue 100
34206239 A zue B 44.11 100
34206239 A ave B 44.05 100
34206239 A bve S 44.15 44
34206239 R xue 100
34206239 A cve S 44.14 100
34206240 A dve B 44.12 100
34206240 R yue 100
34206240 R jse 100
34206240 R bve 44
34206241 A eve S 44.14 44
34206241 R dve 100
34206241 A fve B 44.11 100
34206242 R cve 100
34206243 R zue 100
34206243 A gve B 44.11 100
34206245 A hve B 44.13 100
34206246 R fve 100
34206246 A ive B 44.11 100
34206246 R gve 100
34206247 A jve B 44.13 100
34206247 R hve 100
34206249 R que 100
34206259 R jve 100
34206259 A kve B 44.11 100
34206260 R ive 100
34206261 A lve B 44.11 100
34206270 R kve 100
34206270 A mve B 44.13 100
34206272 A nve B 44.05 100
34206272 R ave 100
34206279 A ove S 44.22 100
34206281 R vue 250
34206283 A pve S 44.17 250
34206286 A qve B 44.13 100
34206286 R qve 100
34206288 R pve 250
34206288 A rve S 44.16 250
34206289 A sve S 44.22 100
34206290 R ove 100
34206290 R sve 100
34206302 A tve B 44.05 100
34206303 R nve 100
34206325 A uve B 44.13 100
34206325 R uve 100
34206327 A vve B 44.13 100
34206329 A wve S 44.22 100
34206330 R rve 250
34206333 A xve S 44.17 250
34206348 A yve S 44.17 600
34206366 R xve 250
34206367 A zve S 44.16 250
34206379 R wue 200
34206380 A awe S 44.17 200
34206380 R ase 250
34206380 A bwe B 44.11 250
34206381 R due 200
34206381 A cwe B 44.11 200
34206390 R zve 250
34206393 A dwe S 44.17 250
34206393 R awe 200
34206394 A ewe S 44.16 200
34206411 R wve 100
34206412 A fwe B 44.05 100
34206413 R tve 100
34206439 R eve 44
34206439 A gwe S 44.16 100
34206440 R lve 100
34206440 A hwe B 44.13 100
34206441 A iwe S 44.23 100
34206442 R vve 100
34206443 R mve 100
34206443 A jwe B 44.13 100
34206443 A kwe B 44.05 100
34206444 R fwe 100
34206444 R hwe 100
34206444 A lwe B 44.13 100
34206444 A mwe B 44.13 100
34206445 R jwe 100
34206445 A nwe B 44.13 100
34206446 R mwe 100
34206447 R lwe 100
34206447 A owe B 44.13 100
34206486 A pwe B 44.13 100
34206486 R pwe 100
34206487 A qwe B 44.13 100
34206512 A rwe B 44.05 100
34206512 R kwe 100
34206530 A swe S 44.23 100
34206530 R iwe 100
34206543 A twe B 44.06 100
34206544 R rwe 100
34206575 A uwe B 44.06 100
34206575 R twe 100
34206904 A vwe S 44.15 72
34206905 R owe 100
34206905 A wwe B 44.13 100
34206943 R nwe 100
34206943 A xwe B 44.13 100
34206963 A ywe S 44.15 72
34206964 R wwe 100
34206964 A zwe B 44.13 100
34206977 R uwe 100
34206993 R qwe 100
34206999 R gwe 100
34206999 A axe S 44.15 100
34207000 R xwe 100
34207000 R zwe 100
34207000 A bxe B 44.12 100
34207001 A cxe B 44.13 100
34207002 A dxe S 44.15 100
34207005 R dxe 100
34207007 A exe B 44.06 100
34207009 R axe 100
34207010 A fxe S 44.16 100
34207010 R bxe 100
34207010 A gxe B 44.13 100
34207014 A hxe B 44.11 100
34207014 A ixe S 44.18 100
34207015 A jxe B 44.13 100
34207016 R cxe 100
34207016 A kxe B 44.13 100
34207018 R jxe 100
34207020 A lxe B 44.13 100
34207020 R gxe 100
34207020 A mxe B 44.13 100
34207022 A nxe B 44.06 100
34207022 R exe 100
34207023 R lxe 100
34207025 R vwe 72
34207025 R ywe 72
34207025 A oxe B 44.15 649
34207026 R fxe 100
34207026 R kxe 100
34207026 R ewe 200
34207026 A pxe B 44.13 100
34207028 A qxe S 44.16 100
34207028 R mxe 100
34207029 A rxe B 44.13 100
34207029 R hxe 100
34207030 R pxe 100
34207030 A sxe B 44.13 100
34207030 A txe B 44.15 100
34207031 R rxe 100
34207031 R txe 100
34207031 A uxe B 44.13 100
34207032 R sxe 100
34207032 A vxe B 44.13 100
34207033 A wxe B 44.15 100
34207033 R uxe 100
34207033 A xxe B 44.14 100
34207035 R wxe 100
34207035 R vxe 100
34207036 A yxe B 44.14 100
34207036 R xxe 100
34207037 A zxe B 44.14 100
34207037 R yxe 100
34207038 A aye B 44.14 100
34207039 R zxe 100
34207039 A bye B 44.14 100
34207040 R aye 100
34207040 A cye B 44.14 100
34207041 A dye B 44.15 100
34207041 R dye 100
34207042 R nxe 100
34207044 A eye B 44.15 100
34207046 R eye 100
34207057 R oxe 649
34207058 R bye 100
34207058 R cye 100
34207058 A fye B 44.13 100
34207058 A gye B 44.13 100
34207058 R qxe 100
34207059 A hye S 44.16 200
34207059 A iye S 44.16 100
34207060 A jye B 44.13 100
34207061 A kye B 44.11 100
34207071 A lye B 44.06 100
34207081 R bwe 250
34207081 A mye B 44.12 250
34207082 R mye 250
34207085 A nye B 44.11 250
34207089 R cwe 200
34207090 A oye B 44.13 200
34207091 R gye 100
34207091 A pye B 44.13 100
34207091 R fye 100
34207092 A qye B 44.13 100
34207092 R jye 100
34207094 A rye B 44.13 100
34207099 R oye 200
34207099 A sye B 44.11 200
34207110 R sye 200
34207110 A tye B 44.11 200
34207111 R lye 100
34207114 R tye 200
34207114 A uye B 44.11 200
34207117 R kye 100
34207117 A vye B 44.11 100
34207120 R swe 100
34207130 R iye 100
34207131 A wye S 44.16 100
34207132 R wye 100
34207132 A xye S 44.16 100
34207134 R vye 100
34207137 R nye 250
34207137 A yye B 44.13 250
34207138 R qye 100
34207139 R rye 100
34207139 A zye B 44.13 100
34207139 R pye 100
34207139 A aze B 44.13 100
34207140 A bze B 44.06 100
34207141 A cze B 44.06 100
34207141 A dze B 44.13 100
34207141 R xye 100
34207141 R bze 100
34207142 A eze S 44.16 100
34207143 R dze 100
34207145 A fze B 44.13 100
34207145 A gze B 44.11 100
34207147 R gze 100
34207147 A hze B 44.11 100
34207149 R eze 100
34207149 A ize S 44.16 100
34207150 A jze S 44.23 100
34207159 R ize 100
34207160 A kze S 44.16 100
34207161 R jze 100
34207169 R kze 100
34207169 A lze S 44.16 100
34207174 R hze 100
34207174 R ixe 100
34207175 A mze S 44.16 100
34207179 A nze B 44.07 100
34207179 R cze 100
34207180 R mze 100
34207180 R lze 100
34207180 A oze S 44.16 100
34207180 A pze S 44.16 100
34207180 R hye 200
34207180 R nze 100
34207182 A qze S 44.17 200
34207183 A rze B 44.11 100
34207184 A sze S 44.18 100
34207184 R rze 100
34207184 R sze 100
34207188 R oze 100
34207188 R pze 100
34207188 R qze 200
34207189 A tze S 44.16 200
34207189 A uze S 44.16 100
34207189 A vze S 44.16 100
34207191 A wze B 44.11 100
34207192 A xze S 44.18 100
34207192 A yze S 44.23 100
34207192 R vze 100
34207193 A zze S 44.16 100
34207193 R xze 100
34207199 R zze 100
34207200 A aaf S 44.16 100
34207201 A baf S 44.23 100
34207201 R yze 100
34207210 A caf B 44.06 100
34207211 A daf B 44.07 100
34207212 R caf 100
34207212 R baf 100
34207218 R daf 100
34207243 A eaf S 44.23 100
34207257 A faf B 44.06 100
34207354 A gaf S 44.15 72
34207355 R aze 100
34207356 A haf B 44.13 100
34207357 R fze 100
34207369 R zye 100
34207369 A iaf B 44.13 100
34207401 R faf 100
34207421 A jaf S 44.23 100
34207421 R eaf 100
34207431 A kaf B 44.06 100
34207451 A laf S 44.23 100
34207452 R jaf 100
34207492 A maf S 44.15 100
34207493 R haf 100
34207494 A naf B 44.13 100
34207510 R wze 100
34207510 A oaf B 44.11 200
34207520 R dwe 250
34207520 A paf S 44.16 250
34207521 R tze 200
34207522 A qaf S 44.16 200
34207538 R qaf 200
34207539 A raf S 44.17 200
34207539 R paf 250
34207540 R raf 200
34207541 A saf S 44.16 200
34207542 A taf S 44.16 250
34207543 R maf 100
34207543 R kaf 100
34207543 A uaf S 44.23 100
34207543 R laf 100
34207545 A vaf S 44.15 100
34207548 R saf 200
34207548 A waf S 44.17 200
34207550 R taf 250
34207552 A xaf S 44.16 250
34207555 R gaf 72
34207555 R vaf 100
34207555 A yaf B 44.15 472
34207556 R yye 250
34207556 R iaf 100
34207556 R uze 100
34207556 R naf 100
34207557 R uye 200
34207557 A zaf B 44.13 100
34207557 A abf B 44.13 200
34207557 A bbf B 44.13 100
34207557 R aaf 100
34207557 A cbf S 44.17 100
34207557 A dbf S 44.17 100
34207558 R zaf 100
34207558 A ebf B 44.13 100
34207559 R bbf 100
34207559 A fbf B 44.13 100
34207559 A gbf B 44.11 250
34207560 R oaf 200
34207560 R xaf 250
34207561 R ebf 100
34207561 A hbf B 44.13 100
34207563 A ibf S 44.17 250
34207564 R fbf 100
34207564 R cbf 100
34207564 A jbf B 44.14 100
34207564 A kbf S 44.16 100
34207565 R hbf 100
34207565 A lbf B 44.14 100
34207566 R jbf 100
34207566 A mbf B 44.14 100
34207566 R yaf 53
34207567 R lbf 100
34207567 A nbf B 44.14 100
34207572 A obf B 44.06 100
34207575 A pbf S 44.22 100
34207575 R uaf 100
34207595 R yaf 419
34207596 R nbf 100
34207596 R abf 200
34207596 R dbf 100
34207597 A qbf B 44.11 200
34207597 A rbf B 44.13 100
34207597 R waf 200
34207597 A sbf S 44.16 200
34207597 A tbf S 44.16 100
34207606 R mbf 100
34207606 R kbf 100
34207606 A ubf B 44.13 100
34207607 A vbf S 44.16 100
34207608 R ubf 100
34207608 A wbf B 44.13 100
34207609 A xbf B 44.11 100
34207620 R gbf 250
34207621 A ybf B 44.12 250
34207621 R rbf 100
34207621 A zbf B 44.13 100
34207622 A acf B 44.12 200
34207622 R qbf 200
34207623 A bcf B 44.13 100
34207623 R wbf 100
34207624 A ccf B 44.13 100
34207624 R zbf 100
34207625 R bcf 100
34207626 A dcf B 44.13 100
34207631 R ccf 100
34207631 A ecf B 44.13 100
34207631 R tbf 100
34207632 A fcf S 44.16 100
34207632 R dcf 100
34207632 A gcf B 44.13 100
34207641 R ybf 250
34207643 R xbf 100
34207643 A hcf B 44.11 250
34207650 R fcf 100
34207650 A icf S 44.16 100
34207652 R ecf 100
34207652 R gcf 100
34207652 A jcf B 44.13 100
34207652 A kcf B 44.13 100
34207656 A lcf B 44.11 100
34207658 A mcf B 44.06 100
34207659 R obf 100
34207659 R pbf 100
34207660 R acf 200
34207661 A ncf B 44.13 200
34207661 R kcf 100
34207662 A ocf B 44.13 100
34207662 R jcf 100
34207662 A pcf B 44.13 100
34207663 R lcf 100
34207664 A qcf B 44.11 200
34207669 R hcf 250
34207669 A rcf B 44.12 250
34207670 R mcf 100
34207670 R ncf 200
34207670 A scf B 44.11 200
34207673 R qcf 200
34207674 A tcf S 44.18 200
34207679 R scf 200
34207679 A ucf B 44.13 200
34207690 A vcf S 44.22 100
34207692 R vcf 100
34207694 A wcf B 44.14 200
34207695 R icf 100
34207696 A xcf S 44.16 100
34207698 A ycf S 44.16 100
34207699 A zcf B 44.06 100
34207710 A adf B 44.06 100
34207710 R zcf 100
34207722 A bdf S 44.23 100
34207724 R wcf 170
34207725 R vbf 100
34207725 A cdf S 44.16 100
34207728 R wcf 30
34207729 R ycf 100
34207729 A ddf B 44.11 100
34207729 R xcf 100
34207730 A edf S 44.16 100
34207732 R rcf 250
34207732 A fdf B 44.13 250
34207732 A gdf B 44.13 100
34207733 R pcf 100
34207733 A hdf B 44.13 100
34207734 R ocf 100
34207734 R gdf 100
34207734 A idf B 44.13 100
34207739 R fdf 250
34207741 A jdf B 44.12 250
34207752 A kdf B 44.06 100
34207753 R adf 100
34207765 A ldf B 44.14 200
34207766 A mdf S 44.16 100
34207766 R edf 100
34207766 A ndf S 44.16 100
34207832 R mdf 100
34207848 R ldf 200
34207849 R ndf 100
34207849 A odf S 44.16 100
34207869 R odf 100
34207869 A pdf S 44.16 100
34207871 A qdf S 44.16 100
34207900 A rdf B 44.07 100
34207900 R kdf 100
34207907 R qdf 100
34207921 R cdf 100
34207921 R sbf 200
34207922 A sdf S 44.16 100
34207922 A tdf S 44.17 200
34207923 A udf B 44.13 100
34207925 A vdf B 44.13 100
34207925 R vdf 100
34207925 R udf 100
34207928 A wdf B 44.13 100
34207930 R wdf 100
34207937 A xdf B 44.14 100
34207940 R idf 100
34207940 R sdf 100
34207940 A ydf B 44.14 100
34207941 A zdf S 44.16 100
34207942 R ddf 100
34207942 R tcf 200
34207942 A aef B 44.11 100
34207952 A bef B 44.07 100
34207953 R rdf 100
34207966 A cef B 44.13 100
34207966 R cef 100
34207966 A def B 44.14 100
34207967 R jdf 250
34207967 R zdf 100
34207967 R xdf 100
34207967 A eef S 44.16 100
34207969 A fef B 44.12 250
34207970 R bdf 100
34207972 A gef B 44.14 100
34207972 R def 100
34207972 R gef 100
34207973 R tdf 200
34207973 A hef S 44.16 200
34207984 R fef 250
34207984 A ief B 44.12 250
34207990 R ief 250
34207990 R hef 200
34207992 A jef B 44.12 250
34208000 A kef S 44.23 100
34208002 A lef S 44.23 100
34208002 R kef 100
34208006 A mef B 44.14 100
34208006 R mef 100
34208006 A nef B 44.14 100
34208011 A oef B 44.14 100
34208022 R ydf 100
34208022 A pef B 44.13 100
34208023 A qef S 44.16 200
34208024 R jef 250
34208026 A ref B 44.12 250
34208040 R hdf 100
34208040 A sef B 44.13 100
34208040 R qef 200
34208041 R pef 100
34208042 A tef B 44.13 100
34208072 A uef S 44.16 200
34208072 A vef S 44.23 100
34208073 R lef 100
34208074 A wef B 44.07 100
34208074 R bef 100
34208076 R aef 100
34208077 A xef S 44.18 100
34208082 R wef 100
34208085 R oef 100
34208086 R sef 100
34208086 A yef B 44.13 100
34208087 R nef 100
34208088 R pdf 100
34208088 A zef S 44.16 100
34208112 A aff B 44.06 100
34208122 R ref 250
34208122 R ucf 200
34208122 A bff B 44.12 200
34208123 A cff B 44.12 250
34208123 R zef 100
34208123 R eef 100
34208123 A dff S 44.16 100
34208123 A eff S 44.16 100
34208124 R bff 200
34208124 A fff B 44.13 200
34208125 A gff B 44.13 100
34208126 A hff B 44.13 100
34208126 R hff 100
34208127 R gff 100
34208141 R eff 100
34208141 A iff S 44.16 100
34208151 R aff 100
34208151 R dff 100
34208151 R uef 200
34208152 A jff S 44.16 100
34208154 A kff S 44.23 100
34208154 R vef 100
34208154 A lff S 44.17 200
34208157 A mff S 44.16 100
34208166 R lff 200
34208166 A nff B 44.13 100
34208166 R nff 100
34208167 A off B 44.13 100
34208167 R off 100
34208170 R kff 100
34208182 A pff B 44.07 100
34208184 A qff B 44.07 100
34208184 R pff 100
34208200 A rff S 44.23 100
34208206 A sff B 44.13 100
34208206 R sff 100
34208338 R iff 100
34208339 A tff S 44.16 100
34208339 A uff S 44.16 200
34208342 A vff B 44.13 100
34208342 R vff 100
34208370 R mff 100
34208371 R qff 100
34208402 A wff B 44.07 100
34208408 R cff 250
34208408 A xff B 44.13 250
34208446 R tff 100
34208447 R yef 100
34208447 A yff B 44.13 100
34208448 A zff B 44.13 100
34208448 A agf S 44.16 100
34208451 A bgf B 44.13 100
34208452 R bgf 100
34208489 R uff 200
34208492 R yff 100
34208493 A cgf B 44.14 100
34208494 R tef 100
34208494 A dgf B 44.14 100
34208496 A egf B 44.13 100
34208496 R zff 100
34208496 R egf 100
34208499 A fgf B 44.13 100
34208499 R cgf 100
34208501 A ggf B 44.14 100
34208501 A hgf B 44.14 100
34208502 R hgf 100
34208520 R rff 100
34208522 A igf B 44.07 100
34208522 R wff 100
34208531 R igf 100
34208533 R xef 100
34208535 A jgf B 44.14 100
34208551 A kgf S 44.23 100
34208561 A lgf B 44.07 100
34208561 R kgf 100
34208581 R lgf 100
34208592 A mgf S 44.23 100
34208610 R dgf 100
34208610 A ngf B 44.13 100
34208610 A ogf B 44.06 100
34208610 A pgf S 44.16 200
34208613 A qgf B 44.07 100
34208614 R ogf 100
34208620 R fgf 100
34208620 A rgf B 44.13 100
34208621 R ngf 100
34208621 A sgf B 44.13 100
34208630 A tgf S 44.23 100
34208631 R mgf 100
34208639 R qgf 100
34208661 A ugf S 44.23 100
34208661 R tgf 100
34208669 A vgf B 44.07 100
34209323 R jgf 100
34209325 R ggf 100
34209369 A wgf B 44.07 100
34209370 R vgf 100
34209806 R wgf 100
34209835 A xgf B 44.07 100
34209846 A ygf S 44.15 72
34209846 R sgf 100
34209846 R rgf 100
34209847 R jff 100
34209847 A zgf B 44.13 100
34209847 A ahf B 44.13 100
34209847 A bhf S 44.16 100
34209849 A chf B 44.13 100
34209850 R chf 100
34209850 R ygf 72
34209851 A dhf B 44.13 100
34209852 R bhf 100
34209852 A ehf S 44.16 100
34209853 A fhf B 44.13 100
34209853 R dhf 100
34209853 R fhf 100
34209855 A ghf B 44.13 100
34209858 A hhf B 44.13 100
34209861 R ehf 100
34209861 A ihf S 44.16 100
34209868 R xff 250
34209869 R agf 100
34209870 A jhf B 44.12 250
34209870 R ihf 100
34209870 A khf S 44.16 100
34209870 A lhf S 44.16 100
34209871 R jhf 250
34209871 R khf 100
34209871 A mhf S 44.16 100
34209873 A nhf B 44.11 250
34209875 R nhf 250
34209876 A ohf B 44.12 250
34209878 R ibf 250
34209879 A phf S 44.16 250
34209883 R ohf 250
34209885 A qhf B 44.11 250
34209901 A rhf S 44.23 100
34209901 R ugf 100
34209909 R phf 250
34209912 R rhf 100
34209912 A shf S 44.17 250
34209918 R ghf 100
34209918 R hhf 100
34209920 A thf B 44.13 100
34209922 A uhf B 44.13 100
34209922 R thf 100
34209922 R uhf 100
34209925 A vhf B 44.13 100
34209926 R vhf 100
34209928 A whf B 44.13 100
34209930 R whf 100
34209941 A xhf S 44.22 100
34209947 R shf 250
34209947 A yhf S 44.16 250
34209959 R ahf 100
34209959 R mhf 100
34209959 R fff 200
34209959 A zhf B 44.11 200
34209960 A aif B 44.13 100
34209960 A bif S 44.16 100
34209968 R pgf 200
34209969 A cif S 44.17 200
34209969 R lhf 100
34209970 A dif S 44.15 100
34209970 R cif 200
34209971 R bif 100
34209971 A eif S 44.16 200
34209971 A fif S 44.15 100
34209978 R fif 100
34209979 A gif S 44.16 100
34209980 R yhf 250
34209982 A hif S 44.17 250
34209991 A iif B 44.13 100
34209991 R xgf 100
34209991 A jif S 44.18 100
34209992 A kif B 44.13 100
34209996 R eif 200
34209997 A lif S 44.16 200
34210001 A mif S 44.22 100
34210001 R xhf 100
34210021 A nif B 44.05 100
34210037 R qhf 250
34210038 A oif B 44.12 250
34210040 R kif 100
34210042 A pif B 44.13 100
34210043 R pif 100
34210051 A qif B 44.13 100
34210058 R hif 250
34210059 A rif S 44.16 250
34210080 R oif 250
34210082 A sif B 44.12 250
34210086 A tif B 44.13 100
34210087 R iif 100
34210087 R tif 100
34210087 R zhf 200
34210087 A uif B 44.13 200
34210088 R uif 200
34210092 A vif B 44.06 100
34210092 R nif 100
34210099 R rif 250
34210102 A wif S 44.17 250
34210118 R sif 250
34210120 A xif B 44.12 250
34210123 A yif B 44.06 100
34210123 R vif 100
34210126 A zif B 44.13 100
34210126 R zif 100
34210142 R zgf 100
34210143 A ajf B 44.09 200
34210143 A bjf B 44.13 100
34210149 R ajf 200
34210149 A cjf B 44.13 200
34210152 R qif 100
34210152 R jif 100
34210153 A djf B 44.06 100
34210154 R yif 100
34210159 A ejf B 44.13 100
34210180 R mif 100
34210184 A fjf B 44.06 100
34210185 R djf 100
34210208 R gif 100
34210209 A gjf S 44.16 100
34210209 R bjf 100
34210209 A hjf S 44.23 100
34210209 A ijf B 44.14 100
34210210 R dif 100
34210211 A jjf S 44.16 100
34210215 A kjf B 44.06 100
34210215 R fjf 100
34210238 R xif 250
34210240 A ljf B 44.12 250
34210246 A mjf B 44.06 100
34210246 R kjf 100
34210251 R lif 200
34210252 A njf S 44.16 100
34210255 A ojf B 44.15 2200
34210256 R gjf 100
34210256 R jjf 100
34210256 R aif 100
34210257 A pjf B 44.14 100
34210257 R ijf 100
34210258 A qjf B 44.15 100
34210258 A rjf S 44.17 100
34210258 A sjf S 44.16 100
34210265 R ejf 100
34210265 A tjf S 44.18 100
34210269 R tjf 100
34210282 R hjf 100
34210287 R qjf 72
34210287 R wif 250
34210291 A ujf S 44.17 250
34210299 A vjf B 44.06 100
34210300 R mjf 100
34210309 R ljf 250
34210309 A wjf B 44.12 250
34210310 R wjf 250
34210311 R qjf 8
34210312 A xjf S 44.23 100
34210313 A yjf B 44.12 250
34210320 R yjf 250
34210321 A zjf B 44.12 250
34210331 R xjf 100
34210351 R njf 100
34210353 A akf B 44.07 100
34210353 R vjf 100
34210361 A bkf S 44.23 100
34210384 A ckf B 44.07 100
34210384 R akf 100
34210394 R iwd 100
34210395 A dkf S 44.19 200
34210406 A ekf S 44.18 100
34210407 A fkf S 44.16 100
34210408 A gkf S 44.16 32
34210413 R ekf 100
34210413 R gkf 32
34210440 R bkf 100
34210471 A hkf S 44.24 100
34210483 A ikf S 44.24 100
34210484 R hkf 100
34210484 R ckf 100
34210484 R ikf 100
34210495 R fcd 50
34210495 A jkf B 44.16 1046
34210496 R rjf 100
34210496 R pjf 100
34210496 R sjf 100
34210497 A kkf S 44.17 100
34210497 A lkf S 44.19 100
34210497 A mkf B 44.15 100
34210497 R ujf 250
34210498 R kkf 100
34210498 A nkf S 44.19 100
34210499 R lkf 100
34210500 A okf S 44.19 100
34210500 A pkf S 44.18 250
34210500 R nkf 100
34210501 A qkf S 44.18 100
34210502 R okf 100
34210502 A rkf S 44.18 100
34210510 R fkf 100
34210511 R qjf 20
34210511 R qkf 100
34210511 A skf B 44.16 20
34210512 R zjf 250
34210512 R pkf 250
34210512 A tkf S 44.18 100
34210514 A ukf B 44.12 250
34210515 A vkf B 44.07 100
34210515 A wkf S 44.19 250
34210516 A xkf S 44.24 100
34210516 R rkf 100
34210516 A ykf S 44.18 100
34210517 R tkf 100
34210518 A zkf S 44.18 100
34210518 A alf B 44.07 100
34210519 R vkf 100
34210520 R ukf 250
34210521 A blf B 44.12 250
34210527 R skf 20
34210529 R jkf 80
34210529 A clf B 44.15 100
34210538 R jkf 966
34210538 R clf 100
34210538 R mkf 100
34210538 R ojf 1334
34210538 R xkf 100
34210539 R zkf 100
34210539 R ykf 100
34210540 A dlf B 44.15 100
34210540 A elf B 44.13 100
34210540 A flf S 44.18 100
34210540 A glf S 44.17 100
34210541 R wkf 250
34210541 R flf 100
34210541 R dlf 100
34210541 A hlf S 44.18 250
34210541 A ilf B 44.13 100
34210541 A jlf S 44.17 100
34210541 R ojf 500
34210542 R elf 100
34210543 A klf B 44.15 100
34210543 A llf B 44.15 100
34210543 R klf 100
34210543 R llf 100
34210545 R ojf 66
34210545 R dkf 200
34210546 A mlf S 44.18 200
34210552 A nlf B 44.07 100
34210552 R alf 100
34210570 R hlf 250
34210570 A olf S 44.25 100
34210570 A plf S 44.17 250
34210571 R ilf 100
34210571 A qlf B 44.15 100
34210572 R mlf 200
34210573 A rlf S 44.19 200
34210574 R qlf 100
34210590 R blf 250
34210591 A slf B 44.13 250
34210591 R slf 250
34210595 A tlf B 44.12 250
34210600 R tlf 250
34210602 A ulf B 44.12 250
34210621 A vlf B 44.07 100
34210622 R nlf 100
34210623 A wlf S 44.25 100
34210623 R olf 100
34210623 R vlf 100
34210654 A xlf S 44.24 100
34210655 R wlf 100
34210655 A ylf B 44.07 100
34210678 R ojf 90
34210694 A zlf S 46.25 11
34210697 A amf S 44.32 11
34210736 A bmf S 44.17 100
34210737 R jlf 100
34210737 A cmf S 44.17 100
34210738 R glf 100
34210738 A dmf S 44.17 100
34210828 R ojf 72
34210838 R ulf 250
34210838 A emf B 44.12 250
34210890 R emf 250
34210892 A fmf B 44.12 250
34210900 R ylf 100
34210901 R fmf 250
34210903 A gmf B 44.12 250
34210910 R gmf 250
34210910 A hmf B 44.12 250
34210930 A imf B 44.07 100
34210951 A jmf B 44.07 100
34210951 R imf 100
34211020 A kmf B 44.15 140
34211042 R hmf 250
34211044 A lmf B 44.12 250
34211073 A mmf S 44.24 100
34211074 R xlf 100
34211078 R lmf 250
34211079 A nmf B 44.12 250
34211110 A omf B 44.07 100
34211110 R jmf 100
34211112 A pmf S 44.24 100
34211112 R mmf 100
34211397 R nmf 250
34211397 A qmf B 44.13 250
34211432 A rmf B 44.08 100
34211432 R omf 100
34211475 R kmf 140
34211476 R cjf 200
34211476 A smf B 44.13 200
34211516 R qmf 250
34211518 A tmf B 44.12 250
34211541 A umf B 44.13 100
34211727 R ojf 138
34211732 A vmf B 44.13 100
34211733 R umf 100
34211733 A wmf B 44.13 100
34211736 A xmf B 44.14 100
34211740 R tmf 250
34211743 A ymf B 44.12 250
34211743 R vmf 100
34211749 R rlf 200
34211750 A zmf S 44.17 200
34211750 R ymf 250
34211750 A anf B 44.12 250
34211751 R anf 250
34211751 R xmf 100
34211752 R zmf 200
34211752 A bnf S 44.17 200
34211753 A cnf B 44.12 250
34211753 R dmf 100
34211753 R smf 200
34211753 A dnf B 44.09 200
34211754 R cmf 100
34211754 A enf S 44.17 100
34211754 A fnf S 44.19 100
34211754 A gnf S 44.17 100
34211754 R dnf 200
34211755 A hnf B 44.12 200
34211780 A inf S 44.24 100
34211780 R pmf 100
34211780 R rmf 100
34211824 A jnf S 44.24 100
34211824 R inf 100
34211825 A knf B 44.06 100
34211831 R cnf 250
34211833 A lnf B 44.11 250
34211851 R lnf 250
34211852 A mnf B 44.12 250
34211882 A nnf B 44.06 100
34211882 R knf 100
34211888 R plf 250
34211889 A onf S 44.17 250
34211891 R bnf 200
34211891 A pnf S 44.17 200
34211923 A qnf B 44.06 100
34211923 R nnf 100
34211970 A rnf B 44.06 100
34211970 R qnf 100
34212003 A snf S 44.15 72
34212034 R snf 72
34212090 R mnf 250
34212092 A tnf B 44.11 250
34212143 A unf B 44.13 100
34212144 A vnf B 44.13 100
34212183 A wnf B 44.15 66
34212184 R enf 100
34212184 R gnf 100
34212184 R onf 250
34212184 R unf 100
34212186 R vnf 100
34212186 A xnf B 44.14 100
34212186 A ynf S 44.17 100
34212187 R wmf 100
34212187 A znf B 44.14 100
34212188 A aof B 44.15 100
34212189 R pnf 200
34212189 A bof S 44.19 200
34212189 A cof B 44.15 100
34212189 R xnf 100
34212190 A dof B 44.14 100
34212193 R znf 100
34212194 A eof B 44.15 100
34212195 R ynf 100
34212195 R dof 100
34212195 A fof S 44.17 100
34212195 A gof B 44.15 100
34212195 R aof 100
34212196 R fof 100
34212196 A hof S 44.17 100
34212197 R bmf 100
34212197 R gof 100
34212197 A iof B 44.13 100
34212197 R cof 100
34212198 R bof 200
34212198 A jof S 44.17 200
34212199 A kof B 44.15 100
34212200 R jof 200
34212200 A lof S 44.19 200
34212201 A mof B 44.15 100
34212201 R kof 100
34212202 R mof 100
34212204 A nof S 44.17 100
34212206 A oof B 44.15 100
34212206 A pof B 44.15 100
34212206 R oof 100
34212207 R pof 100
34212209 A qof B 44.15 100
34212209 R qof 100
34212211 R fnf 100
34212212 A rof B 44.15 100
34212212 R rof 100
34212213 R tnf 250
34212214 A sof B 44.15 100
34212215 A tof B 44.12 250
34212216 A uof B 44.15 100
34212216 R sof 100
34212216 R uof 100
34212221 A vof B 44.15 100
34212221 A wof B 44.15 100
34212231 A xof B 44.06 100
34212231 R rnf 100
34212232 R jnf 100
34212244 R nof 100
34212244 R hof 100
34212245 R iof 100
34212245 A yof B 44.15 100
34212245 A zof S 44.17 100
34212246 A apf B 44.15 100
34212246 R eof 100
34212247 R vof 100
34212247 R yof 100
34212247 A bpf B 44.15 100
34212248 R wof 100
34212248 A cpf S 44.19 100
34212249 R apf 100
34212249 A dpf B 44.16 100
34212250 R bpf 100
34212250 R tof 250
34212250 A epf B 44.16 100
34212250 A fpf B 44.12 250
34212251 R dpf 100
34212251 A gpf B 44.13 100
34212251 R zof 100
34212251 R hnf 200
34212251 A hpf S 44.19 100
34212251 A ipf B 44.13 200
34212260 R fpf 250
34212262 A jpf B 44.07 100
34212262 R xof 100
34212264 A kpf B 44.12 250
34212267 A lpf S 44.24 100
34212277 R cpf 100
34212294 A mpf B 44.07 100
34212294 R jpf 100
34212300 R lpf 100
34212301 R kpf 250
34212301 A npf B 44.12 250
34212324 A opf B 44.07 100
34212325 R mpf 100
34212332 A ppf S 44.25 100
34212338 A qpf S 44.18 250
34212339 R gpf 100
34212339 A rpf B 44.16 100
34212339 R lof 200
34212339 R hpf 100
34212340 A spf S 44.18 200
34212340 A tpf S 44.18 100
34212340 A upf B 44.16 100
34212340 R epf 100
34212341 R rpf 100
34212341 A vpf B 44.16 100
34212342 A wpf B 44.16 100
34212342 R upf 100
34212343 R spf 200
34212344 A xpf S 44.19 200
34212345 R yve 32
34212346 R xpf 200
34212347 A ypf S 44.18 200
34212351 A zpf S 44.25 100
34212351 R ppf 100
34212355 A aqf B 44.07 100
34212355 R opf 100
34212356 R qpf 250
34212359 R zpf 100
34212361 R wpf 100
34212362 R vpf 100
34212362 A bqf B 44.13 100
34212363 A cqf S 44.18 250
34212363 R tpf 100
34212363 A dqf B 44.13 100
34212363 A eqf S 44.17 100
34212364 A fqf B 44.15 100
34212364 R ipf 200
34212364 A gqf B 44.13 200
34212365 R bqf 100
34212365 A hqf B 44.15 100
34212365 R dqf 100
34212365 A iqf B 44.13 100
34212365 A jqf B 44.15 100
34212367 R fqf 100
34212367 R iqf 100
34212367 A kqf B 44.15 100
34212368 R jqf 100
34212369 A lqf B 44.15 100
34212371 A mqf B 44.15 100
34212371 R npf 250
34212372 A nqf B 44.13 250
34212387 A oqf B 44.08 100
34212387 R aqf 100
34212390 A pqf S 44.25 100
34212390 R pqf 100
34212410 R nqf 250
34212415 A qqf B 44.12 250
34212419 A rqf B 44.08 100
34212419 R oqf 100
34212421 A sqf S 44.25 100
34212430 A tqf S 44.25 100
34212431 R sqf 100
34212462 A uqf S 44.24 100
34212462 R tqf 100
34212495 R eqf 20
34212534 R eqf 48
34212569 R eqf 32
34212570 A vqf S 44.18 100
34212591 R lqf 100
34212592 R uqf 100
34212593 R mqf 100
34212600 A wqf B 44.08 100
34212601 R rqf 100
34212601 R qqf 250
34212604 A xqf B 44.13 250
34212609 R cqf 250
34212610 R gqf 200
34212610 A yqf B 44.13 200
34212615 A zqf S 44.18 250
34212622 A arf S 44.25 100
34212631 A brf B 44.08 100
34212632 R wqf 100
34212633 A crf B 44.15 100
34212634 A drf B 44.15 100
34212634 R hqf 100
34212634 R kqf 100
34212634 A erf B 44.15 100
34212647 R zqf 250
34212662 A frf B 44.08 100
34212663 A grf S 44.18 250
34212663 R brf 100
34212672 R grf 250
34212677 A hrf S 44.19 250
34212678 R hrf 250
34212679 A irf S 44.18 250
34212683 R crf 100
34212687 R irf 250
34212690 A jrf S 44.19 250
34212690 A krf B 44.15 100
34212695 A lrf B 44.09 100
34212695 R frf 100
34212702 R ypf 200
34212703 A mrf S 44.19 200
34212703 R erf 100
34212703 R drf 100
34212703 A nrf B 44.16 100
34212703 A orf B 44.16 100
34212724 A prf B 44.14 200
34212725 R krf 100
34212726 A qrf B 44.09 100
34212726 R yqf 200
34212726 A rrf B 44.14 200
34212726 R lrf 100
34212727 R jrf 250
34212728 A srf S 44.18 250
34212730 R srf 250
34212732 A trf B 44.16 100
34212732 A urf S 44.19 250
34212732 R nrf 100
34212733 A vrf B 44.16 100
34212733 A wrf B 44.16 100
34212733 R orf 100
34212749 R arf 100
34212757 A xrf B 44.09 100
34212757 R qrf 100
34212779 A yrf S 44.25 100
34212830 A zrf S 44.25 100
34212830 R yrf 100
34212847 R yve 568
34212851 R urf 250
34212851 A asf S 44.18 250
34212859 R mrf 200
34212860 A bsf S 44.18 100
34212860 R vqf 100
34212860 R asf 250
34212862 A csf S 44.25 100
34212862 R zrf 100
34212863 R prf 200
34212863 A dsf S 44.19 250
34212863 A esf B 44.14 100
34212869 A fsf S 44.18 67
34212877 R trf 100
34212891 R fsf 67
34212892 A gsf B 44.09 100
34212892 R xrf 100
34212895 R xqf 250
34212898 A hsf B 44.14 250
34212900 R hsf 250
34212903 A isf B 44.13 250
34212908 A jsf B 44.16 100
34212910 R isf 250
34212913 A ksf B 44.13 250
34212915 R esf 100
34212916 A lsf B 44.14 100
34212916 R wrf 100
34212916 R vrf 100
34212917 A msf B 44.16 100
34212917 A nsf B 44.16 100
34212922 A osf B 44.09 100
34212923 R gsf 100
34212942 R csf 100
34212950 R bsf 100
34212950 A psf S 44.19 100
34212951 R dsf 250
34212954 A qsf S 44.20 250
34212954 A rsf B 44.09 100
34212954 R osf 100
34212955 R ksf 250
34212955 A ssf B 44.14 250
34212960 R ssf 250
34212963 A tsf B 44.13 250
34212964 R rrf 200
34212964 A usf B 44.16 200
34212964 R psf 100
34212964 A vsf S 44.19 100
34212965 R nsf 100
34212965 A wsf B 44.16 100
34212965 A xsf B 44.16 100
34212965 R msf 100
34212972 A ysf S 44.25 100
34212979 R ysf 100
34212981 R jsf 100
34212985 R tsf 250
34212986 A zsf B 44.14 250
34212986 A atf B 44.10 100
34212987 R rsf 100
34212987 A btf B 44.16 100
34212991 R usf 200
34212992 A ctf B 44.14 200
34213009 A dtf S 44.26 100
34213018 A etf B 44.10 100
34213018 R atf 100
34213022 A ftf S 44.26 100
34213023 R dtf 100
34213037 R lsf 100
34213038 A gtf B 44.15 100
34213049 A htf B 44.10 100
34213049 R etf 100
34213059 R btf 100
34213064 A itf S 44.26 100
34213064 R ftf 100
34213072 A jtf B 44.16 100
34213073 R wsf 100
34213073 A ktf B 44.16 100
34213074 R xsf 100
34213074 A ltf B 44.16 100
34213080 A mtf B 44.10 100
34213081 R htf 100
34213090 R itf 100
34213116 R jtf 100
34213118 A ntf B 44.10 100
34213119 R mtf 100
34213121 A otf S 44.26 100
34213122 A ptf B 44.17 100
34213123 R ktf 100
34213124 A qtf B 44.17 100
34213124 R ltf 100
34213125 A rtf B 44.17 100
34213139 R ptf 100
34213145 A stf B 44.17 100
34213146 A ttf B 44.17 100
34213146 R qtf 100
34213147 R rtf 100
34213147 A utf B 44.17 100
34213148 R ttf 100
34213148 A vtf B 44.17 100
34213150 A wtf B 44.10 100
34213150 R ntf 100
34213180 A xtf B 44.10 100
34213181 R wtf 100
34213188 A ytf S 44.22 100
34213190 R utf 100
34213190 A ztf B 44.17 100
34213212 A auf B 44.10 100
34213212 R xtf 100
34213242 A buf B 44.11 100
34213243 R auf 100
34213271 R zsf 250
34213271 R qsf 250
34213272 R vtf 100
34213272 A cuf B 44.17 100
34213293 A duf S 44.19 300
34213294 R gtf 100
34213300 A euf B 44.11 100
34213301 R buf 100
34213311 R vsf 100
34213312 A fuf S 44.22 100
34213312 R ztf 100
34213312 A guf B 44.18 100
34213313 R ytf 100
34213313 R cuf 100
34213313 A huf B 44.18 100
34213314 A iuf S 44.21 100
34213315 R guf 100
34213315 R fuf 100
34213315 A juf B 44.18 100
34213315 A kuf S 44.21 100
34213316 A luf B 44.18 100
34213316 R huf 100
34213317 R iuf 100
34213317 R juf 100
34213317 A muf B 44.18 100
34213317 A nuf S 44.21 100
34213318 R luf 100
34213318 R kuf 100
34213319 A ouf B 44.18 100
34213319 A puf S 44.21 100
34213319 R otf 100
34213319 R muf 100
34213320 A quf B 44.18 100
34213320 R nuf 100
34213321 A ruf S 44.21 100
34213321 R ouf 100
34213321 A suf B 44.18 100
34213321 R puf 100
34213322 R suf 100
34213322 A tuf S 44.21 100
34213323 R ruf 100
34213323 A uuf S 44.21 100
34213323 A vuf B 44.18 68
34213324 R tuf 100
34213325 R vuf 68
34213325 R quf 32
34213325 A wuf S 44.21 100
34213325 A xuf B 44.16 100
34213326 R uuf 100
34213326 A yuf B 44.17 100
34213327 A zuf S 44.20 100
34213328 R wuf 100
34213329 A avf S 44.20 100
34213329 R quf 68
34213330 R zuf 100
34213331 A bvf S 44.20 100
34213331 A cvf B 44.11 100
34213332 R euf 100
34213332 R stf 100
34213333 R avf 100
34213334 A dvf S 44.20 100
34213341 A evf B 44.17 100
34213342 R xuf 100
34213342 R bvf 100
34213342 A fvf B 44.15 100
34213343 R yuf 100
34213343 A gvf B 44.17 100
34213344 A hvf S 44.20 100
34213349 A ivf S 44.26 100
34213354 A jvf S 44.20 250
34213355 R dvf 100
34213355 A kvf S 44.19 100
34213356 R hvf 100
34213356 A lvf S 44.19 100
34213356 R evf 100
34213357 R gvf 100
34213357 R kvf 100
34213357 A mvf B 44.15 100
34213357 R lvf 100
34213358 A nvf S 44.19 100
34213358 A ovf S 44.19 100
34213358 R fvf 100
34213358 R nvf 100
34213359 A pvf S 44.19 200
34213359 A qvf S 44.19 100
34213360 R jvf 250
34213363 A rvf B 44.11 100
34213363 R cvf 100
34213366 A svf B 44.17 100
34213367 R mvf 100
34213367 A tvf B 44.17 100
34213368 R pvf 200
34213368 R ovf 100
34213368 A uvf S 44.22 100
34213371 R rvf 100
34213382 R tvf 100
34213382 A vvf S 44.20 250
34213382 A wvf B 44.14 100
34213384 R uvf 100
34213384 A xvf S 44.19 100
34213385 A yvf S 44.19 200
34213390 R svf 100
34213401 A zvf B 44.11 100
34213402 A awf B 44.16 100
34213403 A bwf B 44.13 250
34213403 R wvf 100
34213403 A cwf B 44.16 100
34213410 A dwf S 44.26 100
34213411 R ivf 100
34213411 R qvf 100
34213411 R bwf 250
34213411 R yvf 200
34213411 R zvf 100
34213412 A ewf S 44.19 100
34213412 A fwf S 44.19 200
34213412 R xvf 100
34213413 A gwf S 44.19 100
34213414 R ewf 100
34213415 A hwf S 44.19 100
34213415 A iwf B 44.12 250
34213416 R gwf 100
34213416 A jwf S 44.18 100
34213430 R dwf 100
34213439 R iwf 250
34213440 A kwf B 44.13 250
34213440 R hwf 100
34213441 A lwf S 44.18 100
34213442 A mwf B 44.08 100
34213449 R vvf 250
34213449 A nwf S 44.19 250
34213452 R kwf 250
34213454 A owf B 44.12 250
34213459 A pwf B 44.08 100
34213460 R mwf 100
34213462 A qwf S 44.26 100
34213466 R awf 100
34213466 R jwf 100
34213467 A rwf S 44.18 100
34213468 R lwf 100
34213469 A swf S 44.18 100
34213470 A twf S 44.26 100
34213471 R qwf 100
34213475 A uwf B 44.16 100
34213490 A vwf B 44.08 100
34213491 R pwf 100
34213501 A wwf S 44.26 100
34213501 R twf 100
34213522 R owf 250
34213523 R cwf 100
34213523 A xwf B 44.16 100
34213523 R rwf 100
34213523 A ywf S 44.19 100
34213524 R fwf 200
34213524 A zwf B 44.12 250
34213540 R zwf 250
34213540 A axf B 44.12 250
34213551 A bxf S 44.19 200
34213553 A cxf B 44.08 100
34213553 R vwf 100
34213569 R bxf 200
34213569 A dxf S 44.19 200
34213571 A exf S 44.26 100
34213572 R wwf 100
34213580 R dxf 200
34213581 A fxf S 44.19 200
34213592 R axf 250
34213594 A gxf B 44.12 250
34213599 A hxf B 44.08 100
34213600 R cxf 100
34213600 R fxf 200
34213601 A ixf S 44.19 200
34213601 R gxf 250
34213602 A jxf B 44.12 250
34213602 R ixf 200
34213602 A kxf S 44.19 200
34213603 A lxf S 44.26 100
34213603 R exf 100
34213622 R jxf 250
34213625 A mxf B 44.12 250
34213630 A nxf B 44.08 100
34213630 R hxf 100
34213633 R mxf 250
34213633 A oxf B 44.12 250
34213635 A pxf S 44.25 100
34213635 R lxf 100
34213648 R kxf 200
34213661 A qxf B 44.09 100
34213661 R nxf 100
34213693 A rxf B 44.09 100
34213694 R qxf 100
34213788 R oxf 250
34213789 A sxf B 44.13 250
34213830 R sxf 250
34213832 A txf B 44.12 250
34213907 R txf 250
34213907 A uxf B 44.13 250
34214339 A vxf B 44.16 68
34214351 R nwf 250
34214351 A wxf S 44.18 250
34214352 R xwf 100
34214352 R vxf 68
34214352 R ywf 100
34214352 A xxf S 44.19 200
34214353 A yxf B 44.16 68
34214353 A zxf B 44.14 100
34214353 A ayf S 44.18 100
34214354 R xxf 200
34214354 R swf 100
34214354 A byf S 44.18 100
34214354 A cyf S 44.18 200
34214355 R ayf 100
34214356 A dyf S 44.18 100
34214357 A eyf B 44.14 100
34214357 R byf 100
34214357 A fyf S 44.18 100
34214357 A gyf S 44.18 100
34214358 R dyf 100
34214358 A hyf S 44.17 100
34214359 R fyf 100
34214360 A iyf S 44.17 100
34214364 R gyf 100
34214364 R uwf 100
34214370 R uxf 250
34214370 A jyf S 44.17 100
34214372 A kyf B 44.12 250
34214380 A lyf S 44.24 100
34214381 R pxf 100
34214398 R rxf 100
34214403 R yxf 68
34214403 R hyf 100
34214403 R kyf 250
34214403 A myf B 44.14 68
34214403 A nyf S 44.17 100
34214403 R ctf 200
34214403 R cyf 200
34214404 A oyf S 44.17 200
34214404 A pyf B 44.13 200
34214405 R iyf 100
34214405 A qyf S 44.17 100
34214405 A ryf B 44.12 250
34214406 R eyf 100
34214407 R nyf 100
34214408 A syf S 44.17 100
34214408 R qyf 100
34214409 A tyf S 44.17 100
34214409 R syf 100
34214410 A uyf S 44.17 100
34214411 R ryf 250
34214411 R tyf 100
34214413 A vyf B 44.11 250
34214414 R vyf 250
34214414 A wyf B 44.12 250
34214422 R wxf 250
34214422 A xyf S 44.18 250
34214438 A yyf B 44.06 100
34214440 R wyf 250
34214440 R yyf 100
34214440 A zyf B 44.12 250
34214448 R zyf 250
34214450 A azf B 44.12 250
34214453 A bzf S 44.24 100
34214454 R lyf 100
34214470 A czf B 44.06 100
34214481 R xyf 250
34214483 A dzf S 44.18 250
34214489 R azf 250
34214490 A ezf B 44.12 250
34214509 R bzf 100
34214519 A fzf B 44.06 100
34214520 R czf 100
34214539 A gzf S 44.24 100
34214550 A hzf B 44.06 100
34214551 R fzf 100
34214581 A izf B 44.07 100
34214581 R hzf 100
34214612 A jzf B 44.07 100
34214612 R izf 100
34214622 R uyf 100
34214622 R oyf 200
34214622 A kzf S 44.17 100
34214622 A lzf S 44.18 200
34214625 A mzf S 44.17 200
34214643 A nzf B 44.07 100
34214643 R jzf 100
34214674 A ozf B 44.07 100
34214674 R nzf 100
34214704 R kzf 100
34214706 A pzf B 44.07 100
34214706 R ozf 100
34214708 A qzf B 44.12 100
34214710 R mzf 200
34214710 R dzf 250
34214711 R jyf 100
34214713 A rzf S 44.19 250
34214715 A szf S 44.21 100
34214718 A tzf S 44.18 100
34214730 R tzf 100
34214738 A uzf B 44.07 100
34214738 R pzf 100
34214738 R gzf 100
34214769 A vzf S 44.25 100
34214782 R lzf 200
34214782 R ezf 250
34214782 A wzf B 44.13 250
34214783 A xzf S 44.19 200
34214783 R pyf 200
34214783 A yzf B 44.13 200
34214802 A zzf B 44.07 100
34214802 R uzf 100
34214805 A aag S 44.25 100
34214805 R vzf 100
34214812 R aag 100
34214815 A bag S 44.19 100
34214828 R wzf 250
34214828 A cag B 44.14 250
34214829 R yzf 200
34214829 A dag B 44.14 200
34214834 A eag B 44.08 100
34214834 R zzf 100
34214836 R bag 100
34214848 R xzf 200
34214858 R qzf 100
34214860 A fag S 44.25 100
34214863 A gag B 44.13 200
34214865 A hag B 44.08 100
34214866 R eag 100
34214868 A iag S 44.19 100
34214897 A jag B 44.08 100
34214897 R hag 100
34214900 R rzf 250
34214903 A kag S 44.20 250
34214904 R gag 200
34214904 R szf 100
34214904 A lag S 44.19 200
34214904 A mag B 44.13 100
34214905 A nag S 44.21 200
34214908 R iag 100
34214916 A oag S 44.19 67
34214932 R fag 100
34214932 A pag B 44.08 100
34214933 R jag 100
34214959 A qag B 44.15 100
34214959 R zxf 100
34214960 R myf 68
34214960 A rag B 44.15 100
34214960 A sag B 44.15 100
34214961 R dag 200
34214961 A tag B 44.15 200
34214962 A uag S 44.26 100
34214962 R rag 100
34214962 R sag 100
34214962 A vag B 44.15 100
34214962 A wag B 44.15 100
34214968 R cag 250
34214968 A xag B 44.14 250
34214969 R tag 200
34214969 A yag B 44.16 200
34214970 R wag 100
34214970 R vag 100
34214970 A zag B 44.16 100
34214970 A abg B 44.16 100
34214973 A bbg B 44.16 200
34214976 A cbg S 44.19 100
34214982 A dbg B 44.09 100
34214982 R pag 100
34214991 R xag 250
34214991 A ebg B 44.15 250
34214996 R yag 200
34214997 A fbg B 44.14 200
34214998 R fbg 200
34214998 R bbg 200
34214998 A gbg B 44.15 200
34215004 A hbg B 44.16 100
34215005 R abg 100
34215005 R zag 100
34215005 A ibg B 44.16 100
34215005 A jbg B 44.16 100
34215008 R hbg 100
34215012 R ebg 250
34215013 A kbg B 44.15 250
34215013 A lbg B 44.09 100
34215014 R dbg 100
34215036 R oag 67
34215036 R gbg 200
34215037 A mbg B 44.16 200
34215043 A nbg B 44.09 100
34215044 R lbg 100
34215050 A obg B 41.18 100
34215059 R lag 200
34215059 A pbg S 44.21 200
34215068 R pbg 200
34215068 A qbg S 44.19 200
34215068 R mbg 200
34215068 A rbg B 44.16 200
34215069 R qbg 200
34215069 A sbg S 44.21 200
34215070 R jbg 100
34215070 R ibg 100
34215070 A tbg B 44.16 100
34215070 A ubg B 44.16 100
34215070 R kbg 250
34215070 A vbg B 44.16 250
34215075 A wbg B 44.09 100
34215075 R nbg 100
34215078 R rbg 200
34215078 R kag 250
34215079 R vbg 250
34215080 R cbg 100
34215081 A xbg B 44.16 250
34215089 A ybg S 44.20 250
34215090 R ybg 250
34215090 A zbg B 44.16 200
34215098 R xbg 250
34215099 R uag 100
34215101 A acg B 44.15 250
34215102 A bcg S 44.20 250
34215105 A ccg B 44.16 100
34215106 A dcg B 44.10 100
34215106 A ecg B 44.16 100
34215106 R wbg 100
34215106 R tbg 100
34215107 R ubg 100
34215107 A fcg B 44.16 100
34215107 R mag 100
34215107 R nag 200
34215108 R ccg 100
34215108 R ecg 100
34215108 A gcg B 44.17 100
34215109 R qag 100
34215110 A hcg S 44.19 67
34215110 R fcg 100
34215110 A icg B 44.17 100
34215111 R gcg 100
34215111 A jcg B 44.17 100
34215115 R hcg 67
34215116 R icg 100
34215116 A kcg B 44.17 100
34215118 R acg 250
34215119 R jcg 100
34215119 A lcg B 44.17 100
34215121 A mcg B 44.15 250
34215122 R kcg 100
34215122 A ncg B 44.17 100
34215126 A ocg S 44.19 100
34215127 R lcg 100
34215127 A pcg B 44.17 100
34215129 R mcg 250
34215130 R ncg 100
34215130 A qcg B 44.17 100
34215130 A rcg S 44.26 100
34215131 A scg S 44.26 100
34215131 R rcg 100
34215132 A tcg B 44.15 250
34215133 R pcg 100
34215133 A ucg B 44.18 100
34215134 R bcg 250
34215135 R qcg 100
34215135 A vcg B 44.18 100
34215137 A wcg B 44.10 100
34215137 R dcg 100
34215161 R scg 100
34215167 A xcg B 44.10 100
34215168 R wcg 100
34215189 A ycg S 44.20 250
34215190 A zcg B 44.18 100
34215190 R ucg 100
34215191 R vcg 100
34215191 A adg B 44.18 100
34215192 A bdg S 44.26 100
34215192 R zcg 100
34215192 A cdg B 44.18 100
34215198 A ddg S 44.19 100
34215198 A edg B 44.10 100
34215198 R adg 100
34215199 R xcg 100
34215199 A fdg B 44.18 100
34215201 R cdg 100
34215201 R zbg 200
34215201 A gdg B 44.16 100
34215202 A hdg B 44.16 200
34215202 R sbg 200
34215202 A idg S 44.19 200
34215203 R tcg 250
34215204 R ycg 250
34215210 R idg 200
34215211 A jdg B 44.14 250
34215212 R jdg 250
34215212 A kdg B 44.14 250
34215215 R kdg 250
34215216 A ldg B 44.15 250
34215222 A mdg S 44.26 100
34215223 R bdg 100
34215229 R edg 100
34215238 R ldg 250
34215240 A ndg B 44.14 250
34215253 A odg S 44.26 100
34215253 R mdg 100
34215259 A pdg B 44.11 100
34215263 R ocg 100
34215264 R ddg 100
34215264 A qdg S 44.22 100
34215279 R ndg 250
34215283 A rdg B 44.14 250
34215284 R rdg 250
34215290 A sdg B 44.14 250
34215292 R sdg 250
34215310 R pdg 100
34215340 A tdg B 44.11 100
34215359 R duf 300
34215361 A udg S 44.20 250
34215362 R qdg 100
34215363 A vdg S 44.19 100
34215369 A wdg S 44.26 100
34215370 R odg 100
34215385 R fdg 100
34215386 A xdg B 44.16 100
34215386 A ydg S 44.19 200
34215387 A zdg B 44.14 250
34215387 R gdg 100
34215388 A aeg B 44.16 100
34215388 R ydg 200
34215388 R xdg 100
34215388 A beg S 44.20 200
34215389 A ceg B 44.17 100
34215390 R beg 200
34215391 R aeg 100
34215391 A deg B 44.17 100
34215392 A eeg S 44.19 200
34215393 R ceg 100
34215393 A feg B 44.17 100
34215394 R eeg 200
34215395 R deg 100
34215395 A geg B 44.17 100
34215399 R vdg 100
34215399 R feg 100
34215399 A heg B 44.16 100
34215399 A ieg S 44.19 200
34215400 A jeg S 44.19 100
34215400 A keg S 44.26 100
34215401 R wdg 100
34215403 A leg S 44.19 100
34215407 R leg 100
34215409 R zdg 250
34215413 A meg B 44.14 250
34215413 A neg S 44.19 100
34215415 A oeg S 44.19 100
34215415 A peg S 44.21 100
34215416 R oeg 100
34215418 R meg 250
34215418 A qeg B 44.14 250
34215419 R udg 250
34215419 A reg S 44.19 250
34215422 R qeg 250
34215422 A seg B 44.15 250
34215426 R seg 250
34215426 R reg 250
34215431 R tdg 100
34215432 A teg B 44.14 250
34215432 A ueg S 44.20 250
34215436 R neg 100
34215439 A veg S 44.19 100
34215440 R ueg 250
34215440 A weg S 44.19 250
34215448 A xeg S 44.26 100
34215448 R keg 100
34215451 R teg 250
34215452 A yeg B 44.15 250
34215461 A zeg B 44.09 100
34215470 A afg B 44.09 100
34215471 R zeg 100
34215483 R veg 100
34215512 R yeg 250
34215515 A bfg B 44.14 250
34215521 R geg 22
34215521 R bfg 250
34215521 A cfg B 44.15 250
34215522 A dfg S 44.19 100
34215533 R jeg 100
34215533 A efg S 44.19 100
34215539 A ffg B 44.14 100
34215542 R hdg 200
34215542 A gfg B 44.15 200
34215542 R dfg 100
34215543 A hfg S 44.19 100
34215544 R peg 100
34215559 A ifg B 44.16 100
34215561 R heg 100
34215561 A jfg B 44.16 100
34215561 R xeg 100
34215566 R cfg 250
34215567 R ifg 100
34215567 A kfg S 44.19 100
34215568 A lfg B 44.14 250
34215571 A mfg B 44.09 100
34215571 R afg 100
34215592 A nfg S 44.26 100
34215605 R hfg 100
34215606 A ofg S 44.19 100
34215622 A pfg S 44.26 100
34215622 R nfg 100
34215652 A qfg S 44.25 100
34215653 R pfg 100
34215729 R lfg 250
34215731 A rfg B 44.13 250
34215737 R rfg 250
34215737 A sfg B 44.14 250
34215766 A tfg S 44.19 300
34215834 R geg 78
34215835 R efg 100
34215835 R ieg 200
34215836 A ufg S 44.19 200
34215836 A vfg S 44.18 100
34215837 R ofg 100
34215837 A wfg S 44.18 100
34215845 R kfg 100
34215846 R vfg 100
34215846 A xfg S 44.18 100
34215857 A yfg S 44.21 100
34215866 R sfg 250
34215868 A zfg B 44.14 250
34215887 R zfg 250
34215888 A agg B 44.14 250
34215889 A bgg S 44.25 100
34215890 R qfg 100
34215910 R wfg 100
34215911 R gfg 200
34215911 R ufg 200
34215911 A cgg S 44.18 100
34215911 A dgg B 44.14 200
34215911 A egg S 44.19 200
34215912 R xfg 100
34215912 A fgg S 44.18 100
34215913 R jfg 100
34215913 A ggg B 44.14 100
34215914 R cgg 100
34215915 A hgg S 44.18 100
34215916 R fgg 100
34215916 A igg S 44.18 100
34215924 R ffg 100
34215925 R yfg 100
34215925 A jgg B 44.15 100
34215925 A kgg B 44.13 100
34215926 R ggg 100
34215926 A lgg B 44.15 100
34215930 R agg 250
34215932 A mgg B 44.14 250
34215939 R jgg 100
34215940 R mgg 250
34215940 A ngg B 44.14 250
34215944 R mfg 100
34215956 R ngg 250
34215958 A ogg B 44.14 250
34215960 R ogg 250
34215960 A pgg B 44.14 250
34215961 A qgg S 44.25 100
34215961 R bgg 100
34215962 R pgg 250
34215965 A rgg B 44.14 250
34215972 R weg 250
34215972 A sgg S 44.18 250
34215973 R egg 200
34215973 A tgg S 44.18 200
34215973 A ugg B 44.08 100
34215980 R hgg 100
34215981 A vgg S 44.18 100
34215992 A wgg S 44.25 100
34215992 R qgg 100
34215993 R py 500
34216023 A xgg S 44.25 100
34216023 R wgg 100
34216028 R rgg 250
34216029 R igg 100
34216029 A ygg S 44.17 100
34216031 A zgg B 44.13 250
34216054 A ahg S 44.25 100
34216054 R xgg 100
34216061 R zgg 250
34216061 A bhg B 44.14 250
34216062 R bhg 250
34216064 A chg B 44.13 250
34216092 A dhg S 44.24 100
34216093 R ahg 100
34216118 R lgg 100
34216118 A ehg B 44.14 100
34216119 R dgg 200
34216119 R vgg 100
34216120 A fhg B 44.13 200
34216120 A ghg S 44.17 100
34216122 A hhg S 44.19 100
34216124 A ihg S 44.24 100
34216124 R dhg 100
34216139 R chg 250
34216140 R ygg 100
34216140 A jhg S 44.17 100
34216141 A khg B 44.12 250
34216155 A lhg S 44.24 100
34216155 R ihg 100
34216164 R ugg 100
34216170 R hhg 100
34216175 A mhg S 44.15 157
34216176 R ghg 100
34216176 A nhg S 44.17 100
34216176 R mhg 157
34216177 R jhg 100
34216178 R nhg 100
34216178 A ohg S 44.17 100
34216178 A phg S 44.18 100
34216180 A qhg S 44.19 100
34216188 R phg 100
34216188 A rhg S 44.17 100
34216190 R khg 250
34216191 R rhg 100
34216191 A shg S 44.18 100
34216191 A thg S 44.24 100
34216192 R lhg 100
34216192 R thg 100
34216193 A uhg B 44.12 250
34216193 R kgg 100
34216194 A vhg B 44.12 100
34216195 A whg B 44.08 100
34216209 R uhg 250
34216209 R ohg 100
34216210 A xhg S 44.18 100
34216211 A yhg B 44.11 250
34216213 R vhg 100
34216213 R shg 100
34216214 R qhg 100
34216214 A zhg S 44.18 100
34216214 A aig S 44.20 100
34216220 R whg 100
34216224 A big S 44.24 100
34216241 R big 100
34216251 A cig B 44.07 100
34216265 R yhg 250
34216265 A dig B 44.12 250
34216266 R xhg 100
34216266 A eig S 44.18 100
34216267 R zhg 100
34216268 A fig S 44.18 100
34216271 A gig S 44.24 100
34216274 A hig S 44.18 100
34216275 R eig 100
34216276 A iig S 44.18 100
34216293 A jig S 44.24 100
34216293 R gig 100
34216301 A kig S 44.15 72
34216302 R fig 100
34216303 A lig S 44.17 100
34216319 R dig 250
34216320 R iig 100
34216320 A mig S 44.17 100
34216322 A nig B 44.11 250
34216323 R lig 100
34216323 A oig S 44.17 100
34216324 A pig S 44.24 100
34216324 R jig 100
34216327 R aig 100
34216334 R mig 100
34216334 A qig S 44.17 100
34216346 R oig 100
34216347 A rig S 44.17 100
34216350 R cig 100
34216355 A sig S 44.24 100
34216356 R pig 100
34216380 A tig B 44.05 100
34216392 A uig B 44.06 100
34216392 R tig 100
34216409 A vig S 44.24 100
34216409 R sig 100
34216423 A wig B 44.06 100
34216423 R uig 100
34216426 R sgg 250
34216426 A xig S 44.18 250
34216427 R qig 100
34216427 A yig S 44.17 100
34216428 R tgg 200
34216428 A zig S 44.18 200
34216429 R rig 100
34216429 A ajg S 44.17 100
34216430 R yig 100
34216430 A bjg S 44.17 100
34216440 A cjg S 44.24 100
34216440 R vig 100
34216450 R fhg 200
34216450 A djg B 44.11 200
34216451 R ajg 100
34216451 A ejg S 44.16 100
34216452 R bjg 100
34216453 A fjg S 44.16 100
34216453 A gjg B 44.06 100
34216454 R wig 100
34216457 R xig 250
34216458 R ejg 100
34216458 A hjg S 44.16 100
34216460 A ijg S 44.18 250
34216461 R fjg 100
34216462 A jjg S 44.16 100
34216471 A kjg S 44.24 100
34216471 R cjg 100
34216502 A ljg S 44.23 100
34216502 R kjg 100
34216537 R ijg 250
34216539 A mjg S 44.18 250
34216790 R mjg 250
34216791 A njg S 44.17 250
34216792 R zig 200
34216793 A ojg S 44.17 200
34216822 A pjg S 44.23 100
34216822 R ljg 100
34216853 A qjg S 44.23 100
34216853 R pjg 100
34216945 R kig 72
34216946 R wnf 66
34216946 A rjg S 44.15 6
34216946 R jjg 100
34216946 A sjg B 44.13 68
34216946 A tjg S 44.17 100
34216947 R hjg 100
34216947 A ujg B 44.13 14
34216947 R ehg 100
34216948 A vjg S 44.16 100
34216949 R tjg 100
34216949 A wjg S 44.16 100
34216951 A xjg S 44.16 100
34216952 R vjg 100
34216952 A yjg S 44.16 100
34216959 A zjg B 44.13 68
34216959 R wjg 100
34216960 A akg S 44.16 100
34216967 R zjg 68
34216968 R yjg 100
34216968 A bkg S 44.16 100
34216976 R njg 250
34216979 A ckg S 44.18 250
34216987 R ckg 250
34216988 A dkg S 44.17 250
34216992 R dkg 250
34216995 A ekg S 44.18 250
34217000 R ekg 250
34217000 A fkg S 44.17 250
34217013 R rjg 6
34217014 R akg 100
34217015 A gkg S 44.15 100
34217017 R fkg 250
34217019 A hkg S 44.17 250
34217021 R qjg 100
34217021 R gjg 100
34217051 A ikg S 44.23 100
34217052 A jkg B 44.06 100
34217079 A kkg S 44.23 100
34217079 R ikg 100
34217110 A lkg S 44.23 100
34217110 R kkg 100
34217186 R gkg 30
34217279 R lkg 100
34217288 A mkg B 44.06 100
34217289 R jkg 100
34217291 R bkg 100
34217292 A nkg S 44.16 100
34217309 A okg S 44.23 100
34217332 A pkg S 44.23 100
34217333 R okg 100
34217333 R gkg 70
34217341 R hkg 250
34217341 R nkg 100
34217342 A qkg S 44.17 100
34217343 A rkg S 44.18 250
34217345 A skg S 44.18 100
34217345 R skg 100
34217352 R rkg 250
34217352 A tkg S 44.17 250
34217360 R nig 250
34217360 A ukg B 44.12 250
34217361 R djg 200
34217361 A vkg B 44.12 200
34217365 A wkg B 44.13 100
34217366 R sjg 68
34217366 A xkg B 44.13 100
34217367 R ujg 14
34217367 A ykg B 44.13 100
34217368 R tkg 250
34217369 R vkg 200
34217369 A zkg B 44.13 200
34217369 R ykg 100
34217370 A alg B 44.13 100
34217370 R xkg 100
34217370 A blg B 44.13 100
34217370 A clg B 44.06 100
34217371 R mkg 100
34217371 R zkg 200
34217371 R pkg 100
34217371 A dlg S 44.18 250
34217371 A elg B 44.13 200
34217372 R alg 100
34217373 A flg B 44.13 100
34217373 R blg 100
34217373 A glg B 44.13 100
34217392 R ukg 250
34217395 A hlg B 44.11 250
34217401 A ilg B 44.06 100
34217402 R clg 100
34217402 A jlg S 44.24 100
34217406 A klg S 44.16 1000
34217407 R elg 200
34217407 R qkg 100
34217407 A llg B 44.11 200
34217407 A mlg S 44.16 100
34217432 A nlg B 44.06 100
34217432 R ilg 100
34217469 A olg B 44.06 100
34217470 R nlg 100
34217470 A plg S 44.24 100
34217471 R jlg 100
34217492 R hlg 250
34217492 A qlg B 44.12 250
34217493 R llg 200
34217493 A rlg B 44.12 200
34217501 A slg B 44.06 100
34217502 R olg 100
34217508 R qlg 250
34217509 R mlg 100
34217510 A tlg S 44.17 100
34217511 A ulg B 44.12 250
34217520 R plg 100
34217533 A vlg B 44.07 100
34217534 R slg 100
34217542 R ulg 250
34217544 A wlg B 44.12 250
34217550 A xlg S 44.24 100
34217556 R wkg 100
34217559 R rlg 200
34217559 A ylg B 44.13 200
34217560 R flg 100
34217561 A zlg B 44.13 100
34217561 R glg 100
34217561 A amg B 44.13 100
34217562 A bmg B 44.13 100
34217564 A cmg B 44.07 100
34217564 R vlg 100
34217569 R ylg 200
34217569 A dmg B 44.12 200
34217576 R bmg 100
34217579 R ojg 200
34217580 A emg S 44.18 200
34217580 A fmg B 44.14 100
34217581 R amg 100
34217581 A gmg B 44.14 100
34217582 R zlg 100
34217582 A hmg B 44.14 100
34217593 R fmg 100
34217596 A img B 44.07 100
34217596 R cmg 100
34217600 A jmg B 44.14 100
34217601 R gmg 100
34217601 A kmg B 44.14 100
34217602 R hmg 100
34217602 A lmg B 44.14 100
34217627 A mmg B 44.07 100
34217627 R img 100
34217641 R dlg 250
34217643 A nmg S 44.18 250
34217671 A omg B 44.07 100
34217671 R mmg 100
34217678 R nmg 250
34217680 A pmg S 44.18 250
34217703 A qmg B 44.07 100
34217703 R omg 100
34217758 R xjg 100
34217758 R klg 100
34217823 A rmg S 46.25 6
34217835 A smg S 44.32 6
34217869 R xlg 100
34217900 A tmg S 44.24 100
34218014 R jmg 100
34218026 A umg B 44.14 100
34218027 R lmg 100
34218027 A vmg B 44.14 100
34218028 R kmg 100
34218028 A wmg B 44.14 100
34218270 R pmg 250
34218270 A xmg S 44.18 250
34218680 R klg 100
34218816 A ymg S 54.24 50
34218988 R wlg 250
34218989 A zmg B 44.12 250
34218997 R klg 800
34218998 R dmg 200
34218999 R tlg 100
34218999 A ang B 44.13 200
34218999 A bng S 44.18 100
34219002 A cng S 44.19 200
34219004 A dng S 44.17 100
34219005 R bng 100
34219005 A eng S 44.17 100
34219006 R hig 100
34219009 R dng 100
34219043 A fng B 44.08 100
34219043 R qmg 100
34219044 A gng S 44.24 100
34219044 R tmg 100
34219061 R xmg 250
34219063 A hng S 44.18 250
34219064 R emg 200
34219065 A ing S 44.19 200
34219065 A jng S 44.18 100
34219065 R eng 100
34219066 R ing 200
34219067 A kng S 44.18 200
34219073 A lng B 44.08 100
34219074 R fng 100
34219080 A mng B 44.13 200
34219081 A nng S 44.17 100
34219081 R umg 100
34219081 R ang 200
34219081 R jng 100
34219082 A ong B 44.14 200
34219082 A png S 44.18 100
34219083 R cng 200
34219087 R nng 100
34219088 A qng B 44.14 100
34219088 R vmg 100
34219088 R wmg 100
34219088 A rng B 44.14 100
34219088 A sng B 44.14 100
34219088 R kng 200
34219089 A tng S 44.19 200
34219089 A ung B 44.15 200
34219089 R ong 200
34219090 R rng 100
34219090 R sng 100
34219090 R mng 200
34219090 A vng B 44.15 100
34219090 A wng B 44.15 100
34219098 A xng S 44.18 100
34219099 R tng 200
34219100 A yng S 44.18 200
34219100 R png 100
34219101 A zng S 44.18 100
34219101 R ung 200
34219101 A aog B 44.15 200
34219101 R yng 200
34219102 A bog S 44.19 200
34219102 R hng 250
