34219102 R vng 100
34219102 R wng 100
34219102 A cog B 44.15 100
34219103 A dog B 44.15 100
34219104 A eog B 44.08 100
34219104 A fog S 44.20 200
34219104 R lng 100
34219104 A gog S 44.19 250
34219105 R xng 100
34219109 R zng 100
34219110 A hog S 44.18 100
34219110 R bog 200
34219111 A iog S 44.19 200
34219112 R gng 100
34219114 A jog S 44.18 100
34219115 R hog 100
34219116 A kog S 44.18 100
34219116 R iog 200
34219117 A log S 44.19 200
34219122 R jog 100
34219130 A mog S 44.18 100
34219135 A nog B 44.08 100
34219135 R eog 100
34219137 R zmg 250
34219138 R kog 100
34219138 A oog B 44.13 250
34219139 A pog S 44.18 100
34219141 R aog 200
34219141 A qog B 44.13 200
34219142 A rog S 44.25 100
34219142 R rog 100
34219142 A sog S 44.18 100
34219142 A tog S 44.18 100
34219150 R mog 100
34219156 R tog 100
34219160 R sog 100
34219160 A uog S 44.18 100
34219161 A vog S 44.18 100
34219161 R gog 250
34219162 A wog S 44.18 250
34219166 A xog B 44.08 100
34219166 R nog 100
34219168 R pog 100
34219169 R wog 250
34219169 A yog S 44.18 100
34219169 R log 200
34219170 A zog S 44.19 200
34219171 A apg S 44.18 100
34219171 A bpg S 44.19 250
34219172 A cpg S 44.25 100
34219173 A dpg S 44.25 100
34219174 R cpg 100
34219174 R zog 200
34219178 A epg S 44.19 200
34219184 R qng 100
34219196 A fpg B 44.15 100
34219197 A gpg B 44.08 100
34219197 R xog 100
34219205 A hpg S 44.25 100
34219205 R dpg 100
34219224 R epg 200
34219225 R dog 100
34219225 R cog 100
34219225 A ipg B 44.15 100
34219225 A jpg B 44.15 100
34219227 A kpg B 44.09 100
34219228 R gpg 100
34219270 A lpg S 44.19 200
34219278 R yog 100
34219279 A mpg S 44.18 100
34219279 R bpg 250
34219280 A npg S 44.18 250
34219281 R lpg 200
34219281 A opg S 44.18 200
34219282 A ppg S 44.17 100
34219286 A qpg S 44.17 100
34219289 R vog 100
34219290 R oog 250
34219293 A rpg B 44.12 250
34219298 R mpg 100
34219299 A spg S 44.17 100
34219300 R spg 100
34219300 A tpg B 44.09 100
34219300 R kpg 100
34219300 R rpg 250
34219300 A upg S 44.18 100
34219300 R ppg 100
34219302 A vpg B 44.12 250
34219308 R vpg 250
34219308 A wpg B 44.12 250
34219308 A xpg S 44.23 100
34219309 R hpg 100
34219319 R wpg 250
34219321 A ypg B 44.12 250
34219322 R upg 100
34219322 R opg 200
34219322 R ypg 250
34219323 A zpg B 44.13 250
34219323 A aqg S 44.18 100
34219323 A bqg S 44.19 200
34219330 A cqg B 44.09 100
34219331 R tpg 100
34219332 A dqg S 44.17 100
34219332 R fpg 100
34219332 R fog 200
34219332 R aqg 100
34219332 R cqg 100
34219333 A eqg S 44.18 100
34219333 R dqg 100
34219333 A fqg S 44.19 200
34219334 A gqg B 44.13 100
34219334 R fqg 200
34219334 R eqg 100
34219335 A hqg S 44.18 100
34219335 R gqg 100
34219340 R xpg 100
34219343 R qpg 100
34219348 A iqg S 44.20 100
34219353 A jqg S 44.18 100
34219363 A kqg B 44.09 100
34219370 A lqg S 44.25 100
34219371 R zpg 250
34219371 R bqg 200
34219372 R hqg 100
34219372 A mqg S 44.18 200
34219372 A nqg S 44.18 100
34219373 A oqg B 44.12 250
34219374 R nqg 100
34219374 A pqg S 44.18 100
34219381 R mqg 200
34219381 R pqg 100
34219381 A qqg S 44.19 200
34219381 R oqg 250
34219381 A rqg S 44.18 100
34219382 A sqg B 44.13 250
34219388 R qqg 200
34219389 R rqg 100
34219389 A tqg S 44.18 200
34219390 A uqg S 44.18 100
34219391 R tqg 200
34219392 A vqg S 44.19 200
34219392 R uqg 100
34219392 A wqg S 44.18 100
34219398 A xqg B 44.15 100
34219402 A yqg S 44.25 100
34219403 R lqg 100
34219403 A zqg B 44.09 100
34219404 R kqg 100
34219410 R vqg 200
34219411 R yqg 100
34219411 R wqg 100
34219412 R npg 250
34219412 A arg S 44.18 100
34219412 R ipg 100
34219412 R jpg 100
34219412 A brg B 44.15 100
34219413 A crg B 44.15 100
34219413 A drg S 44.19 200
34219414 A erg S 44.19 250
34219416 A frg B 44.14 100
34219436 A grg B 44.09 100
34219436 R zqg 100
34219442 A hrg S 44.24 100
34219442 R hrg 100
34219466 A irg S 44.18 100
34219468 A jrg B 44.09 100
34219468 R grg 100
34219469 R arg 100
34219470 R drg 200
34219470 A krg S 44.18 100
34219470 R irg 100
34219470 A lrg S 44.19 200
34219470 A mrg S 44.18 100
34219471 R krg 100
34219471 A nrg S 44.19 100
34219472 R lrg 200
34219473 A org S 44.25 100
34219478 R nrg 100
34219478 R mrg 100
34219479 A prg S 44.18 100
34219479 A qrg S 44.18 100
34219479 A rrg S 44.19 200
34219489 R qrg 100
34219489 R rrg 200
34219490 A srg S 44.18 100
34219490 R prg 100
34219491 A trg S 44.18 100
34219491 A urg S 44.19 200
34219491 R erg 250
34219492 A vrg S 44.18 250
34219496 R xqg 100
34219498 R srg 100
34219499 A wrg S 44.18 100
34219502 A xrg B 44.09 100
34219502 R jrg 100
34219512 R xrg 100
34219513 A yrg B 44.16 100
34219514 R crg 100
34219514 A zrg B 44.16 100
34219515 R brg 100
34219515 A asg B 44.16 100
34219519 R wrg 100
34219520 A bsg S 44.18 100
34219521 R vrg 250
34219522 R bsg 100
34219522 A csg S 44.18 100
34219524 A dsg S 44.19 250
34219525 R yrg 100
34219536 A esg B 44.16 100
34219536 R zrg 100
34219537 A fsg B 44.16 100
34219537 R asg 100
34219537 A gsg B 44.16 100
34219543 A hsg B 44.09 100
34219552 A isg B 44.09 100
34219552 R hsg 100
34219560 R dsg 250
34219561 A jsg S 44.18 250
34219562 R sqg 250
34219562 R jsg 250
34219565 A ksg B 44.12 250
34219565 R uog 100
34219565 A lsg S 44.19 250
34219591 A msg B 44.09 100
34219591 R isg 100
34219608 R csg 100
34219608 A nsg S 44.19 100
34219621 A osg B 44.10 100
34219621 R msg 100
34219703 R urg 200
34219703 R trg 100
34219704 A psg S 44.19 100
34219709 R frg 100
34219709 R iqg 100
34219722 R apg 100
34219724 A qsg S 44.19 200
34219724 R nsg 100
34219725 A rsg S 44.19 100
34219725 R qsg 200
34219732 R org 100
34219732 R rsg 100
34219734 A ssg S 44.19 100
34219741 A tsg S 44.19 200
34219744 R esg 100
34219745 R tsg 200
34219745 A usg S 44.18 100
34219752 A vsg B 44.10 100
34219753 R osg 100
34219754 A wsg B 44.16 100
34219755 R fsg 100
34219755 A xsg B 44.16 100
34219755 R gsg 100
34219756 A ysg B 44.16 100
34219758 A zsg S 44.19 200
34219762 A atg S 44.25 100
34219783 A btg B 44.10 100
34219784 R vsg 100
34219810 R ksg 250
34219811 A ctg B 44.13 250
34219950 R psg 100
34219950 R zsg 200
34219950 A dtg S 44.18 200
34219951 A etg S 44.18 100
34219951 R ssg 100
34219951 R lsg 250
34219952 A ftg S 44.18 100
34219952 A gtg S 44.18 250
34219957 R wsg 100
34219957 R ysg 100
34219958 R ftg 100
34219958 A htg B 44.13 100
34219958 A itg S 44.18 100
34219964 R jqg 100
34219975 A jtg S 44.18 100
34219976 R itg 100
34219976 A ktg S 44.17 100
34219981 R btg 100
34219984 R xsg 100
34219985 R etg 100
34219985 A ltg B 44.13 44
34219986 A mtg S 44.17 100
34219987 R ktg 100
34219987 A ntg B 44.13 100
34219987 A otg B 44.11 200
34219987 A ptg S 44.17 100
34219988 R htg 100
34219988 A qtg B 44.13 100
34219988 A rtg B 44.14 100
34219988 R mtg 100
34219989 R ltg 44
34219989 A stg B 44.14 100
34219989 A ttg S 44.17 56
34219992 A utg S 44.25 100
34219992 R atg 100
34219996 R qtg 100
34219996 R qog 200
34219997 A vtg B 44.14 200
34220004 A wtg B 44.14 100
34220005 R stg 100
34220005 R rtg 100
34220005 A xtg B 44.14 100
34220006 A ytg B 44.14 100
34220007 R ntg 100
34220011 A ztg B 44.07 100
34220012 R vtg 200
34220012 A aug B 44.13 200
34220016 R wtg 100
34220022 A bug S 44.17 100
34220023 R gtg 250
34220024 A cug S 44.18 250
34220024 R ptg 100
34220025 A dug S 44.17 100
34220025 R dtg 200
34220026 R ttg 56
34220026 A eug S 44.18 200
34220026 A fug S 44.17 56
34220032 A gug B 44.07 100
34220033 R ztg 100
34220034 A hug S 44.25 100
34220034 R utg 100
34220038 R cug 250
34220040 A iug S 44.18 250
34220063 A jug B 44.07 100
34220063 R gug 100
34220065 A kug S 44.24 100
34220065 R hug 100
34220094 A lug B 44.07 100
34220094 R jug 100
34220134 A mug B 44.07 100
34220134 R lug 100
34220162 R ctg 250
34220163 R iug 250
34220163 A nug B 44.14 250
34220163 A oug S 44.18 250
34220164 R aug 200
34220164 A pug B 44.14 200
34220165 A qug B 44.07 100
34220165 R mug 100
34220181 A rug S 44.17 100
34220187 R oug 250
34220190 A sug S 44.18 250
34220192 R nug 250
34220194 A tug S 44.24 100
34220194 R kug 100
34220195 A uug B 44.13 250
34220197 A vug B 44.07 100
34220197 R qug 100
34220228 A wug B 44.07 100
34220228 R vug 100
34220254 A xug B 44.14 100
34220255 R ytg 100
34220255 A yug B 44.14 100
34220256 R xtg 100
34220256 R dug 100
34220256 A zug B 44.14 100
34220257 A avg S 44.17 100
34220258 A bvg B 44.08 100
34220259 R wug 100
34220262 R xug 100
34220265 R otg 200
34220290 A cvg B 44.08 100
34220290 R bvg 100
34220290 R tug 100
34220295 R rug 100
34220321 A dvg S 44.24 100
34220348 R sug 250
34220349 A evg S 44.18 250
34220424 A fvg S 44.16 500
34220425 R pug 200
34220425 R avg 100
34220425 A gvg B 44.13 200
34220425 A hvg S 44.17 100
34220426 R fug 56
34220426 A ivg S 44.16 56
34220453 A jvg B 44.11 600
34220458 R evg 250
34220460 A kvg S 44.18 250
34220466 R kvg 250
34220466 A lvg S 44.18 250
34220468 A mvg S 44.24 100
34220469 R dvg 100
34220485 A nvg B 43.56 25
34220493 R zug 100
34220493 A ovg B 44.13 100
34220496 A pvg B 44.12 100
34220520 R uug 250
34220522 R cvg 100
34220522 A qvg B 44.12 250
34220534 A rvg S 44.24 100
34220534 R mvg 100
34220549 R qvg 250
34220549 A svg B 44.13 250
34220552 A tvg B 44.07 100
34220570 A uvg S 44.24 100
34220570 R rvg 100
34220777 R usg 100
34221230 R lvg 250
34221230 A vvg S 44.17 250
34221231 R eug 200
34221232 A wvg S 44.17 200
34221261 A xvg S 44.24 100
34221261 R uvg 100
34221852 A yvg S 44.16 200
34221890 A zvg S 44.24 100
34221890 R xvg 100
34222291 R ivg 56
34222401 A awg S 44.16 56
34222446 R svg 250
34222448 A bwg B 44.12 250
34222469 R awg 56
34222499 A cwg S 44.17 100
34222500 R hvg 100
34222500 A dwg S 44.17 100
34222502 R cwg 100
34222502 A ewg S 44.17 100
34222503 R dwg 100
34222503 A fwg S 44.16 100
34222504 R ewg 100
34222504 A gwg S 44.16 100
34222515 R bwg 250
34222516 A hwg B 44.13 250
34222535 A iwg S 44.23 100
34222535 R zvg 100
34223322 A jwg S 44.23 100
34223322 R iwg 100
34223377 A kwg S 44.16 100
34223688 R bug 100
34225505 R hwg 250
34225508 A lwg B 44.12 250
34225579 R yug 100
34225579 R fwg 100
34225579 R gvg 200
34225579 A mwg B 44.13 68
34225579 R vvg 250
34225579 A nwg B 44.13 200
34225580 R gwg 100
34225580 A owg S 44.17 250
34225580 A pwg S 44.16 100
34225580 A qwg S 44.16 100
34225581 R wvg 200
34225581 R nwg 200
34225581 A rwg S 44.16 200
34225583 A swg B 44.11 200
34225584 A twg B 44.13 100
34225585 A uwg S 44.16 100
34225586 R mwg 68
34225586 A vwg B 44.14 68
34225587 A wwg B 44.13 100
34225587 R jtg 100
34225588 R swg 200
34225588 A xwg B 44.13 200
34225592 R lwg 250
34225592 R ovg 100
34225592 A ywg B 44.13 100
34225594 R xwg 200
34225594 R rwg 200
34225594 A zwg S 44.16 200
34225595 A axg B 44.12 250
34225596 R pvg 100
34225597 A bxg S 44.16 100
34225598 R pwg 100
34225599 A cxg S 44.16 100
34225599 R qwg 100
34225599 A dxg S 44.16 100
34225602 A exg B 44.12 200
34225609 R wwg 100
34225609 R bxg 100
34225610 A fxg S 44.22 100
34225610 R jwg 100
34225613 A gxg S 44.16 100
34225614 R cxg 100
34225615 A hxg S 44.15 100
34225616 R dxg 100
34225616 A ixg S 44.16 100
34225616 A jxg S 44.15 100
34225617 R axg 250
34225619 A kxg B 44.11 250
34225622 R gxg 100
34225623 R tvg 100
34225630 A lxg S 44.15 100
34225631 R jxg 100
34225631 A mxg S 44.15 100
34225633 R hxg 100
34225633 R vwg 68
34225633 A nxg B 44.13 68
34225634 A oxg S 44.15 100
34225636 R owg 250
34225636 A pxg S 44.16 250
34225639 A qxg S 44.15 100
34225649 R exg 200
34225650 A rxg B 44.11 200
34225651 R kxg 250
34225651 R twg 100
34225653 A sxg B 44.06 100
34225653 A txg B 44.11 250
34225655 A uxg B 44.11 100
34225660 R ywg 100
34225660 A vxg B 44.12 100
34225664 A wxg B 44.06 100
34225664 R sxg 100
34225665 R uxg 100
34225671 R txg 250
34225673 A xxg S 44.15 100
34225673 A yxg B 44.11 250
34225675 A zxg B 44.10 100
34225679 R wxg 100
34225680 R pxg 250
34225680 A ayg S 44.15 250
34225681 R ayg 250
34225683 A byg S 44.16 250
34225692 A cyg S 44.22 100
34225692 R fxg 100
34225710 A dyg B 44.05 100
34226000 R yxg 250
34226001 A eyg B 44.11 250
34226009 R cyg 100
34226019 A fyg B 44.05 100
34226019 R dyg 100
34226040 A gyg S 44.22 100
34226049 A hyg B 44.06 100
34226049 R fyg 100
34226076 R byg 250
34226077 A iyg S 44.15 250
34226320 A jyg S 44.22 100
34226320 R gyg 100
34226351 R eyg 250
34226353 R zwg 200
34226353 A kyg S 44.15 200
34226353 A lyg B 44.11 250
34226723 R kwg 100
34226966 A myg S 44.14 400
34226968 A nyg S 44.14 100
34226969 A oyg S 44.14 100
34226990 R nyg 100
34226991 R zxg 100
34227017 R jyg 100
34227046 A pyg S 44.22 100
34227262 R uwg 100
34227751 A qyg B 42.66 3
34228073 A ryg B 43.63 400
34228170 R iyg 250
34228173 A syg S 44.16 250
34228342 R lyg 250
34228342 A tyg B 44.12 250
34228368 R tyg 250
34228368 A uyg B 44.13 250
34228369 R nxg 68
34228370 A vyg B 44.13 68
34228370 R kyg 200
34228411 A wyg B 44.06 100
34228412 R hyg 100
34228442 A xyg B 44.06 100
34228442 R wyg 100
34228613 R myg 100
34228645 A yyg S 44.14 100
34228748 R myg 100
34229008 R ixg 100
34229159 R myg 20
34229175 R myg 180
34229514 A zyg B 44.13 100
34229515 A azg B 44.13 100
34229547 A bzg S 44.14 180
34229547 R mxg 100
34229548 A czg S 44.14 100
34229548 R vxg 100
34229549 A dzg B 44.11 100
34229612 A ezg S 44.22 100
34229612 R pyg 100
34229884 R azg 100
34229886 R zyg 100
34229969 A fzg B 44.13 100
34229972 A gzg B 44.13 100
34229974 R gzg 100
34230054 A hzg B 44.13 100
34230058 R bzg 180
34230059 R czg 100
34230059 R dzg 100
34230059 A izg S 44.15 100
34230060 A jzg B 44.13 100
34230060 A kzg S 44.14 100
34230060 R hzg 100
34230062 R fzg 100
34230068 R qxg 100
34230106 R kzg 100
34230126 A lzg S 46.25 33
34230129 R ezg 100
34230161 A mzg S 44.22 100
34230293 A nzg B 44.13 100
34230296 A ozg B 44.13 100
34230348 A pzg S 44.65 400
34230352 R ozg 100
34230354 R nzg 100
34230382 R syg 250
34230385 A qzg S 44.17 250
34230486 R yyg 100
34230487 A rzg S 44.16 200
34230487 A szg S 44.14 100
34230487 R szg 100
34230488 A tzg S 44.15 100
34230489 A uzg S 44.14 100
34230808 R uzg 100
34230913 R qzg 250
34230913 A vzg S 44.16 250
34230933 R vzg 250
34230935 A wzg S 44.17 250
34231032 R wzg 250
34231032 A xzg S 44.16 250
34231134 R xzg 250
34231137 A yzg S 44.17 250
34231158 R xxg 100
34231279 R xyg 100
34231308 A zzg B 44.06 100
34231485 R vyg 68
34231485 R uyg 139
34231488 R oxg 100
34231489 A aah S 44.15 100
34231490 R izg 100
34231491 A bah S 44.15 100
34231491 R aah 100
34231492 A cah S 44.15 100
34231493 R bah 100
34231493 A dah S 44.15 100
34231495 R uyg 111
34231495 R yzg 250
34231495 A eah S 44.17 100
34231495 A fah S 44.16 250
34231496 R jzg 100
34231496 R dah 100
34231496 A gah B 44.11 100
34231496 A hah S 44.14 100
34231497 R cah 100
34231497 A iah S 44.14 100
34231498 R rxg 200
34231499 A jah B 44.11 200
34231510 R iah 100
34231510 A kah S 44.15 100
34231518 R kah 100
34231518 A lah S 44.14 100
34231520 A mah S 44.22 100
34231520 R fah 250
34231520 R mzg 100
34231520 R zzg 100
34231521 A nah S 44.15 250
34231551 A oah B 44.05 100
34231570 R lah 100
34231570 A pah S 44.15 100
34231570 R rzg 200
34231571 A qah S 44.15 200
34231590 R pah 100
34231590 R nah 250
34231591 A rah S 44.15 100
34231592 R rah 100
34231592 A sah S 44.15 100
34231594 A tah S 44.16 250
34231600 R tah 250
34231600 A uah S 44.15 250
34231601 R sah 100
34231601 R gah 100
34231601 A vah B 44.13 100
34231601 A wah B 44.05 100
34231602 R oah 100
34231602 A xah S 44.15 100
34231602 A yah S 44.15 100
34231602 R hah 100
34231603 R xah 100
34231604 A zah S 44.15 100
34231610 R uah 250
34231613 A abh S 44.16 250
34231634 A bbh B 44.05 100
34231634 R wah 100
34231877 R tfg 300
34232035 A cbh S 44.14 100
34232036 R vah 100
34232036 R yah 100
34232036 A dbh B 44.11 100
34232037 A ebh S 44.14 100
34232038 R zah 100
34232038 A fbh S 44.14 100
34232038 R lxg 100
34232040 R eah 100
34232040 A gbh B 44.10 100
34232048 R jah 200
34232050 R abh 250
34232051 A hbh S 44.15 250
34232079 A ibh S 44.21 100
34232079 R mah 100
34232156 A jbh S 44.14 300
34232157 R fbh 100
34232158 A kbh S 44.14 100
34232159 R ebh 100
34232159 A lbh S 44.14 100
34232173 R hbh 250
34232174 A mbh S 44.15 250
34232199 A nbh S 44.21 100
34232200 R ibh 100
34232231 A obh S 44.21 100
34232231 R nbh 100
34232261 A pbh S 44.21 100
34232262 R obh 100
34232270 R tzg 100
34232898 A qbh B 44.11 100
34232898 R kbh 100
34232899 R qah 200
34232899 A rbh S 44.14 100
34232899 A sbh S 44.15 200
34232919 R gbh 100
34232928 R bbh 100
34232959 A tbh B 44.05 100
34233903 R mbh 250
34233906 A ubh S 44.17 250
34233957 A vbh S 44.13 200
34233958 R lbh 100
34233958 R qbh 100
34233958 R rbh 100
34233959 R dbh 100
34233959 A wbh B 44.11 100
34233959 A xbh S 44.14 100
34233959 A ybh S 44.13 100
34233959 A zbh B 44.09 200
34233959 A ach B 44.09 100
34233964 R cbh 100
34233989 R ubh 250
34233990 A bch S 44.17 250
34233999 R tbh 100
34234000 A cch S 44.21 100
34234000 R pbh 100
34234026 R bch 250
34234029 A dch B 44.04 100
34234029 A ech S 44.17 250
34234031 R ofe 100
34234032 R xbh 100
34234032 R wbh 100
34234032 A fch B 44.09 100
34234034 A gch S 44.13 100
34234034 R ach 100
34234035 A hch B 44.09 100
34234036 R fch 100
34234036 A ich B 44.09 100
34234036 A jch B 44.09 100
34234037 R hch 100
34234037 A kch B 44.10 100
34234040 R dch 100
34234058 A lch S 44.20 100
34234058 R cch 100
34234071 A mch B 44.04 100
34234078 R mch 100
34234083 R vbh 100
34234084 R ich 100
34234084 A nch B 44.10 100
34234084 R gch 100
34234084 A och S 44.14 100
34234084 R kch 100
34234085 A pch B 44.10 100
34234085 R nch 100
34234085 A qch B 44.10 100
34234087 R pch 100
34234087 A rch B 44.10 100
34234088 R qch 100
34234088 A sch B 44.10 100
34234088 A tch S 44.20 100
34234089 R rch 100
34234089 R lch 100
34234089 A uch B 44.10 100
34234090 A vch B 44.10 100
34234090 R sch 100
34234091 R uch 100
34234091 A wch B 44.10 100
34234092 R vch 100
34234092 A xch B 44.11 100
34234093 R wch 100
34234093 A ych B 44.11 100
34234094 R xch 100
34234094 A zch B 44.11 100
34234095 R ych 100
34234095 A adh B 44.11 100
34234096 R zch 100
34234096 A bdh B 44.11 100
34234113 A cdh B 44.04 100
34234689 R vbh 100
34234690 R adh 100
34234690 R bdh 100
34234690 A ddh B 44.11 100
34234691 A edh B 44.11 100
34234698 R ybh 100
34234698 A fdh S 44.14 100
34234700 R ech 250
34234702 A gdh S 44.18 250
34234709 R edh 100
34234709 A hdh B 44.11 100
34234710 R och 100
34234710 A idh S 44.14 100
34234710 R ddh 100
34234711 A jdh B 44.12 100
34234711 R fdh 100
34234712 A kdh S 44.14 100
34234729 A ldh B 44.04 100
34234729 R cdh 100
34234729 R tch 100
34234730 R hdh 100
34234730 A mdh B 44.11 100
34234745 A ndh S 44.13 1000
34234746 R mdh 100
34234746 R idh 100
34234746 R jdh 100
34234746 R kdh 100
34234746 A odh B 44.09 100
34234746 A pdh B 44.09 100
34234747 A qdh S 44.13 100
34234747 A rdh S 44.13 100
34234747 R zbh 200
34234748 A sdh B 44.10 200
34234749 R odh 100
34234749 A tdh B 44.10 100
34234749 R pdh 100
34234749 A udh B 44.10 100
34234750 R sdh 200
34234750 A vdh B 44.10 200
34234751 R tdh 100
34234751 A wdh B 44.10 100
34234752 R udh 100
34234752 A xdh B 44.10 100
34234753 R vdh 200
34234753 A ydh B 44.10 200
34234754 R wdh 100
34234754 A zdh B 44.10 100
34234754 R gdh 250
34234754 R xdh 100
34234755 A aeh B 44.10 100
34234755 A beh S 44.17 250
34234760 R beh 250
34234761 A ceh S 44.21 100
34234762 A deh S 44.17 250
34234763 R deh 250
34234764 A eeh S 44.17 250
34234766 R eeh 250
34234768 A feh S 44.17 250
34234789 R ldh 100
34234789 A geh S 44.21 100
34234790 R ceh 100
34234819 A heh B 44.04 100
34234821 A ieh S 44.20 100
34234821 R geh 100
34234851 A jeh S 44.20 100
34234852 R ieh 100
34234943 R ndh 100
34235027 A keh S 44.14 100
34235334 A leh S 44.20 100
34235334 R jeh 100
34235382 A meh S 44.15 200
34235400 R feh 250
34235406 A neh S 44.15 250
34235480 R neh 250
34235483 A oeh S 44.16 250
34235788 R jvg 600
34235794 A peh B 44.11 400
34235796 A qeh B 44.10 100
34235797 R aeh 100
34235797 A reh B 44.11 100
34235798 R zdh 100
34235798 A seh B 44.10 100
34235799 R peh 400
34236071 R keh 100
34236154 A teh S 44.14 100
34236298 R oeh 250
34236825 A ueh S 44.16 250
34236918 R ndh 900
34236922 A veh S 44.13 100
34236923 A weh S 44.13 200
34236924 R rdh 100
34236924 A xeh S 44.13 100
34236925 R weh 200
34236929 R ueh 250
34236931 A yeh S 44.17 250
34237843 R teh 100
34238113 R yeh 250
34238113 A zeh S 44.16 250
34238130 A afh B 44.11 300
34238840 A bfh S 44.13 100
34238845 A cfh B 44.12 200
34238846 R seh 100
34238846 R xeh 100
34238846 R qdh 100
34238846 A dfh S 44.14 100
34238846 A efh B 44.11 100
34238846 A ffh S 44.13 100
34238848 R bfh 100
34238849 R reh 100
34238849 A gfh B 44.11 100
34238850 A hfh S 44.13 100
34238850 R jch 100
34238860 R zeh 250
34238860 A ifh S 44.15 250
34238866 R cfh 100
34238890 A jfh B 44.04 100
34238890 R heh 100
34238914 R ifh 250
34238916 A kfh S 44.16 250
34238963 A lfh B 44.13 100
34238964 R ffh 100
34238964 R efh 100
34238964 A mfh B 44.11 100
34238964 A nfh S 44.14 100
34238965 R gfh 100
34238965 A ofh B 44.11 100
34238966 R dfh 100
34238966 A pfh S 44.14 100
34238967 R mfh 100
34238967 A qfh B 44.11 100
34238968 R ofh 100
34238968 A rfh B 44.12 100
34238969 R ydh 200
34238970 A sfh B 44.11 200
34238980 R nfh 100
34238980 A tfh S 44.14 100
34238990 R kfh 250
34238990 A ufh S 44.15 250
34239010 A vfh B 44.05 100
34239011 R jfh 100
34239019 R pfh 100
34239020 A wfh S 44.14 100
34239040 A xfh B 44.05 100
34239040 R vfh 100
34239072 A yfh B 44.05 100
34239073 R xfh 100
34239143 R hfh 100
34239145 R sbh 200
34239202 R meh 200
34239206 R veh 100
34239206 R qfh 100
34239207 A zfh B 44.12 100
34239207 R tfh 100
34239207 A agh S 44.14 100
34239208 A bgh S 44.15 200
34239208 A cgh B 44.12 100
34239208 R rfh 100
34239230 R leh 100
34239261 A dgh S 44.21 100
34239262 A egh S 44.14 100
34239334 R egh 100
34239483 A fgh S 44.14 100
34239737 R fgh 100
34239799 R lfh 100
34239799 R cfh 100
34239799 A ggh S 44.12 800
34239800 R sfh 200
34239800 R zfh 100
34239800 A hgh B 44.11 100
34239800 R agh 100
34239800 R wfh 100
34239800 R cgh 100
34239800 A igh B 44.11 100
34239801 A jgh S 44.13 100
34239801 A kgh S 44.13 100
34239802 R hgh 100
34239802 A lgh B 44.10 100
34239804 A mgh B 44.10 100
34239805 R qeh 100
34239806 A ngh B 44.09 200
34239810 R ufh 250
34239810 A ogh S 44.15 250
34239811 R bgh 200
34239812 A pgh S 44.15 200
34239812 A qgh B 44.11 100
34239814 A rgh B 44.11 100
34239823 R igh 100
34239823 A sgh B 44.10 100
34239826 R mgh 100
34239827 R qgh 100
34239837 R ggh 800
34239838 R kgh 100
34239838 R lgh 100
34239838 A tgh S 44.14 100
34239838 A ugh B 44.11 100
34239839 A vgh S 44.13 100
34239842 A wgh S 44.21 100
34239842 R dgh 100
34239842 R yfh 100
34239846 R ogh 250
34239846 A xgh S 44.14 250
34239852 R sgh 100
34239852 R jgh 100
34239853 A ygh B 44.11 100
34239853 R rgh 100
34239853 R tgh 100
34239853 A zgh S 44.14 100
34239853 A ahh S 44.14 100
34239854 R zgh 100
34239855 A bhh S 44.14 100
34239858 R bhh 100
34239859 A chh S 44.13 100
34239861 R vgh 100
34239864 A dhh S 44.13 100
34239870 R chh 100
34239871 A ehh S 44.14 100
34239873 A fhh B 44.04 100
34239875 R xgh 250
34239881 A ghh S 44.15 250
34239891 R ehh 100
34239891 R ugh 100
34239891 R ahh 100
34239891 A hhh B 44.09 100
34239891 A ihh B 44.09 100
34239891 A jhh S 44.20 100
34239891 A khh S 44.13 100
34239891 R wgh 100
34239892 A lhh B 44.04 100
34239892 A mhh S 44.13 100
34239892 R ygh 100
34239892 R ngh 200
34239892 R fhh 100
34239892 A nhh B 44.09 200
34239893 R ihh 100
34239894 R dhh 100
34239894 A ohh B 44.09 100
34239894 A phh B 44.09 100
34239894 R hhh 100
34239895 R nhh 200
34239895 A qhh S 44.13 100
34239896 A rhh B 44.10 200
34239896 R pgh 200
34239897 A shh S 44.13 200
34239897 R phh 100
34239898 R ohh 100
34239898 A thh B 44.10 100
34239898 A uhh B 44.10 100
34239899 A vhh S 44.13 100
34239899 R jhh 100
34239899 R rhh 200
34239899 A whh B 44.10 200
34239900 R mhh 100
34239900 R khh 100
34239900 A xhh S 44.13 100
34239900 R uhh 100
34239900 R shh 200
34239901 A yhh B 44.10 100
34239901 R thh 100
34239901 A zhh S 44.13 100
34239901 A aih B 44.10 100
34239901 R qhh 100
34239901 A bih S 44.14 200
34239901 R ghh 250
34239902 A cih B 44.09 200
34239902 R whh 200
34239902 A dih S 44.14 250
34239903 R bih 200
34239903 A eih S 44.13 200
34239903 A fih S 44.13 100
34239912 R vhh 100
34239919 A gih S 44.13 100
34239920 R lhh 100
34239921 R fih 100
34239922 R zhh 100
34239922 A hih S 44.13 100
34239923 A iih S 44.13 100
34239923 R xhh 100
34239924 A jih S 44.13 100
34239924 R iih 100
34239925 A kih S 44.12 200
34239926 R gih 100
34239927 R hih 100
34239927 A lih S 44.12 100
34239928 A mih S 44.13 100
34239928 R mih 100
34239941 R kih 200
34239942 R jih 100
34239942 A nih S 44.13 100
34239943 A oih S 44.19 100
34239950 A pih B 44.03 100
34239950 R eih 200
34239950 R lih 100
34239950 A qih B 44.10 200
34239951 A rih S 44.14 200
34239951 A sih S 44.13 100
34239951 R cih 200
34239951 R aih 100
34239951 R yhh 100
34239951 A tih B 44.11 100
34239951 A uih B 44.10 100
34239955 A vih S 44.15 100
34239962 A wih B 44.11 100
34239964 A xih S 44.13 100
34239972 R vih 100
34239973 A yih S 44.19 100
34239973 A zih S 44.12 200
34239973 R oih 100
34239974 R qih 200
34239974 R tih 100
34239974 R rih 200
34239974 A ajh B 44.10 100
34239975 R xih 100
34239975 A bjh B 44.09 200
34239977 A cjh S 44.13 200
34239979 R uih 100
34239979 A djh B 44.10 100
34239980 R dih 250
34239981 A ejh S 44.14 250
34239981 R ajh 100
34239981 A fjh B 44.10 100
34239982 R pih 100
34239982 R yih 100
34239987 R ejh 250
34239989 R djh 100
34239990 A gjh B 44.09 100
34239990 A hjh S 44.14 250
34239992 R hjh 250
34239993 A ijh S 44.14 250
34239995 R zih 200
34239996 R gjh 100
34239996 R cjh 200
34239996 R fjh 100
34239997 A jjh B 44.11 100
34239997 A kjh B 44.11 100
34239997 A ljh S 44.16 200
34239998 R ijh 250
34240002 A mjh S 44.14 250
34240003 R jjh 100
34240003 A njh B 44.11 100
34240011 R mjh 250
34240012 A ojh S 44.13 100
34240013 A pjh B 44.04 100
34240014 A qjh S 44.20 100
34240015 A rjh S 44.14 250
34240015 R sih 100
34240016 A sjh S 44.13 100
34240016 R ljh 200
34240017 A tjh S 44.14 200
34240022 A ujh S 44.20 100
34240023 R qjh 100
34240027 R rjh 250
34240027 A vjh S 44.14 250
34240033 R wih 100
34240038 A wjh S 44.13 100
34240040 R wjh 100
34240040 R njh 100
34240040 R sjh 100
34240041 A xjh B 44.11 100
34240041 R nih 100
34240041 A yjh S 44.13 100
34240041 R kjh 100
34240041 A zjh S 44.13 100
34240041 A akh B 44.09 100
34240042 R xjh 100
34240042 A bkh B 44.09 100
34240042 A ckh S 44.13 100
34240043 R bjh 200
34240043 A dkh B 44.09 200
34240043 R tjh 200
34240044 A ekh S 44.13 200
34240044 R ckh 100
34240044 R bkh 100
34240044 A fkh B 44.09 100
34240045 R akh 100
34240045 A gkh B 44.09 100
34240045 R ekh 200
34240046 R dkh 200
34240046 A hkh B 44.10 200
34240047 R gkh 100
34240047 A ikh B 44.10 100
34240048 R fkh 100
34240048 A jkh B 44.10 100
34240048 R vjh 250
34240049 R hkh 200
34240049 A kkh B 44.10 200
34240050 R jkh 100
34240050 A lkh B 44.10 100
34240051 R ikh 100
34240051 A mkh B 44.10 100
34240053 A nkh S 44.20 100
34240054 R ujh 100
34240054 A okh S 44.14 250
34240055 A pkh S 44.14 200
34240059 R kkh 200
34240060 A qkh B 44.10 200
34240060 R lkh 100
34240061 A rkh B 44.10 100
34240061 R mkh 100
34240061 A skh B 44.10 100
34240069 R pjh 100
34240080 R okh 250
34240081 A tkh S 44.14 250
34240084 A ukh S 44.13 100
34240085 R qkh 200
34240085 A vkh B 44.09 200
34240094 A wkh S 44.12 200
34240095 R pkh 200
34240095 A xkh S 44.13 200
34240096 R ukh 100
34240099 A ykh B 44.03 100
34240151 R skh 100
34240151 A zkh B 44.09 100
34240152 R yjh 100
34240152 A alh S 44.13 100
34240184 A blh S 44.19 100
34240184 R nkh 100
34240184 R ykh 100
34240215 A clh S 44.19 100
34240216 R blh 100
34240217 A dlh B 44.03 100
34240231 A elh B 44.03 100
34240232 R dlh 100
34240588 R afh 63
34240589 R zjh 100
34240589 A flh S 44.12 100
34240589 R tkh 250
34240590 A glh S 44.13 250
34240591 R wkh 200
34240592 R flh 100
34240592 R alh 100
34240592 A hlh S 44.13 100
34240592 A ilh S 44.13 100
34240593 A jlh S 44.12 100
34240593 R zkh 100
34240593 A klh B 44.10 100
34240594 R rkh 100
34240595 A llh B 44.10 100
34240595 R jlh 100
34240595 A mlh S 44.13 100
34240597 R mlh 100
34240597 A nlh S 44.12 100
34240599 R nlh 100
34240607 R afh 39
34240644 R afh 198
34240644 R glh 250
34240644 R klh 100
34240644 R hlh 100
34240644 R xkh 200
34240644 A olh S 44.13 100
34240645 A plh S 44.14 200
34240645 A qlh S 44.13 100
34240646 A rlh B 44.10 100
34240646 A slh B 44.09 100
34240646 R llh 100
34240646 R ilh 100
34240647 A tlh S 44.13 200
34240647 R plh 200
34240647 A ulh S 44.13 100
34240647 A vlh S 44.14 250
34240647 R qlh 100
34240647 A wlh S 44.13 100
34240648 R rlh 100
34240648 A xlh B 44.09 100
34240649 R slh 100
34240650 R olh 100
34240650 A ylh B 44.09 100
34240651 A zlh B 44.10 200
34240651 R xlh 100
34240652 A amh B 44.10 100
34240652 R ylh 100
34240652 A bmh S 44.13 100
34240653 A cmh B 44.10 200
34240653 A dmh B 44.10 100
34240653 R vkh 200
34240654 A emh B 44.03 100
34240654 R amh 100
34240654 A fmh B 44.10 100
34240654 R elh 100
34240656 R zlh 200
34240656 A gmh S 44.13 100
34240657 R dmh 100
34240657 A hmh B 44.10 100
34240657 R ulh 100
34240657 R cmh 200
34240658 R fmh 100
34240658 A imh S 44.12 100
34240658 A jmh B 44.09 200
34240658 R bmh 100
34240658 A kmh B 44.10 100
34240659 R hmh 100
34240659 R wlh 100
34240659 A lmh S 44.13 100
34240659 A mmh B 44.10 100
34240660 R kmh 100
34240660 A nmh B 44.09 100
34240661 R gmh 100
34240661 A omh S 44.13 100
34240661 R omh 100
34240662 R lmh 100
34240662 A pmh S 44.13 100
34240663 A qmh S 44.12 100
34240669 R pmh 100
34240669 R mmh 100
34240669 A rmh B 44.09 100
34240669 A smh S 44.12 100
34240670 R vlh 250
34240670 A tmh S 44.13 250
34240670 R nmh 100
34240670 R imh 100
34240670 A umh B 44.09 100
34240670 A vmh S 44.12 100
34240671 R tlh 200
34240671 A wmh S 44.13 200
34240671 R rmh 100
34240671 A xmh S 44.12 100
34240672 A ymh B 44.10 100
34240672 R qmh 100
34240672 R jmh 200
34240672 R smh 100
34240672 R vmh 100
34240672 A zmh S 44.12 100
34240673 A anh S 44.12 100
34240674 A bnh S 44.13 200
34240674 R ojh 100
34240675 A cnh B 44.10 100
34240680 R ymh 100
34240680 R umh 100
34240680 A dnh B 44.09 100
34240680 A enh B 44.09 100
34240681 R cnh 100
34240684 A fnh B 44.03 100
34240685 R emh 100
34240686 R xmh 100
34240690 A gnh S 44.19 100
34240690 R clh 100
34240691 R gnh 100
34240694 A hnh S 44.12 100
34240694 R tmh 250
34240695 A inh S 44.12 250
34240711 R fnh 100
34240720 R zmh 100
34240720 R hnh 100
34240721 A jnh S 44.18 100
34240722 A knh S 44.18 100
34240722 A lnh S 44.12 100
34240723 R jnh 100
34240723 A mnh S 44.12 100
34240723 R lnh 100
34240724 A nnh S 44.12 100
34240724 R mnh 100
34240724 A onh S 44.11 100
34240725 R anh 100
34240725 A pnh S 44.12 100
34240728 A qnh B 44.09 100
34240731 R nnh 100
34240732 R dnh 100
34240732 A rnh B 44.09 100
34240743 A snh B 44.03 100
34240748 R pnh 100
34240749 R enh 100
34240749 A tnh B 44.09 100
34240749 A unh S 44.12 100
34240758 A vnh S 44.12 100
34240758 R vnh 100
34240761 R qnh 100
34240769 R onh 100
34240769 R inh 250
34240771 A wnh S 44.12 250
34240771 A xnh S 44.12 100
34240772 R bnh 200
34240772 R unh 100
34240772 A ynh S 44.11 100
34240773 A znh S 44.12 100
34240775 R xnh 100
34240775 A aoh S 44.12 100
34240779 R knh 100
34240780 R znh 100
34240780 A boh S 44.12 100
34240780 R ynh 100
34240782 A coh S 44.12 100
34240782 A doh S 44.13 200
34240786 R wnh 250
34240789 A eoh S 44.13 250
34240789 A foh B 44.09 200
34240790 A goh B 44.03 100
34240791 R snh 100
34240809 A hoh S 44.18 100
34240809 R hoh 100
34240809 R goh 100
34240840 A ioh S 44.18 100
34240841 A joh B 44.03 100
34240857 R coh 100
34240859 A koh S 44.12 100
34240860 R foh 200
34240862 R aoh 100
34240863 A loh B 44.09 200
34240871 A moh S 44.12 100
34240872 R loh 200
34240872 R koh 100
34240873 A noh B 44.09 200
34240874 A ooh S 44.12 100
34240875 R noh 200
34240900 R boh 100
34240900 R wmh 200
34240900 A poh B 44.09 200
34240900 R eoh 250
34240901 A qoh S 44.13 200
34240901 A roh S 44.13 100
34240902 R ooh 100
34240903 A soh S 44.14 250
34240903 R poh 200
34240903 A toh B 44.09 200
34240905 A uoh S 44.12 100
34240906 R doh 200
34240906 R tnh 100
34240906 R rnh 100
34240907 A voh B 44.10 100
34240907 A woh B 44.10 100
34240907 R toh 200
34240907 A xoh B 44.09 200
34240911 R moh 100
34240920 R qoh 200
34240921 A yoh S 44.13 200
34240923 R uoh 100
34240924 R xoh 200
34240924 A zoh B 44.10 200
34240929 R zoh 200
34240929 A aph B 44.09 200
34240931 R ioh 100
34240961 A bph S 44.20 100
34240962 A cph S 44.20 100
34240962 R bph 100
34240963 A dph B 44.03 100
34240963 R joh 100
34240994 A eph B 44.03 100
34240995 R dph 100
34241004 R aph 200
34241004 A fph B 44.10 200
34241032 R cph 100
34241052 A gph B 44.12 485
34241053 R roh 100
34241053 R voh 100
34241053 R yoh 200
34241053 R woh 100
34241053 A hph B 44.10 100
34241054 A iph B 44.10 100
34241054 A jph S 44.16 200
34241054 A kph S 44.14 100
34241055 R fph 200
34241055 A lph B 44.10 200
34241056 R iph 100
34241056 A mph B 44.10 100
34241057 R hph 100
34241057 A nph B 44.10 100
34241058 R lph 200
34241058 A oph B 44.10 200
34241059 R mph 100
34241059 A pph B 44.10 100
34241060 R nph 100
34241060 A qph B 44.10 100
34241061 R oph 200
34241061 A rph B 44.10 200
34241062 A sph S 44.20 100
34241062 R pph 100
34241062 A tph B 44.10 100
34241063 R qph 100
34241064 A uph B 44.10 100
34241064 R soh 250
34241065 R rph 200
34241065 A vph B 44.11 200
34241066 R uph 100
34241066 A wph B 44.11 100
34241066 A xph S 44.14 250
34241067 R tph 100
34241067 A yph B 44.11 100
34241068 R kph 100
34241068 A zph S 44.13 100
34241068 A aqh S 44.14 100
34241068 R vph 200
34241068 A bqh B 44.11 200
34241069 R wph 100
34241069 A cqh B 44.11 100
34241070 R yph 100
34241071 A dqh B 44.11 100
34241084 R aqh 100
34241084 A eqh S 44.14 100
34241087 R xph 250
34241088 R bqh 200
34241088 R cqh 100
34241088 A fqh B 44.11 200
34241088 A gqh B 44.13 100
34241088 A hqh S 44.15 100
34241089 R dqh 100
34241090 A iqh B 44.11 100
34241090 A jqh S 44.15 250
34241092 R jqh 250
34241094 A kqh S 44.15 250
34241094 R hqh 100
34241095 R jph 200
34241095 A lqh S 44.16 200
34241096 A mqh S 44.15 200
34241096 R zph 100
34241097 R eqh 100
34241097 A nqh S 44.15 100
34241100 R lqh 200
34241100 R kqh 250
34241101 A oqh S 44.15 250
34241102 R nqh 100
34241102 A pqh B 44.03 100
34241102 A qqh S 44.15 100
34241102 R eph 100
34241112 R sph 100
34241132 A rqh B 44.03 100
34241133 R pqh 100
34241145 A sqh S 44.21 100
34241163 A tqh B 44.04 100
34241163 R rqh 100
34241194 A uqh B 44.04 100
34241194 R tqh 100
34241224 A vqh B 44.04 100
34241224 R uqh 100
34241254 A wqh B 44.04 100
34241255 R vqh 100
34241300 A xqh B 44.04 100
34241300 R wqh 100
34241341 A yqh B 44.04 100
34241342 R xqh 100
34241372 A zqh B 44.04 100
34241372 R yqh 100
34241451 A arh B 44.04 100
34241452 R zqh 100
34241482 A brh B 44.05 100
34241482 R arh 100
34241813 R qqh 100
34241814 A crh S 44.13 100
34241851 A drh S 44.21 100
34241851 R sqh 100
34242347 A erh S 50.40 25
34242365 A frh S 51.00 25
34242811 R oqh 250
34242812 A grh S 44.21 100
34242812 A hrh S 44.14 250
34242812 R drh 100
34242955 R hrh 250
34242957 A irh S 44.15 250
34242989 R irh 250
34242989 A jrh S 44.14 250
34243020 A krh S 44.21 100
34243020 R grh 100
34243182 R crh 100
34243183 A lrh S 44.14 100
34243188 A mrh S 44.16 100
34243192 R jrh 250
34243205 A nrh B 44.11 250
34243207 A orh S 44.15 250
34243220 R orh 250
34243220 A prh S 44.15 250
34243220 R krh 100
34243251 A qrh S 44.21 100
34243358 R lrh 100
34243358 A rrh S 44.15 100
34243359 R nrh 250
34243359 R rrh 100
34243360 A srh S 44.15 100
34243362 A trh B 44.11 250
34243390 A urh B 44.06 100
34243390 R brh 100
34243441 R jbh 300
34243442 R fqh 200
34243442 A vrh B 44.11 200
34243443 R iqh 100
34243443 A wrh B 44.11 100
34243444 A xrh B 44.13 100
34243446 R xrh 100
34243448 A yrh B 44.13 100
34243449 A zrh B 44.13 100
34243453 A ash S 44.14 100
34243459 R srh 100
34243459 R prh 250
34243459 A bsh S 44.15 100
34243462 A csh S 44.15 250
34243462 R ash 100
34243463 R mqh 200
34243470 R wrh 100
34243471 A dsh B 44.13 100
34243471 R csh 250
34243472 A esh S 44.16 200
34243473 A fsh S 44.16 250
34243525 R bsh 100
34243526 A gsh S 44.16 100
34243527 R mrh 100
34243531 R fsh 250
34243534 A hsh S 44.17 250
34243546 A ish B 44.13 100
34243547 R gqh 100
34243548 A jsh B 44.13 100
34243549 R dsh 100
34243549 A ksh B 44.13 100
34243550 R hsh 250
34243550 A lsh S 44.16 250
34243552 R qrh 100
34243552 R yrh 100
34243552 R zrh 100
34243556 A msh B 44.13 100
34243556 A nsh B 44.13 100
34243558 R esh 200
34243558 A osh S 44.16 200
34243563 R oyg 100
34243571 A psh S 44.16 100
34243571 A qsh B 44.06 100
34243572 R urh 100
34243572 R gsh 100
34243573 A rsh S 44.16 100
34243576 R trh 250
34243576 A ssh B 44.12 250
34243578 R vrh 200
34243578 A tsh B 44.12 200
34243578 R psh 100
34243582 A ush S 44.22 100
34243587 A vsh S 44.15 100
34243639 R lsh 250
34243642 A wsh S 44.17 250
34243746 R wsh 250
34243749 A xsh S 44.17 250
34243787 R vsh 100
34243804 R xsh 250
34243807 A ysh S 44.18 250
34243825 R ysh 250
34243825 A zsh S 44.17 250
34243831 R ush 100
34243850 R zsh 250
34243850 A ath S 44.17 250
34243861 A bth S 44.22 100
34243880 R ath 250
34243882 A cth S 44.17 250
34243926 R cth 250
34243927 A dth S 44.17 250
34243956 R dth 250
34243958 A eth S 44.17 250
34243985 R eth 250
34243987 A fth S 44.17 250
34243996 R fth 250
34243997 A gth S 44.17 250
34244026 R gth 250
34244028 A hth S 44.17 250
34244067 R hth 250
34244067 A ith S 44.17 250
34244068 R ith 250
34244070 A jth S 44.17 250
34244087 R jth 250
34244088 A kth S 44.17 250
34244134 R kth 250
34244137 A lth S 44.17 250
34244245 R lth 250
34244246 A mth S 44.17 250
34244274 R mth 250
34244277 A nth S 44.17 250
34244363 R nth 250
34244365 A oth S 44.17 250
34244375 R nsh 100
34244376 R msh 100
34244379 R osh 200
34244379 R rsh 100
34244379 R tsh 200
34244379 A pth B 44.13 200
34244379 A qth S 44.16 100
34244380 A rth S 44.17 200
34244381 A sth B 44.13 100
34244382 A tth S 44.18 100
34244383 A uth B 44.13 100
34244383 R uth 100
34244383 R sth 100
34244412 R bth 100
34244419 R oth 250
34244422 A vth S 44.17 250
34244442 A wth S 44.22 100
34244456 R vth 250
34244458 A xth S 44.18 250
34244464 R xth 250
34244465 A yth S 44.17 250
34244623 A zth S 44.16 100
34244624 R qth 100
34244625 A auh S 44.16 100
34244629 R pth 200
34244629 R ksh 100
34244629 R jsh 100
34244629 A buh B 44.12 200
34244629 R rth 200
34244629 A cuh B 44.12 100
34244629 A duh B 44.12 100
34244630 A euh S 44.16 200
34244630 R yth 250
34244630 R cuh 100
34244630 A fuh S 44.17 250
34244630 R zth 100
34244630 A guh B 44.13 100
34244631 R auh 100
34244631 A huh S 44.16 100
34244631 A iuh S 44.16 100
34244633 R tth 100
34244634 A juh S 44.16 200
34244638 A kuh B 44.12 100
34244638 R guh 100
34244639 R duh 100
34244639 A luh B 44.12 100
34244640 R ish 100
34244641 R kuh 100
34244641 R buh 200
34244641 A muh B 44.12 100
34244641 A nuh S 44.15 100
34244642 A ouh B 44.09 200
34244642 R iuh 100
34244642 R luh 100
34244642 R huh 100
34244642 A puh B 44.12 100
34244642 A quh B 44.13 100
34244642 A ruh S 44.15 100
34244642 A suh S 44.15 100
34244643 R ouh 200
34244643 A tuh B 44.12 200
34244649 R tuh 200
34244649 R nuh 100
34244650 R fuh 250
34244650 A uuh S 44.16 250
34244655 A vuh S 44.15 100
34244656 R ruh 100
34244656 R suh 100
34244656 A wuh S 44.15 100
34244656 A xuh S 44.15 100
34244661 R qsh 100
34244662 A yuh S 44.21 100
34244662 R wth 100
34244663 R vuh 100
34244666 R ssh 250
34244667 A zuh B 44.09 200
34244671 A avh S 44.15 100
34244671 A bvh B 44.11 250
34244672 R wuh 100
34244672 A cvh S 44.15 100
34244673 R zuh 200
34244673 A dvh B 44.11 200
34244678 R avh 100
34244685 A evh S 44.15 100
34244686 R cvh 100
34244686 A fvh S 44.15 100
34244691 A gvh B 44.06 100
34244693 R evh 100
34244701 A hvh S 44.14 100
34244702 R fvh 100
34244702 R muh 100
34244703 A ivh B 44.11 100
34244703 A jvh S 44.14 100
34244709 R uuh 250
34244710 A kvh S 44.15 250
34244737 A lvh B 44.13 100
34244738 R euh 200
34244739 A mvh S 44.15 200
34244739 A nvh B 44.13 100
34244767 R nvh 100
34244768 R lvh 100
34244810 A ovh B 44.13 100
34244813 A pvh B 44.13 100
34244876 R pvh 100
34244879 R ovh 100
34244969 R puh 100
34244969 A qvh B 44.12 100
34244972 R quh 100
34244973 R ivh 100
34244973 A rvh B 44.12 100
34244974 R qvh 100
34244974 A svh B 44.12 100
34244975 A tvh B 44.12 100
34244975 R rvh 100
34244979 R bvh 250
34244982 A uvh B 44.11 250
34244990 R uvh 250
34244990 A vvh B 44.11 250
34245001 R gvh 100
34245015 R vvh 250
34245017 A wvh B 44.11 250
34245032 A xvh B 44.05 100
34245126 R wvh 250
34245126 A yvh B 44.11 250
34245634 R hvh 100
34245657 A zvh S 44.14 100
34245658 R jvh 100
34245659 A awh S 44.14 100
34246344 R awh 100
34246344 A bwh B 44.12 100
34246344 A cwh S 44.15 100
34246344 R svh 100
34246345 R tvh 100
34246345 A dwh B 44.12 100
34246346 R bwh 100
34246346 R xuh 100
34246346 A ewh B 44.13 100
34246346 R juh 200
34246347 A fwh S 44.15 100
34246360 R zvh 100
34246361 R mvh 200
34246361 R cwh 100
34246362 A gwh S 44.15 100
34246362 A hwh S 44.16 200
34246362 A iwh S 44.15 100
34246363 A jwh B 44.13 100
34246365 R jwh 100
34246366 A kwh S 44.17 200
34246371 R yuh 100
34246380 R gwh 100
34246380 A lwh S 44.14 100
34246382 R hwh 200
34246382 A mwh S 44.15 200
34246396 R iwh 100
34246397 R mwh 200
34246397 A nwh S 44.16 200
34246402 A owh S 44.22 100
34246406 R kvh 250
34246408 A pwh B 44.13 100
34246409 A qwh S 44.16 250
34246411 A rwh B 44.13 100
34246412 A swh S 44.22 100
34246412 R owh 100
34246412 R rwh 100
34246423 A twh B 44.05 100
34246423 R xvh 100
34246453 R pwh 100
34246454 R qwh 250
34246454 A uwh S 44.15 250
34246476 R uwh 250
34246478 A vwh S 44.16 250
34246496 R vwh 250
34246497 A wwh S 44.15 250
34246598 R wwh 250
34246600 A xwh B 44.13 100
34246600 A ywh S 44.16 250
34246602 A zwh B 44.13 100
34246603 R zwh 100
34246644 R xwh 100
34247304 A axh B 44.11 300
34247305 R aoe 2
34247306 A bxh B 44.13 100
34247308 A cxh B 44.13 100
34247679 R fwh 100
34247680 A dxh S 44.16 100
34247728 A exh B 44.05 100
34247729 R twh 100
34248101 R pzg 400
34248606 R ewh 100
34248606 R bxh 100
34248606 R cxh 100
34248609 A fxh B 44.10 100
34248610 A gxh B 44.12 100
34248619 R dwh 100
34248619 A hxh B 44.11 100
34248620 R ywh 250
34248620 A ixh S 44.15 250
34248621 R nwh 200
34248621 R dxh 100
34248621 A jxh S 44.15 100
34248621 A kxh S 44.15 200
34248628 R kxh 200
34248628 A lxh S 44.16 200
34248630 R kwh 200
34248630 A mxh S 44.17 100
34248630 R fxh 100
34248636 R lxh 200
34248636 A nxh S 44.15 200
34248639 R exh 100
34248649 A oxh S 44.21 100
34248650 R swh 100
34248669 A pxh B 44.05 100
34248670 A qxh B 44.05 100
34248670 R pxh 100
34248695 A rxh S 44.21 100
34248696 R oxh 100
34248722 A sxh B 44.05 100
34248722 R qxh 100
34248899 A txh S 44.14 300
34248901 A uxh S 44.14 100
34248902 R lwh 100
34248902 A vxh S 44.14 100
34248903 R gxh 100
34248904 A wxh B 44.12 100
34248904 R hxh 100
34248905 A xxh B 44.12 100
34248905 R uxh 100
34248906 R wxh 100
34248906 A yxh B 44.12 100
34248907 A zxh S 44.14 100
34248931 R mxh 100
34249034 R zxh 100
34249034 R xxh 100
34249034 A ayh B 44.12 100
34249123 A byh S 44.14 100
34249124 R yxh 100
34249124 A cyh B 44.12 100
34249250 R gph 400
34249251 R ayh 100
34249251 R dvh 200
34249251 A dyh B 44.11 100
34249295 R yvh 250
34249298 A eyh B 44.11 250
34249298 A fyh B 44.11 200
34249341 R ixh 250
34249342 A gyh S 44.15 250
34249343 R jxh 100
34249343 A hyh S 44.15 100
34249344 R nxh 200
34249344 A iyh S 44.15 200
34249355 R gyh 250
34249358 A jyh S 44.15 250
34249359 A kyh S 44.21 100
34249359 R jyh 250
34249360 R rxh 100
34249360 A lyh S 44.15 250
34249391 A myh S 44.21 100
34249391 R kyh 100
34249422 A nyh S 44.21 100
34249423 R myh 100
34249430 R cyh 100
34249430 A oyh B 44.12 100
34249431 R hyh 100
34249431 A pyh S 44.14 100
34249440 R dyh 100
34249440 A qyh B 44.11 100
34249449 R qyh 100
34249449 A ryh B 44.11 100
34249461 A syh S 44.21 100
34249461 R nyh 100
34249471 R sxh 100
34249475 R eyh 250
34249477 A tyh B 44.10 250
34249492 A uyh S 44.21 100
34249492 R syh 100
34249502 A vyh B 44.04 100
34249508 A wyh B 44.09 100
34249508 A xyh S 44.16 100
34249526 R tyh 250
34249526 A yyh B 44.11 250
34249678 R fyh 200
34249678 R oyh 100
34249679 A zyh B 44.11 100
34249679 A azh B 44.11 100
34249679 R ryh 100
34249681 R lyh 250
34249681 A bzh S 44.14 250
34249681 A czh S 44.13 200
34249684 R byh 100
34249685 R vxh 100
34249685 A dzh S 44.13 100
34249687 A ezh S 44.13 100
34249688 R iyh 200
34249688 A fzh S 44.14 200
34249688 R ezh 100
34249689 R gph 34
34249690 R yyh 250
34249692 A gzh B 44.10 250
34249693 R xyh 100
34249693 A hzh S 44.13 100
34249694 A izh B 44.10 200
34249699 R azh 100
34249699 R pyh 100
34249699 A jzh B 44.10 100
34249700 A kzh S 44.13 100
34249702 R czh 200
34249704 R wyh 100
34249710 A lzh S 44.20 100
34249711 R uyh 100
34249716 R gzh 250
34249718 A mzh B 44.09 250
34249719 A nzh S 44.13 100
34249721 R vyh 100
34249721 R hzh 100
34249722 R dzh 100
34249722 A ozh S 44.13 100
34249723 A pzh S 44.13 100
34249725 R pzh 100
34249734 A qzh S 44.13 100
34249742 A rzh S 44.20 100
34249742 R lzh 100
34249745 R gph 51
34249746 R izh 200
34249746 R zyh 100
34249747 A szh B 44.10 100
34249747 A tzh B 44.10 200
34249747 R jzh 100
34249748 A uzh B 44.10 100
34249748 R szh 100
34249749 A vzh B 44.10 100
34249752 A wzh B 44.04 100
34249767 R mzh 250
34249768 A xzh B 44.10 250
34249769 R bzh 250
34249770 A yzh S 44.14 250
34249785 R xzh 250
34249788 A zzh B 44.09 250
34249788 R uzh 100
34249789 A aai B 44.11 100
34249789 R yzh 250
34249790 R vzh 100
34249790 A bai B 44.11 100
34249792 A cai S 44.14 250
34249905 R cai 250
34249906 A dai S 44.14 250
34249975 R dai 250
34249977 A eai S 44.14 250
34250240 R qzh 100
34250274 A fai S 44.13 100
34250484 R yvg 200
34250540 A gai S 44.14 200
34250790 R fzh 200
34250790 R aai 100
34250790 R kzh 100
34250790 A hai B 44.10 100
34250790 A iai S 44.13 100
34250791 A jai S 44.13 200
34250799 R jai 200
34250799 A kai S 44.13 100
34250799 R iai 100
34250800 A lai S 44.14 200
34250801 R kai 100
34250801 A mai S 44.13 100
34250802 R lai 200
34250802 A nai S 44.13 200
34250805 R nzh 100
34250809 R mai 100
34250809 R nai 200
34250809 A oai S 44.13 100
34250809 R bai 100
34250809 A pai B 44.10 100
34250810 A qai S 44.14 200
34250810 R oai 100
34250810 A rai S 44.13 100
34250811 R qai 200
34250811 R hai 100
34250811 A sai S 44.13 100
34250811 A tai B 44.10 100
34250811 R wzh 100
34250811 A uai S 44.13 200
34250811 R ozh 100
34250812 A vai S 44.13 100
34250812 R pai 100
34250812 A wai B 44.10 100
34250812 R fai 100
34250813 R tai 100
34250813 R sai 100
34250813 A xai B 44.10 100
34250814 A yai S 44.13 100
34250814 R wai 100
34250814 A zai B 44.10 100
34250822 A abi S 44.19 100
34250822 R rzh 100
34250833 A bbi S 44.13 100
34250834 R vai 100
34250835 A cbi S 44.13 100
34250835 R yai 100
34250836 A dbi S 44.14 200
34250837 A ebi S 44.13 100
34250841 A fbi B 44.04 100
34250847 R bbi 100
34250849 R xai 100
34250849 R fbi 100
34250849 A gbi B 44.10 100
34250871 A hbi S 44.19 100
34250871 R abi 100
34250877 R dbi 200
34250878 A ibi S 44.14 100
34250879 A jbi B 44.03 100
34250881 A kbi S 44.12 100
34250883 R ebi 100
34250884 R cbi 100
34250884 A lbi S 44.12 100
34250885 A mbi S 44.12 100
34250887 R mbi 100
34250920 A nbi S 44.19 100
34250920 R eai 250
34250920 A obi S 44.13 250
34250920 R tzh 200
34250920 A pbi B 44.09 200
34250920 R hbi 100
34250921 R pbi 200
34250922 A qbi B 44.10 200
34250924 A rbi S 44.12 100
34250927 R kbi 100
34250940 R gbi 100
34250941 A sbi B 44.09 100
34250942 R sbi 100
34250942 A tbi B 44.10 100
34250943 A ubi S 44.12 100
34250945 R rbi 100
34250946 R lbi 100
34250946 A vbi S 44.12 100
34250947 A wbi S 44.12 100
34250949 R wbi 100
34250949 R qbi 200
34250950 A xbi B 44.09 200
34250952 A ybi S 44.19 100
34250953 R nbi 100
34250954 A zbi B 44.03 100
34250954 R jbi 100
34250955 R xbi 200
34250955 A aci B 44.10 200
34250959 R aci 200
34250959 A bci B 44.09 200
34250960 R ubi 100
34250971 R ybi 100
34250983 A cci S 44.12 100
34250985 R obi 250
34250988 A dci S 44.13 250
34250989 R bci 200
34250990 A eci B 44.10 200
34251010 R tbi 100
34251010 A fci B 44.10 100
34251011 A gci S 44.19 100
34251011 R dci 250
34251011 R zai 100
34251011 A hci B 44.10 100
34251011 R uai 200
34251011 R rai 100
34251012 A ici S 44.13 100
34251012 A jci S 44.14 200
34251013 R hci 100
34251013 A kci B 44.10 100
34251013 A lci S 44.14 250
34251014 R cci 100
34251014 R jci 200
34251014 R fci 100
34251014 A mci B 44.10 100
34251014 A nci S 44.13 200
34251015 R kci 100
34251015 A oci B 44.10 100
34251015 A pci S 44.12 100
34251016 R mci 100
34251016 A qci B 44.10 100
34251017 R oci 100
34251017 A rci B 44.10 100
34251020 R ibi 100
34251020 R axh 100
34251020 R qci 100
34251020 A sci B 44.10 100
34251021 R rci 100
34251021 A tci B 44.10 100
34251022 R sci 100
34251022 A uci B 44.10 100
34251031 R nci 200
34251032 A vci S 44.14 200
34251035 R vci 200
34251036 A wci S 44.13 200
34251039 R gci 100
34251042 R pci 100
34251046 R lci 250
34251048 A xci S 44.14 250
34251048 R wci 200
34251048 R uci 100
34251048 A yci S 44.14 200
34251048 A zci B 44.09 100
34251050 R yci 200
34251050 R zci 100
34251050 A adi B 44.10 100
34251050 R xci 250
34251050 A bdi S 44.13 200
34251051 A cdi S 44.14 250
34251053 A ddi B 44.04 100
34251054 R zbi 100
34251069 A edi S 44.19 100
34251070 R ddi 100
34251081 R edi 100
34251101 A fdi B 44.03 100
34251103 R axh 100
34251106 A gdi S 44.14 100
34251109 R gdi 100
34251111 A hdi S 44.20 100
34251194 A idi S 44.12 100
34251210 R cdi 250
34251213 A jdi S 44.14 250
34251318 R idi 100
34251352 R tci 100
34251388 A kdi S 44.12 100
34251389 R fdi 100
34251419 A ldi B 44.03 100
34251709 R ryg 400
34252257 R gai 200
34252671 R kdi 100
34253239 A mdi B 44.10 100
34253279 A ndi B 44.03 100
34253280 R ldi 100
34253286 R vbi 100
34253287 R adi 100
34253287 A odi B 44.10 100
34253287 A pdi S 44.13 100
34253288 R mdi 100
34253288 A qdi B 44.10 100
34253289 R ici 100
34253289 A rdi S 44.13 100
34253289 R odi 100
34253290 A sdi B 44.10 100
34253290 A tdi S 44.13 100
34253290 A udi S 44.15 200
34253290 A vdi S 44.13 100
34253290 R pdi 100
34253290 A wdi S 44.13 50
34253291 R qdi 100
34253291 A xdi B 44.10 100
34253292 R wdi 50
34253292 A ydi S 44.13 50
34253292 A zdi S 44.13 100
34253294 R zdi 100
34253329 R vdi 100
34253409 R jdi 250
34253412 A aei S 44.14 250
34253481 R ydi 50
34253481 R xdi 100
34253482 A bei S 44.13 100
34253482 A cei B 44.11 50
34253483 A dei S 44.13 100
34253484 R bdi 200
34253485 A eei S 44.14 200
34253485 R dei 100
34253517 R zzh 250
34253517 A fei B 44.10 250
34253521 R hdi 100
34253522 A gei B 44.04 100
34253522 R ndi 100
34253523 A hei S 44.13 100
34253523 R hei 100
34253551 A iei S 44.20 100
34253564 A jei S 44.13 100
34253564 R jei 100
34253603 A kei S 44.13 100
34253940 R cei 50
34253940 A lei B 44.10 100
34253941 R sdi 100
34253941 A mei B 44.10 100
34253981 A nei B 44.04 100
34253981 R gei 100
34254012 A oei B 44.04 100
34254012 R nei 100
34254171 R aei 250
34254171 A pei S 44.14 250
34254172 R lei 100
34254172 A qei B 44.10 100
34254639 A rei B 44.11 100
34254639 R eci 200
34254639 R rdi 100
34254640 R mei 100
34254640 A sei B 44.11 100
34254640 A tei B 44.10 200
34254640 A uei S 44.13 100
34254641 R qei 100
34254641 A vei B 44.11 100
34255450 A wei B 43.74 400
34256855 R hzd 1
34257209 R kei 100
34257219 A xei S 44.50 400
34258405 A yei S 44.13 100
34258512 R tei 200
34259249 A zei B 44.10 200
34259250 R yei 100
34259260 R pei 250
34259262 A afi S 44.14 250
34259528 R bei 100
34259528 R sei 100
34259528 A bfi S 44.13 100
34259528 A cfi B 44.11 100
34259529 R eei 200
34259529 R vei 100
34259529 A dfi B 44.11 100
34259529 A efi S 44.14 200
34259530 R uei 100
34259530 R udi 200
34259530 A ffi S 44.14 100
34259539 R tdi 100
34259539 R bfi 100
34259540 A gfi S 44.14 100
34259540 R efi 200
34259541 A hfi S 44.16 200
34259549 R cfi 100
34259549 A ifi B 44.11 100
34259551 A jfi S 44.14 100
34259552 A kfi S 44.16 100
34259553 R gfi 100
34259553 A lfi S 44.13 100
34259554 R ifi 100
34259554 A mfi B 44.10 100
34259555 R jfi 100
34259557 A nfi S 44.13 100
34259558 R iei 100
34259559 R lfi 100
34259559 A ofi S 44.13 100
34259566 R hfi 200
34259567 A pfi S 44.14 200
34259570 A qfi B 44.04 100
34259570 R oei 100
34259588 A rfi S 44.21 100
34259589 A sfi S 44.21 100
34259589 R rfi 100
34259617 A tfi B 44.04 100
34259618 R qfi 100
34259619 R pfi 200
34259620 A ufi S 44.14 200
34259629 R ufi 200
34259629 A vfi S 44.14 200
34259649 A wfi S 44.20 100
34259650 R sfi 100
34260811 R kfi 100
34260838 R tfi 100
34260868 A xfi B 44.04 100
34261107 R dfi 59
34261108 R nfi 100
34261110 R vfi 200
34261110 R dfi 41
34261111 A yfi S 44.16 200
34261118 R yfi 200
34261118 A zfi S 44.14 200
34261121 R fei 250
34261121 A agi B 44.11 250
34261121 R zfi 200
34261122 A bgi S 44.16 200
34261122 R mfi 100
34261122 A cgi B 44.11 100
34261151 R xfi 100
34261156 R afi 250
34261158 A dgi S 44.15 250
34261159 R bgi 200
34261159 A egi S 44.15 200
34261180 A fgi B 44.04 100
34261277 A ggi B 44.12 300
34261278 R zei 200
34261278 R cgi 100
34261278 A hgi B 44.11 200
34261279 A igi B 44.11 100
34261437 R ggi 300
34261438 R igi 100
34261438 R hgi 200
34261438 A jgi B 44.11 100
34261439 A kgi B 44.09 200
34261914 R dgi 250
34261915 A lgi S 44.14 250
34262274 A mgi S 44.13 100
34262315 R lgi 250
34262318 A ngi S 44.15 250
34262326 R ngi 250
34262326 A ogi S 44.14 250
34263075 R mgi 100
34263301 R jgi 100
34263301 R egi 200
34263302 A pgi B 44.09 100
34263302 A qgi S 44.14 200
34263302 R ogi 250
34263302 A rgi S 44.14 250
34263302 A sgi S 44.13 100
34263302 R ffi 100
34263303 A tgi S 44.13 100
34263304 R ofi 100
34263332 A ugi S 44.20 100
34263333 R wfi 100
34263339 A vgi S 44.15 200
34263341 A wgi S 44.13 100
34263342 R fgi 100
34263342 A xgi S 44.13 100
34263343 R tgi 100
34263343 A ygi S 44.13 100
34263344 R wgi 100
34263347 A zgi S 44.13 100
34263363 A ahi S 44.20 100
34263364 R ugi 100
34263372 A bhi B 44.04 100
34263482 R zgi 100
34263710 R agi 250
34263712 A chi S 44.13 100
34263712 A dhi B 44.10 250
34263713 R pgi 100
34263713 A ehi B 44.10 100
34263761 R chi 100
34264063 A fhi S 44.13 100
34266023 R bvd 100
34268414 R fhi 100
34268426 A ghi S 44.13 100
34268485 A hhi B 44.10 100
34268511 R xgi 100
34268511 R ehi 100
34268512 A ihi B 44.10 100
34268513 R hhi 100
34268513 A jhi B 44.10 100
34268520 R ahi 100
34268522 R ghi 100
34268539 R ihi 100
34268540 A khi B 44.11 100
34268550 A lhi S 44.20 100
34269049 A mhi S 44.40 200
34269399 R khi 100
34269399 A nhi B 44.10 100
34269905 A ohi S 44.33 300
34270339 A phi S 44.13 100
34270340 R ygi 100
34270340 A qhi S 44.12 100
34270978 R qgi 200
34270979 A rhi S 44.13 200
34270980 R vgi 200
34270990 R rgi 250
34270991 A shi S 44.13 250
34270991 R phi 100
34271009 R bhi 100
34271019 A thi S 44.20 100
34271020 R lhi 100
34271039 A uhi B 44.04 100
34271667 R axh 100
34271668 R sgi 100
34271669 A vhi S 44.13 100
34271893 R rei 100
34271896 A whi B 44.08 200
34272111 R uhi 100
34272142 A xhi B 44.04 100
34272189 R dhi 250
34272191 A yhi B 44.09 250
34272370 R jhi 100
34272371 R kgi 200
34272372 A zhi B 44.10 200
34272387 A aii B 44.10 100
34272759 A bii B 42.66 6
34272792 R aii 100
34272808 R whi 200
34272808 A cii B 44.08 100
34272809 A dii S 44.12 100
34272811 R dii 100
34272812 A eii S 44.12 100
34272830 R xhi 100
34272860 A fii B 44.03 100
34273247 A gii S 44.11 200
34273247 R nhi 100
34273248 A hii B 44.10 100
34273248 R qhi 100
34273248 A iii S 44.11 100
34273248 R zhi 200
34273248 A jii B 44.09 200
34273249 R vhi 100
34273249 A kii S 44.12 100
34273249 R rhi 200
34273249 A lii S 44.13 200
34273249 R eii 100
34273252 A mii S 44.11 100
34273253 R hii 100
34273253 A nii B 44.09 100
34273269 R nii 100
34273269 A oii B 44.10 100
34273274 A pii B 44.10 100
34273289 R jii 200
34273292 A qii S 44.19 100
34273292 R thi 100
34273292 R fii 100
34273304 R shi 250
34273305 A rii S 44.12 250
34273323 A sii S 44.19 100
34273323 R qii 100
34273348 A tii B 44.03 100
34273399 A uii S 44.19 100
34273400 R sii 100
34273430 A vii S 44.19 100
34273430 R uii 100
34273461 A wii S 44.19 100
34273461 R vii 100
34273769 A xii S 44.19 100
34273769 R wii 100
34273801 A yii S 44.18 100
34273801 R xii 100
34273829 A zii S 44.11 100
34273847 R oii 100
34273847 A aji B 44.09 100
34273959 R yhi 250
34273962 A bji B 44.09 250
34273962 R cii 100
34273969 R lii 200
34273969 A cji S 44.12 200
34273970 R bji 250
34273970 R pii 100
34273971 R aji 100
34273971 A dji B 44.03 100
34273972 A eji B 44.08 250
34273972 A fji B 44.09 200
34273973 A gji B 44.08 200
34273973 R dji 100
34273974 A hji B 44.08 100
34273990 R tii 100
34274002 R rii 250
34274003 A iji S 44.12 250
34274004 R kii 100
34274004 A jji S 44.12 100
34274027 A kji S 44.11 100
34274035 A lji B 44.03 100
34274081 R fji 200
34274097 R gji 200
34274099 R eji 250
34274101 A mji B 44.07 100
34274101 A nji B 44.08 250
34274103 A oji B 44.08 200
34274130 R nji 250
34274130 A pji B 44.08 250
34274130 R lji 100
34274160 A qji B 44.02 100
34274161 A rji B 44.02 100
34274161 R qji 100
34274223 R pji 250
34274225 A sji B 44.08 250
34274270 R rji 100
34274276 R sji 250
34274278 A tji B 44.07 250
34274300 A uji B 44.02 100
34274319 R vvd 10
34274369 R tji 250
34274369 A vji B 44.08 250
34274374 R gae 400
34274375 R jji 100
34274375 A wji S 44.12 200
34274375 R cji 200
34274375 A xji S 44.11 100
34274383 A yji B 44.08 100
34274389 R vji 250
34274391 A zji B 44.07 250
34274392 R mji 100
34274392 A aki B 44.06 200
34274397 R yji 100
34274422 A bki S 44.18 100
34274422 R yii 100
34274423 R uji 100
34274431 R hji 100
34274431 A cki B 44.08 100
34274432 R oji 200
34274432 A dki B 44.07 200
34274438 A eki B 44.08 100
34274440 R wji 200
34274440 A fki S 44.11 200
34274452 A gki S 44.18 100
34274453 R bki 100
34274453 A hki B 44.01 100
34274485 A iki S 44.18 100
34274485 R gki 100
34274527 R cki 100
34274527 A jki B 44.07 100
34274531 R aki 200
34274545 A kki S 44.11 100
34274545 R eki 100
34274546 R xji 100
34274546 R iii 100
34274546 A lki S 44.11 100
34274547 A mki S 44.11 100
34274548 R mii 100
34274548 R fki 200
34274548 A nki S 44.11 200
34274549 R dki 200
34274549 R mki 100
34274549 R lki 100
34274549 A oki S 44.11 100
34274550 A pki S 44.11 100
34274550 R iji 250
34274550 A qki S 44.11 100
34274551 R qki 100
34274551 A rki S 44.11 250
34274554 A ski S 44.11 100
34274558 R hki 100
34274559 R zji 250
34274559 R rki 250
34274559 R nki 200
34274560 A tki S 44.10 200
34274561 A uki B 44.06 250
34274561 A vki S 44.11 250
34274561 R oki 100
34274562 R pki 100
34274562 A wki B 44.07 200
34274562 A xki B 44.06 100
34274562 A yki S 44.10 100
34274562 A zki S 44.10 100
34274562 R ski 100
34274564 A ali S 44.10 100
34274566 R kji 100
34274569 A bli S 44.18 100
34274570 R iki 100
34274575 A cli B 44.07 100
34274575 R tki 200
34274576 A dli S 44.11 200
34274576 R jki 100
34274576 A eli B 44.07 100
34274579 R eli 100
34274579 A fli B 44.07 100
34274583 R xki 100
34274588 A gli B 44.01 100
34274589 R dli 200
34274590 A hli S 44.10 200
34274590 R yki 100
34274590 A ili S 44.10 100
34274591 R cli 100
34274591 R zki 100
34274591 A jli S 44.10 100
34274591 R ali 100
34274594 A kli S 44.10 100
34274599 R uki 250
34274599 R wki 200
34274600 A lli S 44.17 100
34274600 R bli 100
34274601 A mli B 44.06 250
34274607 A nli B 44.07 100
34274607 A oli B 44.06 200
34274608 R hli 200
34274608 A pli S 44.10 200
34274608 R fli 100
34274609 A qli B 44.07 100
34274609 R ili 100
34274609 R mli 250
34274609 A rli S 44.10 100
34274610 A sli B 44.06 250
34274610 R jli 100
34274610 A tli S 44.10 100
34274610 R kli 100
34274611 R gli 100
34274611 R sli 250
34274613 A uli S 44.10 100
34274613 A vli B 44.06 250
34274618 R pli 200
34274618 A wli S 44.11 200
34274622 R nli 100
34274628 R qli 100
34274628 A xli B 44.06 100
34274629 R wli 200
34274629 A yli S 44.10 200
34274631 A zli S 44.17 100
34274631 R uli 100
34274631 R lli 100
34274631 R tli 100
34274631 R rli 100
34274631 A ami S 44.10 100
34274632 A bmi S 44.10 100
34274632 A cmi S 44.12 200
34274633 A dmi S 44.10 100
34274633 R dmi 100
34274636 A emi S 44.10 100
34274636 A fmi B 44.06 100
34274637 R xli 100
34274637 A gmi B 44.06 100
34274638 R yli 200
34274638 A hmi S 44.11 200
34274641 A imi B 44.00 100
34274642 A jmi B 44.04 200
34274642 R vki 250
34274643 A kmi S 44.11 250
34274644 R hmi 200
34274644 A lmi S 44.10 200
34274651 R fmi 100
34274662 A mmi S 44.16 100
34274663 R zli 100
34274668 A nmi B 44.06 100
34274669 R gmi 100
34274669 A omi B 44.07 100
34274671 R imi 100
34274682 R nmi 100
34274693 A pmi S 44.16 100
34274693 R mmi 100
34274701 A qmi B 44.00 100
34274710 R cmi 200
34274734 R vli 250
34274736 A rmi B 44.05 250
34274738 R qmi 100
34274748 A smi B 43.83 100
34274748 A tmi S 44.92 100
34274768 A umi B 44.00 100
34274846 R rmi 250
34274848 A vmi B 44.05 250
34274883 R gii 200
34274924 R vmi 250
34274925 A wmi B 44.05 250
34274932 A xmi S 44.10 200
34274933 R lmi 200
34274933 A ymi S 44.10 200
34274958 A zmi B 44.07 100
34274967 A ani S 44.10 200
34274967 R ymi 200
34274968 R omi 100
34274968 A bni B 44.07 100
34274968 R ani 200
34274969 A cni S 44.10 200
34274969 R zmi 100
34274969 A dni B 44.07 100
34274977 R cni 200
34274977 A eni S 44.10 200
34274988 R eni 200
34274988 R bni 100
34274988 A fni S 44.11 200
34274988 A gni B 44.06 100
34274989 R fni 200
34274989 A hni S 44.10 200
34274990 A ini S 44.10 100
34274991 R ami 100
34274991 R bmi 100
34274991 A jni S 44.09 100
34274991 A kni S 44.09 100
34274991 R emi 100
34274993 A lni S 44.09 100
34274998 R dni 100
34274998 A mni B 44.06 100
34275000 R pmi 100
34275000 A nni B 44.00 100
34275000 R umi 100
34275008 R oli 200
34275009 A oni B 44.05 200
34275009 R gni 100
34275009 A pni B 44.06 100
34275010 A qni B 44.06 100
34275011 R mni 100
34275011 A rni B 44.06 100
34275011 R lni 100
34275011 R jmi 200
34275012 A sni B 44.07 100
34275012 R pni 100
34275012 A tni B 44.04 100
34275013 R rni 100
34275013 A uni B 44.07 100
34275014 A vni S 44.09 100
34275015 R vni 100
34275016 A wni S 44.09 100
34275025 R qni 100
34275025 R kki 100
34275029 A xni S 44.16 100
34275037 A yni S 44.09 100
34275040 R nni 100
34275040 R wni 100
34275041 R kni 100
34275041 R jni 100
34275041 A zni S 44.09 100
34275041 A aoi S 44.09 100
34275042 A boi S 44.09 100
34275043 R boi 100
34275070 A coi B 44.00 100
34275079 R uni 100
34275082 A doi S 44.09 100
34275083 R doi 100
34275106 R ini 100
34275125 R wmi 250
34275127 A eoi B 44.05 250
34275128 R eoi 250
34275128 A foi B 44.05 250
34275128 A goi S 44.09 100
34275130 R goi 100
34275131 R sni 100
34275131 A hoi B 44.05 100
34275132 R foi 250
34275132 R hni 200
34275132 A ioi S 44.09 200
34275133 R aoi 100
34275133 A joi S 44.09 100
34275134 R zni 100
34275134 A koi S 44.09 100
34275136 A loi B 44.05 250
34275139 R loi 250
34275139 R tni 100
34275140 R oni 200
34275140 A moi B 44.05 200
34275140 R ioi 200
34275140 R hoi 100
34275141 A noi S 44.09 200
34275141 A ooi B 44.00 100
34275141 A poi B 44.04 250
34275141 R joi 100
34275142 R koi 100
34275142 A qoi S 44.09 100
34275142 A roi S 44.09 100
34275142 R ooi 100
34275142 R kmi 250
34275142 A soi B 44.05 100
34275143 R noi 200
34275143 A toi S 44.10 250
34275143 A uoi S 44.09 200
34275146 A voi B 44.02 100
34275146 R qoi 100
34275146 R roi 100
34275147 A woi S 44.08 100
34275147 A xoi S 44.08 100
34275160 R poi 250
34275161 A yoi B 44.05 250
34275162 A zoi S 44.09 100
34275163 R zoi 100
34275163 R coi 100
34275172 A api S 44.16 100
34275172 R xni 100
34275174 R yoi 250
34275176 A bpi B 44.04 250
34275179 R uoi 200
34275179 A cpi S 44.08 200
34275180 R woi 100
34275180 R xoi 100
34275180 R moi 200
34275180 A dpi S 44.08 100
34275180 A epi S 44.08 100
34275180 A fpi B 44.04 200
34275188 R cpi 200
34275189 A gpi S 44.08 200
34275190 A hpi S 44.08 100
34275190 R epi 100
34275190 R voi 100
34275190 R dpi 100
34275191 A ipi S 44.08 100
34275191 A jpi B 44.03 100
34275191 R hpi 100
34275192 A kpi S 44.08 100
34275193 A lpi B 43.98 100
34275194 R ipi 100
34275194 A mpi S 44.08 100
34275198 R soi 100
34275198 A npi B 44.04 100
34275199 R toi 250
34275199 R kpi 100
34275199 A opi S 44.07 100
34275199 A ppi S 44.09 250
34275200 R mpi 100
34275200 A qpi S 44.07 100
34275201 R jpi 100
34275202 R opi 100
34275202 A rpi S 44.07 100
34275203 A spi S 44.15 100
34275203 R api 100
34275207 A tpi B 44.04 100
34275208 R npi 100
34275208 A upi B 44.04 100
34275217 R bpi 250
34275220 A vpi B 44.03 250
34275223 R tpi 100
34275230 R lpi 100
34275234 A wpi S 44.15 100
34275234 R spi 100
34275243 R ppi 250
34275250 R qpi 100
34275250 R fpi 200
34275251 A xpi B 44.04 200
34275251 A ypi S 44.07 100
34275251 A zpi S 44.10 250
34275252 R zpi 250
34275252 R rpi 100
34275252 A aqi S 44.09 250
34275252 A bqi S 44.07 100
34275260 A cqi B 43.98 100
34275281 A dqi S 44.15 100
34275281 R wpi 100
34275282 R cqi 100
34275303 R aqi 250
34275303 A eqi S 44.09 250
34275311 A fqi B 43.97 100
34275319 R upi 100
34275320 A gqi B 44.04 100
34275320 R ypi 100
34275320 A hqi S 44.07 100
34275331 A iqi S 44.15 100
34275331 R dqi 100
34275361 A jqi S 44.15 100
34275361 R iqi 100
34275392 A kqi S 44.14 100
34275392 R jqi 100
34275464 R eqi 250
34275465 A lqi S 44.08 250
34275465 R bqi 100
34275465 A mqi S 44.07 100
34275468 A nqi S 44.09 100
34275479 R lqi 250
34275479 A oqi S 44.14 100
34275480 R kqi 100
34275481 A pqi S 44.08 250
34275488 R hqi 100
34275488 A qqi S 44.07 100
34275489 A rqi S 44.07 100
34275489 R mqi 100
34275499 R pqi 250
34275499 R xpi 200
34275501 A sqi S 44.08 250
34275509 A tqi B 44.04 200
34275510 A uqi S 44.14 100
34275510 R oqi 100
34275513 R tqi 200
34275530 R fqi 100
34275540 A vqi S 44.14 100
34275541 R uqi 100
34275560 A wqi B 43.97 100
34275590 A xqi S 44.13 100
34275590 R vqi 100
34275619 A yqi S 44.07 100
34275619 R qqi 100
34275620 A zqi S 44.06 100
34275621 R rqi 100
34275621 A ari S 44.06 100
34275621 R yqi 100
34275622 A bri S 44.13 100
34275622 R xqi 100
34275624 A cri S 44.06 100
34275667 A dri S 44.13 100
34275668 R bri 100
34275682 A eri S 44.07 100
34275699 A fri S 44.13 100
34275699 R dri 100
34275723 R sqi 250
34275723 A gri S 44.08 250
34275724 R gpi 200
34275724 A hri S 44.07 200
34275724 R cri 100
34275730 A iri S 44.13 100
34275730 R fri 100
34275752 A jri S 44.06 100
34275759 R eri 100
34275761 R xmi 200
34275868 R zqi 100
34275868 A kri S 44.06 100
34275869 R ari 100
34275869 A lri S 44.06 100
34275870 R jri 100
34275888 R gqi 100
34275889 A mri B 43.97 100
34275889 A nri S 44.13 100
34275889 R iri 100
34275898 R mri 100
34275898 A ori B 44.04 100
34275913 A pri B 44.02 200
34275945 R kri 100
34275945 A qri B 43.97 100
34275945 R ori 100
34275946 A rri S 44.13 100
34275946 R yni 100
34275946 A sri S 44.07 250
34275946 R gri 250
34275946 A tri B 44.02 100
34275946 A uri S 44.06 100
34275947 R nri 100
34275947 R sri 250
34275947 A vri B 44.04 200
34275947 R qri 100
34275947 A wri B 44.04 100
34275947 R tri 100
34275948 R lri 100
34275948 A xri B 44.04 100
34275948 R uri 100
34275948 R wqi 100
34275948 A yri S 44.07 100
34275948 A zri S 44.06 100
34275948 R vri 200
34275949 A asi B 44.02 200
34275949 R xri 100
34275949 A bsi S 44.08 250
34275949 A csi B 44.02 100
34275950 R bsi 250
34275951 A dsi S 44.08 250
34275952 R csi 100
34275952 A esi B 44.04 100
34275956 R pri 200
34275956 A fsi B 44.02 100
34275959 R dsi 250
34275959 R asi 200
34275959 A gsi B 44.04 200
34275960 R esi 100
34275960 A hsi B 44.02 100
34275960 R gsi 200
34275961 R wri 100
34275961 A isi B 44.03 200
34275961 A jsi S 44.08 250
34275961 A ksi B 44.04 100
34275961 R hsi 100
34275961 A lsi B 44.04 100
34275962 R isi 200
34275965 A msi S 44.06 100
34275966 R zri 100
34275966 A nsi S 44.06 100
34275967 R ksi 100
34275967 A osi B 44.04 100
34275969 R rri 100
34275970 R lsi 100
34275970 A psi B 44.02 100
34275970 R osi 100
34275970 A qsi B 44.02 100
34275971 A rsi B 44.02 200
34275978 A ssi B 43.97 100
34275978 R psi 100
34275978 R qsi 100
34275979 A tsi B 44.04 100
34275979 A usi B 44.04 100
34275981 R ssi 100
34275983 R msi 100
34275983 R fsi 100
34275983 A vsi B 44.02 200
34275986 R nsi 100
34275987 R rsi 200
34275987 A wsi B 44.04 200
34275988 A xsi S 44.07 94
34275990 A ysi S 44.08 200
34275990 A zsi S 44.07 200
34275991 R yri 100
34275991 A ati S 44.07 100
34275992 R xsi 94
34275992 A bti S 44.07 94
34275992 R wsi 200
34275992 R zsi 200
34275993 A cti B 44.02 200
34275996 A dti S 44.07 100
34276004 A eti S 44.12 100
34276010 A fti B 43.97 100
34276011 R eti 100
34276011 R fti 100
34276024 R jsi 250
34276025 A gti S 44.05 250
34276025 R bti 94
34276025 A hti S 44.06 94
34276025 R ati 100
34276026 A iti S 44.06 100
34276027 R hti 94
34276027 A jti S 44.05 94
34276028 R usi 100
34276028 A kti B 44.02 100
34276033 R gti 250
34276034 R kti 100
34276034 A lti B 44.04 100
34276035 A mti S 44.06 250
34276038 R lti 100
34276039 A nti B 44.02 100
34276041 A oti S 44.13 100
34276042 R ysi 200
34276043 A pti B 43.97 100
34276050 R mti 250
34276051 A qti S 44.05 250
34276052 R jti 94
34276055 R qti 250
34276055 A rti S 44.06 100
34276057 A sti S 44.08 250
34276058 A tti S 44.06 100
34276058 R iti 100
34276059 A uti S 44.06 100
34276059 R rti 100
34276065 R dti 100
34276067 R nti 100
34276067 R tti 100
34276067 A vti S 44.06 100
34276067 A wti B 44.04 100
34276069 A xti S 44.12 100
34276069 R oti 100
34276069 R pti 100
34276080 A yti S 44.06 100
34276081 R tsi 100
34276081 A zti B 44.04 100
34276082 A aui S 44.08 100
34276099 R yti 100
34276100 R wti 100
34276100 A bui B 44.04 100
34276100 R vti 100
34276100 A cui S 44.07 100
34276100 A dui S 44.12 100
34276101 R xti 100
34276101 R zti 100
34276101 R cti 200
34276101 A eui B 43.97 100
34276101 A fui B 44.04 200
34276101 A gui B 44.04 100
34276102 R bui 100
34276102 A hui B 44.04 100
34276110 R dui 100
34276111 A iui B 43.97 100
34276111 R eui 100
34276136 R sti 250
34276139 A jui S 44.08 250
34276141 A kui S 44.13 100
34276158 A lui B 43.97 100
34276158 R iui 100
34276169 R cui 100
34276170 A mui S 44.06 100
34276171 R fui 200
34276171 R hui 100
34276171 A nui B 44.02 200
34276171 A oui B 44.04 100
34276174 R vsi 200
34276174 R jui 250
34276174 A pui S 44.08 250
34276176 R mui 100
34276176 A qui S 44.07 100
34276177 R nui 200
34276177 R oui 100
34276177 A rui B 44.04 200
34276177 A sui B 44.04 100
34276179 R gui 100
34276179 A tui B 44.04 100
34276179 R sui 100
34276179 A uui B 44.04 100
34276179 R rui 200
34276180 A vui B 44.03 200
34276180 R tui 100
34276180 R uti 100
34276180 A wui B 44.04 100
34276181 A xui S 44.07 100
34276181 R pui 250
34276181 R vui 200
34276181 A yui B 44.04 200
34276182 R uui 100
34276182 R qui 100
34276182 A zui B 44.04 100
34276182 A avi S 44.07 100
34276182 R aui 100
34276183 R wui 100
34276183 R xui 100
34276183 A bvi B 44.04 100
34276183 A cvi S 44.07 100
34276183 A dvi S 44.08 250
34276184 R zui 100
34276184 A evi B 44.04 100
34276184 R avi 100
34276184 A fvi S 44.07 100
34276185 R bvi 100
34276185 A gvi S 44.09 200
34276185 A hvi B 44.04 100
34276185 R cvi 100
34276185 A ivi S 44.07 100
34276189 A jvi S 44.07 100
34276189 R dvi 250
34276190 R gvi 200
34276192 A kvi S 44.08 250
34276199 R kvi 250
34276200 A lvi S 44.08 250
34276205 R jvi 100
34276211 R lui 100
34276212 A mvi S 44.13 100
34276213 R kui 100
34276213 R mvi 100
34276213 R lvi 250
34276216 A nvi S 44.08 250
34276217 R evi 100
34276217 R fvi 100
34276217 R hri 200
34276217 A ovi B 44.04 100
34276217 A pvi S 44.07 100
34276218 A qvi S 44.08 200
34276218 R hvi 100
34276219 A rvi B 44.04 100
34276219 R nvi 250
34276221 A svi S 44.08 250
34276228 R pvi 100
34276229 A tvi S 44.07 100
34276229 R ovi 100
34276229 A uvi B 44.05 100
34276230 R ivi 100
34276230 A vvi S 44.07 100
34276231 R rvi 100
34276231 A wvi B 44.05 100
34276231 R uvi 100
34276231 A xvi B 44.04 100
34276232 R tvi 100
34276232 A yvi S 44.06 100
34276233 A zvi B 44.04 100
34276233 R wvi 100
34276234 R xvi 100
34276234 A awi B 44.04 100
34276234 R vvi 100
34276235 A bwi S 44.06 100
34276235 R zvi 100
34276235 A cwi B 44.04 100
34276236 R yvi 100
34276236 A dwi S 44.06 100
34276237 R awi 100
34276237 A ewi B 44.04 100
34276238 R svi 250
34276239 R cwi 100
34276239 A fwi B 44.04 100
34276241 A gwi S 44.09 250
34276241 A hwi B 43.97 100
34276244 A iwi S 44.14 100
34276244 R gwi 250
34276244 A jwi S 44.08 250
34276250 R jwi 250
34276250 A kwi S 44.08 250
34276251 R qvi 200
34276251 A lwi S 44.07 200
34276261 A mwi B 43.97 100
34276262 R hwi 100
34276264 R kwi 250
34276266 A nwi S 44.08 250
34276267 R ewi 100
34276267 A owi B 44.04 100
34276268 R yui 200
34276271 R mwi 100
34276281 A pwi S 44.14 100
34276281 R iwi 100
34276285 R nwi 250
34276285 A qwi S 44.08 250
34276302 A rwi B 43.97 100
34276312 A swi S 44.14 100
34276312 R pwi 100
34276340 R bwi 100
34276341 A twi S 44.06 100
34276342 R dwi 100
34276342 A uwi S 44.06 100
34276342 A vwi S 44.14 100
34276342 R fwi 100
34276343 R swi 100
34276343 A wwi B 44.04 100
34276343 R twi 100
34276343 A xwi S 44.06 100
34276344 R owi 100
34276344 R uwi 100
34276344 A ywi B 44.04 100
34276345 A zwi S 44.06 100
34276345 R wwi 100
34276345 A axi B 44.04 100
34276346 R xwi 100
34276346 R ywi 100
34276346 A bxi B 44.04 100
34276346 A cxi S 44.06 100
34276347 R zwi 100
34276347 R axi 100
34276348 A dxi B 44.04 100
34276348 A exi S 44.05 100
34276349 R bxi 100
34276349 A fxi B 44.04 100
34276349 R cxi 100
34276350 A gxi S 44.05 100
34276350 R dxi 100
34276350 A hxi B 44.04 100
34276358 R hxi 100
34276358 A ixi B 44.04 100
34276359 R fxi 100
34276359 A jxi B 44.04 100
34276387 A kxi B 44.02 200
34276388 A lxi B 44.02 200
34276389 R rwi 100
34276419 A mxi B 43.97 100
34276420 A nxi S 44.13 100
34276420 R vwi 100
34276450 A oxi S 44.13 100
34276451 R nxi 100
34276461 R exi 100
34276461 A pxi S 44.05 100
34276465 R pxi 100
34276465 R gxi 100
34276466 R lxi 200
34276466 A qxi B 44.04 200
34276466 A rxi S 44.07 100
34276466 A sxi S 44.05 100
34276467 R jxi 100
34276467 R ixi 100
34276467 A txi B 44.04 100
34276467 A uxi B 44.04 100
34276468 R qxi 200
34276468 A vxi B 44.02 200
34276468 R sxi 100
34276468 A wxi S 44.07 100
34276468 R txi 100
34276468 A xxi B 44.04 100
34276469 R uxi 100
34276469 A yxi B 44.04 100
34276469 R vxi 200
34276469 A zxi B 44.04 200
34276469 R rxi 100
34276478 A ayi S 44.07 100
34276479 R zxi 200
34276479 A byi B 44.02 200
34276480 R wxi 100
34276480 A cyi S 44.07 100
34276481 R byi 200
34276481 A dyi B 44.04 200
34276490 A eyi B 44.02 200
34276490 R dyi 200
34276492 R ayi 100
34276493 A fyi S 44.13 100
34276494 R oxi 100
34276499 R eyi 200
34276499 A gyi B 44.04 200
34276500 R xxi 100
34276500 R yxi 100
34276500 A hyi B 44.04 100
34276500 A iyi B 44.04 100
34276501 R mxi 100
34276506 A jyi S 44.07 100
34276506 R gyi 200
34276507 A kyi B 44.03 200
34276507 A lyi S 44.07 100
34276507 R cyi 100
34276509 A myi B 44.02 200
34276510 R kyi 200
34276518 A nyi S 44.07 100
34276519 R iyi 100
34276519 R lyi 100
34276519 A oyi B 44.04 100
34276519 A pyi S 44.06 100
34276520 R jyi 100
34276531 A qyi B 43.97 100
34276534 A ryi S 44.07 100
34276539 R oyi 100
34276539 A syi B 44.04 100
34276540 A tyi S 44.13 100
34276540 R fyi 100
34276541 A uyi S 44.06 100
34276541 R syi 100
34276542 A vyi B 44.04 100
34276542 R uyi 100
34276549 R vyi 100
34276550 A wyi B 44.04 100
34276551 R qyi 100
34276552 A xyi S 44.08 100
34276557 R wyi 100
34276558 A yyi B 44.04 100
34276558 A zyi B 44.04 100
34276558 R hyi 100
34276559 R qwi 250
34276560 A azi S 44.07 250
34276560 R ryi 100
34276561 A bzi S 44.07 200
34276561 R lwi 200
34276572 A czi S 44.13 100
34276572 R tyi 100
34276573 A dzi S 44.06 100
34276573 R azi 250
34276574 A ezi S 44.06 100
34276574 R pyi 100
34276575 A fzi S 44.08 250
34276581 A gzi B 43.97 100
34276582 A hzi S 44.06 100
34276582 R hzi 100
34276585 R dzi 100
34276597 A izi S 44.06 100
34276598 R ezi 100
34276598 A jzi S 44.06 100
34276603 A kzi S 44.13 100
34276603 R czi 100
34276614 R fzi 250
34276614 A lzi S 44.07 250
34276617 R nyi 100
34276622 A mzi S 44.06 100
34276622 R mzi 100
34276623 R izi 100
34276636 A nzi S 44.06 100
34276644 A ozi S 44.12 100
34276644 R kzi 100
34276653 R lzi 250
34276654 A pzi S 44.06 100
34276654 R jzi 100
34276655 R yyi 100
34276655 A qzi B 44.02 100
34276655 A rzi S 44.08 250
34276660 R rzi 250
34276660 A szi S 44.07 250
34276660 R qzi 100
34276661 A tzi B 44.04 100
34276661 R bzi 200
34276661 R szi 250
34276661 A uzi S 44.07 200
34276662 R myi 200
34276662 A vzi B 44.04 200
34276663 A wzi S 44.09 250
34276666 R pzi 6
34276667 R xyi 100
34276667 R pzi 94
34276668 A xzi S 44.07 100
34276668 R xzi 100
34276668 R uzi 200
34276669 A yzi S 44.07 100
34276669 A zzi S 44.09 200
34276674 R wzi 250
34276674 A aaj S 44.08 250
34276675 A baj S 44.12 100
34276675 R zzi 200
34276675 A caj S 44.08 200
34276675 R ozi 100
34276679 R nzi 100
34276691 R baj 100
34276693 A daj S 44.07 100
34276701 A eaj B 43.97 100
34276701 R gzi 100
34276701 R aaj 250
34276702 R yzi 100
34276702 A faj S 44.07 100
34276702 A gaj S 44.08 250
34276709 R gaj 250
34276710 A haj S 44.07 250
34276711 R faj 100
34276711 A iaj S 44.07 100
34276714 R haj 250
34276716 A jaj S 44.08 250
34276719 R jaj 250
34276720 A kaj S 44.14 100
34276721 A laj S 44.09 250
34276725 R laj 250
34276727 A maj S 44.09 250
34276734 R maj 250
34276736 A naj S 44.10 250
34276738 R eaj 100
34276750 A oaj S 44.14 100
34276750 R daj 100
34276750 R kaj 100
34276753 R naj 250
34276753 A paj S 44.09 250
34276754 R paj 250
34276757 A qaj S 44.10 250
34276760 R qaj 250
34276760 A raj S 44.09 250
34276761 R raj 250
34276764 A saj S 44.09 250
34276764 R saj 250
34276766 A taj S 44.10 250
34276768 A uaj B 43.97 100
34276776 R taj 250
34276776 A vaj S 44.09 250
34276801 A waj B 43.97 100
34276801 R uaj 100
34276882 R kxi 200
34276884 A xaj B 44.04 100
34276885 R zyi 100
34276885 A yaj B 44.04 100
34276885 A zaj B 44.04 100
34276885 R tzi 100
34276888 R xaj 100
34276888 A abj S 44.07 100
34276892 A bbj B 44.02 200
34276893 R iaj 100
34276893 A cbj S 44.07 100
34276911 R waj 100
34276914 R vaj 250
34276915 A dbj S 44.09 250
34276916 R dbj 250
34276917 R abj 100
34276918 A ebj S 44.10 250
34276932 R cbj 100
34276933 R vzi 200
34276934 A fbj S 44.08 100
34276934 A gbj B 44.04 200
34276934 R ebj 250
34276935 R yaj 100
34276935 R zaj 100
34276935 A hbj S 44.09 250
34276935 A ibj B 44.04 100
34276935 A jbj B 44.04 30
34276935 R hbj 250
34276936 A kbj S 44.09 250
34276937 R bbj 200
34276937 A lbj B 44.02 100
34276938 R gbj 200
34276938 A mbj B 44.04 200
34276941 A nbj B 43.97 100
34276942 R lbj 100
34276950 A obj S 44.08 100
34276950 R fbj 100
34276951 A pbj S 44.08 100
34276961 A qbj B 43.97 100
34276962 R nbj 100
34276963 R obj 100
34276964 R nqi 100
34276970 R kbj 250
34276970 A rbj S 44.08 250
34276971 R qbj 100
34276972 R rbj 250
34276973 A sbj S 44.07 100
34276975 A tbj S 44.09 250
34276976 R pbj 100
34276976 A ubj S 44.06 100
34276978 R tbj 250
34276983 R ubj 100
34276983 A vbj S 44.08 100
34276984 A wbj S 44.09 250
34276985 A xbj B 44.04 100
34276986 R ibj 100
34276986 A ybj B 44.04 100
34276987 R jbj 30
34276987 A zbj B 44.04 30
34276988 R wbj 250
34276989 R sbj 100
34276991 A acj S 44.10 250
34276992 A bcj B 44.04 100
34276993 R ybj 100
34276993 A ccj B 44.05 100
34276994 A dcj S 44.09 200
34276994 R zbj 30
34276994 A ecj B 44.05 30
34277000 A fcj B 43.97 100
34277008 A gcj S 44.08 100
34277010 A hcj B 43.98 100
34277010 R fcj 100
34277016 R acj 250
34277016 A icj S 44.09 250
34277016 R vbj 100
34277017 A jcj S 44.08 100
34277022 R gcj 100
34277032 R icj 250
34277035 A kcj S 44.09 250
34277040 A lcj S 44.08 100
34277042 R kcj 250
34277043 R jcj 100
34277044 A mcj S 44.07 100
34277045 A ncj S 44.10 250
34277047 R dcj 200
34277056 R lcj 100
34277062 R ncj 250
34277062 A ocj S 44.09 250
34277073 R oaj 100
34277073 A pcj S 44.07 60
34277103 A qcj S 44.15 100
34277208 R ocj 250
34277210 A rcj S 44.10 250
34277238 R rcj 250
34277238 A scj S 44.09 250
34277281 R xbj 100
34277289 R bcj 100
34277293 R scj 250
34277295 A tcj S 44.10 250
34277309 R hcj 100
34277327 R tcj 250
34277327 A ucj S 44.09 250
34277339 A vcj B 43.97 100
34277347 R ccj 100
34277348 A wcj B 44.04 100
34277379 A xcj S 44.14 100
34277379 R qcj 100
34277418 A ycj S 44.14 100
34277418 R xcj 100
34277476 A zcj S 44.07 60
34277477 R mcj 100
34277478 A adj S 44.07 100
34277487 R zcj 60
34277487 A bdj S 44.07 60
34277570 R ucj 250
34277571 A cdj S 44.09 250
34277605 R cdj 250
34277607 A ddj S 44.09 250
34278192 A edj S 44.07 100
34278607 R zii 100
34278683 R ddj 250
34278683 A fdj S 44.09 250
34278684 R adj 100
34278684 A gdj S 44.07 100
34278685 R bdj 60
34278685 A hdj S 44.07 64
34278744 R fdj 250
34278746 A idj S 44.09 250
34278754 R idj 250
34278754 A jdj S 44.09 250
34278990 A kdj B 43.97 100
34278991 R vcj 100
34279273 R jdj 250
34279276 A ldj S 44.09 250
34279294 R ldj 250
34279295 A mdj S 44.09 250
34279607 R gdj 100
34279607 A ndj S 44.08 100
34279624 R mdj 250
34279626 A odj S 44.09 250
34279630 R odj 250
34279630 A pdj S 44.09 250
34279639 R pdj 250
34279641 A qdj S 44.09 250
34279642 A rdj B 43.98 100
34279642 R kdj 100
34279649 A sdj B 44.05 100
34279649 R ycj 100
34279650 R ecj 30
34279650 A tdj B 44.05 30
34279651 R wcj 100
34279651 A udj B 44.05 100
34279672 R sdj 100
34279679 R udj 100
34279679 A vdj B 44.04 100
34279679 A wdj S 44.14 100
34279681 A xdj B 44.05 100
34279685 R edj 100
34279691 R qdj 250
34279691 A ydj B 44.05 100
34279691 A zdj S 44.09 250
34279692 R tdj 30
34279692 R vdj 100
34279692 A aej B 44.05 30
34279693 A bej B 44.05 100
34280091 R vpi 250
34280091 A cej B 44.04 250
34280092 R mbj 200
34280092 A dej B 44.04 200
34280133 R cej 250
34280136 A eej B 44.03 250
34280368 R bej 100
34280368 A fej B 44.04 100
34280371 R xdj 100
34280372 R dej 200
34280377 R ydj 100
34280378 A gej B 44.04 200
34280399 R rdj 100
34280403 A hej S 44.08 250
34280403 R zdj 250
34280429 A iej B 43.97 100
34280491 A jej S 44.08 100
34280500 R jej 100
34280506 R ndj 100
34280507 A kej S 44.08 100
34280534 R aej 30
34280535 R pcj 60
34280536 A lej B 44.04 100
34280568 R iej 100
34280569 A mej S 44.14 100
34280570 R wdj 100
34280591 A nej S 44.07 100
34280598 A oej B 43.97 100
34280600 R nej 100
34280627 A pej S 44.14 100
34280627 R mej 100
34280633 A qej S 44.07 100
34280634 R kej 100
34280634 A rej S 44.07 100
34280676 R qej 100
34280677 R hdj 64
34280678 A sej S 44.07 100
34281018 A tej S 44.14 100
34281018 R pej 100
34281019 R rej 100
34281019 A uej S 44.07 100
34281029 A vej B 43.98 100
34281030 R oej 100
34281035 A wej S 44.07 100
34281042 R sej 100
34281042 A xej S 44.06 100
34281057 A yej S 44.14 100
34281057 R tej 100
34281203 R hej 250
34281204 A zej S 44.08 250
34281205 R caj 200
34281205 A afj S 44.07 200
34281208 R zej 250
34281210 A bfj S 44.08 250
34281223 R bfj 250
34281224 A cfj S 44.08 250
34281225 R cfj 250
34281227 A dfj S 44.08 250
34281232 R dfj 250
34281233 A efj S 44.08 250
34281299 R efj 250
34281301 A ffj S 44.08 250
34281330 R ffj 250
34281330 A gfj S 44.08 250
34281331 R yej 100
34281361 A hfj S 44.14 100
34281522 A ifj S 44.14 100
34281522 R hfj 100
34281601 R fej 100
34281601 A jfj B 44.04 100
34281609 R uej 100
34281610 A kfj S 44.06 100
34281610 R xej 100
34281611 A lfj S 44.06 34
34281611 R gej 200
34281616 A mfj S 44.09 100
34281630 R vej 100
34281641 A nfj S 44.13 100
34281642 R ifj 100
34281660 A ofj B 43.97 100
34282008 R lej 100
34282009 A pfj B 44.04 100
34282013 A qfj B 44.02 100
34282014 R jfj 100
34282015 A rfj B 44.04 100
34282023 R qfj 100
34282023 A sfj B 44.02 200
34282024 R pfj 100
34282024 A tfj B 44.02 200
34282024 A ufj B 44.04 100
34282038 R ofj 100
34282068 A vfj B 43.97 100
34282074 R gfj 250
34282074 A wfj S 44.07 250
34282113 R wfj 250
34282115 A xfj S 44.07 250
34282172 R xfj 250
34282175 A yfj S 44.08 250
34282888 R kfj 100
34282888 R tfj 200
34282888 A zfj S 44.07 100
34282888 A agj B 44.04 200
34282888 R rfj 100
34282888 A bgj B 44.04 100
34282889 A cgj B 44.04 100
34282889 R ufj 100
34282890 A dgj B 44.04 100
34282902 A egj B 44.05 100
34282902 R cgj 100
34282903 A fgj B 44.05 100
34282903 R dgj 100
34282919 A ggj B 43.98 100
34282920 R vfj 100
34282950 R yfj 250
34282952 A hgj S 44.08 250
34282956 R lfj 34
34282957 R afj 200
34282957 A igj S 44.08 200
34282957 A jgj S 44.07 34
34282960 R sfj 200
34282960 A kgj B 44.03 100
34282968 R jgj 34
34282969 R egj 100
34282988 R nfj 100
34282999 R eej 250
34283000 A lgj B 44.04 250
34283010 R agj 200
34283010 A mgj B 44.04 200
34283013 R mfj 100
34283018 A ngj S 44.14 100
34283020 R bgj 100
34283020 A ogj B 44.05 100
34283024 R hgj 250
34283025 R fgj 100
34283025 A pgj B 44.05 100
34283026 A qgj S 44.09 250
34283039 R ogj 100
34283039 A rgj B 44.04 100
34283040 R ngj 100
34283052 R kgj 100
34283058 R pgj 100
34283058 A sgj B 44.04 100
34283059 R mgj 200
34283059 R rgj 100
34283059 A tgj B 44.04 100
34283061 R sgj 100
34283061 A ugj B 44.05 100
34283071 A vgj S 44.14 100
34283080 R ggj 100
34283110 A wgj B 43.98 100
34283290 R wej 100
34283291 R tgj 100
34283291 A xgj B 44.04 200
34283291 A ygj B 44.05 100
34283293 A zgj S 44.09 100
34283294 R ugj 100
34283294 A ahj B 44.05 100
34283329 A bhj B 43.98 100
34283329 R wgj 100
34283861 R bhj 100
34283891 A chj B 43.98 100
34283900 R xgj 200
34283900 R ygj 100
34283900 A dhj B 44.04 100
34283910 R lgj 250
34283912 A ehj B 44.03 250
34283913 A fhj B 44.04 200
34283920 R qgj 250
34283920 R zgj 100
34283920 A ghj S 44.08 250
34283929 R ahj 100
34283929 A hhj B 44.04 100
34283929 R chj 100
34283939 A ihj S 44.14 100
34283939 R vgj 100
34283940 R dhj 100
34283940 A jhj B 44.04 100
34283958 A khj S 44.07 100
34283959 A lhj B 43.98 100
34283959 R zfj 100
34283959 A mhj S 44.07 100
34283959 A nhj S 44.07 100
34283960 R mhj 100
34283961 A ohj S 44.07 100
34283970 R lhj 100
34283971 A phj S 44.14 100
34283971 R ihj 100
34284001 A qhj B 43.97 100
34284017 A rhj S 44.14 100
34284017 R phj 100
34284041 R ghj 250
34284041 R hhj 100
34284041 A shj B 44.04 100
34284042 R nhj 100
34284042 A thj S 44.07 100
34284042 R jhj 100
34284043 A uhj B 44.04 100
34284043 A vhj S 44.08 250
34284043 R ohj 100
34284043 R shj 100
34284043 A whj B 44.04 100
34284044 A xhj S 44.07 100
34284047 A yhj S 44.09 100
34284048 A zhj S 44.13 100
34284048 R rhj 100
34284080 A aij S 44.13 100
34284080 R zhj 100
34284090 R fhj 200
34284091 R thj 100
34284092 A bij S 44.07 100
34284092 A cij B 44.04 200
34284093 R xhj 100
34284093 A dij S 44.07 100
34284094 R cij 200
34284094 R bij 100
34284095 A eij S 44.06 100
34284117 R qhj 100
34284121 A fij S 44.13 100
34284121 R aij 100
34284147 A gij B 43.97 100
34284163 A hij B 44.04 100
34284169 R gij 100
34284195 R yhj 100
34284198 A iij B 43.97 100
34284208 R uhj 100
34284208 A jij B 44.04 100
34284210 R vhj 250
34284210 A kij S 44.08 250
34284211 A lij S 44.07 200
34284211 R igj 200
34284215 R kij 250
34284217 A mij S 44.08 250
34284218 R whj 100
34284218 A nij B 44.04 100
34284221 A oij S 44.13 100
34284221 R fij 100
34284221 R iij 100
34284226 R khj 100
34284227 R jij 100
34284227 A pij B 44.04 100
34284231 R mij 250
34284231 A qij S 44.08 250
34284232 R nij 100
34284232 A rij B 44.04 100
34284238 R rij 100
34284238 A sij B 44.04 100
34284238 R dij 100
34284239 A tij S 44.06 100
34284247 R tij 100
34284248 A uij S 44.07 100
34284250 A vij S 44.06 100
34284251 R pij 100
34284251 R uij 100
34284251 A wij B 44.04 100
34284251 R eij 100
34284251 A xij S 44.06 100
34284251 A yij S 44.06 100
34284251 A zij S 44.13 100
34284252 R oij 100
34284252 A ajj B 43.97 100
34284260 R xij 100
34284260 A bjj S 44.07 100
34284269 R qij 250
34284271 A cjj S 44.08 250
34284271 R vij 100
34284283 A djj S 44.12 100
34284283 R zij 100
34284288 R wij 100
34284288 R sij 100
34284288 A ejj B 44.04 100
34284288 A fjj B 44.04 100
34284288 R djj 100
34284289 R cjj 250
34284291 A gjj S 44.09 250
34284294 A hjj B 44.04 200
34284299 R lij 200
34284299 A ijj S 44.09 200
34284308 A jjj B 43.97 100
34284309 R ajj 100
34284320 A kjj S 44.13 100
34284320 R kjj 100
34284328 R fjj 100
34284328 R hjj 200
34284328 A ljj B 44.03 200
34284328 A mjj B 44.04 100
34284340 R gjj 250
34284340 A njj S 44.08 250
34284341 R ijj 200
34284341 A ojj S 44.08 200
34284342 A pjj B 43.97 100
34284343 R jjj 100
34284349 R pjj 100
34284350 A qjj S 44.14 100
34284379 A rjj B 43.97 100
34284419 A sjj S 44.07 1000
34284420 R bjj 100
34284420 A tjj S 44.07 100
34285019 R mjj 100
34285019 A ujj B 44.04 100
34285051 A vjj B 43.98 100
34285051 R rjj 100
34285198 R vjj 100
34285228 A wjj B 43.97 100
34285229 R ujj 100
34285229 A xjj B 44.04 100
34285282 R njj 250
34285283 A yjj S 44.08 250
34285442 R yjj 250
34285444 A zjj S 44.08 250
34285631 R txh 300
34286073 A akj S 44.06 400
34286074 R ljj 200
34286074 R ojj 200
34286074 A bkj S 44.07 200
34286074 R yij 100
34286075 A ckj S 44.06 50
34286075 R bkj 200
34286076 A dkj S 44.07 200
34286087 R dkj 200
34286088 A ekj S 44.07 200
34286089 R ejj 100
34286089 A fkj B 44.04 100
34286118 A gkj S 44.13 100
34286119 R qjj 100
34286119 R wjj 100
34286149 A hkj B 43.97 100
34287038 R fkj 100
34287038 R ekj 200
34287039 R xjj 100
34287039 A ikj S 44.07 200
34287039 A jkj B 44.04 100
34287039 A kkj B 44.04 100
34287054 A lkj B 44.03 100
34287069 A mkj B 43.98 100
34287070 R hkj 100
34287073 R zjj 250
34287075 A nkj S 44.08 250
34287080 R gkj 100
34287127 A okj S 44.14 100
34287242 R nkj 250
34287242 A pkj S 44.08 250
34287370 R kkj 100
34287370 R ikj 200
34287370 A qkj B 44.04 100
34287370 A rkj S 44.07 200
34287373 R lkj 100
34287378 R jkj 100
34287378 A skj B 44.04 100
34287381 R hij 100
34287381 A tkj B 44.02 100
34287397 R mkj 100
34287405 R pkj 250
34287405 A ukj S 44.07 250
34287408 A vkj S 44.13 100
34287408 R okj 100
34287427 A wkj B 43.97 100
34287646 A xkj B 43.72 400
34287941 R akj 400
34287942 R rkj 200
34287943 A ykj S 44.16 200
34287943 R skj 100
34287943 A zkj B 44.04 100
34287944 A alj S 44.07 100
34287949 A blj B 44.04 200
34287950 R ukj 250
34287953 A clj S 44.08 250
34287954 R ykj 200
34287954 A dlj S 44.07 200
34287969 R qkj 100
34287969 A elj B 44.04 100
34287970 R zkj 100
34287970 A flj B 44.04 100
34287980 R vkj 100
34287999 A glj B 43.97 100
34287999 R wkj 100
34288012 A hlj S 44.14 100
34288020 R tkj 100
34288021 A ilj S 44.09 100
34288022 R ilj 100
34288567 R flj 100
34288567 A jlj B 44.04 100
34288598 A klj S 44.14 100
34288598 R hlj 100
34288612 R tjj 100
34288613 A llj S 44.07 40
34288617 R elj 100
34288618 A mlj B 44.04 100
34288618 R jlj 100
34288619 A nlj B 44.04 100
34288619 R blj 200
34288620 R mlj 100
34288620 A olj B 44.04 100
34288648 R glj 100
34288677 A plj B 43.97 100
34289118 A qlj S 44.39 400
34289877 A rlj B 44.04 200
34290360 R olj 100
34290360 R rlj 200
34290361 R clj 250
34290361 A slj B 44.04 100
34290361 A tlj S 44.07 250
34290361 R alj 100
34290364 A ulj S 44.06 100
34290365 R nlj 100
34290365 R dlj 200
34290365 R llj 40
34290365 A vlj B 44.04 100
34290365 A wlj S 44.06 50
34290365 A xlj S 44.07 200
34290379 R ulj 100
34290389 A ylj S 44.13 100
34290390 R klj 100
34290408 R vlj 100
34290409 A zlj B 44.04 100
34290559 R zlj 100
34290559 A amj B 44.04 100
34290590 A bmj S 44.13 100
34290590 R ylj 100
34290658 R tlj 250
34290658 A cmj S 44.06 250
34290738 A dmj S 44.06 100
34291080 R cmj 250
34291081 R wlj 50
34291081 A emj S 44.06 50
34291083 A fmj S 44.07 250
34291383 A gmj B 43.20 30
34291827 R dmj 100
34291840 R bmj 100
34291849 R plj 100
34291870 A hmj S 44.13 100
34291879 A imj B 43.97 100
34291928 R amj 100
34291929 R fmj 250
34291929 A jmj B 44.04 100
34291931 A kmj S 44.08 250
34291941 R slj 100
34291941 A lmj B 44.04 100
34291960 R hmj 100
34291970 A mmj B 43.97 100
34291970 R imj 100
34291990 A nmj S 44.13 100
34292878 R xlj 200
34292879 R ckj 50
34292879 A omj S 44.07 200
34292879 A pmj S 44.07 100
34292908 R nmj 100
34292908 A qmj S 44.09 100
34292912 R kmj 250
34292914 A rmj S 44.08 250
34292919 R rmj 250
34292920 A smj S 44.08 250
34292939 A tmj S 44.13 100
34292964 R smj 250
34292966 A umj S 44.08 250
34292989 R omj 200
34292989 A vmj S 44.07 200
34292990 R umj 250
34292990 A wmj S 44.08 250
34292997 R vmj 200
34292998 A xmj S 44.07 200
34293004 R xmj 200
34293005 A ymj S 44.07 200
34293007 A zmj B 43.98 100
34293017 R mmj 100
34293018 A anj S 44.13 100
34293018 R tmj 100
34293019 R ymj 200
34293020 A bnj S 44.07 200
34293033 R bnj 200
34293033 A cnj S 44.07 200
34293047 A dnj B 43.97 100
34293074 A enj S 44.13 100
34293075 R anj 100
34293083 R zmj 100
34293086 A fnj B 43.98 100
34293568 R jmj 100
34293568 A gnj B 44.04 100
34293575 R dnd 10
34293578 R qmj 100
34293588 R lmj 100
34293588 A hnj B 44.04 100
34293589 R wmj 250
34293589 A inj S 44.07 250
34293598 R gnj 100
34293598 A jnj B 43.98 100
34293598 R hnj 100
34293598 A knj B 43.98 100
34293600 R ehj 250
34293600 A lnj S 44.13 100
34293601 R enj 100
34293601 A mnj B 43.98 200
34293602 R jnj 100
34293602 A nnj B 43.98 100
34293602 A onj B 44.03 250
34293602 R knj 100
34293603 A pnj B 43.98 100
34293603 R nnj 100
34293603 A qnj B 44.03 100
34293604 R pnj 100
34293604 A rnj B 44.03 100
34293613 A snj B 44.03 100
34293625 R snj 100
34293627 A tnj S 44.08 100
34293629 R onj 250
34293631 R dnj 100
34293631 A unj B 44.02 250
34293632 A vnj S 44.13 100
34293632 R lnj 100
34293662 A wnj B 43.96 100
34293662 R mnj 200
34293663 A xnj B 44.02 200
34293663 A ynj S 44.12 100
34293663 R vnj 100
34293679 R unj 250
34293681 R xnj 200
34293681 R qnj 100
34293681 A znj B 44.02 250
34293681 A aoj B 44.02 100
34293682 A boj S 44.06 100
34293684 R boj 100
34293689 A coj B 44.02 200
34293690 R znj 250
34293692 A doj B 44.02 250
34293695 A eoj S 44.06 100
34293696 R pmj 100
34293696 A foj S 44.06 100
34293696 R emj 50
34293697 A goj S 44.06 100
34293697 R coj 200
34293697 A hoj B 44.02 200
34293700 R doj 250
34293700 A ioj B 44.02 250
34293701 R fnj 100
34293701 A joj B 43.96 100
34293702 R wnj 100
34293703 A koj S 44.12 100
34293703 R ynj 100
34293704 A loj B 43.98 100
34293708 R hoj 200
34293709 A moj B 44.02 200
34293709 R joj 100
34293709 R ioj 250
34293710 R moj 200
34293712 A noj B 44.02 250
34293717 R eoj 100
34293718 A ooj B 44.02 200
34293720 R loj 100
34293722 A poj S 44.06 100
34293722 R poj 100
34293724 A qoj B 43.98 100
34293724 A roj S 44.06 100
34293729 R rnj 100
34293729 A soj B 44.03 100
34293729 R aoj 100
34293729 R cnj 200
34293730 A toj S 44.05 200
34293730 A uoj B 44.02 100
34293731 R foj 100
34293731 R goj 100
34293731 A voj S 44.05 100
34293731 A woj S 44.05 100
34293732 R roj 100
34293732 R tnj 100
34293733 A xoj S 44.07 100
34293734 A yoj S 44.12 100
34293734 R koj 100
34293734 A zoj S 44.05 100
34293735 R zoj 100
34293737 A apj S 44.05 100
34293737 R apj 100
34293738 R toj 200
34293738 A bpj S 44.07 200
34293739 A cpj S 44.05 100
34293740 A dpj S 44.05 100
34293740 R woj 100
34293740 R voj 100
34293741 A epj S 44.05 100
34293742 R dpj 100
34293742 A fpj S 44.05 100
34293746 A gpj S 44.05 100
34293746 R gpj 100
34293747 R epj 100
34293747 A hpj S 44.05 100
34293748 R fpj 100
34293748 A ipj S 44.05 100
34293749 R ooj 200
34293749 R hpj 100
34293750 A jpj S 44.04 100
34293752 R inj 250
34293753 A kpj S 44.05 250
34293758 A lpj B 43.96 100
34293760 R qoj 100
34293763 A mpj B 43.98 100
34293765 A npj S 44.12 100
34293765 R yoj 100
34293780 R noj 250
34293782 A opj S 44.04 100
34293782 R opj 100
34293783 A ppj B 44.01 250
34293784 A qpj S 44.04 100
34293785 A rpj B 44.01 200
34293795 A spj S 44.11 100
34293796 R npj 100
34293824 R mpj 100
34293827 A tpj S 44.11 100
34293827 R spj 100
34293850 R soj 100
34293850 R ipj 100
34293850 A upj B 44.02 100
34293850 A vpj S 44.04 100
34293852 R qpj 100
34293853 R xoj 100
34293854 A wpj S 44.06 100
34293855 A xpj S 44.04 100
34293867 R jpj 100
34293867 A ypj S 44.04 100
34293868 R xpj 100
34293871 A zpj S 44.04 100
34293872 A aqj B 44.02 100
34293876 R ypj 100
34293876 R uoj 100
34293876 A bqj S 44.04 100
34293876 R upj 100
34293877 A cqj B 44.02 100
34293877 A dqj B 44.02 50
34293879 R bqj 100
34293879 A eqj S 44.05 100
34293879 A fqj S 44.05 100
34293879 R vpj 100
34293882 A gqj S 44.11 100
34293882 R tpj 100
34293882 R wpj 100
34293890 R ppj 250
34293891 R aqj 100
34293892 A hqj B 44.00 250
34293910 R cpj 100
34293910 R hqj 250
34293910 A iqj B 44.02 100
34293910 A jqj B 44.01 250
34293911 R gqj 100
34293911 R dqj 50
34293911 A kqj B 44.02 50
34293911 R cqj 100
34293911 A lqj B 44.02 100
34293914 R jqj 250
34293916 A mqj B 44.00 250
34293926 R mqj 250
34293927 A nqj B 44.01 250
34293937 R nqj 250
34293939 A oqj B 44.00 250
34293941 A pqj S 44.12 100
34293980 R zpj 100
34293984 A qqj S 44.07 200
34293997 R iqj 100
34293999 A rqj S 44.05 100
34294069 R fqj 100
34294069 R bpj 200
34294069 R eqj 100
34294069 A sqj S 44.04 100
34294069 A tqj S 44.04 100
34294069 A uqj S 44.05 200
34294069 R lqj 100
34294070 A vqj B 44.01 100
34294071 A wqj S 44.12 100
34294072 R pqj 100
34294075 R rqj 100
34294076 A xqj S 44.04 100
34294080 A yqj S 44.05 200
34294090 R oqj 250
34294090 R rpj 200
34294090 A zqj B 44.01 200
34294091 R kqj 50
34294092 A arj B 44.00 250
34294094 A brj B 43.99 100
34294094 R qqj 200
34294100 R arj 250
34294100 R lpj 100
34294100 A crj B 44.00 250
34294106 R xqj 100
34294113 R kpj 250
34294114 A drj S 44.04 100
34294115 A erj S 44.06 250
34294120 R erj 250
34294120 A frj S 44.06 250
34294121 R frj 250
34294121 A grj S 44.12 100
34294122 R wqj 100
34294123 A hrj S 44.06 250
34294123 R hrj 250
34294124 A irj S 44.06 250
34294130 A jrj B 43.94 100
34294131 R irj 250
34294131 A krj S 44.05 250
34294139 R uqj 200
34294139 A lrj S 44.04 200
34294144 R brj 100
34294146 A mrj S 44.06 200
34294149 R zqj 200
34294149 A nrj B 44.00 200
34294152 A orj B 43.95 100
34294152 R jrj 100
34294152 R nrj 200
34294153 A prj B 44.01 200
34294162 A qrj S 44.11 100
34294163 R grj 100
34294178 A rrj B 44.01 100
34294179 R vqj 100
34294179 R orj 100
34294179 A srj B 44.01 100
34294179 R lrj 200
34294180 A trj S 44.05 200
34294194 A urj S 44.11 100
34294194 R qrj 100
34294201 R crj 250
34294202 A vrj B 44.01 250
34294209 A wrj B 43.95 100
34294213 A xrj B 44.00 100
34294220 A yrj B 43.97 100
34294221 R yrj 100
34294225 A zrj B 43.96 100
34294226 R rrj 100
34294230 R trj 200
34294230 A asj S 44.04 200
34294230 A bsj B 43.95 100
34294231 R wrj 100
34294234 R asj 200
34294234 A csj S 44.05 200
34294239 R csj 200
34294239 A dsj S 44.04 200
34294241 R vrj 250
34294244 A esj B 44.00 250
34294245 A fsj B 44.02 100
34294245 R zrj 100
34294245 R dsj 200
34294246 A gsj B 44.02 100
34294246 R srj 100
34294246 A hsj S 44.05 200
34294248 A isj B 43.96 100
34294249 R esj 250
34294250 A jsj B 44.01 250
34294251 R jsj 250
34294253 A ksj B 44.00 250
34294259 R ksj 250
34294259 A lsj B 44.01 250
34294260 R prj 200
34294260 A msj B 44.01 200
34294261 A nsj B 43.95 100
34294261 R bsj 100
34294263 R fsj 100
34294270 R nsj 100
34294270 R tqj 100
34294271 A osj S 44.05 100
34294279 A psj B 44.02 100
34294280 R osj 100
34294280 A qsj S 44.04 100
34294281 R lsj 250
34294281 R gsj 100
34294281 A rsj B 44.02 100
34294282 R qsj 100
34294282 A ssj S 44.05 100
34294283 R drj 100
34294284 R xrj 100
34294284 A tsj B 44.00 100
34294284 A usj B 44.00 250
34294286 A vsj S 44.04 100
34294297 R psj 100
34294300 A wsj B 43.95 100
34294300 A xsj B 43.95 100
34294301 R wsj 100
34294305 R isj 100
34294308 A ysj B 43.97 100
34294310 R urj 100
34294315 A zsj B 44.02 100
34294330 R usj 250
34294331 A atj B 44.01 250
34294331 R rsj 100
34294331 A btj B 44.02 100
34294332 A ctj B 43.96 100
34294332 R xsj 100
34294341 A dtj S 44.11 100
34294344 R zsj 100
34294351 R atj 250
34294354 A etj B 44.00 250
34294355 R ssj 100
34294356 A ftj S 44.04 100
34294357 R msj 200
34294357 A gtj B 44.01 200
34294357 R btj 100
34294357 R hsj 200
34294357 A htj B 44.01 100
34294358 A itj S 44.04 200
34294359 R ftj 100
34294359 A jtj S 44.04 100
34294360 R sqj 100
34294361 A ktj S 44.04 100
34294361 R vsj 100
34294365 A ltj S 44.04 100
34294365 R tsj 100
34294365 R ltj 100
34294366 R ktj 100
34294366 R itj 200
34294366 A mtj S 44.04 100
34294367 A ntj S 44.05 200
34294376 A otj S 44.04 100
34294378 R mtj 100
34294379 A ptj S 44.04 100
34294381 A qtj B 44.01 100
34294381 R otj 100
34294381 R ctj 100
34294382 R jtj 100
34294382 R htj 100
34294382 A rtj B 44.01 100
34294382 A stj S 44.04 100
34294383 R dtj 100
34294383 R ptj 100
34294384 A ttj S 44.04 100
34294385 A utj S 44.04 100
34294385 R utj 100
34294386 R etj 250
34294388 A vtj S 44.04 100
34294389 A wtj B 44.00 250
34294400 R qtj 100
34294401 R stj 100
34294402 A xtj S 44.04 100
34294403 R ttj 100
34294404 R vtj 100
34294404 A ytj S 44.04 100
34294406 A ztj S 44.04 100
34294407 R ztj 100
34294409 A auj S 44.04 100
34294412 R ysj 100
34294413 A buj B 43.94 100
34294413 A cuj B 43.94 100
34294414 R buj 100
34294414 A duj S 44.11 100
34294415 A euj B 43.97 100
34294421 A fuj S 44.11 100
34294422 R duj 100
34294431 R euj 100
34294434 A guj B 43.97 100
34294453 A huj S 44.11 100
34294453 R fuj 100
34294466 R auj 100
34294480 R guj 100
34294483 A iuj B 43.97 100
34294484 R iuj 100
34294484 A juj S 44.11 100
34294485 R huj 100
34294487 A kuj B 43.97 100
34294488 R kuj 100
34294492 A luj B 43.96 100
34294546 R luj 100
34294549 A muj B 43.96 100
34294991 A nuj S 44.04 100
34295121 A ouj B 44.02 82
34295123 R mrj 200
34295124 A puj S 44.06 100
34295135 R puj 100
34295141 R nuj 100
34295150 R juj 100
34295152 R muj 100
34295156 A quj B 43.95 100
34295194 A ruj S 44.11 100
34295207 A suj S 44.04 100
34296130 R wtj 250
34296131 A tuj B 44.00 250
34296160 A uuj B 43.94 100
34296160 R cuj 100
34296194 R quj 100
34296198 A vuj B 43.95 100
34296255 R ytj 100
34296255 R suj 100
34296256 R xtj 100
34296256 A wuj S 44.04 100
34296257 A xuj S 44.04 100
34296257 A yuj S 44.04 100
34296258 A zuj S 44.04 200
34296259 R xuj 100
34296260 A avj S 44.06 100
34296260 R zuj 200
34296261 A bvj S 44.04 100
34296262 R bvj 100
34296265 A cvj S 44.04 100
34296406 R yuj 100
34296438 R ruj 100
34296440 R ntj 200
34296440 A dvj S 44.05 200
34296449 A evj B 43.94 100
34296449 R uuj 100
34296468 A fvj S 44.11 100
34296481 A gvj B 43.95 100
34296481 R evj 100
34296489 R vuj 100
34296492 A hvj B 43.96 100
34296507 R hvj 100
34296510 A ivj B 43.96 100
34296512 A jvj B 43.95 100
34296512 R gvj 100
34296532 R avj 100
34296555 R wuj 100
34296555 R cvj 100
34296555 R krj 200
34296558 A kvj B 44.02 100
34296558 R fvj 100
34296559 R rtj 100
34296559 A lvj B 44.02 100
34296559 R ivj 100
34296559 A mvj B 44.02 100
34296559 A nvj B 44.00 100
34296560 R ouj 82
34296560 A ovj B 44.02 100
34296561 R mvj 100
34296561 R krj 50
34296561 R kvj 100
34296562 R lvj 100
34296562 A pvj B 44.02 100
34296562 A qvj B 43.96 100
34296563 R ovj 100
34296563 A rvj B 44.02 100
34296564 R pvj 100
34296564 A svj B 44.02 100
34296565 R rvj 100
34296565 A tvj B 44.02 100
34296566 R svj 100
34296566 A uvj B 44.02 100
34296566 A vvj B 44.02 100
34296566 A wvj B 44.02 100
34296567 R vvj 100
34296567 R tvj 100
34296567 R wvj 100
34296567 A xvj B 44.03 100
34296567 A yvj S 44.05 100
34296568 A zvj B 43.95 100
34296568 R uvj 100
34296568 A awj B 44.03 100
34296568 A bwj S 44.05 250
34296568 R jvj 100
34296569 R xvj 100
34296569 A cwj B 44.03 100
34296569 A dwj B 44.02 100
34296570 R dwj 100
34296570 R dvj 200
34296570 R awj 100
34296570 A ewj B 44.03 100
34296570 A fwj S 44.05 200
34296570 R tuj 250
34296570 R nvj 100
34296571 A gwj B 44.01 250
34296571 R fwj 200
34296571 R gtj 200
34296572 A hwj B 44.01 200
34296572 A iwj S 44.05 200
34296578 R cwj 100
34296578 A jwj B 44.03 100
34296585 R qvj 100
34296586 A kwj B 44.03 100
34296586 R ewj 100
34296588 A lwj S 44.11 100
34296589 A mwj B 43.96 100
34296599 A nwj B 43.95 100
34296600 R zvj 100
34296628 R iwj 200
34296628 R jwj 100
34296628 A owj B 44.03 100
34296629 A pwj S 44.07 200
34296629 R kwj 100
34296630 A qwj B 44.03 100
34296631 A rwj B 43.96 100
34296631 R nwj 100
34296638 R mwj 100
34296642 A swj B 43.96 100
34296649 R gwj 250
34296649 A twj B 44.02 250
34296661 A uwj B 43.96 100
34296661 R rwj 100
34296682 R swj 100
34296683 R hwj 200
34296683 A vwj B 44.02 200
34296685 A wwj B 43.96 100
34296692 A xwj B 43.96 100
34296692 R uwj 100
34296703 R wwj 100
34296706 A ywj B 43.97 100
34296707 R ywj 100
34296710 A zwj B 43.97 100
34296710 R bwj 250
34296711 R zwj 100
34296711 A axj S 44.05 250
34296714 A bxj B 43.97 100
34296730 R bxj 100
34296733 A cxj B 43.97 100
34296734 R cxj 100
34296738 A dxj B 43.97 100
34296769 R dxj 100
34296772 A exj B 43.97 100
34296837 R qwj 100
34296838 R pwj 200
34296839 A fxj S 44.05 200
34296839 A gxj S 44.05 100
34296839 R vwj 200
34296839 A hxj B 44.03 100
34296840 R fxj 200
34296840 A ixj B 44.02 200
34296841 A jxj S 44.07 200
34296846 R hxj 100
34296847 R jxj 200
34296847 A kxj S 44.05 200
34296848 R ixj 200
34296848 A lxj B 44.03 30
34296849 A mxj B 44.02 200
34296849 R owj 100
34296849 R lxj 30
34296849 A nxj B 44.02 100
34296850 R mxj 200
34296850 A oxj B 44.02 30
34296850 R twj 250
34296852 A pxj B 44.02 200
34296852 A qxj B 44.01 250
34296853 A rxj B 44.03 100
34296853 R nxj 100
34296853 A sxj B 44.03 100
34296853 A txj B 44.01 200
34296853 R oxj 30
34296858 R pxj 200
34296859 R qxj 250
34296859 A uxj B 44.02 250
34296859 R uxj 250
34296860 R gxj 100
34296860 R txj 200
34296860 R sxj 100
34296860 A vxj S 44.04 100
34296860 A wxj B 44.01 100
34296861 R rxj 100
34296861 A xxj B 43.98 100
34296862 R kxj 200
34296862 A yxj B 44.01 250
34296862 A zxj S 44.04 200
34296862 R xxj 100
34296863 R exj 100
34296863 A ayj B 44.01 100
34296866 A byj B 43.98 100
34296866 R wxj 100
34296867 A cyj B 44.01 100
34296868 R zxj 200
34296868 A dyj S 44.05 200
34296869 R ayj 100
34296869 A eyj B 44.02 100
34296870 R dyj 200
34296870 R cyj 100
34296870 A fyj B 44.02 100
34296870 A gyj S 44.04 200
34296871 R eyj 100
34296871 A hyj B 44.02 100
34296872 R gyj 200
34296872 A iyj S 44.05 200
34296879 R xwj 100
34296889 A jyj S 44.11 100
34296890 R lwj 100
34296895 R byj 100
34296908 A kyj B 43.95 100
34296921 A lyj S 44.11 100
34296921 R jyj 100
34296953 A myj B 43.97 100
34296963 R myj 100
34296965 R yxj 250
34296968 A nyj B 44.00 250
34296969 A oyj B 44.01 200
34296989 R nyj 250
34296989 A pyj B 44.01 250
34296999 R pyj 250
34297001 A qyj B 44.00 250
34297001 A ryj B 43.96 100
34297053 R ryj 100
34297056 A syj B 43.96 100
34297057 R syj 100
34297060 A tyj B 43.96 100
34297089 R tyj 100
34297092 A uyj B 43.96 100
34297136 A vyj S 44.06 100
34297417 R kyj 100
34297447 A wyj B 43.95 100
34297841 A xyj B 43.96 250
34297942 A yyj S 44.02 100
34297943 R fyj 100
34297943 R iyj 200
34297943 R uyj 100
34297943 A zyj B 44.01 100
34297943 A azj S 44.04 200
34297943 A bzj S 44.04 100
34297943 R yyj 100
34297944 A czj B 44.02 100
34297944 R vxj 100
34297944 A dzj S 44.04 100
34297945 A ezj B 44.02 100
34297945 R azj 200
34297945 R zyj 100
34297945 A fzj S 44.05 200
34297945 A gzj B 44.02 100
34297945 R bzj 100
34297946 A hzj S 44.04 100
34297946 A izj B 43.96 100
34297946 R czj 100
34297946 R ezj 100
34297946 R hyj 100
34297947 A jzj B 44.02 80
34297947 R dzj 100
34297947 R hzj 100
34297947 A kzj S 44.04 100
34297947 A lzj S 44.04 100
34297979 R wyj 100
34297990 R lyj 100
34298009 A mzj B 43.95 100
34298021 A nzj S 44.11 100
34298044 R izj 100
34298047 A ozj B 43.96 100
34298048 R ozj 100
34298051 A pzj B 43.96 100
34298100 R mzj 100
34298130 A qzj B 43.94 100
34298157 A rzj B 44.02 100
34298159 A szj B 44.02 100
34298391 A tzj B 44.04 100
34298392 R kzj 100
34298392 R gzj 100
34298393 A uzj B 44.02 100
34298393 A vzj S 44.04 25
34298393 R tzj 100
34298394 R lzj 100
34298394 R jzj 80
34298394 A wzj S 44.05 100
34298394 A xzj B 44.02 80
34298395 R rzj 100
34298395 R uzj 100
34298395 R szj 100
34298395 A yzj B 44.01 100
34298396 R wzj 100
34298396 A zzj S 44.04 100
34298396 A aak S 44.04 200
34298396 R fzj 200
34298396 A bak B 44.02 100
34298397 R aak 200
34298398 A cak B 44.02 100
34298398 A dak S 44.05 200
34298398 R cak 100
34298400 A eak B 44.02 100
34298461 A fak B 43.94 100
34298461 R qzj 100
34298533 R eak 100
34298535 R bak 100
34298550 R pzj 100
34298553 A gak B 43.96 100
34298589 R gak 100
34298592 A hak B 43.96 100
34299050 R qyj 250
34299053 A iak B 44.01 250
34299054 R yzj 100
34299054 A jak B 44.01 100
34299055 R oyj 200
34299055 A kak B 44.01 200
34299059 R kak 200
34299060 A lak B 43.96 200
34299061 R iak 250
34299064 A mak B 44.00 250
34299066 A nak B 43.99 100
34299067 R lak 200
34299067 A oak B 44.01 200
34299079 A pak B 43.96 100
34299080 R fak 100
34299089 R pak 100
34299119 A qak B 43.94 100
34299135 R hak 100
34299139 A rak B 43.98 100
34299141 R rak 100
34299144 A sak B 43.96 100
34299160 R dak 200
34299160 A tak S 44.04 200
34299162 A uak B 44.02 100
34299162 R tak 200
34299163 A vak S 44.05 200
34299163 R uak 100
34299164 R vak 200
34299164 A wak S 44.04 200
34299165 A xak B 44.02 100
34299165 R xak 100
34299165 R wak 200
34299166 A yak S 44.05 200
34299173 R yak 200
34299173 A zak S 44.04 200
34299202 A abk B 44.02 100
34299202 R abk 100
34299202 R zak 200
34299203 A bbk S 44.05 200
34299213 R bbk 200
34299215 A cbk S 44.04 200
34299264 R xzj 80
34299264 A dbk B 44.01 100
34299265 R jak 100
34299265 A ebk B 44.01 100
34299266 R dbk 100
34299266 A fbk B 44.01 100
34299289 R fbk 100
34299290 A gbk B 44.01 100
34299292 R ebk 100
34299292 A hbk B 44.02 100
34299294 R cbk 200
34299295 A ibk S 44.05 200
34299317 A jbk B 43.95 100
34299317 R qak 100
34299340 R sak 100
34299343 A kbk B 43.96 100
34299344 R kbk 100
34299347 A lbk B 43.96 100
34299393 R lbk 100
34299397 A mbk B 43.96 100
34299482 A nbk B 44.02 100
34299483 R nbk 100
34299485 A obk B 44.02 100
34299486 R obk 100
34299567 R wei 400
34299668 R ibk 200
34299668 R gbk 100
34299668 A pbk B 44.01 100
34299669 A qbk S 44.04 200
34299670 A rbk B 44.02 100
34299670 R mak 250
34299672 R rbk 100
34299674 A sbk B 44.00 250
34299678 R oak 200
34299679 A tbk B 44.00 200
34299680 R nak 100
34299689 A ubk S 44.04 200
34299698 R jbk 100
34299698 R yvj 100
34299699 R hbk 100
34299699 R zzj 100
34299699 A vbk S 44.04 100
34299699 A wbk B 44.01 100
34299699 A xbk S 44.11 100
34299699 R qbk 200
34299699 R nzj 100
34299700 A ybk S 44.04 200
34299700 R vzj 25
34299700 A zbk S 44.04 100
34299700 R pbk 100
34299700 R ubk 200
34299701 A ack B 44.01 100
34299701 R vbk 100
34299701 A bck S 44.04 100
34299701 R wbk 100
34299701 A cck B 44.01 100
34299702 R zbk 100
34299702 A dck S 44.04 100
34299702 A eck B 44.01 100
34299702 R vyj 100
34299703 R bck 100
34299703 A fck S 44.04 100
34299703 A gck S 44.06 100
34299704 R eck 100
34299705 R dck 100
34299705 A hck S 44.04 100
34299705 A ick B 44.01 100
34299706 A jck B 44.01 100
34299707 R jck 100
34299708 R fck 100
34299708 A kck S 44.04 100
34299708 A lck B 44.01 100
34299709 R hck 100
34299709 A mck S 44.03 100
34299728 A nck B 43.94 100
34299730 A ock S 44.11 100
34299731 R xbk 100
34299737 R nck 100
34299741 R mbk 100
34299744 A pck B 43.96 100
34299761 A qck S 44.10 100
34299761 R ock 100
34299767 A rck B 43.94 100
34299782 R pck 100
34299785 A sck B 43.96 100
34299799 R ack 100
34299799 R cck 100
34299799 A tck B 44.00 100
34299799 A uck B 44.00 100
34299799 R kck 100
34299800 A vck S 44.03 100
34299801 R lck 100
34299801 R mck 100
34299801 A wck S 44.03 100
34299802 A xck B 44.01 100
34299804 R gck 100
34299808 R vck 100
34299808 A yck S 44.03 100
34299809 R tbk 200
34299809 R wck 100
34299809 A zck S 44.03 100
34299810 A adk S 44.10 100
34299810 A bdk B 43.96 200
34299810 R qck 100
34299811 A cdk B 43.94 100
34299811 R rck 100
34299819 R yck 100
34299819 A ddk S 44.03 100
34299820 R axj 250
34299820 R zck 100
34299820 A edk S 44.04 250
34299820 A fdk S 44.03 100
34299821 R ddk 100
34299821 R ybk 200
34299821 A gdk S 44.04 200
34299821 A hdk S 44.04 100
34299828 R hdk 100
34299828 A idk S 44.04 100
34299828 R bdk 200
34299829 R sck 100
34299829 A jdk B 44.00 200
34299830 A kdk S 44.05 200
34299831 A ldk B 43.96 200
34299831 R jdk 200
34299832 A mdk B 43.96 100
34299833 R mdk 100
34299836 A ndk B 43.96 100
34299839 R cdk 100
34299842 A odk S 44.10 100
34299842 R adk 100
34299869 A pdk B 43.93 100
34299873 A qdk S 44.10 100
34299873 R odk 100
34299900 R ldk 200
34299900 A rdk B 44.00 200
34299905 R rdk 200
34299918 A sdk B 43.93 100
34299919 R pdk 100
34299931 A tdk S 44.10 100
34299932 R qdk 100
34299950 A udk B 44.00 200
34299950 R gdk 200
34299951 A vdk S 44.05 200
34299951 R tck 100
34299951 A wdk B 44.00 100
34299951 R uck 100
34299951 R udk 200
34299951 A xdk B 44.00 100
34299952 R vdk 200
34299952 A ydk S 44.04 200
34299952 A zdk B 43.96 200
34299955 R kdk 200
34299959 R edk 250
34299959 R zdk 200
34299959 A aek B 44.00 200
34299959 R ydk 200
34299959 A bek S 44.05 200
34299962 A cek S 44.05 250
34299980 A dek B 43.93 100
34299980 R sdk 100
34299980 R tdk 100
34300001 R aek 200
34300001 A eek B 44.00 200
34300001 R bek 200
34300002 A fek S 44.04 200
34300002 R xdk 100
34300002 A gek B 44.01 100
34300002 R wdk 100
34300003 A hek B 44.01 100
34300004 R eek 200
34300004 A iek B 44.00 200
34300012 A jek S 44.10 100
34300030 A kek B 43.94 100
34300031 R dek 100
34300031 R jek 100
34300062 A lek S 44.11 100
34300092 A mek S 44.11 100
34300092 R lek 100
34300093 A nek B 43.94 100
34300093 R kek 100
34300124 A oek S 44.11 100
34300125 R mek 100
34300157 A pek S 44.10 100
34300157 R oek 100
34300187 A qek S 44.10 100
34300188 R pek 100
34300190 R hek 100
34300191 A rek B 44.01 100
34300193 R ick 100
34300194 R xck 100
34300196 A sek B 44.01 100
34300197 A tek B 44.01 100
34300221 A uek B 43.95 100
34300221 R nek 100
34300221 R ndk 100
34300224 A vek B 43.95 100
34300225 R vek 100
34300229 A wek B 43.96 100
34300340 R sbk 250
34300340 A xek B 44.00 250
34300350 R rek 100
34300350 R xek 250
34300350 A yek B 44.01 100
34300351 R gek 100
34300351 A zek B 44.01 100
34300352 A afk B 44.00 250
34300357 R fdk 100
34300358 R yek 100
34300358 A bfk B 44.01 100
34300359 A cfk S 44.04 100
34300360 A dfk B 44.01 100
34300360 R bfk 100
34300361 R zek 100
34300361 A efk B 44.01 75
34300363 R sek 100
34300364 A ffk S 44.04 100
34300364 R tek 100
34300365 R cfk 100
34300365 A gfk S 44.03 100
34300366 R idk 100
34300366 A hfk S 44.04 100
34300366 R dfk 100
34300366 A ifk B 44.01 100
34300366 A jfk B 44.00 100
34300368 R ifk 100
34300379 R uek 100
34300400 R hfk 100
34300400 A kfk S 44.03 100
34300401 R cek 250
34300401 A lfk S 44.04 250
34300402 R gfk 100
34300402 A mfk B 44.01 100
34300402 A nfk S 44.03 100
34300402 R mfk 100
34300403 R fek 200
34300403 A ofk S 44.04 200
34300403 R kfk 100
34300403 A pfk B 44.01 100
34300403 A qfk S 44.04 100
34300404 R pfk 100
34300406 A rfk B 43.98 200
34300409 A sfk B 43.94 100
34300410 R lfk 250
34300411 A tfk B 44.01 100
34300412 A ufk S 44.04 250
34300413 A vfk B 44.01 100
34300414 R vfk 100
34300421 A wfk B 44.01 100
34300421 R ufk 250
34300422 R ofk 200
34300423 A xfk S 44.05 200
34300423 A yfk S 44.05 250
34300424 R xfk 200
34300425 A zfk S 44.04 200
34300430 R sfk 100
34300431 A agk S 44.10 100
34300431 R qek 100
34300439 R agk 100
34300442 R yfk 250
34300443 A bgk S 44.04 250
34300444 R zfk 200
34300444 A cgk S 44.04 200
34300448 R wek 100
34300452 A dgk B 43.95 100
34300452 R bgk 250
34300453 R dgk 100
34300455 A egk S 44.05 250
34300456 A fgk B 43.95 100
34300460 A ggk B 43.94 100
34300468 R wfk 100
34300469 A hgk S 44.10 100
34300470 R tfk 100
34300472 R efk 75
34300472 A igk B 44.00 100
34300473 R qfk 100
34300474 A jgk S 44.03 100
34300474 R jfk 100
34300474 A kgk B 44.00 100
34300474 A lgk B 44.00 100
34300475 R nfk 100
34300475 R igk 100
34300475 A mgk S 44.03 100
34300475 A ngk B 44.00 100
34300476 A ogk S 44.05 100
34300476 A pgk B 44.00 100
34300476 R lgk 100
34300476 R kgk 100
34300476 A qgk B 44.01 100
34300476 R pgk 100
34300477 R ngk 100
34300477 R jgk 100
34300477 A rgk B 44.01 100
34300478 A sgk S 44.03 100
34300480 R egk 250
34300481 A tgk S 44.04 250
34300490 R tgk 250
34300490 R qgk 100
34300490 A ugk B 44.01 100
34300491 R ugk 100
34300492 R rgk 100
34300492 A vgk B 44.00 100
34300492 A wgk B 44.01 100
34300492 A xgk S 44.05 250
34300499 R iek 200
34300499 R xgk 250
34300499 A ygk B 43.98 200
34300499 A zgk S 44.04 250
34300500 R ygk 200
34300500 A ahk B 44.00 200
34300507 R ggk 100
34300509 R fgk 100
34300509 A bhk S 44.10 100
34300510 R hgk 100
34300510 R rfk 200
34300511 A chk B 44.00 100
34300511 R chk 100
34300512 A dhk B 44.01 100
34300512 R dhk 100
34300512 A ehk B 43.95 100
34300513 A fhk B 44.01 100
34300514 R ehk 100
34300516 A ghk B 44.01 100
34300517 A hhk B 43.95 100
34300519 R bhk 100
34300530 R hhk 100
34300532 A ihk B 43.95 100
34300537 A jhk B 43.94 100
34300539 R jhk 100
34300549 A khk S 44.10 100
34300569 A lhk B 43.94 100
34300569 R ihk 100
34300575 A mhk B 43.95 100
34300591 R mhk 100
34300595 A nhk B 43.95 100
34300600 R lhk 100
34300630 A ohk B 43.94 100
34300639 R nhk 100
34300643 A phk B 43.95 100
34300652 R phk 100
34300655 A qhk B 43.95 100
34300853 A rhk S 44.03 100
34301013 R zgk 250
34301016 A shk S 44.05 250
34301019 A thk B 43.94 100
34301019 R ohk 100
34301092 R qhk 100
34301096 A uhk B 43.95 100
34301257 R xei 400
34301293 R shk 250
34301293 A vhk S 44.04 250
34301941 R uhk 100
34301944 A whk B 43.95 100
34303067 R yqj 200
34303219 A xhk B 44.00 100
34303219 R wgk 100
34303220 R vgk 100
34303220 A yhk B 44.00 100
34303224 R ogk 100
34303248 A zhk S 44.10 100
34303249 R khk 100
34303259 A aik B 43.94 100
34303259 R thk 100
34303294 R whk 100
34303298 A bik B 43.95 100
34304329 R ahk 200
34304329 R xhk 100
34304329 A cik B 43.96 200
34304330 A dik B 43.96 100
34304330 R yhk 100
34304330 R sgk 100
34304330 A eik B 44.00 100
34304330 A fik S 44.03 100
34304331 R mgk 100
34304331 A gik S 44.03 100
34304339 R eik 100
34304339 A hik B 44.00 100
34304339 R dik 100
34304339 R gik 100
34304339 R vhk 250
34304339 A iik B 44.00 100
34304339 A jik S 44.03 100
34304340 A kik S 44.03 250
34304340 R kik 250
34304342 A lik S 44.04 250
34304348 R jik 100
34304348 A mik S 44.03 100
34304348 R hik 100
34304348 A nik B 44.00 100
34304349 R fik 100
34304349 A oik S 44.03 100
34304349 R iik 100
34304350 A pik B 44.00 100
34304358 R cik 200
34304358 A qik B 44.00 200
34304361 R aik 100
34304362 A rik S 44.08 100
34304362 R zhk 100
34304364 R qik 200
34304364 A sik B 43.96 200
34304370 R rik 100
34304391 A tik B 43.93 100
34304392 A uik B 43.93 100
34304392 R tik 100
34304394 R bik 100
34304397 A vik B 43.95 100
34304400 A wik S 44.10 100
34304422 A xik B 43.93 100
34304422 R uik 100
34304437 R vik 100
34304441 A yik B 43.95 100
34304445 R yik 100
34304486 A zik B 43.95 100
34304531 R zik 100
34304534 A ajk B 43.95 100
34304550 R ajk 100
34304553 A bjk B 43.95 100
34304554 R bjk 100
34304557 A cjk B 43.95 100
34305362 A djk B 43.94 100
34305362 R xik 100
34305690 R sjj 1000
34305875 A ejk S 44.07 1000
34306128 R sik 200
34306128 A fjk B 44.00 200
34306129 R nik 100
34306129 A gjk B 44.01 100
34306130 R pik 100
34306130 A hjk B 44.01 100
34306170 A ijk B 43.94 100
34306170 R djk 100
34306242 R cjk 100
34306245 A jjk B 43.95 100
34307205 A kjk S 44.05 200
34307230 R ijk 100
34307261 A ljk B 43.94 100
34307273 R ghk 100
34307275 R fhk 100
34307276 R gjk 100
34307276 A mjk B 44.00 100
34307276 R fjk 200
34307279 A njk B 43.96 200
34307280 A ojk B 43.98 200
34307283 R njk 200
34307283 A pjk B 43.99 200
34307293 R jjk 100
34307296 A qjk B 43.95 100
34307311 R lik 250
34307311 A rjk S 44.03 250
34307679 A sjk B 44.01 100
34307681 A tjk B 44.01 100
34307687 R tjk 100
34307688 R sjk 100
34308098 A ujk B 44.01 100
34308100 R ujk 100
34308141 A vjk B 44.01 100
34308141 A wjk B 44.01 100
34308141 R vjk 100
34308142 R wjk 100
34308181 A xjk B 44.01 100
34308183 A yjk B 44.01 100
34308286 R yjk 100
34308287 R xjk 100
34308312 R pjk 200
34308312 A zjk B 44.00 200
34308355 A akk B 44.01 100
34308357 A bkk B 44.01 100
34308631 A ckk B 44.01 100
34308633 R akk 100
34308634 R bkk 100
34308635 A dkk B 44.01 100
34308636 A ekk B 44.01 100
34310129 A fkk B 43.94 100
34310130 R ljk 100
34310210 R qjk 100
34310213 A gkk B 43.95 100
34310492 A hkk B 43.98 180
34310828 R rjk 250
34310830 A ikk S 44.04 250
34310875 R ikk 250
34310875 A jkk S 44.03 250
34310935 R jkk 250
34310937 A kkk S 44.04 250
34311020 R kkk 250
34311021 A lkk S 44.03 250
34311692 R lkk 250
34311694 A mkk S 44.04 250
34312031 R afk 250
34312032 A nkk B 44.01 250
34312035 R dkk 100
34312035 R ekk 100
34312037 A okk B 44.01 100
34312037 A pkk B 44.01 100
34312062 R mjk 100
34312062 A qkk B 44.01 100
34312079 R qkk 100
34312079 A rkk B 44.00 100
34312079 R mik 100
34312079 A skk S 44.03 100
34312080 R rkk 100
34312080 A tkk B 44.01 100
34312081 R hjk 100
34312081 A ukk B 44.01 100
34312082 R ojk 200
34312091 A vkk B 43.94 100
34312091 R fkk 100
34312103 R nkk 250
34312105 A wkk B 44.00 250
34312108 R vkk 100
34312110 R tkk 100
34312110 A xkk B 44.00 100
34312112 A ykk B 44.02 19
34312113 R skk 100
34312113 R ukk 100
34312113 A zkk S 44.03 100
34312113 A alk B 44.01 100
34312114 R okk 100
34312115 R pkk 100
34312115 R ykk 19
34312116 R mkk 250
34312116 R alk 100
34312116 R zkk 100
34312116 A blk B 44.01 100
34312117 A clk S 44.03 100
34312117 A dlk B 44.01 100
34312117 R blk 100
34312118 A elk B 44.00 100
34312118 R xkk 100
34312119 A flk B 44.00 100
34312119 A glk B 44.01 100
34312119 R dlk 100
34312119 R glk 100
34312119 A hlk S 44.05 250
34312119 A ilk B 44.00 100
34312120 R elk 100
34312132 R gkk 100
34312136 A jlk B 43.95 100
34312137 R jlk 100
34312138 A klk B 43.94 100
34312141 A llk B 43.96 100
34312159 R hlk 250
34312159 A mlk S 44.04 250
34312159 R mlk 250
34312160 R flk 100
34312160 R clk 100
34312160 R ilk 100
34312160 A nlk B 44.01 100
34312160 A olk S 44.03 100
34312161 A plk B 44.01 100
34312161 A qlk B 44.01 100
34312161 R qlk 100
34312162 A rlk B 44.01 100
34312162 A slk S 44.05 250
34312162 R kjk 200
34312162 R rlk 100
34312163 R cgk 200
34312164 A tlk S 44.04 200
34312164 A ulk B 44.01 100
34312166 A vlk B 44.01 100
34312167 A wlk B 44.02 800
34312168 R olk 100
34312168 R oik 100
34312168 R tlk 200
34312168 A xlk S 44.04 100
34312168 A ylk S 44.04 100
34312168 R nlk 100
34312168 A zlk B 44.01 100
34312169 A amk S 44.07 200
34312170 R plk 100
34312170 A bmk B 44.01 100
34312171 R ulk 100
34312171 R vlk 100
34312172 R zlk 100
34312172 A cmk B 44.01 100
34312173 R bmk 100
34312173 A dmk B 44.01 100
34312174 A emk B 44.02 100
34312175 A fmk B 44.02 100
34312175 R cmk 100
34312175 A gmk B 44.02 100
34312176 R dmk 100
34312177 A hmk B 44.02 100
34312181 R wkk 250
34312181 A imk B 44.00 250
34312189 R llk 100
34312191 R wik 100
34312191 R klk 100
34312193 A jmk B 43.95 100
34312194 R jmk 100
34312197 A kmk B 43.95 100
34312197 R zjk 200
34312197 A lmk B 44.01 200
34312222 A mmk S 44.11 100
34312222 A nmk B 43.94 100
34312229 A omk B 43.95 100
34312229 R nmk 100
34312238 R kmk 100
34312242 A pmk B 43.95 100
34312248 R ffk 100
34312271 R pmk 100
34312274 A qmk B 43.95 100
34312278 R rhk 100
34312279 R gmk 100
34312279 A rmk B 44.02 100
34312280 A smk B 43.95 100
34312280 R omk 100
34312280 R xlk 100
34312280 A tmk S 44.05 100
34312281 R hmk 100
34312281 A umk B 44.02 100
34312288 R umk 100
34312288 A vmk B 44.02 100
34312290 R emk 100
34312291 R fmk 100
34312293 A wmk B 44.02 100
34312295 A xmk B 44.02 100
34312298 A ymk S 44.06 200
34312298 R amk 200
34312299 A zmk S 44.06 200
34312322 R mmk 100
34312329 R qmk 100
34312332 A ank B 43.95 100
34312332 R smk 100
34312332 A bnk B 43.96 100
34312333 R bnk 100
34312337 A cnk B 43.96 100
34312352 A dnk S 44.11 100
34312362 A enk B 43.95 100
34312363 R ank 100
34312371 R ylk 100
34312371 R slk 250
34312371 R tmk 48
34312372 R rmk 100
34312373 A fnk B 44.03 48
34312375 R wmk 100
34312376 R xmk 100
34312378 A gnk B 44.03 100
34312379 A hnk B 44.03 100
34312380 R vmk 100
34312380 A ink B 44.03 100
34312381 R fnk 48
34312382 A jnk B 44.03 48
34312382 R gnk 100
34312383 R hnk 100
34312385 A knk B 44.03 100
34312386 A lnk B 44.03 100
34312387 R ink 100
34312387 A mnk B 44.03 100
34312388 A nnk B 44.03 48
34312388 R jnk 48
34312389 A onk S 44.05 250
34312389 R tmk 52
34312391 R knk 100
34312391 R lnk 100
34312391 R nnk 48
34312392 R zmk 200
34312392 A pnk B 44.02 48
34312393 A qnk S 44.05 200
34312393 A rnk B 44.03 100
34312394 A snk B 44.03 100
34312394 A tnk S 44.05 100
34312394 R rnk 100
34312394 R snk 100
34312395 R pnk 48
34312395 R mnk 100
34312395 R qnk 200
34312395 A unk B 44.03 48
34312395 A vnk B 44.03 100
34312395 A wnk S 44.06 200
34312396 R unk 48
34312396 A xnk B 44.02 48
34312396 R wnk 200
34312397 A ynk S 44.05 200
34312397 A znk B 44.03 100
34312397 R znk 100
34312398 R ynk 200
34312398 A aok S 44.06 200
34312399 A bok B 44.03 100
34312400 A cok B 44.03 100
34312407 R cnk 100
34312410 A dok B 43.95 100
34312410 R enk 100
34312410 A eok B 43.96 100
34312419 R imk 250
34312420 A fok B 44.01 250
34312422 R eok 100
34312425 A gok B 43.96 100
34312440 A hok B 43.95 100
34312441 R dok 100
34312471 A iok B 43.95 100
34312472 R hok 100
34312483 R gok 100
34312486 A jok B 43.96 100
34312501 R jok 100
34312505 A kok B 43.97 100
34312506 R kok 100
34312509 A lok B 43.97 100
34312514 R lok 100
34312517 A mok B 44.02 100
34312517 R lmk 200
34312518 A nok B 44.01 200
34312566 A ook B 43.97 100
34313063 R ook 100
34313116 A pok B 43.97 100
34313139 R fok 250
34313139 A qok B 44.02 250
34313201 R qok 250
34313203 A rok B 44.01 250
34313222 R rok 250
34313222 A sok B 44.02 250
34313384 A tok S 44.05 100
34313397 R tnk 100
34313432 A uok S 44.05 100
34313599 R onk 250
34313600 R nok 200
34313600 A vok B 44.02 200
34313600 R xnk 48
34313600 A wok B 44.03 48
34313601 A xok S 44.06 250
34313602 R bok 100
34313603 R aok 200
34313603 A yok S 44.06 200
34313603 R cok 100
34313606 A zok B 44.03 100
34313608 A apk B 44.03 100
34313609 R vnk 100
34313609 A bpk B 44.03 100
34313610 R tok 100
34313610 A cpk S 44.06 100
34313611 R wok 48
34313611 A dpk B 44.04 48
34313612 R yok 200
34313612 A epk S 44.06 200
34313613 R zok 100
34313613 R apk 100
34313613 R epk 200
34313614 R dpk 48
34313614 A fpk B 44.02 48
34313614 A gpk S 44.06 200
34313616 A hpk B 44.04 100
34313616 A ipk B 44.04 100
34313617 R ipk 100
34313617 R hpk 100
34313619 A jpk B 44.04 100
34313620 R jpk 100
34313622 A kpk B 44.04 100
34313624 A lpk B 44.04 100
34313624 R kpk 100
34313624 R lpk 100
34313625 A mpk B 44.04 100
34313626 A npk B 44.04 100
34313627 R mpk 100
34313627 R npk 100
34313628 A opk B 44.04 100
34313629 R opk 100
34313632 A ppk B 44.03 100
34313635 A qpk B 44.03 100
34313639 R fpk 48
34313639 R gpk 200
34313639 A rpk B 44.04 48
34313640 R vok 200
34313640 A spk S 44.06 200
34313640 R xok 250
34313640 R rpk 48
34313641 A tpk B 44.02 48
34313641 A upk S 44.05 250
34313641 R spk 200
34313641 A vpk S 44.06 200
34313642 R cpk 100
34313642 A wpk S 44.05 100
34313642 R ppk 100
34313643 R qpk 100
34313643 R wpk 100
34313643 A xpk S 44.05 100
34313646 A ypk B 44.03 100
34313646 A zpk B 44.03 100
34313647 R zpk 100
34313652 A aqk B 44.02 200
34313652 R xpk 100
34313652 A bqk S 44.05 100
34313653 R upk 250
34313655 A cqk S 44.06 250
34313657 A dqk B 44.03 100
34313661 R cqk 250
34313661 A eqk S 44.05 250
34313669 R eqk 250
34313671 A fqk B 43.96 100
34313671 R iok 100
34313672 A gqk S 44.05 250
34313689 R fqk 100
34313728 A hqk B 43.96 100
34313770 R pok 100
34313773 A iqk B 43.97 100
34313775 R iqk 100
34313778 A jqk B 43.97 100
34313889 R gqk 250
34313893 A kqk S 44.06 250
34313931 R jqk 100
34313934 A lqk B 43.97 100
34313941 R sok 250
34313941 A mqk B 44.02 250
34313951 R kqk 250
34313951 A nqk S 44.05 250
34314310 R bpk 100
34314310 R ypk 100
34314311 R aqk 200
34314311 A oqk S 44.05 100
34314312 A pqk B 44.02 100
34314356 R dqk 100
34314357 R bqk 100
34314357 A qqk S 44.05 100
34314359 A rqk B 44.02 100
34314359 A sqk B 44.01 100
34314360 R rqk 100
34314366 R hkk 180
34314368 R vpk 200
34314368 A tqk S 44.05 200
34314369 R mqk 250
34314371 A uqk B 44.02 250
34314401 A vqk B 44.02 100
34314401 R vqk 100
34314441 A wqk B 44.02 100
34314473 R wqk 100
34314485 A xqk S 44.05 100
34314500 R xqk 100
34314520 R tqk 200
34314521 A yqk B 44.02 200
34314521 A zqk S 44.06 200
34314521 R qqk 100
34314521 A ark S 44.05 100
34314523 A brk B 44.02 100
34314525 R brk 100
34314561 A crk B 44.02 100
34315109 R yqk 200
34315109 R ark 100
34315109 R zqk 200
34315110 A drk S 44.05 100
34315110 A erk S 44.05 200
34315110 R nqk 250
34315110 A frk S 44.05 250
34315110 R crk 100
34315203 A grk B 44.02 100
34315630 R lqk 100
34315634 A hrk B 43.97 100
34315850 R hrk 100
34315853 A irk B 43.97 100
34316093 R irk 100
34316096 A jrk B 43.97 100
34316138 R drk 100
34316138 R erk 200
34316139 A krk B 44.02 200
34316139 A lrk S 44.05 100
34316139 A mrk S 44.06 200
34316140 R frk 250
34316142 A nrk S 44.05 250
34316181 R nrk 250
34316184 A ork S 44.06 250
34316187 R krk 200
34316187 R lrk 100
34316188 R mrk 200
34316188 A prk S 44.05 100
34316188 A qrk S 44.06 200
34316189 R ork 250
34316190 A rrk S 44.05 250
34316191 R qrk 200
34316191 A srk S 44.05 200
34316301 R oqk 100
34316303 A trk S 44.04 100
34316337 R hqk 100
34316352 R uqk 250
34316354 A urk B 44.01 250
34316355 A vrk B 44.01 200
34316359 R pqk 100
34316359 A wrk B 44.01 100
34316360 R prk 100
34316361 A xrk S 44.04 100
34316362 R sqk 100
34316367 A yrk B 43.96 100
34316370 R urk 250
34316371 A zrk B 44.02 250
34316371 R trk 100
34316372 A ask S 44.04 100
34316372 R wrk 100
34316372 A bsk B 44.02 100
34316389 R yrk 100
34316391 R zrk 250
34316393 A csk B 44.01 250
34316401 A dsk S 44.11 100
34316401 R dnk 100
34316410 R csk 250
34316410 A esk B 44.02 250
34316411 R esk 250
34316414 A fsk B 44.01 250
34316419 R xrk 100
34316419 A gsk B 43.95 100
34316419 A hsk S 44.05 100
34316440 A isk B 43.95 100
34316441 R gsk 100
34316453 R jrk 100
34316456 A jsk B 43.97 100
34316458 R jsk 100
34316461 A ksk B 43.97 100
34316710 R ksk 100
34316713 A lsk B 43.97 100
34316772 R lsk 100
34316775 A msk B 43.97 100
34316777 R tpk 48
34316777 A nsk B 44.02 100
34316778 R bsk 100
34316778 A osk B 44.02 100
34316792 R fsk 250
34316792 R msk 100
34316796 A psk B 43.96 100
34316797 A qsk B 44.00 250
34316819 R grk 100
34316819 R wlk 152
34317270 R psk 100
34317273 A rsk B 43.96 100
34317311 R rrk 250
34317312 A ssk S 44.05 250
34317461 A tsk B 43.95 100
34317462 R isk 100
34317511 R rsk 100
34317514 A usk B 43.96 100
34317579 R tsk 100
34317609 A vsk B 43.95 100
34317651 R usk 100
34317654 A wsk B 43.96 100
34317809 R wlk 600
34317810 R nsk 100
34317810 R hsk 100
34317811 A xsk B 44.01 100
34317811 A ysk S 44.04 100
34317848 R vsk 100
34317878 A zsk B 43.95 100
34317895 R wsk 100
34317899 A atk B 43.96 100
34317931 A btk B 43.95 100
34317931 R zsk 100
34318001 R atk 100
34318004 A ctk B 43.96 100
34318046 R qsk 250
34318047 A dtk B 44.01 250
34318102 R ssk 250
34318105 A etk S 44.05 250
34318230 R dtk 250
34318232 R wlk 48
34318232 R mok 52
34318232 A ftk B 44.00 250
34318233 R ysk 100
34318234 A gtk S 44.04 100
34318234 R vrk 200
34318235 R ask 100
34318235 A htk S 44.04 100
34318235 A itk B 44.01 200
34318236 A jtk B 44.00 100
34318260 R btk 100
34318284 R ctk 100
34318287 A ktk B 43.96 100
34318290 A ltk B 43.95 100
34318297 R gtk 100
34318298 A mtk S 44.05 100
34318298 R htk 100
34318299 A ntk S 44.05 100
34318330 R dsk 100
34318332 A otk B 43.95 100
34318332 R ltk 100
34318361 A ptk S 44.11 100
34318363 A qtk B 43.95 100
34318363 R otk 100
34318380 R ktk 100
34318383 A rtk B 43.96 100
34318385 R rtk 100
34318388 A stk B 43.96 100
34318661 A ttk S 44.11 100
34318661 R ptk 100
34318666 A utk B 43.69 400
34318671 R jtk 100
34318679 R ttk 100
34318709 A vtk S 44.11 100
34318762 R ftk 250
34318762 A wtk B 44.01 250
34318763 R itk 200
34318763 A xtk B 44.01 200
34319197 A ytk B 43.88 100
34319433 R stk 100
34319436 A ztk B 43.96 100
34319550 R ztk 100
34319553 A auk B 43.97 100
34319964 A buk B 43.27 300
34319969 A cuk S 44.80 200
34320330 A duk S 44.37 400
34320718 R ytk 100
34321438 A euk B 43.95 100
34321439 R qtk 100
34321469 A fuk B 43.95 100
34321469 R euk 100
34321514 R ckk 100
34321530 R auk 100
34321533 A guk B 43.97 100
34321609 R mok 48
34322014 A huk B 44.03 100
34322015 R xsk 100
34322015 R srk 200
34322015 A iuk B 44.02 100
34322015 A juk S 44.06 200
34322016 R osk 100
34322016 A kuk B 44.02 100
34322068 R wtk 250
34322068 A luk B 44.02 250
34322069 R juk 200
34322070 A muk S 44.05 200
34322419 R iuk 100
34322420 A nuk B 44.02 100
34322579 R huk 100
34322580 R nuk 100
34322580 R luk 250
34322580 A ouk B 44.01 100
34322582 A puk B 44.01 250
34322588 R xtk 200
34322588 R kuk 100
34322588 A quk B 43.96 200
34322588 R muk 200
34322589 A ruk B 44.01 100
34322589 A suk S 44.05 200
34322590 R mtk 100
34322590 A tuk S 44.04 100
34322591 A uuk B 44.03 100
34322591 A vuk B 44.02 100
34322591 R ntk 100
34322591 A wuk S 44.04 100
34322591 A xuk B 44.00 100
34322591 R ouk 100
34322592 R suk 200
34322592 A yuk B 44.01 100
34322592 R ruk 100
34322592 A zuk B 44.02 100
34322592 A avk B 44.01 200
34322592 R quk 200
34322592 A bvk S 44.05 200
34322595 R vuk 100
34322599 R etk 250
34322599 R avk 200
34322599 A cvk S 44.05 250
34322600 R cvk 250
34322601 R xuk 100
34322602 A dvk S 44.05 250
34322608 A evk B 44.01 200
34322609 R fuk 100
34322619 A fvk S 44.11 100
34322619 R vtk 100
34322629 A gvk S 44.04 100
34322631 R uuk 100
34322638 R evk 200
34322638 A hvk B 44.01 200
34322639 A ivk B 43.95 100
34322640 R fvk 100
34322642 R hvk 200
34322643 A jvk B 44.01 200
34322648 A kvk B 43.95 100
34322649 R ivk 100
34322650 R dvk 250
34322650 R jvk 200
34322650 A lvk S 44.05 250
34322651 A mvk B 44.01 200
34322651 R lvk 250
34322652 R mvk 200
34322652 A nvk B 44.01 200
34322653 A ovk S 44.05 250
34322654 A pvk B 44.00 100
34322655 R pvk 100
34322655 A qvk B 44.00 100
34322668 R gvk 100
34322678 A rvk S 44.11 100
34322678 R kvk 100
34322679 R rvk 100
34322692 R guk 100
34322696 A svk B 43.97 100
34322708 A tvk B 43.95 100
34322709 A uvk B 44.03 100
34322710 A vvk S 44.11 100
34322727 R qvk 100
34322752 A wvk S 44.04 100
34322776 A xvk B 44.03 180
34322777 R yuk 100
34322778 A yvk B 44.02 100
34322779 R zuk 100
34322779 A zvk B 44.02 100
34322979 A awk S 44.06 100
34323448 R tuk 100
34323449 A bwk S 44.05 100
34323449 R puk 250
34323449 A cwk B 44.02 250
34323481 A dwk B 43.95 100
34323481 R tvk 100
34323500 R uvk 100
34323502 R wvk 100
34323503 A ewk B 44.00 100
34323512 A fwk B 43.95 100
34323512 R dwk 100
34323580 R svk 100
34323583 A gwk B 43.97 100
34323610 R ul 200
34323740 A hwk B 43.57 200
34323767 A iwk S 44.04 100
34323870 R cwk 250
34323871 R yvk 100
34323871 A jwk B 44.01 100
34323872 A kwk B 44.01 250
34323886 A lwk B 44.03 100
34323900 R fwk 100
34323909 A mwk S 44.11 100
34323909 R vvk 100
34323919 A nwk S 44.04 100
34323921 R iwk 100
34323923 R lwk 100
34323928 R mwk 100
34323930 A owk B 43.95 100
34323932 R nwk 100
34323938 A pwk B 43.95 100
34323938 R owk 100
34323940 R gwk 100
34323943 A qwk B 43.97 100
34323959 A rwk S 44.11 100
34324021 R qwk 100
34324024 A swk B 43.97 100
34324389 R kwk 250
34324389 A twk B 44.02 250
34324439 R twk 250
34324441 A uwk B 44.01 250
34324540 R ewk 100
34324554 A vwk B 44.03 100
34324568 R pwk 100
34324579 A wwk S 44.11 100
34324580 R rwk 100
34324598 A xwk B 43.95 100
34324628 R wwk 100
34324635 R swk 100
34324638 A ywk B 43.95 100
34324638 R xwk 100
34324638 A zwk B 43.97 100
34324658 A axk S 44.11 100
34325190 R ovk 250
34325191 A bxk S 44.05 250
34325469 R uwk 250
34325469 A cxk B 44.02 250
34325470 A dxk B 44.02 100
34325470 R jwk 100
34326299 R bxk 250
34326301 A exk S 44.05 250
34327083 A fxk B 44.00 500
34327105 A gxk B 44.00 300
34327123 A hxk B 44.04 100
34327124 R wuk 100
34327124 R zvk 100
34327124 R bvk 200
34327124 R dxk 100
34327124 A ixk S 44.05 100
34327125 A jxk B 44.03 100
34327125 A kxk B 44.02 100
34327125 A lxk S 44.06 200
34327173 R hxk 100
34327174 R kxk 100
34327174 R jxk 100
34327174 R ixk 100
34327174 A mxk B 44.02 100
34327175 A nxk B 44.02 100
34327175 A oxk S 44.05 100
34327175 R lxk 200
34327176 A pxk S 44.05 200
34327180 R pxk 200
34327185 R vwk 100
34327189 A qxk S 44.05 200
34327189 A rxk B 43.95 100
34327190 R ywk 100
34327199 R bwk 100
34327199 R mxk 100
34327199 A sxk B 44.02 100
34327199 A txk S 44.04 100
34327200 R nxk 100
34327200 A uxk B 44.02 100
34327201 R txk 100
34327201 R sxk 100
34327201 A vxk B 44.02 100
34327201 A wxk S 44.05 100
34327208 R qxk 200
34327208 A xxk B 44.00 100
34327209 R xxk 100
34327220 A yxk B 43.96 100
34327221 R rxk 100
34327231 R yxk 100
34327231 R zwk 100
34327234 A zxk B 43.97 100
34327235 R zxk 100
34327238 A ayk B 43.97 100
34327278 A byk B 43.96 100
34327328 R ayk 100
34327332 A cyk B 43.97 100
34327468 A dyk S 44.05 200
34328059 R uxk 100
34328059 R wxk 100
34328059 A eyk B 44.02 100
34328059 R exk 250
34328059 A fyk S 44.05 250
34328060 A gyk S 44.04 100
34328061 R oxk 100
34328061 A hyk S 44.04 100
34328086 R uok 100
34328091 A iyk S 44.11 100
34328091 R axk 100
34328101 R eyk 100
34328101 R gyk 100
34328101 A jyk B 44.02 100
34328101 R vxk 100
34328102 A kyk B 44.01 100
34328102 A lyk S 44.04 100
34328103 R kyk 100
34328103 A myk B 44.02 100
34328103 R lyk 100
34328104 R hyk 100
34328104 A nyk S 44.04 100
34328104 A oyk S 44.04 100
34328105 R ymk 200
34328105 A pyk B 44.00 100
34328120 R cxk 250
34328122 A qyk B 44.01 250
34328132 R byk 100
34328138 A ryk S 44.06 200
34328152 R qyk 250
34328153 A syk B 44.02 250
34328162 A tyk B 43.95 100
34328199 R syk 250
34328201 A uyk B 44.01 250
34328204 R cyk 100
34328207 A vyk B 43.97 100
34328424 R uyk 250
34328425 A wyk B 44.02 250
34328460 R myk 100
34328460 R nvk 200
34328460 R jyk 100
34328460 A xyk B 44.01 100
34328460 R nyk 100
34328460 A yyk S 44.04 200
34328460 R dyk 200
34328460 A zyk S 44.04 100
34328461 A azk B 44.00 200
34328461 A bzk B 44.02 100
34328461 R fyk 250
34328461 A czk S 44.04 250
34328462 R oyk 100
34328462 A dzk S 44.04 100
34328470 R xyk 100
34328470 R wyk 250
34328470 A ezk B 44.01 100
34328471 R zyk 100
34328471 A fzk S 44.04 100
34328472 R pyk 100
34328472 A gzk B 44.01 250
34328472 R ryk 200
34328473 R ezk 100
34328473 R dzk 100
34328473 A hzk B 44.01 100
34328474 A izk S 44.04 100
34328490 A jzk S 44.10 100
34328490 R xvk 80
34328490 R iyk 100
34328491 R fzk 100
34328491 A kzk S 44.04 100
34328492 A lzk S 44.05 200
34328500 R tyk 100
34328541 R vyk 100
34328544 A mzk B 43.95 100
34328544 A nzk B 43.97 100
34328559 R nzk 100
34328563 A ozk B 43.97 100
34328574 R ozk 100
34328591 R hzk 100
34328591 R gzk 250
34328591 R izk 100
34328591 R yyk 200
34328591 A pzk B 44.01 100
34328591 R czk 250
34328591 R kzk 100
34328591 A qzk S 44.04 100
34328592 A rzk S 44.05 200
34328592 A szk S 44.04 100
34328592 R bzk 100
34328592 R pzk 100
34328592 A tzk B 44.03 100
34328593 A uzk S 44.05 200
34328593 A vzk B 44.02 100
34328593 R qzk 100
34328593 A wzk S 44.04 100
34328594 R tzk 100
34328594 A xzk B 44.00 250
34328594 A yzk B 44.01 100
34328594 R lzk 200
34328594 R szk 100
34328594 R wzk 100
34328594 R uzk 200
34328594 A zzk S 44.05 250
34328594 A aal S 44.04 100
34328594 A bal S 44.05 100
34328595 R vzk 100
34328595 A cal S 44.05 100
34328595 R yzk 100
34328595 A dal B 44.01 100
34328595 A eal B 44.02 100
34328595 R rzk 200
34328596 A fal S 44.04 200
34328598 R fal 200
34328598 A gal S 44.07 200
34328620 R jzk 100
34328620 R mzk 100
34328627 R aal 100
34328632 A hal B 44.03 100
34328641 A ial S 44.04 100
34328642 R cal 100
34328642 R bal 100
34328642 A jal S 44.04 100
34328642 A kal S 44.04 100
34328644 R awk 100
34328650 A lal S 44.11 100
34328650 A mal B 43.95 100
34328652 R xvk 100
34328656 R ial 100
34328670 A nal S 44.04 100
34328671 R kal 100
34328671 A oal S 44.04 100
34328730 R hal 100
34328731 R gal 200
34328731 R jal 100
34328731 A pal S 44.04 200
34328732 A qal S 44.04 100
34328735 A ral B 44.03 100
34328736 R qal 100
34328736 R oal 100
34328736 R pal 200
34328737 A sal S 44.04 100
34328737 A tal S 44.04 100
34328737 A ual S 44.07 200
34328738 A val B 44.02 100
34328745 A wal B 43.97 100
34328824 A xal B 44.03 100
34328825 R sal 100
34328825 A yal S 44.04 100
34328826 R val 100
34328858 R xal 100
34329007 R ral 100
34329008 R ual 200
34329008 R yal 100
34329008 A zal S 44.04 200
34329008 A abl S 44.04 100
34329028 R abl 100
34329028 R eal 100
34329029 A bbl B 44.01 100
34329029 A cbl S 44.04 100
34329030 R dal 100
34329030 R tal 100
34329030 A dbl B 44.01 100
34329030 A ebl S 44.04 100
34329031 R bbl 100
34329031 R cbl 100
34329031 A fbl B 44.01 100
34329032 A gbl S 44.04 100
34329032 R ebl 100
34329033 A hbl S 44.03 100
34329053 A ibl B 43.99 100
34329058 R mal 100
34329069 A jbl S 44.10 100
34329070 R lal 100
34329079 R xzk 250
34329079 R jbl 100
34329080 R ibl 100
34329081 A kbl B 44.00 250
34329089 A lbl B 43.94 100
34329108 R lbl 100
34329119 A mbl S 44.10 100
34329131 R azk 200
34329131 A nbl B 44.00 200
34329137 A obl B 43.94 100
34329139 A pbl B 44.01 100
34329140 R nbl 200
34329140 R fbl 100
34329140 A qbl B 44.00 200
34329140 A rbl B 44.01 100
34329141 R rbl 100
34329141 A sbl B 44.01 100
34329142 R qbl 200
34329142 R dbl 100
34329142 A tbl B 44.01 100
34329143 A ubl B 44.00 200
34329150 R ubl 200
34329151 A vbl B 44.00 200
34329151 R sbl 100
34329151 A wbl B 44.01 100
34329152 R vbl 200
34329152 R wbl 100
34329153 A xbl B 44.01 100
34329153 A ybl B 44.00 200
34329154 R tbl 100
34329154 A zbl B 44.01 100
34329155 R xbl 100
34329155 A acl B 44.01 100
34329158 R acl 100
34329158 R ybl 200
34329158 A bcl B 44.00 200
34329159 A ccl B 44.01 100
34329160 R mbl 100
34329169 R gbl 100
34329169 A dcl S 44.04 100
34329181 R pbl 100
34329189 R wal 100
34329189 R obl 100
34329191 A ecl S 44.10 100
34329192 A fcl B 43.97 100
34329193 R fcl 100
34329196 A gcl B 43.95 100
34329197 R gcl 100
34329200 A hcl B 43.95 100
34329217 R kbl 250
34329218 A icl B 44.00 250
34329219 A jcl B 43.94 100
34329286 R icl 250
34329288 A kcl B 44.00 250
34329327 R kcl 250
34329328 A lcl B 44.00 250
34329350 R hcl 100
34329353 A mcl B 43.95 100
34329413 R hbl 100
34329413 A ncl B 44.04 550
34329414 R zal 200
34329414 R dcl 100
34329414 A ocl S 44.07 100
34329414 A pcl S 44.07 200
34329414 A qcl S 44.07 100
34329415 R zbl 100
34329415 A rcl B 44.01 100
34329415 R ncl 121
34329415 R qcl 100
34329416 R ccl 100
34329416 A scl B 44.02 100
34329417 R ncl 308
34329418 R rcl 100
34329418 A tcl B 44.02 100
34329419 R ocl 100
34329419 A ucl S 44.04 100
34329420 R scl 100
34329420 A vcl B 44.02 100
34329420 R tcl 100
34329421 A wcl B 44.01 100
34329439 R nal 100
34329442 R ecl 100
34329443 A xcl B 43.94 100
34329443 R jcl 100
34329445 R ncl 121
34329471 R zzk 250
34329472 A ycl S 44.11 100
34329473 A zcl S 44.05 250
34329474 A adl B 43.95 100
34329474 R xcl 100
34329491 R zcl 250
34329492 A bdl S 44.05 250
34329498 R mcl 100
34329499 A cdl B 44.02 100
34329502 A ddl B 43.95 100
34329502 A edl S 44.04 100
34329503 R ddl 100
34329507 A fdl B 43.96 100
34329523 A gdl S 44.11 100
34329523 R ycl 100
34329523 A hdl B 43.95 100
34329524 R adl 100
34329539 R edl 100
34329551 R cdl 100
34329562 R fdl 100
34329565 A idl B 43.96 100
34329569 R gdl 100
34329572 A jdl B 43.95 100
34329572 R hdl 100
34329599 A kdl S 44.11 100
34329603 A ldl B 43.95 100
34329603 R jdl 100
34329604 R idl 100
34329607 A mdl B 43.96 100
34329620 R bdl 250
34329623 A ndl S 44.05 250
34329631 A odl B 44.02 100
34329631 A pdl B 44.02 100
34329632 R vcl 100
34329632 R pcl 200
34329632 A qdl B 44.02 100
34329632 A rdl S 44.05 200
34329633 A sdl B 43.95 100
34329634 R ldl 100
34329641 R mdl 100
34329644 A tdl B 43.96 100
34329645 R tdl 100
34329648 A udl B 43.96 100
34329650 R lcl 250
34329650 R ndl 250
34329650 A vdl B 44.01 250
